Workbook

Sheet 新系统下单指引以及新发票箱单
AQ32: 【注意】我司将于2024年1月1日正式上线全新的物流系统，1月1日之后的新订单需要在新系统下单，过渡期间原morelink系统还可正常使用，新系统下单指引图已插入报价表中，详情请查看报价表，如您在新系统使用过程中，有任何疑问或者建议，可在群里随时与我们联系，感谢您的支持。 新系统登录链接：登录原morelink系统，点击【下单】后会自动跳转到鲲运系统下单界面；新系统账号密码：与原morelink系统的账号密码一致，建议您后续自行修改。（表格同时已添加最新发票箱单，可自行下载。）

Sheet 首页目录
B1: 东莞劲港跨境物流有限公司
B2: 网址：www.link trans.com 电话：400-150-5156 客诉邮箱：voc@link-trans.com
B3: 公司优势：亚马逊跨境承运伙伴SEND · Ship Track · TSPN · SPN 国内16+收货网点、海外80万尺的海外仓、24小时亚马逊预约团队、自有清关行、 15+拖车、30+卡车、 自研可视化系统 安全稳定高效
B4: 生效日期：2026-07-01
B5: 产品名称 | C5: 产品简介 | D5: 参考时效 | E5: 报价链接 | F5: 主要动态
B6: 快递派渠道 | C6: 海派渠道,美森、ZIM、OA船司 Z快线-美西-快递派，15天提取 | D6: 15-30个自然日 | E6: 进入报价 | F6: 下调RMB 0.5/KG。
B7: Z快线-美西 | C7: 全链路把控，华南第一快线产品 13天航程，独家PP服务，免预约提柜，Local仓当周提拆派 | D7: 18-30个自然日 | E7: 进入报价 | F7: 下调RMB 0.5/KG，100/CBM左右。
B8: Z快线-US监管仓 | C8: 全链路把控，华南第一快线产品 13天航程，独家PP服务，免预约提柜，Local仓当周提拆派 | D8: 18-30个自然日 | E8: 进入报价 | F8: 下调RMB 0.5/KG，100/CBM左右。
B9: 特惠舱位-美西 | C9: OA船司时效保障，华南华东华北仓收货 | D9: 20--31个自然日 | E9: 进入报价 | F9: 下调RMB 0.5/KG，100/CBM左右。
B10: 特惠舱位-美西-US监管仓 | C10: OA船司时效保障，华南华东华北仓收货 | D10: 20--31个自然日 | E10: 进入报价 | F10: 下调RMB 0.5/KG，100/CBM左右。
B11: 特惠舱位-美东 | C11: OA船司时效保障，华南华东华北仓收货 | D11: 40--45个自然日 | E11: 进入报价 | F11: 下调RMB 0.5/KG，100/CBM左右。
B12: 普船系列--美西 | C12: 普船经济线，普船船司统配，覆盖范围广 | D12: 28--38个自然日 | E12: 进入报价 | F12: 下调RMB 0.5/KG，100/CBM左右。
B13: 普船系列--美中 | C13: 普船经济线，普船船司统配，覆盖范围广 | D13: 33--48个自然日 | E13: 进入报价 | F13: 达拉斯专线：价格不变。 休斯敦专线、美中接力派：下调RMB 0.5/KG，100/CBM左右。
B14: 普船系列--美东 | C14: 普船经济线，普船船司统配，覆盖范围广 | D14: 48--55个自然日 | E14: 进入报价 | F14: 下调RMB 0.5/KG，100/CBM左右。
B15: 华东限时23 | C15: 华东起运，13天航程，23天时效付费，PP服务免预约提柜 | D15: 23个自然日 | E15: 进入报价 | F15: 下调RMB 0.5/KG，100/CBM左右。
B16: 华东限时23-US监管仓 | C16: 华东起运，13天航程，23天时效付费，PP服务免预约提柜 | D16: 23个自然日 | E16: 进入报价 | F16: 下调RMB 0.5/KG，100/CBM左右。
... B23: 限时达 | C23: 美森正班卡派，时效王者，又快又稳 | D23: 15--25个自然日 | E23: 进入报价 | F23: 下调RMB 0.5/KG，100/CBM左右。
B24: 特别 申明 | C24: 发货前请您详细了解我司各产品具体说明，注意事项，赔偿标标，时效等相关说明，您在我司下单预报成功后，表示您同意我司走货各项要求，接受我司各项条款约束，如您发货违反国家相关法律、或出口货物管制要求，或我司产品走货限制，导致货物被国家行政机关查扣及以此带来法律后果，我司不承担相关损失和责任，同时我司有权追究相关法律责任，请详细查阅各项说明，谢谢您的理解和支持！(我司保留对各产品最终解释权)
B25: 东莞总部地址：广东省东莞市南城区南城街道白马黄金一路3号联宇集团 深圳办公地址：广东省深圳市龙岗区坂田街道吉华路489号乐荟科创中心12栋8层E室
B26: 微信公众号：

Sheet 注意事项
B2: 东莞劲港跨境物流有限公司
B3: 注意事项
B4: 1、包装要求：只接方正/硬朗纸箱，拒接其他包装,每件外箱必须贴有2个以上FBA标签（条形码字体清晰，防潮湿耐磨）,外箱和产品贴有“MADE IN CHINA”标签。如因包装及标签问题导致亚马逊仓库拒收或清关出现问题，所有责任及费用由发货人承担。
B5: 2、资料要求：按要求提供货物的真实信息，提供准确的美国的海关编码，如不能提供准确的美国的海关编码,我司清关行会根据实际品名,材质和用途申报，最终产生的关税以海关提供的税金单为准，不得争议。实际货物必须如实申报，货物信息要与发票资料一致，不可瞒报漏报（例如：有牌子申报无牌）和申报不符，如因申报不符导致海关扣货等后果及产生的所有费用由发货人承担，并且罚款RMB5000/票.
B6: 3、禁止运输的货物：液体，纯电池，食品，粉末，医疗用品，仿牌商品，化工产品，儿童玩具用品及美国反倾销产品等。如发现冲货罚款RMB5000/票。不接纯电池，内置电池请提供图片及MSDS,海运运输鉴定报告单独确认。
B7: 4、所有刀具制品：出口需要客户自行提前备好公安局备案文件再发货，如果不属于管制刀具，公安局也会出具不予备案的说明文件。 否则如果查验导致送检或上处置科，将对此收取RMB5000罚款，此费用不包括产生的额外仓租和柜租等费用，且此费用不接受减免。
B8: 5、如美国海关认定货物涉及品牌侵权或蓝牙、HDMI、FCC、UL、FDA,DOT，EPA等认证问题，客户需按要求提供相关认证和品牌授权书等文件，如因无法提供或者提供的文件得不到美国海关及相关部门的认可而导致扣货或者退运，所有责任和费用由该发货人承担。
B9: 6.关税豁免的产品：出货前提供详细的产品说明（图片，用途参数，销售链接或其他有用产品信息）审核货物是否符合豁免关税资格，最终以海关审核结果为准
B10: 7、装柜后如需扣货或更改派送计划，要求最迟在货物到港前5天向我司提出才可操作，扣货和更改派送计划将收取操作费RMB 600/票，由于扣货/更改派送计划所产生的所有费用由客户承担，具体费用请单独咨询。扣货或更改派送方式有风险，我司不承担任何责任且不保证扣货成功或更改派送方式成功。
B11: 8、CPSC,FDA提柜后仍未审核放行，货物需要的扣货在仓等通知放行，期间产生的费用需由发货方承担（基础费用：扣货费，拆柜费，仓储费，以及产生的其他费用）
B12: 9、以下情况，我司会协助处理，不承担任何责任 A.产品如需要FCC,CE,FDA,TSCA,DOT，CPSC,CPC，EPA等认证而客户无法提供有效证明及文件，导致海关扣货等后果 B.产品不符合美国当地法规的，如反倾销，侵权且无法提供有效证及及文件，导致海关扣货等后果 如因以上情况而产生的退运，销毁，仓租等一切费用，由发货方自行承担
B13: 10、因美国本地费用变化频繁且即时生效，我司保留即时更改价格的权利（包括在途中的货物）
... B16: 13、出口报关：深圳各海关继续严查，严厉打击虚假贸易，严打虚报，高报，乱报错报。 海关近期将针对上述虚假贸易行为，进行整顿，具体的形式为： A:审核单票货物的每项品名的单价和总价，如果申报的单价，以及总价超过实际货物的正常价格范围，此票货物将被查验，如果发现高报价格属实，第一、二次经营单位被记过，第三次将直接移送缉私处理。 B:单票报关总金额超过10万美金的，将进入人工审核环节，不在进行计算机快速审核通道。 C:对于单票价格过高的单子，如果申报属实的，海关将要求经营单位提供此票货物相对应的增值税发票或银行往来货款证明。 对于打击虚假贸易，总署要求统一，但是各个海关对于高报价格的金额不相同，深圳海关审核要求5万美金，对于前期已经放行的有上述情况的货物，海关统计科将进行2次核查，如果核查结果有高报价格情况，也要做相对应的处理！ 验发票要提供营业执照复印件盖公章，增值税发票原件，出口专用发票原件，增值税发票复印件盖公章，外贸合同，银行的收款水单，货物图片盖公章最好是彩色的，税务登记证也要提供（备注：上述5万美金说的是一个柜子申报超过5万美金就要提供发票和其他相关资料，不是单票申报超过5万美金才提供发票，所以通常一旦出货需要退税的就要准备发票及相关资料，以备海关验票使用）

Sheet 赔偿标准和免赔声明
B2: 东莞劲港跨境物流有限公司
B3: 赔偿标准和免赔声明
B4: 一、时效赔付界定：以不同渠道时效说明为准
B5: 二、时效免赔说明
B6: 1、船公司船期/航线变更/延迟到港，自然灾害、天气原因，如台风、地震、洪水、冰雹,，暴风雪，雾；政府行为，社会异常事件包括战争，罢工等
B7: 2、海关查验
B8: 3、亚马逊拒收或者亚马逊更改预约时间
B9: 4、亚马逊爆仓及预约困难
B10: 5、客户FBA ID & 内部编码失误等相关原因
B11: 6、客户要求扣货后派送或者因客户自身原因导致的延误
B12: 7、由于船公司卸船效率慢，预约困难，拒收等不可抗力导致的延迟交仓,不在赔偿范围,此项如与具体渠道的时效赔付标准有区分，则与具体渠道的标准为准
B13: 8、特殊时期导致的进出口报关/清关延误，提柜，还柜延误等
... B33: 2、快递派索赔程序： ①未提取的，在打单日起算最早第30个自然日向我司客服人员发起开查申请（整票未提取或者单票超10箱未提取，需要提供快递开查记录）。最晚发起时间应当在打单日(含打单当天)起第60个自然日内发起索赔需求,逾期我司将不再接受理赔申请。 ②已提取未签收的以快递开查结果为准，不在我司索赔责任范围内； 注：若逾期未提供完整相应索赔资料，则相应责任由客户自行承担，我司不再接受理赔申请。

Sheet 产品发货需知
A2: 东莞劲港跨境物流有限公司
A3: 后段派送方式 | B3: 下单渠道 | C3: 附加费 | D3: 查验费 | E3: 单证报关费 | F3: 空仓费 | G3: 最低消费 | H3: 重货优惠
A4: 卡派 | B4: 至尊达 | C4: 含税：税率＜50%：免收附加费 税率≥50%：+1 RMB/KG 不含税：关税实报实销 服装（包括手套、袜子、围巾、头巾、腰带、帽子等服饰配件）（+1.5RMB/KG起）单询； 鞋子+1 RMB/KG； 箱包袋类+1RMB/KG。 钢铝目录制品及汽车配件232目录制品 （50%及以上税率） +1RMB/KG。 软木制品、带软垫木制坐具 +1RMB/KG。 FDA正本申报附加费：+0.5/kg(含税），+75/cbm(不含税），最高RMB 1500。 非自有IOR和BOND清关的CPSC货物，收取操作费RMB 150/票/SO 商检费（单票收费）：+RMB 1/kg(含税），+RMB 200/cbm(不含税）。单票限制5000KG/30CBM内，单票低消RMB 200，单票封顶RMB 500。 超长附加费： 120CM ＜ X ≤ 150CM：不含税+ RMB100/CBM，含税+RMB 0.6/KG。 150CM ＜ X ≤ 200CM：不含税+RMB200/CBM，含税+RMB1.2/KG。 超过2米且在3米内请单询 | D4: 包 | E4: RMB 150/份单证资料 | F4: RMB 600/CBM 按实际体积计算收费 | G4: 单票计费重要求50KG以上 1CBM=363KG（不含税） 1CBM=167KG（含税） 最低消费：0.5CBM（不含税）/50KG(含税) 至尊达系列渠道最低100KG起收 商业地址： 1、单票最低消费：2CBM（不含税）/334KG(含税) 不足2CBM/334KG，按2CBM/334KG计费 2、可接收100KG/1CBM起收的Walmart/Tiktok目的仓详见以上价格单价详情。 | H4: 单个SO实际体积满0.7CBM以上 1:200货型：单价优惠RMB 0.5元/KG。 1:300货型：单价优惠RMB 1.2元/KG。 1:400货型：单价优惠RMB1.5/KG。 1:500货型：单价优惠RMB 2/KG。 满足条件： ①只针对走包税渠道 （大货中转头程渠道、至尊达同样适用。） ②自提渠道、快递派渠道、大货中转后段派送不适用。 ③不合并计算
B5: 美森限时达 | D5: 含税货物包
B6: Z快线-美东 | D6: 含税货物包
B7: 华东限时 18-美东 | D7: 含税货物包
B8: 华东限时 18-美西 | D8: 含税货物包 | F8: RMB 300/CBM 按实际体积计算收费
B9: 华东限时23 | D9: 含税货物包
B10: 华东限时23-US监管仓 | D10: 含税货物包
B11: 华东限时23-一体化 | D11: 含税货物包
B12: 特惠舱位-美西 | D12: 含税货物包
B13: 特惠舱位-美西-US监管仓 | D13: 含税货物包
B14: 特惠舱位-美东 | D14: 含税货物包
B15: Z快线-美西 | D15: 含税货物包
B16: Z快线-US监管仓 | D16: 含税货物包
B17: 普船时必达 | D17: 含税货物包
B18: 普船美西接力派 | D18: 含税货物包
B19: 普船美东接力派 | D19: 含税货物包
B20: 萨凡纳专线 | D20: 含税货物包
... B25: FBA大货中转头程 | D25: 含税货物包
B26: 美森快递派 | C26: 含税：税率＜50%：免收附加费 税率≥50%：+1 RMB/KG 不含税：关税实报实销 服装（包括手套、袜子、围巾、头巾、腰带、帽子等服饰配件）（+1.5RMB/KG起）单询； 鞋子+1 RMB/KG； 箱包袋类+1RMB/KG。 钢铝目录制品及汽车配件232目录制品 （50%及以上税率） +1RMB/KG。 软木制品、带软垫木制坐具 +1RMB/KG。 FDA正本申报附加费：+0.5/kg(含税），最高RMB 1500。 非自有IOR和BOND清关的CPSC货物，收取操作费RMB 150/票/SO 商检费（单票收费）：+RMB 1/kg(含税），+RMB 200/cbm(不含税）。单票限制5000KG内，单票低消RMB 200，单票封顶RMB 500。 美线私人住宅地址：+$3.65/包裹 | D26: 含税货物包 | E26: RMB 150/份单证资料 | F26: RMB 600/CBM 按实际体积计算收费 | G26: 单票货物计费重达到12KG才收 单件实量为12-22KG
B27: 华东限时 18-快递派 | D27: 含税货物包
B28: 特惠舱位-快递派 | D28: 含税货物包
B29: Z快线-美西-快递派 | D29: 含税货物包
B30: 1、货物体积重计算方式为长x 宽x高(CM)/6000，1CBM=167KG，体积重与实重取大计费。 单箱实重不足12kg 按照12kg收取。超尺寸货物：单箱实重不足18kg 按照18kg收取。（超尺寸货标准见附件"美国UPS&FEDEX 额外费用"第17点超尺寸/超大尺寸） 单件实量为12-22KG，单件实重超过22KG产生额外费用。 2、包裹基本超重超尺寸收费标准（见附件UPS&FEDEX 额外费用），不含燃油附加费 3、UPS/FEDEX派送时遇到FBA/收货人拒收、无法投递导致退件，货物可退回海外仓，退件过程中产生的费用，我司将向发件人收取，如有退回货物要求重发的货物，运费单询。不收派送到阿拉斯加,夏威夷,波多黎各,关岛,及各岛屿的货物。 4、同一批次的非亚马逊地址的货物，如其中一件已递送，则默认整批票已签收，不再接受理赔。
B31: 美国UPS&FEDEX 额外费用
A32: 如遇美国临时加征关税，我司将根据增涨的幅度进行相应补收。
A33: 特别提示:此价格表一经发送，如客户一旦交货至我司，我司默认客户已仔细阅读此价格表的所有内容并接受各条款。
A34: 一、注意事项
A35: 1、此上含查验费的部分渠道是指：含海关查验及查验引起的一切费用（含查验费指普通进口美国查验产生的费用，查验结果最后海关放行且不产生扣货/退运等结果的普通查验费。若查验原因是因为客户的产品及相关资料文件引起的海关查验、扣货、退运等结果产生的所有相关费用由发货方承担)，不含非我司原因导致的亚马逊拒收产生的一切相关费用，亚马逊爆仓引起的仓租/柜租，申报不符引起的海关惩罚金及额外费用等，请客户将这些官方收费也考虑到成本中，以免引起误会；如因报关资料问题引起的出口查验由客人承担所有相关费用（如仓租，柜租，改船费等）；以上不含查验费的部分渠道的查验费收费标准：海关查验费及因查验引起的费用不含税价格统一按68CBM/柜分摊，分摊后实报实销（以计费重为准），包税价格统一按RMB 0.5/KG收取。（查验基础费用：提柜进查验场的提柜费、托架费、查验费、柜租，以及产生的其他费用）。 客户原因造成的时效延误不在赔偿范围内；不可抗力因素造成的时效延误不在赔偿范围内，如：海关查验（现仅有至尊达渠道遇普通的目的港海关查验计入理赔时效）、船公司船期/航线变更/延迟到港、甩柜、自然灾害、如台风、地震、洪水、冰雹,，暴风雪、政府行为；社会异常事件、如罢工、骚乱三方面、疫情原因、码头不放约、亚马逊仓库预约困难或亚马逊跳约、删约、拒收等。(遇国外法定节假日不计入理赔时效)
A36: 2、空仓费产生情况：过了截单时间做的行为；更改渠道、客户原因延船期等；货物在截货时间前未到我司国内仓库
A37: 3、材质是原木或带有原木的货物要求熏蒸。
A38: 4、需要商检的货物：木家私，木制工艺品，木架，竹制品，藤制品，草制品，植物制品，户外游乐设施等（仅供参考）
A39: 5、品名限制：每票货限5个品名，超出5个加收RMB30/个。（至尊达渠道：每票货限3个品名，超出不收；一类医疗用品，激光类，眼镜类产品不收）
A40: 6、由于塞港、罢工、码头原因导致提柜/还柜所产生的相关费用将实报实销（如柜租、拖架、拥堵、预提、堆存费等费用）
A41: 7、若货物是在国内打卡板出货，海运费价格需要单询。若是非纸箱包装出货（如木架、木箱、木框等），海运费价格需要单询。
A42: 8、后段派送至私人住宅地址、商业地址，需要带尾板车派送所产生的尾板费用 实报实销。
A43: 9、发往亚马逊托拍AWD仓库（如IUSW、IUTE仓等），建仓标准应当符合亚马逊派送限制条件，我司对产生的入库配置费概不负责。亚马逊标准：散货单个PO，SKU需要≤10个，总箱数≥50件；卡板拆派模式，单个卡板单个SKU，尺寸在40*48*60Inch内，不能混SKU。
... A48: 14、客户自有BOND清关的订单，只能走【监管仓】渠道，非监管仓渠道拒接客户自有BOND清关的订单。

Sheet 国内仓库地址及增值服务费用
A2: 东莞劲港跨境物流有限公司
A3: 分拨中心增值价格表
A4: 类型 | B4: 收费项目 | C4: 参考信息 | D4: 价格 | E4: 低消金额 | F4: 备注
A5: 入仓费 | B5: / | C5: 广州/中山/汕头/塘厦：RMB30/票 金华/苏州/宁波/杭州/温州/义乌/厦门/福州/泉州/郑州/长沙/青岛：RMB15/CBM（最低消费1CBM) 上海：RMB15/CBM+停车费现场结算（最低消费1CBM) 货交所有国内仓库：下单走含税货物免收入仓费，下单走不含税货物按照以上标准收费。 同一票货若分多个仓库送货，入仓费按照当地国内仓库的收费标准计费（最低消费1CBM)
A6: 超时费用 | B6: 加班费 | C6: 提前报备，超过运营时间一小时内不收加班费： | D6: 0元/cbm | E6: 0 | F6: 按照当地分点的运营时间计费。 （不报备车辆正常收取加班费）
B7: 加班费 | C7: 提前报备，超过运营时间一小时之后收加班费； | D7: 10元/cbm | E7: 100元/车
B8: 加班费 | C8: 超过运营时间三小时之后到仓延至次日卸货，特殊情况提前跟区域负责人沟通
A9: 贴标费用 | B9: 贴唛头/FBA | C9: 未贴唛头、FBA标签入仓货物 | D9: 0.5元/张 | E9: 20元/票 | F9: 客户提供标签由我司代贴，按照0.5元/张收取，我司提供标签给客户，按照0.1元/张收取。
B10: 覆盖唛头/FBA | C10: 唛头不符标准和标签错误（无需对应要求覆盖） | D10: 1元/张 | E10: 20元/票 | F10: 唛头规格不得小于10CM*10CM。
B11: 贴SKU/玩具追踪标 | C11: 未贴追踪标、SKU的货物 | D11: 0.5元/张 | E11: 20元/票 | F11: 纸张大小7CM*5CM。客户提供标签由我司代贴同样收取0.4元/张），我司提供标签给客户/司机或业务自贴按照0.1元/张收取。
B12: 贴中国制造 | C12: 未贴MADE IN CHINA等有关标签货物 | D12: 0.5元/张 | E12: 20元/票 | F12: 客户提供标签由我司代贴同样收取0.5元/张），我司提供标签给客户/司机或业务自贴按照0.2元/张收取。
B13: 覆盖SKU/玩具追踪标 | C13: 产品标签不符和标签错误 | D13: 0.5元/张 | E13: 20元/票 | F13: 如有不能覆盖的信息请通知仓库。
B14: 贴电池标 | C14: 货物带电需要电池标的货物 | D14: 0.5元/张 | E14: 20元/票 | F14: 只提供3481/3091的电池标。
B15: 处理FBA标签 | C15: 处理加拿大线的FBA标签客户/公司名称和收货人名称 | D15: 1元/张 | E15: 20元/票 | F15: 此费用为加拿大线特殊费用。
B16: 外箱标签 | C16: 客户要求粘贴外箱的标签 | D16: 0.5元/张 | E16: 20元/票 | F16: 标签是规格不得小于10CM*10CM，请提供好模板给仓库。
A17: 仓租费用 | B17: 仓储费 | C17: 存放一个星期（含7天）免费 | D17: 无 | E17: 无 | F17: 货物入仓时间开始计算
B18: 仓储费 | C18: 超7天 | D18: 4元/CBM/天 | E18: 20元/票 | F18: 每月结算
A19: 货物区分费用 | B19: 挑货费 | C19: 从一票货挑出指定箱数 | D19: 1元/箱 | E19: 20元/票 | F19: 按一票总箱数计费
B20: 分货费 | C20: 货物送仓混装 | D20: 1元/箱 | E20: 20元/车 | F20: 按一车总箱数计费
A21: 外箱处理费用 | B21: 换箱 | C21: 需要换新的纸箱或纸箱损坏和错误 | D21: 20元/箱 | E21: 20元/票 | F21: (含纸箱、两张FBA标签、唛头) 只提供43*36*30/60*38*38/40*50*60三种尺寸的箱子
B22: 换箱(客户提供纸箱) | C22: 需要换新的纸箱或纸箱损坏和错误 | D22: 10元/箱 | E22: 20元/票 | F22: (含两张FBA标签、唛头) 如箱子过大，仓库不进行修改纸箱，防止亚马逊拒收。
B23: 割绑带/蛇皮袋/缠膜/割护角 | C23: 外箱有绑带/蛇皮袋/缠膜等需要处理的 | D23: 1元/箱 | E23: 20元/票 | F23: （不含贴唛头FBA）
B24: 撕带有黄色胶布箱子 | C24: 箱子有黄色胶布 | D24: 10 元/箱 | E24: 20元/票 | F24: (包含贴唛头+FBA),
B25: 拆卡板/卡板围膜 | C25: 打卡板进仓，需散货走的 | D25: 5元/板 | E25: 20元/票 | F25: （不含贴唛头FBA）
A26: 其他费用 | B26: 打出口板 | C26: 货物超尺寸或货物特殊 | D26: 150元/板 | E26: 150元/票 | F26: (含卡板，如需打板，请提前2-4天告知仓库）； 只提供1*1.2M三合木卡板。
B27: 打出口板(不含卡板） | C27: 货物超尺寸或货物特殊 | D27: 75元/板 | E27: 75元/票 | F27: (不含卡板，客户提供卡板） 亚马逊打卡板标准：120*100CM
B28: 入仓单 | C28: 司机没有带纸质入仓单 | D28: 1元/张 | E28: 1元/张 | F28: （入仓需带一式两份）
B29: 理货清点产品数量 | C29: 实际货物跟发票对不上，需仓库处理 | D29: 0.5元/个 | E29: 20元/票 | F29: （含清点数量+SKU拍照）
B30: 开箱拍照 | C30: 客户指定要求开箱拍照 | D30: 5元/张 | E30: 5元/张 | F30: （同时拍FBA+SKU+产品，可三种类型各独立一张）
B31: 货物拍照 | C31: 拍货物外箱或标签 | D31: 1元/张 | E31: 1元/张 | F31: 客户要求拍外箱情况和标签情况
B32: 撕标签 | C32: 货物退仓/改渠道等 | D32: 1元/箱 | E32: 20元/票 | F32: 非我司原因导致的退仓
B33: 退仓 | C33: 货物退仓 | D33: 15元/CBM/吨 | E33: 20元/票 | F33: 非我司原因导致的退仓
A34: 支持核爆品渠道货物免超时和项目低消费用。
A35: 国内仓库地址及工作时间
A36: 东莞塘厦分拨中心地址：东莞市塘厦镇西荣路96号盈仓1号仓（东莞分拨中心） 联系人：林先生 联系方式：13825713766 收货时间： 1） 周一到周日：9：00—21：00
A37: 广州白云分拨中心地址：广东省广州市白云区钟落潭镇良田工业区良园二横路27号一楼6、7号门 联系人：蔡先生 17666197966 收货时间： 1） 周一到周五：09：00-21：00 周六至周日：09：00-18：00
A38: 中山分拨中心地址：广东省中山市黄圃镇纵四线丰树中山现代物流园1栋盈仓4号仓 联系人：关先生 15323909927 收货时间： 1） 周一到周五：09：00-21：00 周六至周日：09：00-18：00
A39: 厦门分拨中心地址：福建省厦门市海沧区囷瑶路83号盈仓6号仓（园区进门右手边） 联系人：谢先生 热线电话：15359020440 收货时间： 1）周一到周五：09：00-20：00 周六：09：00-18：00，周日休息
A40: 福州分拨中心仓地址：福州市闽侯县荆溪镇石井路22号 联系人：张女士 热线电话： 18705013277 收货时间： 1）周一到周五：09：00-20：00 周六：09：00-18：00，周日休息
A41: 金华分拨中心地址：浙江省金华市金东区孝顺镇黄泥塘村兴盛街顺丰丰泰产业园2期（盈仓3号仓，金华分拨中心） 联系人：黄先生 18314916970 收货时间 ： 1）周一至周日 09：00-20：00
...

Sheet 第27周船期
A1: 如果截货时间是12点，截单时间是前一天的下午18点； 如果截货时间是下午18点，截单时间是当天的中午12点； 以上时间都不适用于美森。 美森截单时间是周五中午12点！！（注意：截单时间是以我司客服受理订单为准） | D1: 已经下单的订单:如有变动等问题，请在截单之前通知我司客服取消或延一水，超时通知需要收取空仓费用，美森渠道RMB 600/CBM 最低按1CBM收取，普船渠道RMB 300/CBM 最低按1CBM收取，请知悉（提早截单的情况下的订单，来不及送货需要变动，截单时间提前已过 ，会产生空舱费。）注意：下单后发票箱单以及报关资料需要在规定时间内给到，以免赶不上本周的船期
A2: 国家 | B2: 下单渠道 | C2: 船东 | D2: 目的地 | E2: 截单时间 | F2: 截文件 | G2: 华南 | O2: 华中 | S2: 华东 | AE2: 华北
G3: 塘厦 | H3: 凤岗 | I3: 中山 | J3: 广州 | K3: 汕头 | L3: 长沙 | M3: ETD | N3: ETA | O3: 福州/泉州仓 | P3: 厦门仓 | Q3: ETD | R3: ETA | S3: 郑州仓 | T3: 温州仓 | U3: 金华仓 | V3: 义乌集拼仓 | W3: 宁波仓 | X3: 杭州仓 | Y3: ETD | Z3: ETA | AA3: 苏州仓 | AB3: 上海仓 | AC3: ETD | AD3: ETA | AE3: 青岛仓 | AF3: ETD | AG3: ETA
G4: 截货时间 | O4: 截货时间 | S4: 截货时间 | AA4: 截货时间 | AE4: 截货时间
A5: 美国 | B5: 至尊达 | C5: MATSON-CLX | D5: LB | E5: 如果截货时间是12点，截单时间是前一天的下午18点； 如果截货时间是下午18点，截单时间是当天的中午12点； 以上时间都不适用于美森。 美森截单时间是周五中午12点！！ ONLY18杭州仓的截单时间周六18点截单 ONLY23金华仓的截单时间周天12点截单；义乌集拼仓周日18点截单，周日18点截单截资料 奥克兰塘厦仓截单时间为周四12点 | F5: 同截单时间 | G5: 7-4 (12点) | H5: - | I5: 7-3 (18点) | J5: 7-3 (18点) | K5: 7-3 (18点) | L5: 7-3 (12点) | M5: 07/08 (上海起运) | N5: 07/19 (LB) | O5: 7-3 (18点) | P5: 7-3 (18点) | Q5: 07/08 (上海起运) | R5: 07/19 (LB) | S5: 7-2 (18点) | T5: 7-2 (18点) | U5: 7-4 (18点) | V5: - | W5: 7-3 (18点） | X5: 7-3 (18点） | Y5: 07/08 (上海起运) | Z5: 07/19 (LB) | AA5: 7-4 (18点) | AB5: 7-3 (18点） | AC5: 07/08 (上海起运) | AD5: 07/19 (LB) | AE5: 7-3 (18点） | AF5: 07/08 (上海起运) | AG5: 07/19 (LB)
B6: 美森限时达 大货中转头程-美森-美西仓 | C6: MATSON-CLX
B7: Z快线-美西 | C7: 盐田：ZIM | D7: LA | G7: 7-4 (18点) | H7: - | I7: 7-3 (18点) | J7: 7-4 (18点) | K7: 7-3 (18点) | L7: 7-2 (18点) | M7: 07/08 (深圳起运) | N7: 07/21 (LA) | O7: 7-3 (18点) | P7: 7-4 (12点) | Q7: 07/08 (深圳起运) | R7: 07/21 (LA) | S7: - | T7: - | U7: - | V7: - | W7: - | X7: - | Y7: - | Z7: - | AA7: - | AB7: - | AC7: - | AD7: - | AE7: - | AF7: - | AG7: -
B8: Z快线-US监管仓 | C8: 盐田：ZIM | D8: LA | G8: 7-4 (18点) | H8: - | I8: 7-3 (18点) | J8: 7-3 (18点) | K8: 7-3 (18点) | L8: 7-2 (18点) | M8: 07/08 (深圳起运) | N8: 07/21 (LA) | O8: 7-3 (18点) | P8: 7-3 (18点) | Q8: 07/08 (深圳起运) | R8: 07/21 (LA) | S8: - | T8: - | U8: - | V8: - | W8: - | X8: - | Y8: - | Z8: - | AA8: - | AB8: - | AC8: - | AD8: - | AE8: - | AF8: - | AG8: -
B9: Z快线-美东 | C9: 盐田：ZIM | D9: NY | G9: 7-4 (18点) | H9: - | I9: 7-3 (18点) | J9: 7-3 (18点) | K9: 7-3 (18点) | L9: 7-2 (18点) | M9: 07/08 (深圳起运) | N9: 07/21 (LA) | O9: 7-3 (18点) | P9: 7-3 (18点) | Q9: 07/08 (深圳起运) | R9: 07/21 (LA) | S9: - | U9: - | V9: - | W9: - | X9: - | Y9: - | Z9: - | AA9: - | AB9: - | AC9: - | AD9: - | AE9: - | AF9: - | AG9: -
B10: 华东限时18-美东 | C10: 上海：CMA | D10: NY | G10: - | H10: - | I10: - | J10: - | K10: - | L10: - | M10: - | N10: - | O10: - | P10: - | Q10: - | R10: - | S10: 7-2 (18点) | T10: 7-2 (18点) | U10: 7-4 (18点) | V10: - | W10: 7-3 (18点) | X10: 7-6 (12点) | Y10: 07/09 (上海起运) | Z10: 07/20 (LA) | AA10: 7-3 (18点) | AB10: 7-4 (18点) | AC10: 07/09 (上海起运) | AD10: 07/20 (LA) | AE10: 7-3 (18点) | AF10: 07/09 (上海起运) | AG10: 07/20 (LA)
B11: 华东限时 18-美西 | C11: 上海：CMA | D11: LA | G11: 7-4 (12点) | H11: - | I11: 7-3 (18点) | J11: 7-3 (18点) | K11: 7-3 (18点) | L11: 7-3 (12点) | M11: 07/09 (上海起运) | N11: 07/20 (LA) | O11: 7-3 (18点) | P11: 7-3 (18点) | Q11: 07/09 (上海起运) | R11: 07/20 (LA) | S11: 7-2 (18点) | T11: 7-2 (18点) | U11: 7-4 (18点) | V11: - | W11: 7-3 (18点) | X11: 7-6 (12点) | Y11: 07/09 (上海起运) | Z11: 07/20 (LA) | AA11: 7-3 (18点) | AB11: 7-4 (18点) | AC11: 07/09 (上海起运) | AD11: 07/20 (LA) | AE11: 7-3 (18点) | AF11: 07/09 (上海起运) | AG11: 07/20 (LA)
B12: 华东限时 23 华东限时23-US监管仓 华东限时 23-一体化 （一体化不交集拼仓，交金华仓，最晚周一18点） | C12: 宁波：ZIM | D12: LA | G12: 7-3 (18点) | H12: - | I12: 7-3 (12点) | J12: 7-3 (12点) | K12: 7-3 (12点) | L12: 7-3 (12点) | M12: 07/09 (宁波起运) | N12: 07/22 (LA) | O12: 7-3 (18点) | P12: 7-3 (18点) | Q12: 07/09 (宁波起运) | R12: 07/22 (LA) | S12: 7-2 (18点) | T12: 7-2 (18点) | U12: 7-6 (12点) | V12: 7-6 (18点) | W12: 7-4 (18点) | X12: 7-3 (18点) | Y12: 07/09 (宁波起运) | Z12: 07/22 (LA) | AA12: 7-3 (18点) | AB12: 7-4 (18点) | AC12: 07/09 (宁波起运) | AD12: 07/22 (LA) | AE12: 7-3 (18点) | AF12: 07/09 (宁波起运) | AG12: 07/22 (LA)
B13: 特惠仓位-美西 商业地址-LALB | C13: OA | D13: LA/LB | G13: 7-2 (18点) | H13: - | I13: 7-1 (18点) | J13: 7-1 (18点) | K13: 7-1 (12点) | L13: 6-30 (18点) | M13: 07/07 (盐田起运) | N13: 07/21 (LA/LB) | O13: 7-4 (12点) | P13: 7-4 （18点） | Q13: 07/10 (厦门起运) | R13: 07/28 (LB) | S13: 6-29 (18点) | T13: 6-29 (18点) | U13: 7-1 (18点) | V13: - | W13: 6-30 (18点) | X13: 6-30 (18点) | Y13: 07/07 （上海/宁波起运） | Z13: 07/20 （LB） | AA13: 6-30 (18点) | AB13: 7-1 (18点) | AC13: 07/07 （上海/宁波起运） | AD13: 07/20 （LB） | AE13: 7-4 (18点) | AF13: 07/11-07/13 (青岛起运) | AG13: 07/29 (LA)
G14: 7-4 (18点) | H14: - | I14: 7-3 (18点) | J14: 7-3 (18点) | K14: 7-2 (18点) | L14: 7-2 (12点) | M14: 07/09 (盐田起运) | N14: 07/25 (LA/LB) | S14: 7-2 (18点) | T14: 7-2 (18点) | U14: 7-4 (18点) | V14: - | W14: 7-3 (18点) | X14: 7-3 (18点) | Y14: 07/09 （上海/宁波起运） | Z14: 07/22-07/23 （LA/LB) | AA14: 7-3 (18点) | AB14: 7-4 (18点) | AC14: 07/09 （上海/宁波起运） | AD14: 07/22-07/23 （LA/LB)
B15: 特惠舱位-美西-US监管仓 | C15: OA | D15: LA/LB | G15: 7-4 (18点) | H15: - | I15: 7-3 (18点) | J15: 7-3 (18点) | K15: 7-2 (18点) | L15: 7-2 (12点) | M15: 07/07-07/09 (盐田起运) | N15: 07/21-07/25 (LA/LB) | O15: 7-3 (12点) | P15: 7-3 (18点) | Q15: 07/07-07/10 (盐田起运) | R15: 07/21-07/25 (LA/LB) | S15: 7-2 (18点) | T15: 7-2 (18点) | U15: 7-4 (18点) | V15: - | W15: 7-3 (18点) | X15: 7-3 (18点) | Y15: 07/07-07/09 （上海/宁波起运） | Z15: 07/20-7/23 （LA/LB) | AA15: 7-3 (18点) | AB15: 7-4 (18点) | AC15: 07/07-07/09 （上海/宁波起运） | AD15: 07/20-7/23 （LA/LB) | AE15: 7-3 (18点) | AF15: 07/07-07/09 （上海/宁波起运） | AG15: 07/20-7/23 （LA/LB)
B16: 特惠仓位-美东 商业地址-NY | C16: OA | D16: NEW YORK | G16: 7-7 (12点) | H16: - | I16: 7-6 (18点) | J16: 7-6 (18点) | K16: 7-6 (18点) | L16: 7-4 (12点) | M16: 07/12 (盐田起运) | N16: 08/11 (NY) | O16: 7-8 (12点) | P16: 7-8 (18点) | Q16: 07/14 （厦门起运) | R16: 08/11 (NY) | S16: 7-2 (18点) | T16: 7-2 (18点) | U16: 7-4 (18点) | V16: - | W16: 7-3 (18点) | X16: 7-3 (18点) | Y16: 07/09 (上海起运） | Z16: 08/04 (NY) | AA16: 7-3 (18点) | AB16: 7-4 (18点) | AC16: 07/09 (上海起运） | AD16: 08/04 (NY) | AE16: 7-4 (18点) | AF16: 07/11 (青岛起运） | AG16: 08/13 (NY)
B17: 普船奥克兰 | C17: 盐田:EMC 上海：EMC/WHL | D17: OAKLAND | G17: 7-10 (12点) | H17: - | I17: 7-9 (12点) | J17: 7-9 (12点) | K17: 7-8 (18点) | L17: 7-8 (12点) | M17: 07/13 (盐田起运) | N17: 08/03 (OAK) | O17: 7-8 (12点) | P17: 7-8 (18点) | Q17: 07/13 (盐田起运) | R17: 08/03 (OAK) | S17: 7-4 (18点) | T17: 7-4 (18点) | U17: 7-7 (18点) | V17: - | W17: 7-6 (18点) | X17: 7-6 (18点) | Y17: 07/13-07/16 (上海起运） | Z17: 08/03-08/07 (OAK) | AA17: 7-6 (18点) | AB17: 7-7 (18点) | AC17: 07/13-07/16 (上海起运） | AD17: 08/03-08/07 (OAK) | AE17: 7-6 (18点) | AF17: 07/13-07/16 (上海起运） | AG17: 08/03-08/07 (OAK)
B18: 普船时必达 普船美西接力派 FBA大货中转普船美西 | C18: 非OA | D18: LA/LB | G18: - | H18: - | I18: - | J18: - | K18: - | L18: - | M18: - | N18: - | O18: 7-8 (12点) | P18: 7-8 (18点) | Q18: 07/13 (厦门起运) | R18: 07/28 (LB) | S18: 6-29 (18点) | T18: 6-29 (18点) | U18: 7-1 (18点) | V18: - | W18: 6-30 (18点) | X18: 6-30 (18点) | Y18: 07/08 （上海起运） | Z18: 07/26 （LA/LB） | AA18: 6-30 (18点) | AB18: 7-1 (18点) | AC18: 07/08 （上海起运） | AD18: 07/26 （LA/LB） | AE18: 7-4 (18点) | AF18: 07/10 (青岛起运） | AG18: 07/27 (LA)
G19: 7-4 (18点) | H19: - | I19: 7-3 (18点) | J19: 7-3 (18点) | K19: 7-2 (18点) | L19: 7-2 (18点) | M19: 07/08-07/12 (深圳起运) | N19: 07/26-07/30 (LALB) | S19: 7-2 (18点) | T19: 7-2 (18点) | U19: 7-4 (18点) | V19: - | W19: 7-3 (18点) | X19: 7-3 (18点) | Y19: 07/10-07/13 （上海/宁波起运） | Z19: 07/26-07/28 （LA/LB) | AA19: 7-3 (18点) | AB19: 7-4 (18点) | AC19: 07/10-07/13 （上海/宁波起运） | AD19: 07/26-07/28 （LA/LB)
B20: 普船美西接力派-US监管仓 | C20: 非OA | D20: LA/LB | G20: 7-4 (18点) | H20: - | I20: 7-3 (18点) | J20: 7-3 (18点) | K20: 7-2 (18点) | L20: 7-2 (18点) | M20: 07/08-07/12 (深圳起运) | N20: 07/26-07/30 (LALB) | O20: 7-3 (12点) | P20: 7-3 (18点) | Q20: 07/08-07/12 (深圳起运) | R20: 07/26-07/30 (LALB) | S20: 7-2 (18点) | T20: 7-2 (18点) | U20: 7-4 (18点) | V20: - | W20: 7-3 (18点) | X20: 7-3 (18点) | Y20: 07/06-07/12 （上海/宁波起运） | Z20: 07/26-07/28 （LA/LB) | AA20: 7-3 (18点) | AB20: 7-4 (18点) | AC20: 07/06-07/12 （上海/宁波起运） | AD20: 07/26-07/28 （LA/LB) | AE20: 7-3 (18点) | AF20: 07/06-07/12 （上海/宁波起运） | AG20: 07/26-07/28 （LA/LB)
B21: 普船美中接力派 商业地址-芝加哥 | C21: 盐田：OA 上海：OA | D21: CHICAGO | G21: 7-3 (18点） | H21: - | I21: 7-3 (12点) | J21: 7-3 (12点) | K21: 7-2 (18点) | L21: 7-2 (12点) | M21: 07/09 (深圳起运) | N21: 07/25 (LB) | O21: 7-2 (12点) | P21: 7-2 (18点) | Q21: 07/10 (深圳起运) | R21: 07/25 (LB) | S21: 7-2 (18点) | T21: 7-2 (18点) | U21: 7-4 (18点) | V21: - | W21: 7-3 (18点) | X21: 7-3 (18点) | Y21: 07/09 (上海起运) | Z21: 07/22 (LB) | AA21: 7-3 (18点) | AB21: 7-4 (18点) | AC21: 07/09 (上海起运) | AD21: 07/22 (LB) | AE21: 7-3 (18点) | AF21: 07/09 (上海起运) | AG21: 07/22 (LB)
B22: 美东接力派 FBA大货中转美东 | C22: 非OA | D22: NEW YORK | G22: 7-5 (18点) | H22: - | I22: 7-4 (18点) | J22: 7-4 (18点) | K22: 7-4 (12点) | L22: 7-3 (18点) | M22: 07/12 (深圳起运) | N22: 08/20 (NY) | O22: 7-4 (12点) | P22: 7-4 (18点) | Q22: 07/12 (深圳起运) | R22: 08/20 (NY) | S22: 6-30 (18点) | T22: 6-30 (18点) | U22: 7-2 (18点) | V22: - | W22: 7-1 (18点) | X22: 7-1 (18点) | Y22: 07/07 (上海起运) | Z22: 08/10 (NY) | AA22: 7-1 (18点) | AB22: 7-2 (18点) | AC22: 07/07 (上海起运) | AD22: 08/10 (NY) | AE22: 7-1 (18点) | AF22: 07/07 (上海起运) | AG22: 08/10 (NY)
G23: - | H23: - | I23: - | J23: - | K23: - | L23: - | M23: - | N23: - | O23: - | P23: - | Q23: - | R23: - | S23: 7-2 (18点) | T23: 7-2 (18点) | U23: 7-4 (18点) | V23: - | W23: 7-3 (18点) | X23: 7-3 (18点) | Y23: 07/10-07/11 (上海起运) | Z23: 08/11-08/17 (NY) | AA23: 7-3 (18点) | AB23: 7-4 (18点) | AC23: 07/10-07/11 (上海起运) | AD23: 08/11-08/17 (NY) | AE23: 7-3 (18点) | AF23: 07/10-07/11 (上海起运) | AG23: 08/11-08/17 (NY)
B24: 达拉斯专线 商业地址-达拉斯 | C24: 盐田：OA 上海：OA | D24: DALLAS | G24: 7-3 (18点） | H24: - | I24: 7-3 (12点) | J24: 7-3 (12点) | K24: 7-2 (18点) | L24: 7-2 (12点) | M24: 07/10 (深圳起运) | N24: 07/25 (LB) | O24: 7-2 (12点) | P24: 7-2 (18点) | Q24: 07/10 (深圳起运) | R24: 07/25 (LB) | S24: 7-2 (18点) | T24: 7-2 (18点) | U24: 7-4 (18点) | V24: - | W24: 7-3 (18点) | X24: 7-3 (18点) | Y24: 07/09 (上海起运) | Z24: 07/22 (LB) | AA24: 7-3 (18点) | AB24: 7-4 (18点) | AC24: 07/09 (上海起运) | AD24: 07/22 (LB) | AE24: 7-3 (18点) | AF24: 07/09 (上海起运) | AG24: 07/22 (LB)
B25: 休斯敦专线 商业地址-休斯敦拆派 | C25: 上海：EMC 深圳：COSCO | D25: HOUSTON | G25: 7-7 (18点) | H25: - | I25: 7-6 (18点) | J25: 7-6 (18点) | K25: 7-4 (18点) | L25: 7-4 (12点) | M25: 07/13 (盐田起运) | N25: 08/07 (HOUSTON) | O25: 7-4 (12点) | P25: 7-4 (18点) | Q25: 07/13 (盐田起运) | R25: 08/07 (HOUSTON) | S25: 7-4 (18点) | T25: 7-4 (18点) | U25: 7-7 (18点) | V25: - | W25: 7-6 (18点) | X25: 7-6 (18点) | Y25: 07/12 (上海起运) | Z25: 08/10 (HOUSTON) | AA25: 7-6 (18点) | AB25: 7-7 (18点) | AC25: 07/12 (上海起运) | AD25: 08/10 (HOUSTON) | AE25: 7-6 (18点) | AF25: 07/12 (上海起运) | AG25: 08/10 (HOUSTON)
B26: 萨凡纳专线 商业地址-萨凡纳拆派 | C26: 深圳：COSCO 宁波：EMC | D26: SAVANNAH | G26: 7-4 (18点) | H26: - | I26: 7-3 (18点) | J26: 7-3 (18点) | K26: 7-3 (12点) | L26: 7-2 (18点) | M26: 07/11 (盐田起运) | N26: 08/11 (SAVANNAH) | O26: 7-3 (12点) | P26: 7-3 (18点) | Q26: 07/11 (盐田起运) | R26: 08/11 (SAVANNAH) | S26: 7-1 (18点) | T26: 7-1 (18点) | U26: 7-3 (18点) | V26: - | W26: 7-2 (18点) | X26: 7-2 (18点) | Y26: 07/08 (宁波起运) | Z26: 08/08 (SAVANNAH) | AA26: 7-2 (18点) | AB26: 7-3 (18点) | AC26: 07/08 (宁波起运) | AD26: 08/08 (SAVANNAH) | AE26: 7-2 (18点) | AF26: 07/08 (宁波起运) | AG26: 08/08 (SAVANNAH)

Sheet 价格快速查找表 
G2: 渠道价格快速查找（仅限拆派查找）
F3: 输入右边信息 | G3: 国内仓 | I3: 目的仓 | J3: 计费重 | K3: 送仓方式
G4: 深圳/广州/中山/汕头/塘厦 | I4: GEU3 | J4: 不含税：大于10CBM | K4: 拆派 | O4: 直送价格请查看直送渠道
C6: 系列 | D6: 具体渠道 | E6: 渠道单价 (KG/CBM) | F6: 参考时效 (开船次日算起) | G6: 理赔时效 (开船次日开始算起) | H6: 预计送达该仓日期 ①第一水 ;②第二水 | I6: 截货时间 | M6: ETD | N6: ETA | O6: 备注 | BL6: 系列 | BM6: 具体渠道 | BN6: 渠道单价 （KG/CBM） | BO6: 参考时效 (开船次日算起) | BP6: 理赔时效 (开船次日开始算起) | BQ6: 截货时间 | BR6: ETD | BS6: ETA | BT6: 备注 | BU6: 预计送到
C7: 至尊达 | D7: 至尊达(含税100KG+) | E7: =BN7 -> - | F7: =BO7 -> - | G7: =BP7 -> - | H7: =BU7 -> - | I7: =BQ7 -> - | M7: =BR7 -> - | N7: =BS7 -> - | O7: =BT7 -> 此渠道无不含税 | BI7: =_xlfn.IFS(K4="直送","此渠道无直送",$G$4="义乌集拼仓","此国内仓不收该渠道",OR(J4="不含税：大于10CBM",J4="不含税：0.5-10CBM之间"),"此渠道无不含税",COUNTIF(至尊达系列!C6:C17,"*"&I4&"*")=0,"渠道无此仓",K4="拆派",IF(COUNTIF(至尊达系列!C6:C17,"*"&I4&"*")=0,"无此仓拆派","拆派")) -> 此渠道无不含税 | BL7: 至尊达 | BM7: 至尊达(含税100KG+) | BN7: =IFERROR(IF($G$4="义乌集拼仓","-",IF(AND(K4="拆派",OR(J4="含税：50-1000KG之间",J4="含税：大于1000KG")),VLOOKUP("*"&I4&"*",至尊达系列!C6:D17,COLUMN(至尊达系列!D6)-COLUMN(至尊达系列!B6),0),"-")),"-") -> - | BO7: =IFERROR(IF(BN7="-","-",VLOOKUP("*"&I4&"*",至尊达系列!C6:F17,COLUMN(至尊达系列!F6)-COLUMN(至尊达系列!B6),0)),"-") -> - | BP7: =IFERROR(IF(BN7="-","-",IF(BN7="-","-",VLOOKUP("*"&I4&"*",至尊达系列!C6:G17,COLUMN(至尊达系列!G6)-COLUMN(至尊达系列!B6),0))),"-") -> - | BQ7: =_xlfn.IFS(BN7="-","-",G4="深圳/广州/中山/汕头/塘厦","塘厦:"&第27周船期!G5&"; 中山:"&第27周船期!I5&"; 广州:"&第27周船期!J5&"; 汕头:"&第27周船期!K5,G4="长沙","长沙："&第27周船期!L5,G4="厦门/福州/泉州","福州/泉州:"&第27周船期!O5&"; 厦门:"&第27周船期!P5,G4="金华/温州","金华:"&第27周船期!U5&"; 温州:"&第27周船期!T5,G4="苏州/宁波/上海/杭州","宁波:"&第27周船期!W5&"; 杭州:"&第27周船期!X5&"; 苏州:"&第27周船期!AA5&"; 上海:"&第27周船期!AB5,G4="郑州","郑州："&第27周船期!S5,G4="青岛","青岛："&第27周船期!AE5) -> - | BR7: =_xlfn.IFS(BN7="-","-",OR(G4="深圳/广州/中山/汕头/塘厦",$G$4="长沙"),第27周船期!M5,G4="厦门/福州/泉州",第27周船期!Q5,OR(OR(G4="苏州/宁波/上海/杭州",G4="金华/温州"),G4="郑州"),第27周船期!Y5,G4="青岛",第27周船期!AF5) -> - | BS7: =_xlfn.IFS(BN7="-","-",OR(G4="深圳/广州/中山/汕头/塘厦",G4="长沙"),第27周船期!N5,G4="厦门/福州/泉州",第27周船期!R5,OR(OR(G4="苏州/宁波/上海/杭州",G4="金华/温州"),G4="郑州"),第27周船期!Z5,G4="青岛",第27周船期!AG5) -> - | BT7: =BI7 -> 此渠道无不含税 | BU7: =IFERROR(IF(BN7="-","-",VLOOKUP("*"&I4&"*",至尊达系列!C6:F17,COLUMN(至尊达系列!E6)-COLUMN(至尊达系列!B6),0)),"-") -> -
D8: 至尊达MAX(含税100KG+) | E8: =BN8 -> - | F8: =BO8 -> - | G8: =BP8 -> - | H8: =BU8 -> - | I8: =BQ8 -> - | M8: =BR8 -> - | N8: =BS8 -> - | O8: =BT8 -> 此渠道无不含税 | BI8: =_xlfn.IFS(K4="直送","此渠道无直送",$G$4="义乌集拼仓","此国内仓不收该渠道",OR(J4="不含税：大于10CBM",J4="不含税：0.5-10CBM之间"),"此渠道无不含税",COUNTIF(至尊达系列!#REF!,"*"&I4&"*")=0,"渠道无此仓",K4="拆派",IF(COUNTIF(至尊达系列!#REF!,"*"&I4&"*")=0,"无此仓拆派","拆派")) -> 此渠道无不含税 | BM8: 至尊达MAX(含税100KG+) | BN8: =IFERROR(IF($G$4="白沟","-",IF(AND(K4="拆派",OR(J4="含税：50-1000KG之间",J4="含税：大于1000KG")),VLOOKUP("*"&I4&"*",至尊达系列!#REF!,COLUMN(至尊达系列!D6)-COLUMN(至尊达系列!B6),0),"-")),"-") -> - | BO8: =IFERROR(IF(BN8="-","-",VLOOKUP("*"&I4&"*",至尊达系列!#REF!,COLUMN(至尊达系列!F6)-COLUMN(至尊达系列!B6),0)),"-") -> - | BP8: =IFERROR(IF(BN8="-","-",VLOOKUP("*"&I4&"*",至尊达系列!#REF!,COLUMN(至尊达系列!G6)-COLUMN(至尊达系列!B6),0)),"-") -> - | BQ8: =_xlfn.IFS(BN8="-","-",$G$4="深圳/广州/中山/汕头/塘厦","塘厦:"&第27周船期!G5&"; 中山:"&第27周船期!I5&"; 广州:"&第27周船期!J5&"; 汕头:"&第27周船期!K5,$G$4="长沙","长沙："&第27周船期!L5,$G$4="厦门/福州/泉州","福州/泉州:"&第27周船期!O5&"; 厦门:"&第27周船期!P5,G4="金华","金华:"&第27周船期!U5,G4="苏州/宁波/上海/杭州","宁波:"&第27周船期!W5&"; 杭州:"&第27周船期!X5&"; 苏州:"&第27周船期!AA5&"; 上海:"&第27周船期!AB5,$G$4="郑州","郑州："&第27周船期!S5,$G$4="青岛","青岛："&第27周船期!AE5) -> - | BR8: =_xlfn.IFS(BN8="-","-",OR($G$4="深圳/广州/中山/汕头/塘厦",$G$4="长沙"),第27周船期!M5,$G$4="厦门/福州/泉州",第27周船期!Q5,OR(OR(G4="苏州/宁波/上海/杭州",G4="金华"),$G$4="郑州"),第27周船期!Y5,$G$4="青岛",第27周船期!AF5) -> - | BS8: =_xlfn.IFS(BN8="-","-",OR($G$4="深圳/广州/中山/汕头/塘厦",$G$4="长沙"),第27周船期!N5,AND($G$4="厦门/福州/泉州",BN7>0),第27周船期!R5,AND(OR(OR(G4="苏州/宁波/上海/杭州",G4="金华"),$G$4="郑州"),BN7>0),第27周船期!Z5,AND($G$4="青岛",BN7>0),第27周船期!AG5) -> - | BT8: =BI8 -> 此渠道无不含税 | BU8: =IFERROR(IF(BN8="-","-",VLOOKUP("*"&I4&"*",至尊达系列!#REF!,COLUMN(至尊达系列!E6)-COLUMN(至尊达系列!B6),0)),"-") -> -
C9: 美森限时达 | D9: 美森限时达 | E9: =BN9 -> 1860 | F9: =BO9 -> 18天 | G9: =BP9 -> 20天 | H9: =BU9 -> 7月26日 | I9: =BQ9 -> 塘厦:7-4 (12点); 中山:7-3 (18点); 广州:7-3 (18点); 汕头:7-3 (18点) | M9: =BR9 -> 07/08 (上海起运) | N9: =BS9 -> 07/19 (LB) | O9: =BT9 -> 拆派 | BI9: =_xlfn.IFS($G$4="义乌集拼仓","此国内仓不收该渠道",COUNTIF(美森限时达!C6:C42,"*"&I4&"*")=0,"渠道无此仓",K4="直送","此渠道无直送",K4="拆派",IF(COUNTIF(美森限时达!C6:C42,"*"&I4&"*")=0,"无此仓拆派","拆派")) -> 拆派 | BL9: 美森限时达 | BM9: 美森限时达 | BN9: =IFERROR(_xlfn.IFS(AND(K4="拆派",J4="不含税：0.5-10CBM之间",OR(G4="苏州/宁波/上海/杭州",G4="金华/温州")),VLOOKUP("*"&I4&"*",美森限时达!C6:D42,COLUMN(美森限时达!D1)-COLUMN(美森限时达!B1),0),AND(K4="拆派",J4="含税：50-1000KG之间",OR(G4="苏州/宁波/上海/杭州",G4="金华/温州")),VLOOKUP("*"&I4&"*",美森限时达!C6:E42,COLUMN(美森限时达!E1)-COLUMN(美森限时达!B1),0),AND(K4="拆派",J4="不含税：大于10CBM",OR(G4="苏州/宁波/上海/杭州",G4="金华/温州")),VLOOKUP("*"&I4&"*",美森限时达!C6:D42,COLUMN(美森限时达!D1)-COLUMN(美森限时达!B1),0),AND(K4="拆派",J4="含税：大于1000KG",OR(G4="苏州/宁波/上海/杭州",G4="金华/温州")),VLOOKUP("*"&I4&"*",美森限时达!C6:E42,COLUMN(美森限时达!E1)-COLUMN(美森限时达!B1),0),AND(K4="拆派",J4="不含税：0.5-10CBM之间",G4="深圳/广州/中山/汕头/塘厦"),VLOOKUP("*"&I4&"*",美森限时达!C6:F42,COLUMN(美森限时达!F1)-COLUMN(美森限时达!B1),0),AND(K4="拆派",J4="含税：50-1000KG之间",G4="深圳/广州/中山/汕头/塘厦"),VLOOKUP("*"&I4&"*",美森限时达!C6:G42,COLUMN(美森限时达!G1)-COLUMN(美森限时达!B1),0),AND(K4="拆派",J4="不含税：大于10CBM",G4="深圳/广州/中山/汕头/塘厦"),VLOOKUP("*"&I4&"*",美森限时达!C6:F42,COLUMN(美森限时达!F1)-COLUMN(美森限时达!B1),0),AND(K4="拆派",J4="含税：大于1000KG",G4="深圳/广州/中山/汕头/塘厦"),VLOOKUP("*"&I4&"*",美森限时达!C6:G42,COLUMN(美森限时达!G1)-COLUMN(美森限时达!B1),0),AND(K4="拆派",J4="不含税：0.5-10CBM之间",G4="厦门/福州/泉州"),VLOOKUP("*"&I4&"*",美森限时达!C6:H42,COLUMN(美森限时达!H1)-COLUMN(美森限时达!B1),0),AND(K4="拆派",J4="含税：50-1000KG之间",G4="厦门/福州/泉州"),VLOOKUP("*"&I4&"*",美森限时达!C6:I42,COLUMN(美森限时达!I1)-COLUMN(美森限时达!B1),0),AND(K4="拆派",J4="不含税：大于10CBM",G4="厦门/福州/泉州"),VLOOKUP("*"&I4&"*",美森限时达!C6:H42,COLUMN(美森限时达!H1)-COLUMN(美森限时达!B1),0),AND(K4="拆派",J4="含税：大于1000KG",G4="厦门/福州/泉州"),VLOOKUP("*"&I4&"*",美森限时达!C6:I42,COLUMN(美森限时达!I1)-COLUMN(美森限时达!B1),0),AND(K4="拆派",J4="不含税：0.5-10CBM之间",OR(G4="青岛",G4="郑州",G4="长沙")),VLOOKUP("*"&I4&"*",美森限时达!C6:J42,COLUMN(美森限时达!J1)-COLUMN(美森限时达!B1),0),AND(K4="拆派",J4="含税：50-1000KG之间",OR(G4="青岛",G4="郑州",G4="长沙")),VLOOKUP("*"&I4&"*",美森限时达!C6:K42,COLUMN(美森限时达!K1)-COLUMN(美森限时达!B1),0),AND(K4="拆派",J4="不含税：大于10CBM",OR(G4="青岛",G4="郑州",G4="长沙")),VLOOKUP("*"&I4&"*",美森限时达!C6:J42,COLUMN(美森限时达!J1)-COLUMN(美森限时达!B1),0),AND(K4="拆派",J4="含税：大于1000KG",OR(G4="青岛",G4="郑州",G4="长沙")),VLOOKUP("*"&I4&"*",美森限时达!C6:K42,COLUMN(美森限时达!K1)-COLUMN(美森限时达!B1),0),AND(K4="直送",J4="不含税：0.5-10CBM之间",OR(G4="苏州/宁波/上海/杭州",G4="金华/温州")),VLOOKUP("*"&I4&"*",美森限时达!#REF!,COLUMN(美森限时达!D1)-COLUMN(美森限时达!B1),0),AND(K4="直送",J4="含税：50-1000KG之间",OR(G4="苏州/宁波/上海/杭州",G4="金华/温州")),VLOOKUP("*"&I4&"*",美森限时达!#REF!,COLUMN(美森限时达!E1)-COLUMN(美森限时达!B1),0),AND(K4="直送",J4="不含税：大于10CBM",OR(G4="苏州/宁波/上海/杭州",G4="金华/温州")),VLOOKUP("*"&I4&"*",美森限时达!#REF!,COLUMN(美森限时达!D1)-COLUMN(美森限时达!B1),0),AND(K4="直送",J4="含税：大于1000KG",OR(G4="苏州/宁波/上海/杭州",G4="金华/温州")),VLOOKUP("*"&I4&"*",美森限时达!#REF!,COLUMN(美森限时达!E1)-COLUMN(美森限时达!B1),0),AND(K4="直送",J4="不含税：0.5-10CBM之间",G4="深圳/广州/中山/汕头/塘厦"),VLOOKUP("*"&I4&"*",美森限时达!#REF!,COLUMN(美森限时达!F1)-COLUMN(美森限时达!B1),0),AND(K4="直送",J4="含税：50-1000KG之间",G4="深圳/广州/中山/汕头/塘厦"),VLOOKUP("*"&I4&"*",美森限时达!#REF!,COLUMN(美森限时达!G1)-COLUMN(美森限时达!B1),0),AND(K4="直送",J4="不含税：大于10CBM",G4="深圳/广州/中山/汕头/塘厦"),VLOOKUP("*"&I4&"*",美森限时达!#REF!,COLUMN(美森限时达!F1)-COLUMN(美森限时达!B1),0),AND(K4="直送",J4="含税：大于1000KG",G4="深圳/广州/中山/汕头/塘厦"),VLOOKUP("*"&I4&"*",美森限时达!#REF!,COLUMN(美森限时达!G1)-COLUMN(美森限时达!B1),0),AND(K4="直送",J4="不含税：0.5-10CBM之间",G4="厦门/福州/泉州"),VLOOKUP("*"&I4&"*",美森限时达!#REF!,COLUMN(美森限时达!H1)-COLUMN(美森限时达!B1),0),AND(K4="直送",J4="含税：50-1000KG之间",G4="厦门/福州/泉州"),VLOOKUP("*"&I4&"*",美森限时达!#REF!,COLUMN(美森限时达!I1)-COLUMN(美森限时达!B1),0),AND(K4="直送",J4="不含税：大于10CBM",G4="厦门/福州/泉州"),VLOOKUP("*"&I4&"*",美森限时达!#REF!,COLUMN(美森限时达!H1)-COLUMN(美森限时达!B1),0),AND(K4="直送",J4="含税：大于1000KG",G4="厦门/福州/泉州"),VLOOKUP("*"&I4&"*",美森限时达!#REF!,COLUMN(美森限时达!I1)-COLUMN(美森限时达!B1),0),AND(K4="直送",J4="不含税：0.5-10CBM之间",OR(G4="青岛",G4="郑州",G4="长沙")),VLOOKUP("*"&I4&"*",美森限时达!#REF!,COLUMN(美森限时达!J1)-COLUMN(美森限时达!B1),0),AND(K4="直送",J4="含税：50-1000KG之间",OR(G4="青岛",G4="郑州",G4="长沙")),VLOOKUP("*"&I4&"*",美森限时达!#REF!,COLUMN(美森限时达!K1)-COLUMN(美森限时达!B1),0),AND(K4="直送",J4="不含税：大于10CBM",OR(G4="青岛",G4="郑州",G4="长沙")),VLOOKUP("*"&I4&"*",美森限时达!#REF!,COLUMN(美森限时达!J1)-COLUMN(美森限时达!B1),0),AND(K4="直送",J4="含税：大于1000KG",OR(G4="青岛",G4="郑州",G4="长沙")),VLOOKUP("*"&I4&"*",美森限时达!#REF!,COLUMN(美森限时达!K1)-COLUMN(美森限时达!B1),0)),"-") -> 1860 | BO9: =IFERROR(IF(BN9="-","-",IF(K4="直送","-",VLOOKUP("*"&I4&"*",美森限时达!C6:M42,COLUMN(美森限时达!M1)-COLUMN(美森限时达!B1),0))),"-") -> 18天 | BP9: =IFERROR(IF(BN9="-","-",IF(K4="直送","-",VLOOKUP("*"&I4&"*",美森限时达!C6:N42,COLUMN(美森限时达!N1)-COLUMN(美森限时达!B1),0))),"-") -> 20天 | BQ9: =_xlfn.IFS(BN9="-","-",$G$4="深圳/广州/中山/汕头/塘厦","塘厦:"&第27周船期!G5&"; 中山:"&第27周船期!I5&"; 广州:"&第27周船期!J5&"; 汕头:"&第27周船期!K5,$G$4="长沙","长沙："&第27周船期!L5,$G$4="厦门/福州/泉州","福州/泉州:"&第27周船期!O5&"; 厦门:"&第27周船期!P5,G4="金华/温州","金华:"&第27周船期!U5&"; 温州:"&第27周船期!T5,G4="苏州/宁波/上海/杭州","宁波:"&第27周船期!W5&"; 杭州:"&第27周船期!X5&"; 苏州:"&第27周船期!AA5&"; 上海:"&第27周船期!AB5,$G$4="郑州","郑州："&第27周船期!S5,$G$4="青岛","青岛："&第27周船期!AE5) -> 塘厦:7-4 (12点); 中山:7-3 (18点); 广州:7-3 (18点); 汕头:7-3 (18点) | BR9: =_xlfn.IFS(BN9="-","-",OR($G$4="深圳/广州/中山/汕头/塘厦",$G$4="长沙"),第27周船期!M5,$G$4="厦门/福州/泉州",第27周船期!Q5,OR(OR(G4="苏州/宁波/上海/杭州",G4="金华/温州"),$G$4="郑州"),第27周船期!Y5,$G$4="青岛",第27周船期!AF5) -> 07/08 (上海起运) | BS9: =_xlfn.IFS(BN9="-","-",OR($G$4="深圳/广州/中山/汕头/塘厦",$G$4="长沙"),第27周船期!N5,$G$4="厦门/福州/泉州",第27周船期!R5,OR(OR(G4="苏州/宁波/上海/杭州",G4="金华/温州"),$G$4="郑州"),第27周船期!Z5,$G$4="青岛",第27周船期!AG5) -> 07/19 (LB) | BT9: =BI9 -> 拆派 | BU9: =IFERROR(IF(BN9="-","-",IF(K4="直送","-",VLOOKUP("*"&I4&"*",美森限时达!C6:M42,COLUMN(美森限时达!L1)-COLUMN(美森限时达!B1),0))),"-") -> 7月26日
C10: 华东限时系列 | D10: 华东限时 18-美西 | E10: =BN10 -> 1501 | F10: =BO10 -> 20天 | G10: =BP10 -> 22天 | H10: =BU10 -> 7月29日 | I10: =BQ10 -> 塘厦:-; 中山:7-3 (18点); 广州:7-3 (18点); 汕头:7-3 (18点) | M10: =BR10 -> 07/09 (上海起运) | N10: =BS10 -> 07/20 (LA) | O10: =BT10 -> 拆派 | BI10: =_xlfn.IFS($G$4="义乌集拼仓","此国内仓不收该渠道",COUNTIF('华东限时18-美西'!C5:C47,"*"&I4&"*")=0,"渠道无此仓",K4="直送","此渠道无直送",K4="拆派",IF(COUNTIF('华东限时18-美西'!C5:C47,"*"&I4&"*")=0,"无此仓拆派","拆派")) -> 拆派 | BL10: 华东限时系列 | BM10: 华东限时 18 | BN10: =IFERROR(_xlfn.IFS(AND(K4="拆派",J4="不含税：0.5-10CBM之间",OR(G4="深圳/广州/中山/汕头/塘厦",G4="长沙",G4="郑州")),VLOOKUP("*"&I4&"*",'华东限时18-美西'!C5:D47,COLUMN('华东限时18-美西'!D1)-COLUMN('华东限时18-美西'!B1),0),AND(K4="拆派",J4="含税：50-1000KG之间",OR(G4="深圳/广州/中山/汕头/塘厦",G4="长沙",G4="郑州")),VLOOKUP("*"&I4&"*",'华东限时18-美西'!C5:E47,COLUMN('华东限时18-美西'!E1)-COLUMN('华东限时18-美西'!B1),0),AND(K4="拆派",J4="不含税：大于10CBM",OR(G4="深圳/广州/中山/汕头/塘厦",G4="长沙",G4="郑州")),VLOOKUP("*"&I4&"*",'华东限时18-美西'!C5:D47,COLUMN('华东限时18-美西'!D1)-COLUMN('华东限时18-美西'!B1),0),AND(K4="拆派",J4="含税：大于1000KG",OR(G4="深圳/广州/中山/汕头/塘厦",G4="长沙",G4="郑州")),VLOOKUP("*"&I4&"*",'华东限时18-美西'!C5:E47,COLUMN('华东限时18-美西'!E1)-COLUMN('华东限时18-美西'!B1),0),AND(K4="拆派",J4="不含税：0.5-10CBM之间",G4="厦门/福州/泉州"),VLOOKUP("*"&I4&"*",'华东限时18-美西'!C5:K47,COLUMN('华东限时18-美西'!J1)-COLUMN('华东限时18-美西'!B1),0),AND(K4="拆派",J4="含税：50-1000KG之间",G4="厦门/福州/泉州"),VLOOKUP("*"&I4&"*",'华东限时18-美西'!C5:K47,COLUMN('华东限时18-美西'!K1)-COLUMN('华东限时18-美西'!B1),0),AND(K4="拆派",J4="不含税：大于10CBM",G4="厦门/福州/泉州"),VLOOKUP("*"&I4&"*",'华东限时18-美西'!C5:K47,COLUMN('华东限时18-美西'!J1)-COLUMN('华东限时18-美西'!B1),0),AND(K4="拆派",J4="含税：大于1000KG",G4="厦门/福州/泉州"),VLOOKUP("*"&I4&"*",'华东限时18-美西'!C5:K47,COLUMN('华东限时18-美西'!K1)-COLUMN('华东限时18-美西'!B1),0),AND(K4="拆派",J4="不含税：0.5-10CBM之间",G4="白沟"),VLOOKUP("*"&I4&"*",'华东限时18-美西'!C5:K47,COLUMN('华东限时18-美西'!#REF!)-COLUMN('华东限时18-美西'!B1),0),AND(K4="拆派",J4="含税：50-1000KG之间",G4="白沟"),VLOOKUP("*"&I4&"*",'华东限时18-美西'!C5:K47,COLUMN('华东限时18-美西'!#REF!)-COLUMN('华东限时18-美西'!B1),0),AND(K4="拆派",J4="不含税：大于10CBM",G4="白沟"),VLOOKUP("*"&I4&"*",'华东限时18-美西'!C5:K47,COLUMN('华东限时18-美西'!#REF!)-COLUMN('华东限时18-美西'!B1),0),AND(K4="拆派",J4="含税：大于1000KG",G4="白沟"),VLOOKUP("*"&I4&"*",'华东限时18-美西'!C5:K47,COLUMN('华东限时18-美西'!#REF!)-COLUMN('华东限时18-美西'!B1),0),AND(K4="拆派",J4="不含税：0.5-10CBM之间",OR(G4="苏州/宁波/上海/杭州",G4="金华/温州")),VLOOKUP("*"&I4&"*",'华东限时18-美西'!C5:F47,COLUMN('华东限时18-美西'!F1)-COLUMN('华东限时18-美西'!B1),0),AND(K4="拆派",J4="含税：50-1000KG之间",OR(G4="苏州/宁波/上海/杭州",G4="金华/温州")),VLOOKUP("*"&I4&"*",'华东限时18-美西'!C5:G47,COLUMN('华东限时18-美西'!G1)-COLUMN('华东限时18-美西'!B1),0),AND(K4="拆派",J4="不含税：大于10CBM",OR(G4="苏州/宁波/上海/杭州",G4="金华/温州")),VLOOKUP("*"&I4&"*",'华东限时18-美西'!C5:F47,COLUMN('华东限时18-美西'!F1)-COLUMN('华东限时18-美西'!B1),0),AND(K4="拆派",J4="含税：大于1000KG",OR(G4="苏州/宁波/上海/杭州",G4="金华/温州")),VLOOKUP("*"&I4&"*",'华东限时18-美西'!C5:G47,COLUMN('华东限时18-美西'!G1)-COLUMN('华东限时18-美西'!B1),0),AND(K4="拆派",J4="不含税：0.5-10CBM之间",G4="青岛"),VLOOKUP("*"&I4&"*",'华东限时18-美西'!C5:H47,COLUMN('华东限时18-美西'!H1)-COLUMN('华东限时18-美西'!B1),0),AND(K4="拆派",J4="含税：50-1000KG之间",G4="青岛"),VLOOKUP("*"&I4&"*",'华东限时18-美西'!C5:I47,COLUMN('华东限时18-美西'!I1)-COLUMN('华东限时18-美西'!B1),0),AND(K4="拆派",J4="不含税：大于10CBM",G4="青岛"),VLOOKUP("*"&I4&"*",'华东限时18-美西'!C5:H47,COLUMN('华东限时18-美西'!H1)-COLUMN('华东限时18-美西'!B1),0),AND(K4="拆派",J4="含税：大于1000KG",G4="青岛"),VLOOKUP("*"&I4&"*",'华东限时18-美西'!C5:I47,COLUMN('华东限时18-美西'!I1)-COLUMN('华东限时18-美西'!B1),0),AND(K4="直送",J4="不含税：0.5-10CBM之间",OR(G4="深圳/广州/中山/汕头/塘厦",G4="长沙",G4="郑州")),VLOOKUP("*"&I4&"*",'华东限时18-美西'!#REF!,COLUMN('华东限时18-美西'!D1)-COLUMN('华东限时18-美西'!B1),0),AND(K4="直送",J4="含税：50-1000KG之间",OR(G4="深圳/广州/中山/汕头/塘厦",G4="长沙",G4="郑州")),VLOOKUP("*"&I4&"*",'华东限时18-美西'!#REF!,COLUMN('华东限时18-美西'!E1)-COLUMN('华东限时18-美西'!B1),0),AND(K4="直送",J4="不含税：大于10CBM",OR(G4="深圳/广州/中山/汕头/塘厦",G4="长沙",G4="郑州")),VLOOKUP("*"&I4&"*",'华东限时18-美西'!#REF!,COLUMN('华东限时18-美西'!D1)-COLUMN('华东限时18-美西'!B1),0),AND(K4="直送",J4="含税：大于1000KG",OR(G4="深圳/广州/中山/汕头/塘厦",G4="长沙",G4="郑州")),VLOOKUP("*"&I4&"*",'华东限时18-美西'!#REF!,COLUMN('华东限时18-美西'!E1)-COLUMN('华东限时18-美西'!B1),0),AND(K4="直送",J4="不含税：0.5-10CBM之间",G4="厦门/福州/泉州"),VLOOKUP("*"&I4&"*",'华东限时18-美西'!#REF!,COLUMN('华东限时18-美西'!J1)-COLUMN('华东限时18-美西'!B1),0),AND(K4="直送",J4="含税：50-1000KG之间",G4="厦门/福州/泉州"),VLOOKUP("*"&I4&"*",'华东限时18-美西'!#REF!,COLUMN('华东限时18-美西'!K1)-COLUMN('华东限时18-美西'!B1),0),AND(K4="直送",J4="不含税：大于10CBM",G4="厦门/福州/泉州"),VLOOKUP("*"&I4&"*",'华东限时18-美西'!#REF!,COLUMN('华东限时18-美西'!J1)-COLUMN('华东限时18-美西'!B1),0),AND(K4="直送",J4="含税：大于1000KG",G4="厦门/福州/泉州"),VLOOKUP("*"&I4&"*",'华东限时18-美西'!#REF!,COLUMN('华东限时18-美西'!K1)-COLUMN('华东限时18-美西'!B1),0),AND(K4="直送",J4="不含税：0.5-10CBM之间",OR(G4="苏州/宁波/上海/杭州",G4="金华/温州")),VLOOKUP("*"&I4&"*",'华东限时18-美西'!#REF!,COLUMN('华东限时18-美西'!F1)-COLUMN('华东限时18-美西'!B1),0),AND(K4="直送",J4="含税：50-1000KG之间",OR(G4="苏州/宁波/上海/杭州",G4="金华/温州")),VLOOKUP("*"&I4&"*",'华东限时18-美西'!#REF!,COLUMN('华东限时18-美西'!G1)-COLUMN('华东限时18-美西'!B1),0),AND(K4="直送",J4="不含税：大于10CBM",OR(G4="苏州/宁波/上海/杭州",G4="金华/温州")),VLOOKUP("*"&I4&"*",'华东限时18-美西'!#REF!,COLUMN('华东限时18-美西'!F1)-COLUMN('华东限时18-美西'!B1),0),AND(K4="直送",J4="含税：大于1000KG",OR(G4="苏州/宁波/上海/杭州",G4="金华/温州")),VLOOKUP("*"&I4&"*",'华东限时18-美西'!#REF!,COLUMN('华东限时18-美西'!G1)-COLUMN('华东限时18-美西'!B1),0),AND(K4="直送",J4="不含税：0.5-10CBM之间",G4="青岛"),VLOOKUP("*"&I4&"*",'华东限时18-美西'!#REF!,COLUMN('华东限时18-美西'!H1)-COLUMN('华东限时18-美西'!B1),0),AND(K4="直送",J4="含税：50-1000KG之间",G4="青岛"),VLOOKUP("*"&I4&"*",'华东限时18-美西'!#REF!,COLUMN('华东限时18-美西'!I1)-COLUMN('华东限时18-美西'!B1),0),AND(K4="直送",J4="不含税：大于10CBM",G4="青岛"),VLOOKUP("*"&I4&"*",'华东限时18-美西'!#REF!,COLUMN('华东限时18-美西'!H1)-COLUMN('华东限时18-美西'!B1),0),AND(K4="直送",J4="含税：大于1000KG",G4="青岛"),VLOOKUP("*"&I4&"*",'华东限时18-美西'!#REF!,COLUMN('华东限时18-美西'!I1)-COLUMN('华东限时18-美西'!B1),0)),"-") -> 1501 | BO10: =IFERROR(IF(BN10="-","-",IF(K4="直送",VLOOKUP("*"&I4&"*",'华东限时18-美西'!#REF!,COLUMN('华东限时18-美西'!M1)-COLUMN('华东限时18-美西'!B1),0),VLOOKUP("*"&I4&"*",'华东限时18-美西'!C5:M47,COLUMN('华东限时18-美西'!M1)-COLUMN('华东限时18-美西'!B1),0))),"-") -> 20天 | BP10: =IFERROR(IF(BN10="-","-",IF(K4="直送",VLOOKUP("*"&I4&"*",'华东限时18-美西'!#REF!,COLUMN('华东限时18-美西'!N1)-COLUMN('华东限时18-美西'!B1),0),VLOOKUP("*"&I4&"*",'华东限时18-美西'!C5:N47,COLUMN('华东限时18-美西'!N1)-COLUMN('华东限时18-美西'!B1),0))),"-") -> 22天 | BQ10: =_xlfn.IFS(BN10="-","-",$G$4="深圳/广州/中山/汕头/塘厦","塘厦:"&第27周船期!H11&"; 中山:"&第27周船期!I11&"; 广州:"&第27周船期!J11&"; 汕头:"&第27周船期!K11,$G$4="长沙","长沙："&第27周船期!L11,$G$4="厦门/福州/泉州","福州/泉州:"&第27周船期!O11&"; 厦门:"&第27周船期!P11,G4="金华/温州","金华:"&第27周船期!U11&"; 温州:"&第27周船期!T11,G4="苏州/宁波/上海/杭州","宁波:"&第27周船期!W11&"; 杭州:"&第27周船期!X11&"; 苏州:"&第27周船期!AA11&"; 上海:"&第27周船期!AB11,$G$4="郑州","郑州："&第27周船期!S11,$G$4="青岛","青岛："&第27周船期!AE11,$G$4="白沟","白沟："&第27周船期!#REF!) -> 塘厦:-; 中山:7-3 (18点); 广州:7-3 (18点); 汕头:7-3 (18点) | BR10: =_xlfn.IFS(BN10="-","-",OR($G$4="深圳/广州/中山/汕头/塘厦",$G$4="长沙"),第27周船期!M11,$G$4="厦门/福州/泉州",第27周船期!Q11,OR(OR(G4="苏州/宁波/上海/杭州",G4="金华/温州"),$G$4="郑州"),第27周船期!Y11,$G$4="青岛",第27周船期!AF11,$G$4="白沟",第27周船期!#REF!) -> 07/09 (上海起运) | BS10: =_xlfn.IFS(BN10="-","-",OR($G$4="深圳/广州/中山/汕头/塘厦",$G$4="长沙"),第27周船期!N11,$G$4="厦门/福州/泉州",第27周船期!R11,OR(OR(G4="苏州/宁波/上海/杭州",G4="金华/温州"),$G$4="郑州"),第27周船期!Z11,$G$4="青岛",第27周船期!AG11,$G$4="白沟",第27周船期!AH11) -> 07/20 (LA) | BT10: =BI10 -> 拆派 | BU10: =IFERROR(IF(BN10="-","-",IF(K4="直送",VLOOKUP("*"&I4&"*",'华东限时18-美西'!#REF!,COLUMN('华东限时18-美西'!L1)-COLUMN('华东限时18-美西'!B1),0),VLOOKUP("*"&I4&"*",'华东限时18-美西'!C5:M47,COLUMN('华东限时18-美西'!L1)-COLUMN('华东限时18-美西'!B1),0))),"-") -> 7月29日
D11: 华东限时 18-美东 | E11: =BN11 -> - | F11: =BO11 -> - | G11: =BP11 -> - | H11: =BU11 -> - | I11: =BQ11 -> - | M11: =BR11 -> - | N11: =BS11 -> - | O11: =BT11 -> - | BI11: =_xlfn.IFS(BN11="-","-",K4="直送","此渠道无直送",COUNTIF('华东限时18-美东'!C6:C43,"*"&I4&"*")=0,"渠道无此仓",K4="拆派",IF(COUNTIF('华东限时18-美东'!C6:C43,"*"&I4&"*")=0,"无此仓拆派","拆派")) -> - | BM11: 华东限时 18-美东 | BN11: =IFERROR(_xlfn.IFS(AND(K4="拆派",J4="不含税：0.5-10CBM之间",OR(G4="苏州/宁波/上海/杭州",G4="金华/温州")),VLOOKUP("*"&I4&"*",'华东限时18-美东'!C6:D32,COLUMN('华东限时18-美东'!D6)-COLUMN('华东限时18-美东'!B6),0),AND(K4="拆派",J4="含税：50-1000KG之间",OR(G4="苏州/宁波/上海/杭州",G4="金华/温州")),VLOOKUP("*"&I4&"*",'华东限时18-美东'!C6:E32,COLUMN('华东限时18-美东'!E6)-COLUMN('华东限时18-美东'!B6),0),AND(K4="拆派",J4="不含税：大于10CBM",OR(G4="苏州/宁波/上海/杭州",G4="金华/温州")),VLOOKUP("*"&I4&"*",'华东限时18-美东'!C6:D32,COLUMN('华东限时18-美东'!D6)-COLUMN('华东限时18-美东'!B6),0),AND(K4="拆派",J4="含税：大于1000KG",OR(G4="苏州/宁波/上海/杭州",G4="金华/温州")),VLOOKUP("*"&I4&"*",'华东限时18-美东'!C6:E32,COLUMN('华东限时18-美东'!E6)-COLUMN('华东限时18-美东'!B6),0),AND(K4="拆派",J4="不含税：0.5-10CBM之间",OR(G4="青岛",G4="白沟",G4="郑州")),VLOOKUP("*"&I4&"*",'华东限时18-美东'!C6:F32,COLUMN('华东限时18-美东'!F6)-COLUMN('华东限时18-美东'!B6),0),AND(K4="拆派",J4="含税：50-1000KG之间",OR(G4="青岛",G4="白沟",G4="郑州")),VLOOKUP("*"&I4&"*",'华东限时18-美东'!C6:G32,COLUMN('华东限时18-美东'!G6)-COLUMN('华东限时18-美东'!B6),0),AND(K4="拆派",J4="不含税：大于10CBM",OR(G4="青岛",G4="白沟",G4="郑州")),VLOOKUP("*"&I4&"*",'华东限时18-美东'!C6:F32,COLUMN('华东限时18-美东'!F6)-COLUMN('华东限时18-美东'!B6),0),AND(K4="拆派",J4="含税：大于1000KG",OR(G4="青岛",G4="白沟",G4="郑州")),VLOOKUP("*"&I4&"*",'华东限时18-美东'!C6:G32,COLUMN('华东限时18-美东'!G6)-COLUMN('华东限时18-美东'!B6),0)),"-") -> - | BO11: =IFERROR(IF(BN11="-","-",IF(K4="直送","-",VLOOKUP("*"&I4&"*",'华东限时18-美东'!C6:I32,COLUMN('华东限时18-美东'!I6)-COLUMN('华东限时18-美东'!B6),0))),"-") -> - | BP11: =IFERROR(IF(BN11="-","-",IF(K4="直送","-",VLOOKUP("*"&I4&"*",'华东限时18-美东'!C6:J32,COLUMN('华东限时18-美东'!J6)-COLUMN('华东限时18-美东'!B6),0))),"-") -> - | BQ11: =_xlfn.IFS(BN11="-","-",$G$4="深圳/广州/中山/汕头/塘厦","塘厦:"&第27周船期!G10&"; 中山:"&第27周船期!I10&"; 广州:"&第27周船期!J10&"; 汕头:"&第27周船期!K10,$G$4="长沙","长沙："&第27周船期!L10,$G$4="厦门/福州/泉州","福州/泉州:"&第27周船期!O10&"; 厦门:"&第27周船期!P10,G4="金华/温州","金华:"&第27周船期!U10&"; 温州:"&第27周船期!T10,G4="苏州/宁波/上海/杭州","宁波:"&第27周船期!W10&"; 杭州:"&第27周船期!X10&"; 苏州:"&第27周船期!AA10&"; 上海:"&第27周船期!AB10,$G$4="郑州","郑州："&第27周船期!S10,$G$4="青岛","青岛："&第27周船期!AE10,$G$4="白沟","白沟："&第27周船期!#REF!) -> - | BR11: =_xlfn.IFS(BN11="-","-",OR($G$4="深圳/广州/中山/汕头/塘厦",$G$4="长沙"),第27周船期!M10,$G$4="厦门/福州/泉州",第27周船期!Q10,OR(OR(G4="苏州/宁波/上海/杭州",G4="金华/温州"),$G$4="郑州"),第27周船期!Y10,$G$4="青岛",第27周船期!AF10,$G$4="白沟","白沟："&第27周船期!#REF!) -> - | BS11: =_xlfn.IFS(BN11="-","-",OR($G$4="深圳/广州/中山/汕头/塘厦",$G$4="长沙"),第27周船期!N10,$G$4="厦门/福州/泉州",第27周船期!R10,OR(OR(G4="苏州/宁波/上海/杭州",G4="金华/温州"),$G$4="郑州"),第27周船期!Z10,$G$4="青岛",第27周船期!AG10,$G$4="白沟","白沟："&第27周船期!#REF!) -> - | BT11: =BI11 -> - | BU11: =IFERROR(IF(BN11="-","-",IF(K4="直送","-",VLOOKUP("*"&I4&"*",'华东限时18-美东'!C6:I32,COLUMN('华东限时18-美东'!H6)-COLUMN('华东限时18-美东'!B6),0))),"-") -> -
D12: 华东限时 23 | E12: =BN12 -> 1446 | F12: =BO12 -> 20天 | G12: =BP12 -> 22天 | H12: =BU12 -> 7月29日 | I12: =BQ12 -> 塘厦:7-3 (18点); 中山:7-3 (12点); 广州:7-3 (12点); 汕头:7-3 (12点) | M12: =BR12 -> 07/09 (宁波起运) | N12: =BS12 -> 07/22 (LA) | O12: =BT12 -> 拆派 | BI12: =_xlfn.IFS(COUNTIF(华东限时23!C4:C84,"*"&I4&"*")=0,"渠道无此仓",OR(G4="长沙"),"此国内仓不收该渠道",K4="直送",IF(COUNTIF(华东限时23!C4:C4,"*"&I4&"*")=0,"无此仓直送","直送"),K4="拆派",IF(COUNTIF(华东限时23!C5:C84,"*"&I4&"*")=0,"无此仓拆派","拆派")) -> 拆派 | BM12: 华东限时 23 | BN12: =IFERROR(_xlfn.IFS(AND(K4="拆派",J4="不含税：0.5-10CBM之间",OR(G4="苏州/宁波/上海/杭州",G4="金华/温州",$G$4="义乌集拼仓")),VLOOKUP("*"&I4&"*",华东限时23!C5:D84,COLUMN(华东限时23!D1)-COLUMN(华东限时23!B1),0),AND(K4="拆派",J4="含税：50-1000KG之间",OR(G4="苏州/宁波/上海/杭州",G4="金华/温州",$G$4="义乌集拼仓")),VLOOKUP("*"&I4&"*",华东限时23!C5:E84,COLUMN(华东限时23!E1)-COLUMN(华东限时23!B1),0),AND(K4="拆派",J4="不含税：大于10CBM",OR(G4="苏州/宁波/上海/杭州",G4="金华/温州",$G$4="义乌集拼仓")),VLOOKUP("*"&I4&"*",华东限时23!C5:F84,COLUMN(华东限时23!F1)-COLUMN(华东限时23!B1),0),AND(K4="拆派",J4="含税：大于1000KG",OR(G4="苏州/宁波/上海/杭州",G4="金华/温州",$G$4="义乌集拼仓")),VLOOKUP("*"&I4&"*",华东限时23!C5:G84,COLUMN(华东限时23!G1)-COLUMN(华东限时23!B1),0),AND(K4="拆派",J4="不含税：0.5-10CBM之间",OR(G4="厦门/福州/泉州",G4="青岛",G4="郑州",G4="深圳/广州/中山/汕头/塘厦",G4="长沙")),VLOOKUP("*"&I4&"*",华东限时23!C5:H84,COLUMN(华东限时23!H1)-COLUMN(华东限时23!B1),0),AND(K4="拆派",J4="含税：50-1000KG之间",OR(G4="厦门/福州/泉州",G4="青岛",G4="郑州",G4="深圳/广州/中山/汕头/塘厦",G4="长沙")),VLOOKUP("*"&I4&"*",华东限时23!C5:I84,COLUMN(华东限时23!I1)-COLUMN(华东限时23!B1),0),AND(K4="拆派",J4="不含税：大于10CBM",OR(G4="厦门/福州/泉州",G4="青岛",G4="郑州",G4="深圳/广州/中山/汕头/塘厦",G4="长沙")),VLOOKUP("*"&I4&"*",华东限时23!C5:J84,COLUMN(华东限时23!J1)-COLUMN(华东限时23!B1),0),AND(K4="拆派",J4="含税：大于1000KG",OR(G4="厦门/福州/泉州",G4="青岛",G4="郑州",G4="深圳/广州/中山/汕头/塘厦",G4="长沙")),VLOOKUP("*"&I4&"*",华东限时23!C5:K84,COLUMN(华东限时23!K1)-COLUMN(华东限时23!B1),0),AND(K4="直送",J4="不含税：0.5-10CBM之间",OR(G4="苏州/宁波/上海/杭州",G4="金华/温州")),VLOOKUP("*"&I4&"*",华东限时23!#REF!,COLUMN(华东限时23!D1)-COLUMN(华东限时23!B1),0),AND(K4="直送",J4="含税：50-1000KG之间",OR(G4="苏州/宁波/上海/杭州",G4="金华/温州")),VLOOKUP("*"&I4&"*",华东限时23!#REF!,COLUMN(华东限时23!E1)-COLUMN(华东限时23!B1),0),AND(K4="直送",J4="不含税：大于10CBM",OR(G4="苏州/宁波/上海/杭州",G4="金华/温州")),VLOOKUP("*"&I4&"*",华东限时23!#REF!,COLUMN(华东限时23!F1)-COLUMN(华东限时23!B1),0),AND(K4="直送",J4="含税：大于1000KG",OR(G4="苏州/宁波/上海/杭州",G4="金华/温州")),VLOOKUP("*"&I4&"*",华东限时23!#REF!,COLUMN(华东限时23!G1)-COLUMN(华东限时23!B1),0),AND(K4="直送",J4="不含税：0.5-10CBM之间",OR(G4="厦门/福州/泉州",G4="青岛",G4="郑州",G4="深圳/广州/中山/汕头/塘厦",G4="长沙")),VLOOKUP("*"&I4&"*",华东限时23!#REF!,COLUMN(华东限时23!H1)-COLUMN(华东限时23!B1),0),AND(K4="直送",J4="含税：50-1000KG之间",OR(G4="厦门/福州/泉州",G4="青岛",G4="郑州",G4="深圳/广州/中山/汕头/塘厦",G4="长沙")),VLOOKUP("*"&I4&"*",华东限时23!#REF!,COLUMN(华东限时23!I1)-COLUMN(华东限时23!B1),0),AND(K4="直送",J4="不含税：大于10CBM",OR(G4="厦门/福州/泉州",G4="青岛",G4="郑州",G4="深圳/广州/中山/汕头/塘厦",G4="长沙")),VLOOKUP("*"&I4&"*",华东限时23!#REF!,COLUMN(华东限时23!J1)-COLUMN(华东限时23!B1),0),AND(K4="直送",J4="含税：大于1000KG",OR(G4="厦门/福州/泉州",G4="青岛",G4="郑州",G4="深圳/广州/中山/汕头/塘厦",G4="长沙")),VLOOKUP("*"&I4&"*",华东限时23!#REF!,COLUMN(华东限时23!K1)-COLUMN(华东限时23!B1),0)),"-") -> 1446 | BO12: =IFERROR(IF(BN12="-","-",VLOOKUP("*"&I4&"*",华东限时23!C5:M84,COLUMN(华东限时23!M5)-COLUMN(华东限时23!B5),0)),"-") -> 20天 | BP12: =IFERROR(IF(BN12="-","-",VLOOKUP("*"&I4&"*",华东限时23!C5:N84,COLUMN(华东限时23!N5)-COLUMN(华东限时23!B5),0)),"-") -> 22天 | BQ12: =_xlfn.IFS(BN12="-","-",$G$4="深圳/广州/中山/汕头/塘厦","塘厦:"&第27周船期!G12&"; 中山:"&第27周船期!I12&"; 广州:"&第27周船期!J12&"; 汕头:"&第27周船期!K12,$G$4="长沙","长沙："&第27周船期!L12,$G$4="厦门/福州/泉州","福州/泉州:"&第27周船期!O12&"; 厦门:"&第27周船期!P12,G4="金华/温州","金华:"&第27周船期!U12&"; 温州:"&第27周船期!T12,G4="苏州/宁波/上海/杭州","宁波:"&第27周船期!W12&"; 杭州:"&第27周船期!X12&"; 苏州:"&第27周船期!AA12&"; 上海:"&第27周船期!AB12,$G$4="郑州","郑州："&第27周船期!S12,$G$4="青岛","青岛："&第27周船期!AE12,$G$4="义乌集拼仓","义乌集拼仓："&第27周船期!V12) -> 塘厦:7-3 (18点); 中山:7-3 (12点); 广州:7-3 (12点); 汕头:7-3 (12点) | BR12: =_xlfn.IFS(BN12="-","-",OR($G$4="深圳/广州/中山/汕头/塘厦",$G$4="长沙"),第27周船期!M12,$G$4="厦门/福州/泉州",第27周船期!Q12,OR(OR(G4="苏州/宁波/上海/杭州",G4="金华/温州",$G$4="义乌集拼仓"),$G$4="郑州"),第27周船期!Y12,$G$4="青岛",第27周船期!AF12) -> 07/09 (宁波起运) | BS12: =_xlfn.IFS(BN12="-","-",OR($G$4="深圳/广州/中山/汕头/塘厦",$G$4="长沙"),第27周船期!N12,$G$4="厦门/福州/泉州",第27周船期!R12,OR(OR(G4="苏州/宁波/上海/杭州",G4="金华/温州"),$G$4="郑州",$G$4="义乌集拼仓"),第27周船期!Z12,$G$4="青岛",第27周船期!AG12) -> 07/22 (LA) | BT12: =BI12 -> 拆派 | BU12: =IFERROR(IF(BN12="-","-",VLOOKUP("*"&I4&"*",华东限时23!C5:M84,COLUMN(华东限时23!L5)-COLUMN(华东限时23!B5),0)),"-") -> 7月29日
D13: 华东限时23-US监管仓 | E13: =BN13 -> 1586 | F13: =BO13 -> 22天 | G13: =BP13 -> 24天 | H13: =BU13 -> 7月31日 | I13: =BQ13 -> 塘厦:7-3 (18点); 中山:7-3 (12点); 广州:7-3 (12点); 汕头:7-3 (12点) | M13: =BR13 -> 07/09 (宁波起运) | N13: =BS13 -> 07/22 (LA) | O13: =BT13 -> 拆派 | BM13: 华东限时23-US监管仓 | BN13: =IFERROR(_xlfn.IFS(AND(K4="拆派",J4="不含税：0.5-10CBM之间",OR(G4="苏州/宁波/上海/杭州",G4="金华/温州",$G$4="义乌集拼仓")),VLOOKUP("*"&I4&"*",'华东限时23-US监管仓'!C5:D84,COLUMN('华东限时23-US监管仓'!D1)-COLUMN('华东限时23-US监管仓'!B1),0),AND(K4="拆派",J4="含税：50-1000KG之间",OR(G4="苏州/宁波/上海/杭州",G4="金华/温州",$G$4="义乌集拼仓")),VLOOKUP("*"&I4&"*",'华东限时23-US监管仓'!C5:E84,COLUMN('华东限时23-US监管仓'!E1)-COLUMN('华东限时23-US监管仓'!B1),0),AND(K4="拆派",J4="不含税：大于10CBM",OR(G4="苏州/宁波/上海/杭州",G4="金华/温州",$G$4="义乌集拼仓")),VLOOKUP("*"&I4&"*",'华东限时23-US监管仓'!C5:F84,COLUMN('华东限时23-US监管仓'!F1)-COLUMN('华东限时23-US监管仓'!B1),0),AND(K4="拆派",J4="含税：大于1000KG",OR(G4="苏州/宁波/上海/杭州",G4="金华/温州",$G$4="义乌集拼仓")),VLOOKUP("*"&I4&"*",'华东限时23-US监管仓'!C5:G84,COLUMN('华东限时23-US监管仓'!G1)-COLUMN('华东限时23-US监管仓'!B1),0),AND(K4="拆派",J4="不含税：0.5-10CBM之间",OR(G4="厦门/福州/泉州",G4="青岛",G4="郑州",G4="深圳/广州/中山/汕头/塘厦",G4="长沙")),VLOOKUP("*"&I4&"*",'华东限时23-US监管仓'!C5:H84,COLUMN('华东限时23-US监管仓'!H1)-COLUMN('华东限时23-US监管仓'!B1),0),AND(K4="拆派",J4="含税：50-1000KG之间",OR(G4="厦门/福州/泉州",G4="青岛",G4="郑州",G4="深圳/广州/中山/汕头/塘厦",G4="长沙")),VLOOKUP("*"&I4&"*",'华东限时23-US监管仓'!C5:I84,COLUMN('华东限时23-US监管仓'!I1)-COLUMN('华东限时23-US监管仓'!B1),0),AND(K4="拆派",J4="不含税：大于10CBM",OR(G4="厦门/福州/泉州",G4="青岛",G4="郑州",G4="深圳/广州/中山/汕头/塘厦",G4="长沙")),VLOOKUP("*"&I4&"*",'华东限时23-US监管仓'!C5:J84,COLUMN('华东限时23-US监管仓'!J1)-COLUMN('华东限时23-US监管仓'!B1),0),AND(K4="拆派",J4="含税：大于1000KG",OR(G4="厦门/福州/泉州",G4="青岛",G4="郑州",G4="深圳/广州/中山/汕头/塘厦",G4="长沙")),VLOOKUP("*"&I4&"*",'华东限时23-US监管仓'!C5:K84,COLUMN('华东限时23-US监管仓'!K1)-COLUMN('华东限时23-US监管仓'!B1),0),AND(K4="直送",J4="不含税：0.5-10CBM之间",OR(G4="苏州/宁波/上海/杭州",G4="金华/温州")),VLOOKUP("*"&I4&"*",'华东限时23-US监管仓'!#REF!,COLUMN('华东限时23-US监管仓'!D1)-COLUMN('华东限时23-US监管仓'!B1),0),AND(K4="直送",J4="含税：50-1000KG之间",OR(G4="苏州/宁波/上海/杭州",G4="金华/温州")),VLOOKUP("*"&I4&"*",'华东限时23-US监管仓'!#REF!,COLUMN('华东限时23-US监管仓'!E1)-COLUMN('华东限时23-US监管仓'!B1),0),AND(K4="直送",J4="不含税：大于10CBM",OR(G4="苏州/宁波/上海/杭州",G4="金华/温州")),VLOOKUP("*"&I4&"*",'华东限时23-US监管仓'!#REF!,COLUMN('华东限时23-US监管仓'!F1)-COLUMN('华东限时23-US监管仓'!B1),0),AND(K4="直送",J4="含税：大于1000KG",OR(G4="苏州/宁波/上海/杭州",G4="金华/温州")),VLOOKUP("*"&I4&"*",'华东限时23-US监管仓'!#REF!,COLUMN('华东限时23-US监管仓'!G1)-COLUMN('华东限时23-US监管仓'!B1),0),AND(K4="直送",J4="不含税：0.5-10CBM之间",OR(G4="厦门/福州/泉州",G4="青岛",G4="郑州",G4="深圳/广州/中山/汕头/塘厦",G4="长沙")),VLOOKUP("*"&I4&"*",'华东限时23-US监管仓'!#REF!,COLUMN('华东限时23-US监管仓'!H1)-COLUMN('华东限时23-US监管仓'!B1),0),AND(K4="直送",J4="含税：50-1000KG之间",OR(G4="厦门/福州/泉州",G4="青岛",G4="郑州",G4="深圳/广州/中山/汕头/塘厦",G4="长沙")),VLOOKUP("*"&I4&"*",'华东限时23-US监管仓'!#REF!,COLUMN('华东限时23-US监管仓'!I1)-COLUMN('华东限时23-US监管仓'!B1),0),AND(K4="直送",J4="不含税：大于10CBM",OR(G4="厦门/福州/泉州",G4="青岛",G4="郑州",G4="深圳/广州/中山/汕头/塘厦",G4="长沙")),VLOOKUP("*"&I4&"*",'华东限时23-US监管仓'!#REF!,COLUMN('华东限时23-US监管仓'!J1)-COLUMN('华东限时23-US监管仓'!B1),0),AND(K4="直送",J4="含税：大于1000KG",OR(G4="厦门/福州/泉州",G4="青岛",G4="郑州",G4="深圳/广州/中山/汕头/塘厦",G4="长沙")),VLOOKUP("*"&I4&"*",'华东限时23-US监管仓'!#REF!,COLUMN('华东限时23-US监管仓'!K1)-COLUMN('华东限时23-US监管仓'!B1),0)),"-") -> 1586 | BO13: =IFERROR(IF(BN13="-","-",VLOOKUP("*"&I4&"*",'华东限时23-US监管仓'!C5:M84,COLUMN('华东限时23-US监管仓'!M5)-COLUMN('华东限时23-US监管仓'!B5),0)),"-") -> 22天 | BP13: =IFERROR(IF(BN13="-","-",VLOOKUP("*"&I4&"*",'华东限时23-US监管仓'!C5:N84,COLUMN('华东限时23-US监管仓'!N5)-COLUMN('华东限时23-US监管仓'!B5),0)),"-") -> 24天 | BQ13: =_xlfn.IFS(BN13="-","-",$G$4="深圳/广州/中山/汕头/塘厦","塘厦:"&第27周船期!G12&"; 中山:"&第27周船期!I12&"; 广州:"&第27周船期!J12&"; 汕头:"&第27周船期!K12,$G$4="长沙","长沙："&第27周船期!L12,$G$4="厦门/福州/泉州","福州/泉州:"&第27周船期!O12&"; 厦门:"&第27周船期!P12,G4="金华/温州","金华:"&第27周船期!U12&"; 温州:"&第27周船期!T12,G4="苏州/宁波/上海/杭州","宁波:"&第27周船期!W12&"; 杭州:"&第27周船期!X12&"; 苏州:"&第27周船期!AA12&"; 上海:"&第27周船期!AB12,$G$4="郑州","郑州："&第27周船期!S12,$G$4="青岛","青岛："&第27周船期!AE12,$G$4="义乌集拼仓","义乌集拼仓："&第27周船期!V12) -> 塘厦:7-3 (18点); 中山:7-3 (12点); 广州:7-3 (12点); 汕头:7-3 (12点) | BR13: =_xlfn.IFS(BN13="-","-",OR($G$4="深圳/广州/中山/汕头/塘厦",$G$4="长沙"),第27周船期!M12,$G$4="厦门/福州/泉州",第27周船期!Q12,OR(OR(G4="苏州/宁波/上海/杭州",G4="金华/温州",$G$4="义乌集拼仓"),$G$4="郑州"),第27周船期!Y12,$G$4="青岛",第27周船期!AF12) -> 07/09 (宁波起运) | BS13: =_xlfn.IFS(BN13="-","-",OR($G$4="深圳/广州/中山/汕头/塘厦",$G$4="长沙"),第27周船期!N12,$G$4="厦门/福州/泉州",第27周船期!R12,OR(OR(G4="苏州/宁波/上海/杭州",G4="金华/温州"),$G$4="郑州",$G$4="义乌集拼仓"),第27周船期!Z12,$G$4="青岛",第27周船期!AG12) -> 07/22 (LA) | BT13: =BI12 -> 拆派 | BU13: =IFERROR(IF(BN13="-","-",VLOOKUP("*"&I4&"*",'华东限时23-US监管仓'!C5:M84,COLUMN('华东限时23-US监管仓'!L5)-COLUMN('华东限时23-US监管仓'!B5),0)),"-") -> 7月31日
D14: 华东限时 23-一体化 | E14: =BN14 -> 1386 | F14: =BO14 -> 20天 | G14: =BP14 -> 22天 | H14: =BU14 -> 7月29日 | I14: =BQ14 -> 塘厦:7-3 (18点); 中山:7-3 (12点); 广州:7-3 (12点); 汕头:7-3 (12点) | M14: =BR14 -> 07/09 (宁波起运) | N14: =BS14 -> 07/22 (LA) | O14: =BT14 -> 拆派 | BM14: 华东限时 23-一体化 | BN14: =IFERROR(_xlfn.IFS(AND(K4="拆派",J4="不含税：0.5-10CBM之间",OR(G4="苏州/宁波/上海/杭州",G4="金华/温州")),VLOOKUP("*"&I4&"*",'华东限时23-一体化'!C5:D84,COLUMN('华东限时23-一体化'!D1)-COLUMN('华东限时23-一体化'!B1),0),AND(K4="拆派",J4="含税：50-1000KG之间",OR(G4="苏州/宁波/上海/杭州",G4="金华/温州")),VLOOKUP("*"&I4&"*",'华东限时23-一体化'!C5:E84,COLUMN('华东限时23-一体化'!E1)-COLUMN('华东限时23-一体化'!B1),0),AND(K4="拆派",J4="不含税：大于10CBM",OR(G4="苏州/宁波/上海/杭州",G4="金华/温州")),VLOOKUP("*"&I4&"*",'华东限时23-一体化'!C5:F84,COLUMN('华东限时23-一体化'!F1)-COLUMN('华东限时23-一体化'!B1),0),AND(K4="拆派",J4="含税：大于1000KG",OR(G4="苏州/宁波/上海/杭州",G4="金华/温州")),VLOOKUP("*"&I4&"*",'华东限时23-一体化'!C5:G84,COLUMN('华东限时23-一体化'!G1)-COLUMN('华东限时23-一体化'!B1),0),AND(K4="拆派",J4="不含税：0.5-10CBM之间",OR(G4="厦门/福州/泉州",G4="青岛",G4="郑州",G4="深圳/广州/中山/汕头/塘厦",G4="长沙")),VLOOKUP("*"&I4&"*",'华东限时23-一体化'!C5:H84,COLUMN('华东限时23-一体化'!H1)-COLUMN('华东限时23-一体化'!B1),0),AND(K4="拆派",J4="含税：50-1000KG之间",OR(G4="厦门/福州/泉州",G4="青岛",G4="郑州",G4="深圳/广州/中山/汕头/塘厦",G4="长沙")),VLOOKUP("*"&I4&"*",'华东限时23-一体化'!C5:I84,COLUMN('华东限时23-一体化'!I1)-COLUMN('华东限时23-一体化'!B1),0),AND(K4="拆派",J4="不含税：大于10CBM",OR(G4="厦门/福州/泉州",G4="青岛",G4="郑州",G4="深圳/广州/中山/汕头/塘厦",G4="长沙")),VLOOKUP("*"&I4&"*",'华东限时23-一体化'!C5:J84,COLUMN('华东限时23-一体化'!J1)-COLUMN('华东限时23-一体化'!B1),0),AND(K4="拆派",J4="含税：大于1000KG",OR(G4="厦门/福州/泉州",G4="青岛",G4="郑州",G4="深圳/广州/中山/汕头/塘厦",G4="长沙")),VLOOKUP("*"&I4&"*",'华东限时23-一体化'!C5:K84,COLUMN('华东限时23-一体化'!K1)-COLUMN('华东限时23-一体化'!B1),0),AND(K4="直送",J4="不含税：0.5-10CBM之间",OR(G4="苏州/宁波/上海/杭州",G4="金华/温州")),VLOOKUP("*"&I4&"*",'华东限时23-一体化'!#REF!,COLUMN('华东限时23-一体化'!D1)-COLUMN('华东限时23-一体化'!B1),0),AND(K4="直送",J4="含税：50-1000KG之间",OR(G4="苏州/宁波/上海/杭州",G4="金华/温州")),VLOOKUP("*"&I4&"*",'华东限时23-一体化'!#REF!,COLUMN('华东限时23-一体化'!E1)-COLUMN('华东限时23-一体化'!B1),0),AND(K4="直送",J4="不含税：大于10CBM",OR(G4="苏州/宁波/上海/杭州",G4="金华/温州")),VLOOKUP("*"&I4&"*",'华东限时23-一体化'!#REF!,COLUMN('华东限时23-一体化'!F1)-COLUMN('华东限时23-一体化'!B1),0),AND(K4="直送",J4="含税：大于1000KG",OR(G4="苏州/宁波/上海/杭州",G4="金华/温州")),VLOOKUP("*"&I4&"*",'华东限时23-一体化'!#REF!,COLUMN('华东限时23-一体化'!G1)-COLUMN('华东限时23-一体化'!B1),0),AND(K4="直送",J4="不含税：0.5-10CBM之间",OR(G4="厦门/福州/泉州",G4="青岛",G4="郑州",G4="深圳/广州/中山/汕头/塘厦",G4="长沙")),VLOOKUP("*"&I4&"*",'华东限时23-一体化'!#REF!,COLUMN('华东限时23-一体化'!H1)-COLUMN('华东限时23-一体化'!B1),0),AND(K4="直送",J4="含税：50-1000KG之间",OR(G4="厦门/福州/泉州",G4="青岛",G4="郑州",G4="深圳/广州/中山/汕头/塘厦",G4="长沙")),VLOOKUP("*"&I4&"*",'华东限时23-一体化'!#REF!,COLUMN('华东限时23-一体化'!I1)-COLUMN('华东限时23-一体化'!B1),0),AND(K4="直送",J4="不含税：大于10CBM",OR(G4="厦门/福州/泉州",G4="青岛",G4="郑州",G4="深圳/广州/中山/汕头/塘厦",G4="长沙")),VLOOKUP("*"&I4&"*",'华东限时23-一体化'!#REF!,COLUMN('华东限时23-一体化'!J1)-COLUMN('华东限时23-一体化'!B1),0),AND(K4="直送",J4="含税：大于1000KG",OR(G4="厦门/福州/泉州",G4="青岛",G4="郑州",G4="深圳/广州/中山/汕头/塘厦",G4="长沙")),VLOOKUP("*"&I4&"*",'华东限时23-一体化'!#REF!,COLUMN('华东限时23-一体化'!K1)-COLUMN('华东限时23-一体化'!B1),0)),"-") -> 1386 | BO14: =IFERROR(IF(BN14="-","-",VLOOKUP("*"&I4&"*",'华东限时23-一体化'!C5:M84,COLUMN('华东限时23-一体化'!M5)-COLUMN('华东限时23-一体化'!B5),0)),"-") -> 20天 | BP14: =IFERROR(IF(BN14="-","-",VLOOKUP("*"&I4&"*",'华东限时23-一体化'!C5:N84,COLUMN('华东限时23-一体化'!N5)-COLUMN('华东限时23-一体化'!B5),0)),"-") -> 22天 | BQ14: =_xlfn.IFS(BN14="-","-",$G$4="深圳/广州/中山/汕头/塘厦","塘厦:"&第27周船期!G12&"; 中山:"&第27周船期!I12&"; 广州:"&第27周船期!J12&"; 汕头:"&第27周船期!K12,$G$4="长沙","长沙："&第27周船期!L12,$G$4="厦门/福州/泉州","福州/泉州:"&第27周船期!O12&"; 厦门:"&第27周船期!P12,G4="金华/温州","金华:"&第27周船期!U12&"; 温州:"&第27周船期!T12,G4="苏州/宁波/上海/杭州","宁波:"&第27周船期!W12&"; 杭州:"&第27周船期!X12&"; 苏州:"&第27周船期!AA12&"; 上海:"&第27周船期!AB12,$G$4="郑州","郑州："&第27周船期!S12,$G$4="青岛","青岛："&第27周船期!AE12) -> 塘厦:7-3 (18点); 中山:7-3 (12点); 广州:7-3 (12点); 汕头:7-3 (12点) | BR14: =_xlfn.IFS(BN14="-","-",OR($G$4="深圳/广州/中山/汕头/塘厦",$G$4="长沙"),第27周船期!M12,$G$4="厦门/福州/泉州",第27周船期!Q12,OR(OR(G4="苏州/宁波/上海/杭州",G4="金华/温州"),$G$4="郑州"),第27周船期!Y12,$G$4="青岛",第27周船期!AF12) -> 07/09 (宁波起运) | BS14: =_xlfn.IFS(BN14="-","-",OR($G$4="深圳/广州/中山/汕头/塘厦",$G$4="长沙"),第27周船期!N12,$G$4="厦门/福州/泉州",第27周船期!R12,OR(OR(G4="苏州/宁波/上海/杭州",G4="金华/温州"),$G$4="郑州"),第27周船期!Z12,$G$4="青岛",第27周船期!AG12) -> 07/22 (LA) | BT14: =BI12 -> 拆派 | BU14: =IFERROR(IF(BN14="-","-",VLOOKUP("*"&I4&"*",'华东限时23-一体化'!C5:M84,COLUMN('华东限时23-一体化'!L5)-COLUMN('华东限时23-一体化'!B5),0)),"-") -> 7月29日
C15: Z快线系列 | D15: Z快线-美西 | E15: =BN15 -> 1331 | F15: =BO15 -> 20天 | G15: =BP15 -> 22天 | H15: =BU15 -> 7月28日 | I15: =BQ15 -> 塘厦:7-4 (18点); 中山:7-3 (18点); 广州:7-4 (18点); 汕头:7-3 (18点) | M15: =BR15 -> 07/08 (深圳起运) | N15: =BS15 -> 07/21 (LA) | O15: =BT15 -> 拆派 | BI15: =_xlfn.IFS($G$4="义乌集拼仓","此国内仓不收该渠道",COUNTIF('Z快线-美西'!C6:C85,"*"&I4&"*")=0,"渠道无此仓",K4="直送",IF(COUNTIF('Z快线-美西'!C6:C123,"*"&I4&"*")=0,"无此仓直送","直送"),K4="拆派",IF(COUNTIF('Z快线-美西'!C6:C85,"*"&I4&"*")=0,"无此仓拆派","拆派")) -> 拆派 | BL15: Z快线系列 | BM15: Z快线-美西 | BN15: =IFERROR(_xlfn.IFS(AND(K4="拆派",J4="不含税：0.5-10CBM之间",G4="深圳/广州/中山/汕头/塘厦"),VLOOKUP("*"&I4&"*",'Z快线-美西'!C6:D85,COLUMN('Z快线-美西'!D1)-COLUMN('Z快线-美西'!B1),0),AND(K4="拆派",J4="含税：50-1000KG之间",G4="深圳/广州/中山/汕头/塘厦"),VLOOKUP("*"&I4&"*",'Z快线-美西'!C6:E85,COLUMN('Z快线-美西'!E1)-COLUMN('Z快线-美西'!B1),0),AND(K4="拆派",J4="不含税：大于10CBM",G4="深圳/广州/中山/汕头/塘厦"),VLOOKUP("*"&I4&"*",'Z快线-美西'!C6:F85,COLUMN('Z快线-美西'!F1)-COLUMN('Z快线-美西'!B1),0),AND(K4="拆派",J4="含税：大于1000KG",G4="深圳/广州/中山/汕头/塘厦"),VLOOKUP("*"&I4&"*",'Z快线-美西'!C6:G85,COLUMN('Z快线-美西'!G1)-COLUMN('Z快线-美西'!B1),0),AND(K4="拆派",J4="不含税：0.5-10CBM之间",OR(G4="厦门/福州/泉州",G4="长沙")),VLOOKUP("*"&I4&"*",'Z快线-美西'!C6:H85,COLUMN('Z快线-美西'!H1)-COLUMN('Z快线-美西'!B1),0),AND(K4="拆派",J4="含税：50-1000KG之间",OR(G4="厦门/福州/泉州",G4="长沙")),VLOOKUP("*"&I4&"*",'Z快线-美西'!C6:I85,COLUMN('Z快线-美西'!I1)-COLUMN('Z快线-美西'!B1),0),AND(K4="拆派",J4="不含税：大于10CBM",OR(G4="厦门/福州/泉州",G4="长沙")),VLOOKUP("*"&I4&"*",'Z快线-美西'!C6:J85,COLUMN('Z快线-美西'!J1)-COLUMN('Z快线-美西'!B1),0),AND(K4="拆派",J4="含税：大于1000KG",OR(G4="厦门/福州/泉州",G4="长沙")),VLOOKUP("*"&I4&"*",'Z快线-美西'!C6:K85,COLUMN('Z快线-美西'!K1)-COLUMN('Z快线-美西'!B1),0),AND(K4="直送",J4="不含税：0.5-10CBM之间",G4="深圳/广州/中山/汕头/塘厦"),VLOOKUP("*"&I4&"*",'Z快线-美西'!#REF!,COLUMN('Z快线-美西'!D1)-COLUMN('Z快线-美西'!B1),0),AND(K4="直送",J4="含税：50-1000KG之间",G4="深圳/广州/中山/汕头/塘厦"),VLOOKUP("*"&I4&"*",'Z快线-美西'!#REF!,COLUMN('Z快线-美西'!E1)-COLUMN('Z快线-美西'!B1),0),AND(K4="直送",J4="不含税：大于10CBM",G4="深圳/广州/中山/汕头/塘厦"),VLOOKUP("*"&I4&"*",'Z快线-美西'!#REF!,COLUMN('Z快线-美西'!F1)-COLUMN('Z快线-美西'!B1),0),AND(K4="直送",J4="含税：大于1000KG",G4="深圳/广州/中山/汕头/塘厦"),VLOOKUP("*"&I4&"*",'Z快线-美西'!#REF!,COLUMN('Z快线-美西'!G1)-COLUMN('Z快线-美西'!B1),0),AND(K4="直送",J4="不含税：0.5-10CBM之间",OR(G4="厦门/福州/泉州",G4="长沙")),VLOOKUP("*"&I4&"*",'Z快线-美西'!#REF!,COLUMN('Z快线-美西'!H1)-COLUMN('Z快线-美西'!B1),0),AND(K4="直送",J4="含税：50-1000KG之间",OR(G4="厦门/福州/泉州",G4="长沙")),VLOOKUP("*"&I4&"*",'Z快线-美西'!#REF!,COLUMN('Z快线-美西'!I1)-COLUMN('Z快线-美西'!B1),0),AND(K4="直送",J4="不含税：大于10CBM",OR(G4="厦门/福州/泉州",G4="长沙")),VLOOKUP("*"&I4&"*",'Z快线-美西'!#REF!,COLUMN('Z快线-美西'!J1)-COLUMN('Z快线-美西'!B1),0),AND(K4="直送",J4="含税：大于1000KG",OR(G4="厦门/福州/泉州",G4="长沙")),VLOOKUP("*"&I4&"*",'Z快线-美西'!#REF!,COLUMN('Z快线-美西'!K1)-COLUMN('Z快线-美西'!B1),0)),"-") -> 1331 | BO15: =IFERROR(IF(BN15="-","-",VLOOKUP("*"&I4&"*",'Z快线-美西'!C6:M85,COLUMN('Z快线-美西'!M6)-COLUMN('Z快线-美西'!B6),0)),"-") -> 20天 | BP15: =IFERROR(IF(BN15="-","-",VLOOKUP("*"&I4&"*",'Z快线-美西'!C6:N85,COLUMN('Z快线-美西'!N6)-COLUMN('Z快线-美西'!B6),0)),"-") -> 22天 | BQ15: =_xlfn.IFS(BN15="-","-",$G$4="深圳/广州/中山/汕头/塘厦","塘厦:"&第27周船期!G7&"; 中山:"&第27周船期!I7&"; 广州:"&第27周船期!J7&"; 汕头:"&第27周船期!K7,$G$4="长沙","长沙："&第27周船期!L7,$G$4="厦门/福州/泉州","福州/泉州:"&第27周船期!O7&"; 厦门:"&第27周船期!P7,G4="金华/温州","金华:"&第27周船期!U7&"; 温州:"&第27周船期!T7,G4="苏州/宁波/上海/杭州","宁波:"&第27周船期!W7&"; 杭州:"&第27周船期!X7&"; 苏州:"&第27周船期!AA7&"; 上海:"&第27周船期!AB7,$G$4="郑州","郑州："&第27周船期!S7,$G$4="青岛","青岛："&第27周船期!AE7) -> 塘厦:7-4 (18点); 中山:7-3 (18点); 广州:7-4 (18点); 汕头:7-3 (18点) | BR15: =_xlfn.IFS(BN15="-","-",OR($G$4="深圳/广州/中山/汕头/塘厦",$G$4="长沙"),第27周船期!M7,$G$4="厦门/福州/泉州",第27周船期!Q7,OR(OR(G4="苏州/宁波/上海/杭州",G4="金华/温州"),$G$4="郑州"),第27周船期!Y7,$G$4="青岛",第27周船期!AF7) -> 07/08 (深圳起运) | BS15: =_xlfn.IFS(BN15="-","-",OR($G$4="深圳/广州/中山/汕头/塘厦",$G$4="长沙"),第27周船期!N7,$G$4="厦门/福州/泉州",第27周船期!R7,OR(OR(G4="苏州/宁波/上海/杭州",G4="金华/温州"),$G$4="郑州"),第27周船期!Z7,$G$4="青岛",第27周船期!AG7) -> 07/21 (LA) | BT15: =BI15 -> 拆派 | BU15: =IFERROR(IF(BN15="-","-",VLOOKUP("*"&I4&"*",'Z快线-美西'!C6:M85,COLUMN('Z快线-美西'!L6)-COLUMN('Z快线-美西'!B6),0)),"-") -> 7月28日
