Workbook

Sheet 目录
A1: 深圳市博创兴供应链有限公司 Your Global Chance, We Deliver
A4: 国家 | B4: 渠道类型 | C4: 渠道名称 | D4: 价格表 | E4: 渠道特点 | F4: 最新动态
A5: 美国 | B5: 海派专线 | C5: 美森正班 | D5: 进入报价表 | E5: 美森正班船，船期准点，时效快且稳！
C6: 以星合德 | E6: 以星合德带车架服务，时效稳定有保障
C7: OA快船 | E7: OA，价优时效快捷 （纯正OA）
B8: 经济线 | C8: 直送~经济线 | D8: 进入报价表 | E8: 普船统配，航期16~20天，75%保柜率
B9: 美中专线 | C9: 休斯顿专线 | D9: 进入报价表 | E9: 休斯顿直航，覆盖7邮编的卡派
C10: 芝加哥专线 | D10: 进入报价表 | E10: 芝加哥专线，覆盖美中4~6邮编的卡派
B11: 美东专线 | C11: 纽约专线 | D11: 进入报价表 | E11: 纽约直航，覆盖美东区域0~3邮编的卡派
C12: 纽约快速达 | E12: 以星（COSCO）铁路快线快船转纽约，美东性价比首选
B13: 萨瓦纳专线 | C13: 萨瓦纳专线 | D13: 进入报价表 | E13: 美东南18仓普船价格性价比高
B14: 美西快线 | C14: 美森正班 | D14: 进入报价表 | E14: 美森正班船，船期准点，时效快且稳！
C15: 以星合德 | E15: 以星合德带车架服务，时效稳定有保障
C16: OA快船 | E16: OA，价优时效快捷 （纯正OA）
A17: 加拿大 | B17: 加拿大直航 | C17: 多伦多专线 | D17: 进入报价表 | E17: 加拿大直航，时效优，航线优，价格优，服务优
C18: 温哥华专线
C19: 卡尔加里专线
B20: 美转加 | C20: 美森正班 | D20: 进入报价表 | E20: 头程至美国，二程转派加拿大
C21: 以星合德
C22: OA快船
B23: 美转加海派 | C23: 美森正班 | D23: 进入报价表 | E23: 加拿大直航，时效优，航线优，价格优，服务优
C24: 以星合德 | E24: 头程至美国，二程转派加拿大
C25: OA快船
A26: 其它 | B26: 发货必读 | D26: 点击进入 | E26: 附加费、开查、赔偿等说明
B27: 船期表 | D27: 点击进入 | E27: 每周更新
B28: 反倾销列表 | D28: 点击进入 | E28: 附加费、开查、赔偿等说明

Sheet 发货必读
A1: 发货必读
A2: 附加费 | B2: 费用类型 | C2: 海卡专线 | D2: 海卡专线CBM | E2: 海派 | G2: 国内仓增值服务
B3: 末端派送类型 | C3: 卡派 | E3: UPS*FEDEX | G3: 收费项目 | H3: 单价*RMB | I3: 单位 | J3: 最低消费 | K3: 备注
A4: 报关费 | B4: 代理报关 | C4: 0 | G4: 更改包装费 | H4: 10 | I4: 箱 | J4: 20 | K4: 不含纸箱费用
B5: 一般贸易报关费 | C5: 350*份(超过5个品名，需加收续页费¥50*页) | G5: 产品贴标签 | H5: 0.5 | I5: 个标签 | J5: 20 | K5: 含标签纸
B6: 手册报关 | C6: 盐田出口500*份，其他口岸无服务 | G6: 换外箱标签 | H6: 1 | I6: 个标签 | J6: 20 | K6: 含标签纸
A7: 产品附加费 | B7: 纺织品 | C7: 1*KG | D7: 0 | E7: 1*KG | G7: 割包装袋*带 | H7: 1 | I7: 箱 | J7: 20
B8: 床上用品-美线 | C8: 0.5*KG | D8: 0 | E8: 0.5*KG | G8: 开木箱查货 | H8: 30 | I8: 箱 | J8: 30 | K8: 含封箱
B9: 床上用品-加线 | C9: 1*KG | D9: 0 | E9: 1*KG | G9: 开箱拍照 | H9: 10 | I9: 票 | J9: 10 | K9: 含操作耗材
B10: 钢制品*铝制品 | C10: 1*KG | D10: 0 | E10: 1*KG | G10: 拆单合票 | H10: 1 | I10: 箱 | J10: 20 | K10: 含二次分货
B11: 汽车配件 | C11: 0.5*KG | D11: 0 | E11: 0.5*KG | G11: 国内退货 | H11: 2 | I11: 箱 | J11: 10 | K11: 含装卸费
B12: 木制品（报关件单询） | C12: 1*KG | D12: 500*票 | E12: 1*KG | G12: 仓租 | H12: 3.5*天 | I12: CBM | J12: 50RMB,，不足一个方按一个方计算 | K12: 自入仓日起免租期7天
B13: 二类医疗 | C13: 无服务 | G13: 仓租 | H13: 5*天 | I13: CBM | K13: 超过1个月出货
B14: EPA\DOT产品 | C14: 180*票（需提供符合目的地海关要求的认证 ） | G14: 仓租 | H14: 7*天 | I14: CBM | K14: 超过2个月出货
B15: 涉FDA产品 | C15: 180RMB*品名
B16: 厨房刀具\太阳能产品\笔 | C16: 1*KG | D16: 150*CBM | E16: 1*KG
B17: 移动电源\纯电池\暖手宝 | C17: 1*KG | D17: 150*CBM | E17: 1*KG
A18: 超尺寸货物附加费 | B18: 120cm≤最长边＜140cm | C18: 0 | E18: 100*件
B19: 140cm≤最长边＜175cm | C19: 1*KG | D19: 190*CBM | E19: 100*件
B20: 单边≥175cm的单询 | C20: 单询 | E20: 无服务
B21: 第二边长≥76cm | C21: 0 | E21: 100*件
B22: 22.5KG≤实重≤40KG | C22: 0 | E22: 120*件
B23: 实重＞40KG | C23: 单询 | E23: 无服务
B24: 260cm≤长+2x(宽+高)≤320cm | C24: 0 | E24: 100*件
B25: 320cm≤长+2x(宽+高)≤390cm | C25: 单询 | E25: 无服务
B26: 长+2x(宽+高)＞390cm | C26: 无服务
B27: 玩具附加费 | C27: 1*KG
B28: 超箱附加费 | C28: 单箱尺寸小于0.05CBM的货物，收取超箱数附加RMB2/箱
A29: 其他附加费 | B29: 清关超品名费（5个以上起收) | C29: 30RMB*品名
B30: 美国 CPC/GCC eFiling 新规申报费 | C30: 1.我司拒接涉CPC儿童产品（客户使用自有进口商以外，且须提供指定机构的有效CPC等认证及申报）。 2.GCC成人消费品，需在发货前提供完整GCC证书，若因无法提供且产品不达质量要求，导致的没收与店铺损失需客户自行承担。 3.代申报服务费：180元/品名(按认证）
B31: 目的港扣货 | C31: 拆柜前 | D31: USD100*票 同柜扣多票+USD50*票 封顶USD200*柜 (加拿大扣货费150USD*票，同柜扣多票+USD100*票） 不保证扣货一定成功，不承担失败产生的费用
C32: 拆柜后 | D32: 扣货费USD200*票+重新分货费USD2*件(低消50USD*票) 同柜扣多票+USD50*票+重新分货费USD2*件（低消50USD*票） (加拿大扣货费150USD*票，同柜扣多票+USD100*票） 不保证扣货一定成功，不承担失败产生的费用
B33: 申请POD | C33: 免费 | E33: 35*RMB主单号
B34: 退运附加费 | C34: 包税渠道需要我司包含5H和9H退运，表价单价自行+1RMB/KG , 不含税+ 200RMB/CBM, 如不需要我司包5H和9H退运，遇到美国海关5H/9H查验，相关仓租、柜租、查验费、退运指定启运港的来回运费 ,产生相关所有费用由客户自行承担，我司实报实销。 但不包含贴标换标费、暂存仓租费，不含改派送地址的派送费(实际派送地址-原先派送地址，差价多退少补)
B35: 卡派私人仓*自提 | C35: 提柜起免租7天，30天内USD1*CBM*天,第31~60天收取USD1.5*CBM*天,第61~90天收取USD2*CBM*天,第91~180天收取USD3*CBM*天,超出180天单询（低消1CBM） 非FBA地址打托只接受混合打板（不分客户，不分唛头，没有任何区分要求)， 如需一一对应，单独打托（（举例：如单个SKU等。是指要求按唛头打板，不接受任何形式的混打）），请单询价格；
A36: 方数换算重货 | C36: * | D36: 每363KG=1CBM | E36: *
A37: 方式计算算重结 | C37: * | D37: CBM结算重保留两位小数 | E37: *
A38: 拒收产品 | B38: 1、带有以下标识：LASER，ACT等授权认证的产品（无论是否有认证）
B39: 2、手机、笔记本电脑、各国国旗，婴儿用品（包括衣服），激光产品，蝴蝶刀、液体、粉末、U盘、光驱、内存条、家具、指尖陀螺、电弧打火机，手机，带压缩机产品，活性植物，太阳眼镜、化妆品、铅笔等
B40: 3、仿牌产品，液体、粉末、食品、药品、易燃易爆、古董、货币等国家禁止出口产品，如发现罚款2000*票，情节严重上报公安局处理
...

Sheet 船期表
A1: 深圳市博创兴供应链有限公司 Your Global Chance, We Deliver
A4: 渠道名称 | C4: 仓库 | D4: 船司 | E4: 截收货 | F4: 船名*航次 | G4: ETD | H4: ETA
A5: 美西快线 美西海派 | B5: 美森正班CLX | C5: 深圳 | D5: MAT | E5: 46207 | F5: DANIEL K. INOUYE 099E | G5: 46211 | H5: 46222
C6: 义乌 | D6: MAT | E6: 46207 | F6: DANIEL K. INOUYE 099E | G6: 46211 | H6: 46222
B7: ZIM*合德带托快提 | C7: 深圳 | D7: ZIM/HEDE | E7: 46207 | F7: MISSISSIPPI 18E（带车架拥有快卸快提服务） HANSA DUBURG 2606E（ETD7.8 ETA7.22） | G7: 46211 | H7: 46224
C8: 义乌 | D8: HEDE | E8: 46207 | F8: PONTRESINA 2606E（ETD7.9 ETA7.22） | G8: 46212 | H8: 46225
B9: EMC快速达 | C9: 深圳 | D9: EMC/ZIM/HEDE | E9: 46207 | F9: EVER MEMO 1461-012E（ETD7.7 ETA 7.21）MISSISSIPPI 18E（ETD7.8 ETA7.21） HANSA DUBURG 2606E（ETD7.8 ETA7.22） | G9: 46211 | H9: 46225
C10: 义乌 | D10: COSCO/HEDE | E10: 46207 | F10: CSCL BOHAI SEA 077E（ETD7.9 ETA7.22） PONTRESINA 2606E（ETD7.9 ETA7.22） | G10: 46212 | H10: 46227
B11: OA快船 | C11: 深圳 | D11: EMC/COSCO | E11: 46207 | F11: COSCO SHIPPING DENALI 054E | G11: 46212 | H11: 46227
E12: 46212 | F12: EVER LOYAL 0022-076E（ETD7.14 ETA 7.28） OOCL LONDON 124E（ETD7.14 ETA7.28） | G12: 46217 | H12: 46227
C13: 义乌 | D13: EMC/COSCO | E13: 46207 | F13: EVER LIVELY 1228-078E（ETD7.7 ETA 7.22） CSCL BOHAI SEA 077E（ETD7.9 ETA7.22） CSCL YELLOW SEA 071E（ETD7.9 ETA7.23） COSCO PORTUGAL 083E（ETD7.7 ETA7.20） | G13: 46212 | H13: 46227
A14: 美中专线 | B14: 芝加哥普船卡派 | C14: 深圳 | D14: EMC/COSCO | E14: 46207 | F14: EVER MEMO 1461-012E（ETD7.7 ETA 7.21） COSCO SHIPPING DENALI 054E（ETD7.9 ETA7.24） | G14: 46212 | H14: 46238
C15: 义乌 | D15: COSCO | E15: 46207 | F15: CSCL BOHAI SEA 077E（ETD7.9 ETA7.22） COSCO PORTUGAL 083E（ETD7.7 ETA7.20） | G15: 46212 | H15: 46238
B16: 芝加哥快速达卡派包税 | C16: 深圳 | D16: ZIM | E16: 46207 | F16: MISSISSIPPI 18E | G16: 46211 | H16: 46231
C17: 义乌 | D17: ZIM | E17: 46206 | F17: MISSISSIPPI 18E | G17: 46211 | H17: 46233
B18: 休斯顿专线卡派 | C18: 深圳 | D18: EMC | E18: 46209 | F18: XIN YA ZHOU 176E | G18: 46215 | H18: 46243
C19: 义乌 | D19: COSCO | E19: 46206 | F19: XIN YA ZHOU 176E（ETD7.8 ETA8.7） CMA CGM RHONE 0PGO5E1MA | G19: 46215 | H19: 46248
A20: 萨凡纳专线 | B20: 萨凡纳专线 | C20: 深圳 | D20: EMC | E20: 46209 | F20: EVER MERCY 1366-007E | G20: 46213 | H20: 46245
C21: 义乌 | D21: COSCO | E21: 46206 | F21: OOCL KOREA 058E（ETD7.10 ETA8.6） OOCL KAPOK 004E（ETD7.9 ETA8.9） EVER FULL 1274E（ETD7.13 ETA8.14） | G21: 46216 | H21: 46246
A22: 美东专线 | B22: 纽约普船 | C22: 深圳 | D22: EMC | E22: 46209 | F22: OOCL LAVENDER 003E | G22: 46215 | H22: 46247
C23: 义乌 | D23: COSCO | E23: 46206 | F23: OOCL KOREA 058E（ETD7.10 ETA8.6） OOCL KAPOK 004E（ETD7.9 ETA8.4） | G23: 46213 | H23: 46239
B24: 纽约快船 | C24: 深圳 | D24: COSCO | E24: 46207 | F24: COSCO SHIPPING DENALI 054E | G24: 46212 | H24: 46232
C25: 义乌 | D25: COSCO | E25: 46205 | F25: COSCO SHIPPING DENALI 054E | G25: 46212 | H25: 46232
B26: 纽约特快 | C26: 深圳 | D26: ZIM | E26: 46207 | F26: MISSISSIPPI 18E | G26: 46211 | H26: 46231
C27: 义乌 | D27: ZIM | E27: 46206 | F27: MISSISSIPPI 18E | G27: 46211 | H27: 46231
A28: 加拿大直航 | B28: 温哥华 | C28: 深圳 | D28: COSCO | E28: 46209 | F28: OOCL SAN FRANCISCO 197E | G28: 46213 | H28: 46233
C29: 义乌 | D29: COSCO | E29: 46208 | F29: OOCL SAN FRANCISCO 197E | G29: 46213 | H29: 46233
B30: 多伦多 | C30: 深圳 | D30: COSCO | E30: 46209 | F30: XIN RI ZHAO 393N | G30: 46211 | H30: 46239
B31: 多伦多 | C31: 义乌 | D31: COSCO | E31: 46208 | F31: COSCO JEDDAH 096N（ETD7.7 ETA7.22） XIN RI ZHAO 393N | G31: 46211 | H31: 46239
B32: 卡尔加里 | C32: 深圳 | D32: COSCO | E32: 46209 | F32: OOCL SAN FRANCISCO 197E | G32: 46213 | H32: 46241
C33: 义乌 | D33: COSCO | E33: 46208 | F33: OOCL SAN FRANCISCO 197E | G33: 46213 | H33: 46241

Sheet 快捷查询
A1: 深圳市博创兴供应链有限公司 Your Global Chance, We Deliver | D1: 快捷查价
D2: 国内站点 | E2: 目的仓 | F2: 清关方式
D3: 深圳 | E3: MDW2 | F3: 包税
A4: 国家 | B4: 渠道类型 | C4: 渠道名称 | D4: 下单渠道 | E4: 单价（KG*CBM） | G4: 参考时效(天）
A5: 美国 | B5: 经济线 | C5: 直送~经济线 | D5: 美西经济线-卡派包税 * 不包税 | E5: {=IFERROR(INDEX(经济线!C6:F34,MATCH(E3,经济线!A6:A34,0),IF(D3="深圳",IF(F3="包税",1,2),IF(D3="义乌/宁波",IF(F3="包税",3,4)))),"*")} -> 8.9 | G5: =IFERROR(VLOOKUP(E3,经济线!A:H,7,0),"*") -> 30~38
B6: 美中专线 | C6: 休斯顿专线 | D6: 休斯顿专线-卡派包税 *不包税 | E6: {=IFERROR(INDEX(美中专线!O7:R31,MATCH(E3,美中专线!N7:N31,0),IF(D3="深圳",IF(F3="包税",1,2),IF(D3="义乌/宁波",IF(F3="包税",3,4)))),"*")} -> * | G6: =IFERROR(VLOOKUP(E3,美中专线!N:T,7,0),"*") -> *
C7: 芝加哥专线 | D7: 芝加哥专线-卡派包税 * 不包税 | E7: {=IFERROR(INDEX(美中专线!B7:E26,MATCH(E3,美中专线!A7:A26,0),IF(D3="深圳",IF(F3="包税",1,2),IF(D3="义乌/宁波",IF(F3="包税",3,4)))),"*")} -> 9.4 | G7: =IFERROR(VLOOKUP(E3,美中专线!A:G,7,0),"*") -> 39~46
B8: 美东专线 | C8: 纽约普船 | D8: 纽约普船-卡派包税 * 不包税 | E8: {=IFERROR(INDEX(美东专线!B7:E63,MATCH(E3,美东专线!A7:A63,0),IF(D3="深圳",IF(F3="包税",1,2),IF(D3="义乌/宁波",IF(F3="包税",3,4)))),"*")} -> * | G8: =IFERROR(VLOOKUP(E3,美东专线!A:G,7,0),"*") -> *
C9: 纽约快船 | D9: 纽约快船-卡派包税 *不包税 | E9: {=IFERROR(INDEX(美东专线!H7:K63,MATCH(E3,美东专线!A7:A63,0),IF(D3="深圳",IF(F3="包税",1,2),IF(D3="义乌/宁波",IF(F3="包税",3,4)))),"*")} -> * | G9: =IFERROR(VLOOKUP(E3,美东专线!A:M,13,0),"*") -> *
C10: 纽约特快 | D10: 纽约特快-卡派包税 *不包税 | E10: {=IFERROR(INDEX(美东专线!N7:Q63,MATCH(E3,美东专线!A7:A63,0),IF(D3="深圳",IF(F3="包税",1,2),IF(D3="义乌/宁波",IF(F3="包税",3,4)))),"*")} -> * | G10: =IFERROR(VLOOKUP(E3,美东专线!A:S,19,0),"*") -> *
B11: 萨瓦纳专线 | C11: 萨瓦纳专线 | D11: 萨瓦纳专线-卡派包税 *不包税 | E11: {=IFERROR(INDEX(萨瓦纳专线!B7:E28,MATCH(E3,萨瓦纳专线!A7:A28,0),IF(D3="深圳",IF(F3="包税",1,2),IF(D3="义乌/宁波",IF(F3="包税",3,4)))),"*")} -> * | G11: =IFERROR(VLOOKUP(E3,萨瓦纳专线!A:G,7,0),"*") -> *
B12: 美西快线 | C12: 美森正班 | D12: 美森-卡派包税 *不包税 | E12: {=IFERROR(INDEX(王牌渠道!B6:E63,MATCH(E3,王牌渠道!A6:A63,0),IF(D3="深圳",IF(F3="包税",1,2),IF(D3="义乌/宁波",IF(F3="包税",3,4)))),"*")} -> 14.5 | G12: =IFERROR(VLOOKUP(E3,王牌渠道!A:F,6,0),"*") -> 19~24
C13: 以星合德 | D13: 限时达-卡派包税 *不包税 | E13: {=IFERROR(INDEX(王牌渠道!G6:K63,MATCH(E3,王牌渠道!A6:A63,0),IF(D3="深圳",IF(F3="包税",1,2),IF(D3="义乌/宁波",IF(F3="包税",3,4)))),"*")} -> 32.02 | G13: =IFERROR(VLOOKUP(E3,王牌渠道!A:L,12,0),"*") -> 20~25
C14: EMC快速达 | D14: EMC快速达卡派包税*不包税 | E14: {=IFERROR(INDEX(王牌渠道!N6:Q63,MATCH(E3,王牌渠道!A6:A63,0),IF(D3="深圳",IF(F3="包税",1,2),IF(D3="义乌/宁波",IF(F3="包税",3,4)))),"*")} -> 10.6 | G14: =IFERROR(VLOOKUP(E3,王牌渠道!A:R,18,0),"*") -> 20~25
C15: OA快船 | D15: OA快船-卡派包税 * 不包税 | E15: {=IFERROR(INDEX(美西专线!B7:E72,MATCH(E3,美西专线!A7:A72,0),IF(D3="深圳",IF(F3="包税",1,2),IF(D3="义乌/宁波",IF(F3="包税",3,4)))),"*")} -> 10.2 | G15: =IFERROR(VLOOKUP(E3,美西专线!A:G,7,0),"*") -> 23~29
A16: 加拿大 | B16: 加拿大直航 | C16: 多伦多 * 温哥华 * 卡尔加里 专线 | D16: 加拿大直航-卡派包税 | E16: =IFERROR(IF(F3="包税",IF(D3="深圳",_xlfn.XLOOKUP(E3,加拿大直航!A6:A30,加拿大直航!B6:B30,"*"),IF(D3="义乌/宁波",_xlfn.XLOOKUP(E3,加拿大直航!A6:A30,加拿大直航!C6:C30,"*"),"*")),"*"),"*") -> * | G16: =IFERROR(VLOOKUP(E3,加拿大直航!A:D,4,0),"*") -> *
B17: 美转加 | C17: 美森正班 | D17: 美转加特快包税 | E17: =IFERROR(IF(F3="包税",IF(D3="深圳",_xlfn.XLOOKUP(E3,#REF!,#REF!,"*"),IF(D3="义乌/宁波",_xlfn.XLOOKUP(E3,#REF!,#REF!,"*"),"*")),"*"),"*") -> * | G17: =IFERROR(VLOOKUP(E3,#REF!,8,0),"*") -> *
C18: 以星合德 | D18: 美转加快船包税 | E18: =IFERROR(IF(F3="包税",IF(D3="深圳",_xlfn.XLOOKUP(E3,#REF!,#REF!,"*"),IF(D3="义乌/宁波",_xlfn.XLOOKUP(E3,#REF!,#REF!,"*"),"*")),"*"),"*") -> * | G18: =IFERROR(VLOOKUP(E3,#REF!,4,0),"*") -> *
B19: 美转加海派 | C19: 美森正班 | D19: 美森海派 | E19: =IFERROR(IF(F3="包税",IF(D3="深圳",_xlfn.XLOOKUP(E3,#REF!,#REF!,"*"),IF(D3="义乌/宁波",_xlfn.XLOOKUP(E3,#REF!,#REF!,"*"),IF(D3="山东/青岛",_xlfn.XLOOKUP(E3,#REF!,#REF!,"*"),"*"))),"*"),"*") -> * | G19: /
C20: 以星合德 | D20: 以星合德海派 | E20: =IFERROR(IF(F3="包税",IF(D3="深圳",_xlfn.XLOOKUP(E3,#REF!,#REF!,"*"),IF(D3="义乌/宁波",_xlfn.XLOOKUP(E3,#REF!,#REF!,"*"),IF(D3="山东/青岛",_xlfn.XLOOKUP(E3,#REF!,#REF!,"*"),"*"))),"*"),"*") -> * | G20: /
C21: OA快船 | D21: OA快船海派 | E21: =IFERROR(IF(F3="包税",IF(D3="深圳",_xlfn.XLOOKUP(E3,#REF!,#REF!,"*"),IF(D3="义乌/宁波",_xlfn.XLOOKUP(E3,#REF!,#REF!,"*"),IF(D3="山东/青岛",_xlfn.XLOOKUP(E3,#REF!,#REF!,"*"),"*"))),"*"),"*") -> * | G21: /

Sheet 海派专线
A1: 深圳市博创兴供应链有限公司 SHENZHEN BOCHANCE SHIPPING INTERNATIONAL SUPPLY CHAIN CO.LTD
A3: 海派专线
A4: 邮编分区 | B4: 美森海派 | D4: 以星合德（统配）海派 | F4: EMC快速达海派 | H4: OA快船海派
B5: 深圳 | C5: 义乌\宁波 | D5: 深圳 | E5: 义乌\宁波 | F5: 深圳 | G5: 义乌\宁波 | H5: 深圳 | I5: 义乌\宁波
B6: 50KG+ | C6: 50KG+ | D6: 50KG+ | E6: 50KG+ | F6: 50KG+ | G6: 50KG+ | H6: 50KG+ | I6: 50KG+
A7: 美国西岸（邮编8.9开头） | B7: 15.6 | C7: 15.1 | D7: 13 | E7: 12.7 | F7: 12 | G7: 12.2 | H7: 11.2 | I7: 11.2
A8: 美国西岸北（邮编97.98.99开头） | B8: 16.6 | C8: 16.1 | D8: 14 | E8: 13.7 | F8: 13 | G8: 13.2 | H8: 12.2 | I8: 12.2
A9: 美国中部(邮编5.6.7开头) | B9: 17.6 | C9: 17.1 | D9: 15.5 | E9: 15.2 | F9: 14.5 | G9: 14.7 | H9: 13.7 | I9: 13.7
A10: 美国东岸(邮编0.1.2.3.4开头) | B10: 19.1 | C10: 18.6 | D10: 17 | E10: 16.7 | F10: 16 | G10: 16.2 | H10: 15.2 | I10: 15.2
A11: 预配船司 | B11: Matson | D11: ZIM.HEDE | F11: EMC定提 | H11: OA普船
A12: 时效参考（非赔付时效） | B12: 开船后11个工作日提取 | D12: 开船后13个工作日提取 | F12: 开船后14个工作日提取 | H12: 开船后16个工作日提取
A13: 说明 | B13: 1、含关税和查验费；尾程UPS*FEDEX派送，不接受指定打单 ； 2、材积重=长cm*宽cm*高cm*6000，不分泡； 3、单件低消12KG，单票12-99KG，单价+4元*KG； 4、私人地址 25*件； 5、偏远附加费 +40*件； 6、单边＞120cm、实重＞22.5KG，长+2宽+2高＞260CM参考《发货必读》 7、表价不含5H,9H退运费,及罚没。
A14: 赔付渠道 | B14: 赔付标准
A15: 美森海派 | B15: 从上海离港后第二天算起，超过11个工作日未提取的，赔偿RMB1*KG*工作日，最高3RMB*KG。 船期延误、进出口查验、亚马逊问题不赔(例如删约*不放约*拒收等不可控因素)
A16: 以星合德海派 | B16: 从离港后第二天算起，超过17个工作日未提取的，赔偿RMB0.5*KG*工作日，最高1.5RMB*KG。 船期延误、进出口查验、亚马逊问题不赔(例如删约*不放约*拒收等不可控因素)

Sheet 王牌渠道
A1: 深圳市博创兴供应链有限公司
A2: SHENZHEN BOCHANCE SHIPPING INTERNATIONAL SUPPLY CHAIN CO.LTD
A3: 美森正班卡派 | H3: 以星*合德*带托（统配）卡派 | N3: EMC快速达卡派
A4: 仓库代码 | B4: 深圳 | D4: 义乌\宁波 | F4: 参考时效 (开船后第二天起)*天 | G4: 理赔时效(开船后第二天起)*天 | H4: 深圳 | J4: 义乌\宁波 | L4: 参考时效 (开船后第二天起)*天 | M4: 理赔时效(开船后第二天起)*天 | N4: 深圳 | P4: 义乌\宁波 | R4: 参考时效 (开船后第二天起)*天 | S4: 理赔时效(开船后第二天起)*天
B5: 21KG+ | C5: 0.5CBM+ | D5: 21KG+ | E5: 0.5CBM+ | H5: 21KG+ | I5: 0.5CBM+ | J5: 21KG+ | K5: 0.5CBM+ | N5: 21KG+ | O5: 0.5CBM+ | P5: 21KG+ | Q5: 0.5CBM+
A6: ONT8 | B6: 11.6 | C6: 1940 | D6: 11.1 | E6: 1845 | F6: 13~16 | G6: 19.02 | H6: 9 | I6: 1430 | J6: 8.5 | K6: 1330 | L6: 15~20 | M6: 22.02 | N6: 7.8 | O6: 1250 | P6: 8 | Q6: 1290 | R6: 16~20 | S6: 24.02
A7: LGB8 | B7: 11.6 | C7: 1940 | D7: 11.1 | E7: 1845 | F7: 13~16 | G7: 19.02 | H7: 9 | I7: 1430 | J7: 8.5 | K7: 1330 | L7: 15~20 | M7: 22.02 | N7: 7.8 | O7: 1250 | P7: 8 | Q7: 1290 | R7: 16~20 | S7: 24.02
A8: LAX9 | B8: 11.6 | C8: 1940 | D8: 11.1 | E8: 1845 | F8: 13~16 | G8: 19.02 | H8: 9 | I8: 1430 | J8: 8.5 | K8: 1330 | L8: 15~20 | M8: 22.02 | N8: 7.8 | O8: 1250 | P8: 8 | Q8: 1290 | R8: 16~20 | S8: 24.02
A9: SBD1 | B9: 11.6 | C9: 1940 | D9: 11.1 | E9: 1845 | F9: 13~16 | G9: 19.02 | H9: 9 | I9: 1430 | J9: 8.5 | K9: 1330 | L9: 15~20 | M9: 22.02 | N9: 7.8 | O9: 1250 | P9: 8 | Q9: 1290 | R9: 16~20 | S9: 24.02
A10: POC1 | B10: 11.9 | C10: 1950 | D10: 11.4 | E10: 1855 | F10: 14~18 | G10: * | H10: 9 | I10: 1440 | J10: 8.5 | K10: 1340 | L10: 16~22 | M10: 24.02 | N10: 7.8 | O10: 1280 | P10: 8 | Q10: 1320 | R10: 17~22 | S10: *
A11: POC2 | B11: 11.9 | C11: 1950 | D11: 11.4 | E11: 1855 | F11: 14~18 | G11: * | H11: 9 | I11: 1440 | J11: 8.5 | K11: 1340 | L11: 16~22 | M11: 24.02 | N11: 7.8 | O11: 1280 | P11: 8 | Q11: 1320 | R11: 17~22 | S11: *
A12: POC3 | B12: 11.9 | C12: 1950 | D12: 11.4 | E12: 1855 | F12: 14~18 | G12: * | H12: 9 | I12: 1440 | J12: 8.5 | K12: 1340 | L12: 16~22 | M12: 24.02 | N12: 7.8 | O12: 1280 | P12: 8 | Q12: 1320 | R12: 17~22 | S12: *
A13: IUSP | B13: 12.1 | C13: 1970 | D13: 11.6 | E13: 1875 | F13: 15~20 | G13: * | H13: 9.1 | I13: 1490 | J13: 8.6 | K13: 1390 | L13: 16~23 | M13: 26.02 | N13: 7.9 | O13: 1290 | P13: 7.9 | Q13: 1290 | R13: 18~23 | S13: 28.02
A14: LGB4 | B14: / | C14: / | D14: / | E14: / | F14: / | G14: / | H14: 9.1 | I14: 1450 | J14: 8.6 | K14: 1350 | L14: 16~22 | M14: * | N14: 8.1 | O14: 1330 | P14: 8.3 | Q14: 1370 | R14: 17~22 | S14: *
A15: LGB6 | B15: / | C15: / | D15: / | E15: / | F15: / | G15: / | H15: 9.4 | I15: 1530 | J15: 8.9 | K15: 1430 | L15: 16~22 | M15: * | N15: 8.2 | O15: 1350 | P15: 8.4 | Q15: 1390 | R15: 17~22 | S15: *
A16: FAT2 | B16: / | C16: / | D16: / | E16: / | F16: / | G16: / | H16: 9.8 | I16: 1570 | J16: 9.3 | K16: 1470 | L16: 16~22 | M16: 24.02 | N16: 8.3 | O16: 1380 | P16: 8.5 | Q16: 1420 | R16: 17~22 | S16: *
A17: SNA4 | B17: / | C17: / | D17: / | E17: / | F17: / | G17: / | H17: 9.4 | I17: 1530 | J17: 8.9 | K17: 1430 | L17: 16~22 | M17: 24.02 | N17: 8.3 | O17: 1350 | P17: 8.5 | Q17: 1390 | R17: 17~22 | S17: *
A18: SBD2 | B18: / | C18: / | D18: / | E18: / | F18: / | G18: / | H18: 9.4 | I18: 1530 | J18: 8.9 | K18: 1430 | L18: 16~22 | M18: 24.02 | N18: 8.3 | O18: 1350 | P18: 8.5 | Q18: 1390 | R18: 17~22 | S18: *
A19: PSP3 | B19: / | C19: / | D19: / | E19: / | F19: / | G19: / | H19: 9 | I19: 1490 | J19: 8.5 | K19: 1390 | L19: 17~22 | M19: * | N19: 7.9 | O19: 1290 | P19: 8.1 | Q19: 1330 | R19: 18~23 | S19: *
A20: LAS6 | B20: / | C20: / | D20: / | E20: / | F20: / | G20: / | H20: 10 | I20: 1650 | J20: 9.5 | K20: 1550 | L20: 17~22 | M20: 24.02 | N20: 8.9 | O20: 1450 | P20: 9.1 | Q20: 1490 | R20: 17~22 | S20: 26.02
A21: MCE1 | B21: / | C21: / | D21: / | E21: / | F21: / | G21: / | H21: 10.2 | I21: 1650 | J21: 9.7 | K21: 1550 | L21: 17~22 | M21: 24.02 | N21: 9 | O21: 1480 | P21: 9.2 | Q21: 1520 | R21: 17~22 | S21: 26.02
A22: PHX5 | B22: / | C22: / | D22: / | E22: / | F22: / | G22: / | H22: 10.2 | I22: 1650 | J22: 9.7 | K22: 1550 | L22: 16~21 | M22: 24.02 | N22: 9 | O22: 1480 | P22: 9.2 | Q22: 1520 | R22: 16~21 | S22: 26.02
A23: PHX7 | B23: / | C23: / | D23: / | E23: / | F23: / | G23: / | H23: 9.6 | I23: 1550 | J23: 9.1 | K23: 1450 | L23: 16~21 | M23: 24.02 | N23: 8.7 | O23: 1450 | P23: 8.9 | Q23: 1490 | R23: 16~21 | S23: 26.02
A24: LAS1 | B24: 12.6 | C24: 2070 | D24: 12.1 | E24: 1975 | F24: 13~17 | G24: 23.02 | H24: 9.7 | I24: 1570 | J24: 9.2 | K24: 1470 | L24: 16~21 | M24: 24.02 | N24: 8.6 | O24: 1380 | P24: 8.8 | Q24: 1420 | R24: 16~21 | S24: 26.02
A25: GYR2 | B25: 12.6 | C25: 2070 | D25: 12.1 | E25: 1975 | F25: 13~17 | G25: 23.02 | H25: 9.7 | I25: 1570 | J25: 9.2 | K25: 1470 | L25: 16~21 | M25: 24.02 | N25: 8.6 | O25: 1380 | P25: 8.8 | Q25: 1420 | R25: 16~21 | S25: 26.02
A26: GYR3 | B26: 12.6 | C26: 2070 | D26: 12.1 | E26: 1975 | F26: 13~17 | G26: 23.02 | H26: 9.7 | I26: 1570 | J26: 9.2 | K26: 1470 | L26: 16~21 | M26: 24.02 | N26: 8.6 | O26: 1380 | P26: 8.8 | Q26: 1420 | R26: 16~21 | S26: 26.02
A27: VGT2 | B27: 12.6 | C27: 2070 | D27: 12.1 | E27: 1975 | F27: 13~17 | G27: 23.02 | H27: 9.7 | I27: 1570 | J27: 9.2 | K27: 1470 | L27: 16~21 | M27: 24.02 | N27: 8.6 | O27: 1380 | P27: 8.8 | Q27: 1420 | R27: 16~21 | S27: 26.02
A28: GEU3 | B28: 12.6 | C28: 2070 | D28: 12.1 | E28: 1975 | F28: 13~17 | G28: 23.02 | H28: 9.7 | I28: 1580 | J28: 9.2 | K28: 1480 | L28: 16~21 | M28: 24.02 | N28: 8.6 | O28: 1380 | P28: 8.8 | Q28: 1420 | R28: 16~21 | S28: 26.02
A29: HLI2 | B29: 12.7 | C29: 2090 | D29: 12.2 | E29: 1995 | F29: 13~17 | G29: * | H29: 9.8 | I29: 1610 | J29: 9.3 | K29: 1510 | L29: 16~21 | M29: 24.02 | N29: 8.6 | O29: 1400 | P29: 8.8 | Q29: 1440 | R29: 16~21 | S29: *
A30: MIT2 | B30: 12.6 | C30: 2070 | D30: 12.1 | E30: 1975 | F30: 13~17 | G30: 23.02 | H30: 9.7 | I30: 1579 | J30: 9.2 | K30: 1479 | L30: 16~21 | M30: 24.02 | N30: 8.6 | O30: 1380 | P30: 8.8 | Q30: 1420 | R30: 16~21 | S30: 26.02
A31: GEU2 | B31: 12.6 | C31: 2070 | D31: 12.1 | E31: 1975 | F31: 13~17 | G31: 23.02 | H31: 9.7 | I31: 1590 | J31: 9.2 | K31: 1490 | L31: 16~21 | M31: 24.02 | N31: 8.6 | O31: 1380 | P31: 8.8 | Q31: 1420 | R31: 16~21 | S31: 26.02
A32: SMF3 | B32: 12.6 | C32: 2070 | D32: 12.1 | E32: 1975 | F32: 13~17 | G32: 25.02 | H32: 9.7 | I32: 1590 | J32: 9.2 | K32: 1490 | L32: 16~21 | M32: 25.02 | N32: 8.6 | O32: 1380 | P32: 8.8 | Q32: 1420 | R32: 16~21 | S32: 28.02
A33: SMF6 | B33: / | C33: / | D33: / | E33: / | F33: / | G33: / | H33: 9.9 | I33: 1600 | J33: 9.4 | K33: 1500 | L33: 17~22 | M33: 25.02 | N33: 8.6 | O33: 1410 | P33: 8.8 | Q33: 1450 | R33: 17~22 | S33: 28.02
A34: SCK1 | B34: / | C34: / | D34: / | E34: / | F34: / | G34: / | H34: 9.9 | I34: 1600 | J34: 9.4 | K34: 1500 | L34: 17~22 | M34: 25.02 | N34: 8.6 | O34: 1410 | P34: 8.8 | Q34: 1450 | R34: 17~22 | S34: 28.02
A35: SCK8 | B35: 12.6 | C35: 2070 | D35: 12.1 | E35: 1975 | F35: 14~18 | G35: * | H35: 9.7 | I35: 1560 | J35: 9.2 | K35: 1460 | L35: 17~22 | M35: * | N35: 8.4 | O35: 1380 | P35: 8.6 | Q35: 1420 | R35: 17~22 | S35: *
A36: SCK4 | B36: 12.6 | C36: 2070 | D36: 12.1 | E36: 1975 | F36: 13~17 | G36: 25.02 | H36: 9.7 | I36: 1600 | J36: 9.2 | K36: 1500 | L36: 16~21 | M36: 26.02 | N36: 8.5 | O36: 1380 | P36: 8.7 | Q36: 1420 | R36: 16~21 | S36: 28.02
A37: TCY1 | B37: 12.6 | C37: 2070 | D37: 12.1 | E37: 1975 | F37: 14~18 | G37: * | H37: 9.7 | I37: 1600 | J37: 9.2 | K37: 1500 | L37: 17~22 | M37: 26.02 | N37: 8.4 | O37: 1380 | P37: 8.6 | Q37: 1420 | R37: 17~22 | S37: *
A38: TCY2 | B38: 12.6 | C38: 2070 | D38: 12.1 | E38: 1975 | F38: 14~18 | G38: * | H38: 9.7 | I38: 1600 | J38: 9.2 | K38: 1500 | L38: 17~22 | M38: 26.02 | N38: 8.4 | O38: 1380 | P38: 8.6 | Q38: 1420 | R38: 17~22 | S38: *
A39: QXY8 | B39: 13.2 | C39: 2170 | D39: 12.7 | E39: 2075 | F39: 16~21 | G39: * | H39: 10.3 | I39: 1690 | J39: 9.8 | K39: 1590 | L39: 16~22 | M39: * | N39: 9 | O39: 1470 | P39: 9.2 | Q39: 1510 | R39: 19~24 | S39: *
A40: QZZ7 | B40: 13.2 | C40: 2150 | D40: 13.2 | E40: 2150 | F40: 16~21 | G40: * | H40: 10.2 | I40: 1670 | J40: 10.2 | K40: 1670 | L40: 16~21 | M40: 24.02 | N40: 9.3 | O40: 1490 | P40: 9.3 | Q40: 1490 | R40: 16~21 | S40: 26.02
...

Sheet 美西专线
A1: 深圳市博创兴供应链有限公司
A2: SHENZHEN BOCHANCE SHIPPING INTERNATIONAL SUPPLY CHAIN CO.LTD
A4: 美西OA快船专线
A5: 仓库代码 | B5: 深圳 | D5: 义乌\宁波 | F5: 预计航期*天 | G5: 参考时效 (开船后第二天起)*天
B6: 21KG+ | C6: 0.5CBM+ | D6: 21KG+ | E6: 0.5CBM+
A7: ONT8 | B7: 7.2 | C7: 1300 | D7: 7.2 | E7: 1300 | F7: 16 | G7: 19~24
A8: LGB8 | B8: 7.2 | C8: 1300 | D8: 7.2 | E8: 1300 | F8: 16 | G8: 19~24
A9: LAX9 | B9: 7.2 | C9: 1300 | D9: 7.2 | E9: 1300 | F9: 16 | G9: 19~24
A10: SBD1 | B10: 7.2 | C10: 1300 | D10: 7.2 | E10: 1300 | F10: 16 | G10: 19~24
A11: POC1 | B11: 7.3 | C11: 1310 | D11: 7.3 | E11: 1310 | F11: 16 | G11: 20~25
A12: POC2 | B12: 7.3 | C12: 1310 | D12: 7.3 | E12: 1310 | F12: 16 | G12: 22~28
A13: POC3 | B13: 7.3 | C13: 1310 | D13: 7.3 | E13: 1310 | F13: 16 | G13: 20~25
A14: SNA4 | B14: 7.7 | C14: 1370 | D14: 7.7 | E14: 1370 | F14: 16 | G14: 22~28
A15: XLX7 | B15: 7.9 | C15: 1290 | D15: 7.9 | E15: 1290 | F15: 16 | G15: 22~28
A16: SBD2 | B16: 7.7 | C16: 1370 | D16: 7.7 | E16: 1370 | F16: 16 | G16: 22~28
A17: LGB4 | B17: 7.7 | C17: 1270 | D17: 7.7 | E17: 1270 | F17: 16 | G17: 22~28
A18: LGB6 | B18: 7.7 | C18: 1370 | D18: 7.7 | E18: 1370 | F18: 16 | G18: 22~28
... A72: SWF2 | B72: 11.7 | C72: 1950 | D72: 11.7 | E72: 1950 | F72: 16 | G72: 24~30
A73: 备注 | B73: 1、含关税和查验费； 2、单票低消10KG，单票不足50KG加1*KG，另沃尔玛仓10~99KG加1*KG； 3、计费重：体积重和实重取大者，体积重=长cm*宽cm*高cm*6000； 4、单边超120CM以上，单件超50KG以上的货物，请参考《发货必读》 5、如因客户资料\产品问题，需承担因此产生的所有仓租、柜租、罚金、销毁费等，恶意瞒报的还需承担进口商损失费2000美金； 1、不含关税、如遇查验费实销； 2、计费重=长cm*宽cm*高cm*1000000，不分泡； 3、单边超120CM以上，请参考《发货必读》 4、如因客户资料\产品问题，需承担因此产生的所有仓租、柜租、罚金、销毁费等，恶意瞒报的还需承担进口商损失费2000美金； 5、沃尔玛仓点100+起收价格 6、表价不含5H,9H退运费,及罚没。

Sheet 经济线
A1: 深圳市博创兴供应链有限公司
A2: SHENZHEN BOCHANCE SHIPPING INTERNATIONAL SUPPLY CHAIN CO.LTD
A3: 经济线
A4: 仓库代码 | B4: 卸货港 | C4: 深圳 | E4: 义乌\宁波 | G4: 预计航期*天 | H4: 参考时效 (开船后第二天起)*天 | I4: 理赔时效(开船后第二天起)*天
C5: 21KG+ | D5: 1CBM+ | E5: 21KG+ | F5: 1CBM+
A6: ONT8 | B6: LA | C6: 6.9 | D6: 1220 | E6: 6.9 | F6: 1260 | G6: 16 | H6: 19~24 | I6: *
A7: LGB8 | B7: LA | C7: 6.9 | D7: 1220 | E7: 6.9 | F7: 1260 | G7: 16 | H7: 19~24 | I7: *
A8: SBD1 | B8: LA | C8: 6.9 | D8: 1220 | E8: 6.9 | F8: 1260 | G8: 16 | H8: 19~24 | I8: *
A9: LAX9 | B9: LA | C9: 6.9 | D9: 1220 | E9: 6.9 | F9: 1260 | G9: 16 | H9: 19~24 | I9: *
A10: POC1 | B10: LA | C10: 7 | D10: 1220 | E10: 7 | F10: 1260 | G10: 16 | H10: 19~24 | I10: *
A11: POC2 | B11: LA | C11: 7 | D11: 1220 | E11: 7 | F11: 1260 | G11: 16 | H11: 19~24 | I11: *
A12: POC3 | B12: LA | C12: 7 | D12: 1230 | E12: 7 | F12: 1270 | G12: 16 | H12: 19~24 | I12: *
A13: SMF3 | B13: LA | C13: 7.6 | D13: 1340 | E13: 7.6 | F13: 1380 | G13: 20 | H13: 23~29 | I13: *
A14: SCK4 | B14: LA | C14: 7.6 | D14: 1340 | E14: 7.6 | F14: 1380 | G14: 20 | H14: 23~29 | I14: *
A15: SCK8 | B15: LA | C15: 7.7 | D15: 1340 | E15: 7.7 | F15: 1380 | G15: 20 | H15: 23~29 | I15: *
A16: PSC2 | B16: LA | C16: 9.7 | D16: 1650 | E16: 9.7 | F16: 1690 | G16: 20 | H16: 24~27 | I16: *
A17: LAS1 | B17: LA | C17: 7.6 | D17: 1310 | E17: 7.6 | F17: 1350 | G17: 16 | H17: 19~25 | I17: *
... A25: ABQ2 | B25: LA | C25: 8.7 | D25: 1500 | E25: 8.7 | F25: 1540 | G25: 16 | H25: 20~26 | I25: *
A26: IAH3 | B26: HOU | C26: 7.8 | D26: 1290 | E26: 7.8 | F26: 1330 | G26: 28~35 | H26: 31~44 | I26: *
A27: FTW1 | B27: HOU | C27: 8.4 | D27: 1430 | E27: 8.4 | F27: 1470 | G27: 28~35 | H27: 31~44 | I27: *
A28: MDW2 | B28: CHI | C28: 8.9 | D28: 1510 | E28: 8.9 | F28: 1550 | G28: 30~38 | H28: 39~46 | I28: *
A29: IND9 | B29: CHI | C29: 9 | D29: 1510 | E29: 9 | F29: 1550 | G29: 30~38 | H29: 39~46 | I29: *
A30: ABE8 | B30: NY | C30: 7.9 | D30: 1310 | E30: 7.9 | F30: 1350 | G30: 32 | H30: 36~41 | I30: *
A31: TEB9 | B31: NY | C31: 7.9 | D31: 1310 | E31: 7.9 | F31: 1350 | G31: 32 | H31: 36~41 | I31: *
A32: SWF2 | B32: NY | C32: 8.1 | D32: 1390 | E32: 8.1 | F32: 1430 | G32: 32 | H32: 36~41
A33: AVP1 | B33: NY | C33: 8.2 | D33: 1400 | E33: 8.2 | F33: 1440 | G33: 32 | H33: 36~41 | I33: *
A34: CLT2 | B34: SAV | C34: 8 | D34: 1350 | E34: 8 | F34: 1390 | G34: 34 | H34: 40~45 | I34: *
A35: 备注 | C35: 1、含关税和查验费； 2、体积*6000； 3、不分泡，单件最低消费5KG 4、50-99KG +1*KG 5、21-49KG +2*KG 6、不足21KG按21KG计算 单边超120CM以上，单件超50KG以上的货物，请参考《发货必读》 —————————— 1、不含关税、如遇查验费实销； 2、计费重=长cm*宽cm*高cm*1000000，不分泡； 3、单边超120CM以上，请参考《发货必读》 4、如因客户资料\产品问题，需承担因此产生的所有仓租、柜租、罚金、销毁费等，恶意瞒报的还需承担进口商损失费2000美金； 5、表价不含5H,9H退运费,及罚没。

Sheet 美中专线
A1: 深圳市博创兴供应链有限公司 SHENZHEN BOCHANCE SHIPPING INTERNATIONAL SUPPLY CHAIN CO.LTD
A4: 芝加哥普船卡派 | H4: 芝加哥快速达卡派包税 | N4: 休斯顿专线卡派
A5: 仓库代码 | B5: 深圳 | D5: 义乌\宁波 | F5: 预计航期*天 | G5: 参考时效 (开船后第二天起)*天 | H5: 深圳 | J5: 义乌\宁波 | L5: 预计航期*天 | M5: 参考时效 (开船后第二天起)*天 | N5: 仓库代码 | O5: 深圳 | Q5: 义乌\宁波 | S5: 预计航期*天 | T5: 参考时效 (开船后第二天起)*天
B6: 21KG+ | C6: 0.5CBM+ | D6: 21KG+ | E6: 0.5CBM+ | H6: 21KG+ | I6: 0.5CBM+ | J6: 21KG+ | K6: 0.5CBM+ | O6: 21KG+ | P6: 0.5CBM+ | Q6: 21KG+ | R6: 0.5CBM+
A7: MDW2 | B7: 9.4 | C7: 1610 | D7: 9.4 | E7: 1610 | F7: 30-38 | G7: 39~46 | H7: 10.7 | I7: 1820 | J7: 10.7 | K7: 1820 | L7: 20.32 | M7: 24~29 | N7: HOU1 | O7: 8.4 | P7: 1410 | Q7: 8.7 | R7: 1470 | S7: 28~35 | T7: 32~46
A8: MDW6 | B8: 9.2 | C8: 1570 | D8: 9.2 | E8: 1570 | F8: 30-38 | G8: 39~46 | H8: 10.7 | I8: 1820 | J8: 10.7 | K8: 1820 | L8: 20.32 | M8: 24~29 | N8: HOU2 | O8: 8.4 | P8: 1410 | Q8: 8.7 | R8: 1470 | S8: 28~35 | T8: 32~46
A9: ORD2 | B9: 9.2 | C9: 1570 | D9: 9.2 | E9: 1570 | F9: 30-38 | G9: 39~46 | H9: 10.7 | I9: 1820 | J9: 10.7 | K9: 1820 | L9: 20.32 | M9: 24~29 | N9: HOU3 | O9: 8.4 | P9: 1410 | Q9: 8.7 | R9: 1470 | S9: 28~35 | T9: 32~46
A10: IGQ2 | B10: 9.2 | C10: 1570 | D10: 9.2 | E10: 1570 | F10: 30-38 | G10: 39~46 | H10: 10.7 | I10: 1820 | J10: 10.7 | K10: 1820 | L10: 20.32 | M10: 25~30 | N10: HOU7 | O10: 8.4 | P10: 1410 | Q10: 8.7 | R10: 1470 | S10: 28~35 | T10: 32~46
A11: RFD4 | B11: 9.3 | C11: 1590 | D11: 9.3 | E11: 1590 | F11: 30-38 | G11: 39~46 | H11: 11 | I11: 1840 | J11: 11 | K11: 1840 | L11: 20.32 | M11: 25~30 | N11: HOU8 | O11: 8.4 | P11: 1410 | Q11: 8.7 | R11: 1470 | S11: 28~35 | T11: 31~44
A12: RFD2 | B12: 9.3 | C12: 1590 | D12: 9.3 | E12: 1590 | F12: 30-38 | G12: 39~46 | H12: 11 | I12: 1840 | J12: 11 | K12: 1840 | L12: 20.32 | M12: 25~30 | N12: IAH3 | O12: 8.5 | P12: 1410 | Q12: 8.8 | R12: 1470 | S12: 28~35 | T12: 31~44
A13: STL3 | B13: 9.9 | C13: 1640 | D13: 9.9 | E13: 1640 | F13: 30-38 | G13: 42~48 | H13: 11.6 | I13: 1960 | J13: 11.6 | K13: 1960 | L13: 20.32 | M13: 25~30 | N13: FTW1 | O13: 8.9 | P13: 1520 | Q13: 9.2 | R13: 1580 | S13: 28~35 | T13: 31~44
A14: STL4 | B14: 9.9 | C14: 1640 | D14: 9.9 | E14: 1640 | F14: 30-38 | G14: 42~48 | H14: 11.6 | I14: 1960 | J14: 11.6 | K14: 1960 | L14: 20.32 | M14: 25~30 | N14: SAT6 | O14: 9 | P14: 1520 | Q14: 9.3 | R14: 1580 | S14: 28~35 | T14: 32~46
A15: IND5 | B15: 9.9 | C15: 1640 | D15: 9.9 | E15: 1640 | F15: 30-38 | G15: 42~48 | H15: 11.6 | I15: 1960 | J15: 11.6 | K15: 1960 | L15: 20.32 | M15: 25~30 | N15: SAT1 | O15: 9 | P15: 1520 | Q15: 9.3 | R15: 1580 | S15: 28~35 | T15: 31~44
A16: IND9 | B16: 9.9 | C16: 1640 | D16: 9.9 | E16: 1640 | F16: 30-38 | G16: 42~48 | H16: 11.6 | I16: 1960 | J16: 11.6 | K16: 1960 | L16: 20.32 | M16: 25~30 | N16: DFW6 | O16: 9 | P16: 1520 | Q16: 9.3 | R16: 1580 | S16: 28~35 | T16: 31~44
A17: MQJ1 | B17: 9.9 | C17: 1640 | D17: 9.9 | E17: 1640 | F17: 30-38 | G17: 42~48 | H17: 11.6 | I17: 1960 | J17: 11.6 | K17: 1960 | L17: 20.32 | M17: 25~30 | N17: FTW2 | O17: 9.1 | P17: 1520 | Q17: 9.4 | R17: 1580 | S17: 28~35 | T17: 32~46
A18: FWA4 | B18: 9.9 | C18: 1640 | D18: 9.9 | E18: 1640 | F18: 30-38 | G18: 42~48 | H18: 11.6 | I18: 1960 | J18: 11.6 | K18: 1960 | L18: 20.32 | M18: 25~30 | N18: FTW3 | O18: 9.1 | P18: 1520 | Q18: 9.4 | R18: 1580 | S18: 28~35 | T18: 32~46
... A26: MKC4 | B26: 10.5 | C26: 1790 | D26: 10.5 | E26: 1790 | F26: 30-38 | G26: 42~48 | H26: 12.7 | I26: 2200 | J26: 12.7 | K26: 2200 | L26: 20.32 | M26: 25~30 | N26: MEM8 | O26: 9.6 | P26: 1610 | Q26: 9.9 | R26: 1670 | S26: 28~35 | T26: 32~46
A27: MCI4 | B27: 11.98 | C27: 2090 | D27: 11.98 | E27: 2090 | F27: 30-38 | G27: 42~48 | H27: / | I27: / | J27: / | K27: / | L27: / | M27: / | N27: LFT1 | O27: 9.7 | P27: 1610 | Q27: 10 | R27: 1670 | S27: 28~35 | T27: 31~44
A28: * | B28: * | C28: * | D28: * | E28: * | F28: * | G28: * | H28: * | I28: * | J28: * | K28: * | L28: * | M28: * | N28: OKC2 | O28: 9.7 | P28: 1610 | Q28: 10 | R28: 1670 | S28: 28~35 | T28: 31~44
A29: * | B29: * | C29: * | D29: * | E29: * | F29: * | G29: * | H29: * | I29: * | J29: * | K29: * | L29: * | M29: * | N29: ICT2 | O29: 9.7 | P29: 1610 | Q29: 10 | R29: 1670 | S29: 28~35 | T29: 31~44
A30: * | B30: * | C30: * | D30: * | E30: * | F30: * | G30: * | H30: * | I30: * | J30: * | K30: * | L30: * | M30: * | N30: LIT2 | O30: 9.7 | P30: 1610 | Q30: 10 | R30: 1670 | S30: 28~35 | T30: 34~48
A31: * | B31: * | C31: * | D31: * | E31: * | F31: * | G31: * | H31: * | I31: * | J31: * | K31: * | L31: * | M31: * | N31: FOE1 | O31: 10.1 | P31: 1650 | Q31: 10.4 | R31: 1710 | S31: 28~35 | T31: 34~48
A32: 备注 | B32: 1、含关税和查验费； 2、单票低消10KG，单票不足50KG加1/KG； 3、计费重：体积重和实重取大者，体积重=长cm*宽cm*高cm/6000； 4、单边超120CM以上，单件超50KG以上的货物，请参考《发货必读》； 5、如因客户资料\产品问题，需承担因此产生的所有仓租、柜租、罚金、销毁费等，恶意瞒报的还需承担进口商损失费2000美金； 6、表价不含5H,9H退运费,及罚没。

Sheet 美东专线
A1: 深圳市博创兴供应链有限公司 SHENZHEN BOCHANCE SHIPPING INTERNATIONAL SUPPLY CHAIN CO.LTD
A4: 纽约普船 | H4: 纽约快船 | N4: 纽约特快
A5: 仓库代码 | B5: 深圳 | D5: 义乌\宁波 | F5: 预计航期*天 | G5: 参考时效 (开船后第二天起)*天 | H5: 深圳 | J5: 义乌\宁波 | L5: 预计航期*天 | M5: 参考时效 (开船后第二天起)*天 | N5: 深圳 | P5: 义乌\宁波 | R5: 预计航期*天 | S5: 参考时效 (开船后第二天起)*天 | T5: 理赔时效
B6: 21KG+ | C6: 0.5CBM+ | D6: 21KG+ | E6: 0.5CBM+ | H6: 21KG+ | I6: 0.5CBM+ | J6: 21KG+ | K6: 0.5CBM+ | N6: 21KG+ | O6: 0.5CBM+ | P6: 21KG+ | Q6: 0.5CBM+
A7: TEB3 | B7: 8.4 | C7: 1430 | D7: 8.4 | E7: 1430 | F7: 32 | G7: 37~43 | H7: 11.6 | I7: 1970 | J7: 11.6 | K7: 1970 | L7: 25 | M7: 29~33 | N7: 13.9 | O7: 2410 | P7: 13.9 | Q7: 2410 | R7: 21 | S7: 25~29 | T7: *
A8: TEB4 | B8: 8.4 | C8: 1430 | D8: 8.4 | E8: 1430 | F8: 32 | G8: 37~43 | H8: 11.6 | I8: 1970 | J8: 11.6 | K8: 1970 | L8: 25 | M8: 30~34 | N8: 13.9 | O8: 2410 | P8: 13.9 | Q8: 2410 | R8: 21 | S8: 26~30 | T8: *
A9: TEB6 | B9: 8.4 | C9: 1430 | D9: 8.4 | E9: 1430 | F9: 32 | G9: 36~41 | H9: 11.6 | I9: 1970 | J9: 11.6 | K9: 1970 | L9: 25 | M9: 29~33 | N9: 13.9 | O9: 2410 | P9: 13.9 | Q9: 2410 | R9: 21 | S9: 25~29 | T9: *
A10: TEB9 | B10: 8.4 | C10: 1430 | D10: 8.4 | E10: 1430 | F10: 32 | G10: 36~41 | H10: 11.6 | I10: 1970 | J10: 11.6 | K10: 1970 | L10: 25 | M10: 29~33 | N10: 13.9 | O10: 2410 | P10: 13.9 | Q10: 2410 | R10: 21 | S10: 25~29 | T10: 35
A11: ABE3 | B11: 8.5 | C11: 1470 | D11: 8.5 | E11: 1470 | F11: 32 | G11: 37~43 | H11: 11.7 | I11: 2020 | J11: 11.7 | K11: 2020 | L11: 25 | M11: 29~33 | N11: 14 | O11: 2450 | P11: 14 | Q11: 2450 | R11: 21 | S11: 25~29 | T11: *
A12: ABE4 | B12: 8.5 | C12: 1470 | D12: 8.5 | E12: 1470 | F12: 32 | G12: 37~43 | H12: 11.7 | I12: 2020 | J12: 11.7 | K12: 2020 | L12: 25 | M12: 29~33 | N12: 14 | O12: 2450 | P12: 14 | Q12: 2450 | R12: 21 | S12: 25~29 | T12: *
A13: ABE8 | B13: 8.4 | C13: 1430 | D13: 8.4 | E13: 1430 | F13: 32 | G13: 36~41 | H13: 11.6 | I13: 1970 | J13: 11.6 | K13: 1970 | L13: 25 | M13: 29~33 | N13: 14 | O13: 2410 | P13: 14 | Q13: 2410 | R13: 21 | S13: 25~29 | T13: 35
A14: ACY2 | B14: 8.4 | C14: 1430 | D14: 8.4 | E14: 1430 | F14: 32 | G14: 36~41 | H14: 11.6 | I14: 1970 | J14: 11.6 | K14: 1970 | L14: 25 | M14: 29~33 | N14: 14 | O14: 2410 | P14: 14 | Q14: 2410 | R14: 21 | S14: 25~29 | T14: 35
A15: ILG1 | B15: 8.9 | C15: 1540 | D15: 8.9 | E15: 1540 | F15: 32 | G15: 37~43 | H15: 12.1 | I15: 2090 | J15: 12.1 | K15: 2090 | L15: 25 | M15: 34~40 | N15: 14.4 | O15: 2520 | P15: 14.4 | Q15: 2520 | R15: 21 | S15: 30~36 | T15: *
A16: HEA2 | B16: 8.8 | C16: 1540 | D16: 8.8 | E16: 1540 | F16: 32 | G16: 37~43 | H16: 11.7 | I16: 2020 | J16: 11.7 | K16: 2020 | L16: 25 | M16: 32~38 | N16: 14.2 | O16: 2440 | P16: 14.2 | Q16: 2440 | R16: 21 | S16: 25~29 | T16: *
A17: AVP1 | B17: 8.8 | C17: 1460 | D17: 8.8 | E17: 1460 | F17: 32 | G17: 36~41 | H17: 11.7 | I17: 2020 | J17: 11.7 | K17: 2020 | L17: 25 | M17: 29~33 | N17: 14.2 | O17: 2440 | P17: 14.2 | Q17: 2440 | R17: 21 | S17: 25~29 | T17: 35
A18: AVP9 | B18: 8.8 | C18: 1460 | D18: 8.8 | E18: 1460 | F18: 32 | G18: 37~43 | H18: 11.7 | I18: 2020 | J18: 11.7 | K18: 2020 | L18: 25 | M18: 32~38 | N18: 14.2 | O18: 2440 | P18: 14.2 | Q18: 2440 | R18: 21 | S18: 28~34 | T18: *
A19: XEW5 | B19: 8.8 | C19: 1460 | D19: 8.8 | E19: 1460 | F19: 32 | G19: 36~41 | H19: 11.7 | I19: 2060 | J19: 11.7 | K19: 2060 | L19: 25 | M19: 29~33 | N19: 14.2 | O19: 2440 | P19: 14.2 | Q19: 2440 | R19: 21 | S19: 25~29 | T19: *
A20: PHL4 | B20: 9 | C20: 1520 | D20: 9 | E20: 1520 | F20: 32 | G20: 37~43 | H20: 12.2 | I20: 2070 | J20: 12.2 | K20: 2070 | L20: 25 | M20: 30~34 | N20: 14.4 | O20: 2510 | P20: 14.4 | Q20: 2510 | R20: 21 | S20: 26~30 | T20: *
A21: PHL5 | B21: 8.8 | C21: 1480 | D21: 8.8 | E21: 1480 | F21: 32 | G21: 37~43 | H21: 12 | I21: 2030 | J21: 12 | K21: 2030 | L21: 25 | M21: 30~34 | N21: 14.2 | O21: 2470 | P21: 14.2 | Q21: 2470 | R21: 21 | S21: 26~30 | T21: *
A22: PHL6 | B22: 8.8 | C22: 1480 | D22: 8.8 | E22: 1480 | F22: 32 | G22: 38~44 | H22: 12 | I22: 2030 | J22: 12 | K22: 2030 | L22: 25 | M22: 29~33 | N22: 14.2 | O22: 2470 | P22: 14.2 | Q22: 2470 | R22: 21 | S22: 25~29 | T22: 36
A23: SWF1 | B23: 8.8 | C23: 1480 | D23: 8.8 | E23: 1480 | F23: 32 | G23: 37~43 | H23: 12 | I23: 2030 | J23: 12 | K23: 2030 | L23: 25 | M23: 30~35 | N23: 14.2 | O23: 2470 | P23: 14.2 | Q23: 2470 | R23: 21 | S23: 26~31 | T23: 36
A24: SWF2 | B24: 8.8 | C24: 1480 | D24: 8.8 | E24: 1480 | F24: 32 | G24: 37~43 | H24: 12 | I24: 2030 | J24: 12 | K24: 2030 | L24: 25 | M24: 30~34 | N24: 14.2 | O24: 2470 | P24: 14.2 | Q24: 2470 | R24: 21 | S24: 26~30 | T24: 37
A25: MDT1 | B25: 8.8 | C25: 1480 | D25: 8.8 | E25: 1480 | F25: 32 | G25: 37~43 | H25: 12 | I25: 2030 | J25: 12 | K25: 2030 | L25: 25 | M25: 29~33 | N25: 14.2 | O25: 2470 | P25: 14.2 | Q25: 2470 | R25: 21 | S25: 25~29 | T25: *
A26: MDT4 | B26: 8.8 | C26: 1480 | D26: 8.8 | E26: 1480 | F26: 32 | G26: 37~43 | H26: 12 | I26: 2020 | J26: 12 | K26: 2020 | L26: 25 | M26: 30~35 | N26: 14.2 | O26: 2470 | P26: 14.2 | Q26: 2470 | R26: 21 | S26: 26~31 | T26: *
A27: DCA6 | B27: 8.8 | C27: 1510 | D27: 8.8 | E27: 1510 | F27: 32 | G27: 37~43 | H27: 12.1 | I27: 2050 | J27: 12.1 | K27: 2050 | L27: 25 | M27: 33~39 | N27: 14.4 | O27: 2510 | P27: 14.4 | Q27: 2510 | R27: 21 | S27: 29~35 | T27: 36
A28: TTN2 | B28: 8.9 | C28: 1480 | D28: 8.9 | E28: 1480 | F28: 32 | G28: 37~43 | H28: 11.8 | I28: 2000 | J28: 11.8 | K28: 2000 | L28: 25 | M28: 30~34 | N28: 14.3 | O28: 2460 | P28: 14.3 | Q28: 2460 | R28: 21 | S28: 26~30 | T28: 37
A29: HIA1 | B29: 9.2 | C29: 1480 | D29: 9.2 | E29: 1480 | F29: 32 | G29: 37~43 | H29: 12.2 | I29: 2060 | J29: 12.2 | K29: 2060 | L29: 25 | M29: 34~40 | N29: 14.6 | O29: 2470 | P29: 14.6 | Q29: 2470 | R29: 21 | S29: 30~36 | T29: 40
A30: LBE1 | B30: 9.2 | C30: 1480 | D30: 9.2 | E30: 1480 | F30: 32 | G30: 37~43 | H30: 12.2 | I30: 2040 | J30: 12.2 | K30: 2040 | L30: 25 | M30: 32~38 | N30: 14.6 | O30: 2470 | P30: 14.6 | Q30: 2470 | R30: 21 | S30: 28~34 | T30: 40
A31: ALB1 | B31: 9.3 | C31: 1530 | D31: 9.3 | E31: 1530 | F31: 32 | G31: 37~43 | H31: 12.2 | I31: 2090 | J31: 12.2 | K31: 2090 | L31: 25 | M31: 30~34 | N31: 14.7 | O31: 2510 | P31: 14.7 | Q31: 2510 | R31: 21 | S31: 26~30 | T31: 36
A32: PIT2 | B32: 9.3 | C32: 1530 | D32: 9.3 | E32: 1530 | F32: 32 | G32: 37~43 | H32: 12.2 | I32: 2090 | J32: 12.2 | K32: 2090 | L32: 25 | M32: 31~37 | N32: 14.7 | O32: 2510 | P32: 14.7 | Q32: 2510 | R32: 21 | S32: 27~33 | T32: *
A33: XLX1 | B33: 9.3 | C33: 1530 | D33: 9.3 | E33: 1530 | F33: 32 | G33: 37~43 | H33: 12.2 | I33: 2090 | J33: 12.2 | K33: 2090 | L33: 25 | M33: 32~38 | N33: 14.7 | O33: 2510 | P33: 14.7 | Q33: 2510 | R33: 21 | S33: 28~34 | T33: 36
A34: HGR6 | B34: 9.3 | C34: 1530 | D34: 9.3 | E34: 1530 | F34: 32 | G34: 37~43 | H34: 12.5 | I34: 2110 | J34: 12.5 | K34: 2110 | L34: 25 | M34: 32~38 | N34: 14.7 | O34: 2510 | P34: 14.7 | Q34: 2510 | R34: 21 | S34: 28~34 | T34: 40
A35: BOS7 | B35: 9.3 | C35: 1570 | D35: 9.3 | E35: 1570 | F35: 32 | G35: 37~43 | H35: 12.5 | I35: 2110 | J35: 12.5 | K35: 2110 | L35: 25 | M35: 31~37 | N35: 14.7 | O35: 2550 | P35: 14.7 | Q35: 2550 | R35: 21 | S35: 27~33 | T35: 36
A36: BWI4 | B36: 9.3 | C36: 1570 | D36: 9.3 | E36: 1570 | F36: 32 | G36: 37~43 | H36: 12.5 | I36: 2110 | J36: 12.5 | K36: 2110 | L36: 25 | M36: 30~35 | N36: 14.7 | O36: 2550 | P36: 14.7 | Q36: 2550 | R36: 21 | S36: 26~31 | T36: *
A37: BDL6 | B37: 9.3 | C37: 1570 | D37: 9.3 | E37: 1570 | F37: 32 | G37: 38~44 | H37: 12.5 | I37: 2110 | J37: 12.5 | K37: 2110 | L37: 25 | M37: 33~39 | N37: 14.7 | O37: 2550 | P37: 14.7 | Q37: 2550 | R37: 21 | S37: 29~35 | T37: *
A38: CHO1 | B38: 9.3 | C38: 1570 | D38: 9.3 | E38: 1570 | F38: 32 | G38: 37~43 | H38: 12.5 | I38: 2110 | J38: 12.5 | K38: 2110 | L38: 25 | M38: 34~36 | N38: 14.7 | O38: 2550 | P38: 14.7 | Q38: 2550 | R38: 21 | S38: 30~32 | T38: 38
A39: XRI3 | B39: 9.3 | C39: 1570 | D39: 9.3 | E39: 1570 | F39: 32 | G39: 37~43 | H39: 12.5 | I39: 2110 | J39: 12.5 | K39: 2110 | L39: 25 | M39: 29~33 | N39: 14.7 | O39: 2550 | P39: 14.7 | Q39: 2550 | R39: 21 | S39: 25~29 | T39: *
A40: ORF2 | B40: 9.3 | C40: 1570 | D40: 9.3 | E40: 1570 | F40: 32 | G40: 37~43 | H40: 12.5 | I40: 2110 | J40: 12.5 | K40: 2110 | L40: 25 | M40: 34~36 | N40: 14.7 | O40: 2550 | P40: 14.7 | Q40: 2550 | R40: 21 | S40: 30~32 | T40: 38
A41: RMN3 | B41: 9.3 | C41: 1570 | D41: 9.3 | E41: 1570 | F41: 32 | G41: 37~43 | H41: 12.5 | I41: 2110 | J41: 12.5 | K41: 2110 | L41: 25 | M41: 32~38 | N41: 14.7 | O41: 2550 | P41: 14.7 | Q41: 2550 | R41: 21 | S41: 28~34 | T41: 38
A42: CLT2 | B42: 9.4 | C42: 1630 | D42: 9.4 | E42: 1630 | F42: 32 | G42: 37~43 | H42: 12.7 | I42: 2190 | J42: 12.7 | K42: 2190 | L42: 25 | M42: 32~38 | N42: 14.9 | O42: 2610 | P42: 14.9 | Q42: 2610 | R42: 21 | S42: 28~34 | T42: 37
...

Sheet 萨瓦纳专线
A1: 深圳市博创兴供应链有限公司 SHENZHEN BOCHANCE SHIPPING INTERNATIONAL SUPPLY CHAIN CO.LTD
A4: 萨瓦纳专线
A5: 仓库代码 | B5: 深圳 | D5: 义乌\宁波 | F5: 预计航期*天 | G5: 参考时效 (开船后第二天起)*天 | H5: 理赔时效(开船后第二天起)*天
B6: 21KG+ | C6: 0.5CBM+ | D6: 21KG+ | E6: 0.5CBM+
A7: JAX3 | B7: 8.7 | C7: 1470 | D7: 9 | E7: 1530 | F7: 34 | G7: 39~44 | H7: *
A8: XLX6 | B8: 8.7 | C8: 1470 | D8: 9 | E8: 1530 | F8: 34 | G8: 40~45 | H8: *
A9: GSO1 | B9: 8.7 | C9: 1470 | D9: 9 | E9: 1530 | F9: 34 | G9: 39~44 | H9: *
A10: RYY2 | B10: 8.7 | C10: 1470 | D10: 9 | E10: 1530 | F10: 34 | G10: 39~44 | H10: *
A11: CLT3 | B11: 8.7 | C11: 1470 | D11: 9 | E11: 1530 | F11: 34 | G11: 41~46 | H11: *
A12: CLT6 | B12: 8.7 | C12: 1470 | D12: 9 | E12: 1530 | F12: 34 | G12: 41~46 | H12: *
A13: RDU2 | B13: 8.7 | C13: 1470 | D13: 9 | E13: 1530 | F13: 34 | G13: 40~45 | H13: *
A14: IUSR | B14: 8.9 | C14: 1490 | D14: 9.2 | E14: 1550 | F14: 34 | G14: 40~45 | H14: *
A15: MGE3 | B15: 8.9 | C15: 1490 | D15: 9.2 | E15: 1550 | F15: 34 | G15: 39~44 | H15: *
A16: CLT2 | B16: 8.9 | C16: 1490 | D16: 9.2 | E16: 1550 | F16: 34 | G16: 40~45 | H16: *
A17: MCO2 | B17: 8.9 | C17: 1510 | D17: 9.2 | E17: 1570 | F17: 34 | G17: 39~44 | H17: *
A18: TPA2 | B18: 8.9 | C18: 1510 | D18: 9.2 | E18: 1570 | F18: 34 | G18: 40~45 | H18: *
... A28: MEM1 | B28: 9.3 | C28: 1530 | D28: 9.6 | E28: 1590 | F28: 34 | G28: 40~45 | H28: *
A29: 备注 | B29: 优先OA联盟： 1、含关税和查验费； 2、体积*6000； 3、不分泡，单件最低消费5KG 4、50-99KG +1*KG 5、21-49KG +2*KG 6、不足21KG按21KG计算 单边超120CM以上，单件超50KG以上的货物，请参考《发货必读》 —————————— 1、不含关税、如遇查验费实销； 2、计费重=长cm*宽cm*高cm*1000000，不分泡； 3、单边超120CM以上，请参考《发货必读》 4、如因客户资料\产品问题，需承担因此产生的所有仓租、柜租、罚金、销毁费等，恶意瞒报的还需承担进口商损失费2000美金； 5、表价不含5H,9H退运费,及罚没。

Sheet 海运整柜
A1: 深圳市凯琦供应链管理有限公司
A2: 地址：深圳市龙岗区坂田高新技术工业园2栋B座501-514
A3: 财务ATTN:洪小姐 电话：0755-28314752 网址：www.catchfba.com
A4: 海运整柜
A5: 渠道代码 仓库地址 | B5: F01-盐田普船 | E5: F01-盐田以星 | G5: F01-上海美森
B6: 运费 | C6: 卸货港 | D6: 备注 | E6: 运费 | F6: 备注 | G6: 运费 | H6: 备注
A7: 91邮编海外仓 | B7: 单询 | C7: 洛杉矶 | D7: 1、4截1开/5截3开，EMC，正常航期14天（塞港除外）； 2、其他船公司单询； | E7: - | F7: 1、7截3开，ZIM，正常航期12天 | G7: - | H7: 1、6截3开，MASTON，正常航期11天;
A8: ONT8、LGB8、LAX9 | B8: 单询 | C8: 洛杉矶 | E8: - | G8: -
A9: SMF3/SJC7/OAK3 | B9: 单询 | C9: 奥克兰 | E9: LA拆柜送 | G9: LA拆柜送
A10: LAS1、GYR3 | B10: 单询 | C10: 洛杉矶 | E10: LA拆柜送 | G10: LA拆柜送
A11: FTW1/FTW2/DFW6 | B11: - | C11: 达拉斯 | E11: LA拆柜送 | G11: LA拆柜送
A12: STA1 | B12: - | C12: 达拉斯 | E12: LA拆柜送 | G12: LA拆柜送
A13: MDW2 | B13: - | C13: 芝加哥 | E13: LA拆柜送 | G13: LA拆柜送
A14: IND9 | B14: - | C14: 芝加哥 | E14: LA拆柜送 | G14: LA拆柜送
A15: MEM1 | B15: - | C15: 孟菲斯 | E15: LA拆柜送 | G15: LA拆柜送
A16: ABE8 | B16: - | C16: 纽约 | E16: LA拆柜送 | G16: LA拆柜送
A17: 产品说明
A18: 以上为直送价格，亚马逊仓库请务必按亚马逊要求装柜，否则亚马逊有可能会拒收，我司不承担因仓库拒收产生的费用和责任
A19: 以上价格包含：基本运费，起运港杂费，目的港清关费（5个HSCODE），派送费，3天托架费，1-2个小时等候费（美西2小时，美中、美东1小时)
A20: 以上价格不包含：国内拖车费，码头提进费&落箱费（华东地区会产生），报关费，商检费，熏蒸费，政府部门申报费（如FDA,LACEY,EPA等），查验及查验引起的一切费用，关税，亚马逊预约及爆仓引起的仓租/柜租/预提/拒收等非可控因素导致的额外费用
A21: 实报实销费用明细：
A22: 1、HS CODE费用:RMB30/个
A23: 2、FDA/TSCA/LACEY/DOT/EPA等申报费：USD30/票
A24: 3、拖架费：USD35/天/柜,以星USD125/柜/天
A25: 4、预提费：USD150/柜；货柜存储费：USD35/天/柜（预提出来的柜子放海外仓仓库）
A26: 5、超时等候费：USD75/小时（美西） USD85/小时（美中&美东）
A27: 6、底盘分离: USD150-200/柜（等同于甩柜，商业海外仓才会产生，亚马逊仓不产生）
A28: 7、Layover fee：USD350/柜
... A37: 疫情期间因亚马逊不提供POD，所以暂不接受丢失索赔，建议自行购买保险

Sheet 美东海卡
A1: 深圳市凯琦供应链管理有限公司
A2: 地址：深圳市龙岗区坂田高新技术工业园2栋B座501-514
A3: 财务ATTN:洪小姐 电话：0755-28314752 网址：www.catchfba.com
A4: 美东海运+卡车派送
A5: 仓库地址 | B5: K15-纽约海卡（不包税） | F5: K15-纽约海卡B（含税） | H5: 时效参考
B6: 2CBM | C6: 10CBM | D6: 20CBM | E6: 备注 | F6: 150KG+ | G6: 关税附加费
A7: 美东海外仓 | B7: - | C7: 1440 | D7: 1440 | E7: 1、非报关件5CBM以内的+350/票， 2、关税、查验费实报实销(查验费按65CBM均摊) 3、重货按每300KG=1CBM | F7: 10(800KG+) | G7: 1、体积/6000,单件最低消费8KG，不分泡！ 2、含关税和查验费； 3、附加费见下 | H7: 提柜后3-7天
A8: ABE4、ABE8，TEB3、TEB6 | B8: 1750 | C8: 1700 | D8: 1700 | F8: 10.5 | H8: 提柜后3-7天
A9: EWR4、AVP3、AVP1 | B9: 1900 | C9: 1850 | D9: 1850 | F9: 11.5 | H9: 提柜后3-7天
A10: PHL5、PHL6 | B10: 1900 | C10: 1850 | D10: 1850 | F10: 11.5 | H10: 提柜后3-7天
A11: MDT1、MDT2 | B11: 1900 | C11: 1850 | D11: 1850 | F11: 11.5 | H11: 提柜后3-7天
A12: BWI4、RIC1、BOS7 | B12: 2100 | C12: 2050 | D12: 2050 | F12: 12.5 | H12: 提柜后4-8天
A13: CLT2、CLT3、GSP1 | B13: 2180 | C13: 2130 | D13: 2130 | F13: 13 | H13: 提柜后5-9天
A14: MGE3、ATL8、JAX3 | B14: - | C14: 2190 | D14: 2190 | F14: 13.5 | H14: 提柜后5-9天
A15: PIT5、TPA2、TPA1、BNA2 | B15: - | C15: 2190 | D15: 2190 | F15: 13.5 | H15: 提柜后5-9天
A16: CHA2、MCO5、LAL1 | B16: - | C16: 2190 | D16: 2190 | F16: 13.5 | H16: 提柜后5-9天
A17: 船期说明 | B17: 5截3开，航期29天到纽约（因美国塞港，最终船期和航期船公司以为准，预计38天+）
A18: 产品说明
A19: 1、单边超120cm的货物需按1.2倍体积计费，超过1.7cm的货物需双板派送，按2倍体积计费
A20: 2、因海关查验，船公司船期/航线变更/延迟到港，不可抗力如罢工、疫情原因导致亚马逊仓库关闭不在此时效范围内
A21: 一、附加费
A22: 1、报关件+350RMB/份单，备案大鹏海关！一达通报关件+500/票！漏报关仅赔偿3倍报关费，不接受可不出！
A23: 2、申报品名超5个以上的部分需加收30元/个
A24: 3、自税渠道：涉FDA、EPA产品+300RMB/品名；商检产品+500/票，移动电源+300/方，纯电池+400/方，需提供MSDS和运输报告
A25: 4、含税渠道：纺织品、木制品、FDA\EPA产品+1；厨房刀具、太阳能产品+2、移动电源、纯电池单询
A26: 5、涉认证产品需提供认证审核，确认OK后方可以出；我司不保证所有认证均可被目的国海关认可，不接受可以不出！
A27: 6、目的港扣货：操作费USD200/票；免柜租7天，超过7天收取USD5/CBM/天，最低收费15USD/天；超过3个月货物自动销毁；
A28: 二、注意事项：
A29: 1、自税渠道不足2CBM按2CBM计费，只保留小数点后1位（进位）
... A46: 3、如派送中收件方或寄件方要求或者错误地址无法投递导致退件,我司只接受货件退回我司美国仓库并免费保存货物7天,超出7天的按人民币5RMB/件/天计费,最低消费10RMB/票;退件过程产生的费用,我司将向发件方收取；如有退回货物要求重发的快件我们将按照12/KG的运费结算并加收50RMB/件操作费。

Sheet 美中海卡
A1: 深圳市凯琦供应链管理有限公司
A2: 地址：深圳市龙岗区坂田高新技术工业园2栋B座501-514
A3: 财务ATTN:洪小姐 电话：0755-28314752 网址：www.catchfba.com
A4: 美中海运+卡车派送
A5: 仓库地址 | B5: K13-美中海卡（不包税） | F5: K13-美中海卡B（含税） | H5: 时效参考
B6: 2CBM | C6: 10CBM | D6: 20CBM | E6: 备注 | F6: 150KG+ | G6: 关税附加费
A7: MDW6、MDW7、MDW9 | B7: 1180 | C7: 1180 | D7: 1180 | E7: 1、非报关件5CBM以内的+350/票， 2、关税、查验费实报实销(查验费按65CBM均摊) 3、重货按每300KG=1CBM | F7: 8.5 | G7: 1、体积/6000，单件最低消费8KG，不分泡！ 2、含关税和查验费； 3、附加费见下 | H7: 到芝加哥后5-7天递送
A8: MDW8 | B8: 1180 | C8: 1180 | D8: 1180 | F8: 8.5 | H8: 到芝加哥后5-7天递送
A9: JVL1 | B9: 1230 | C9: 1230 | D9: =D8+50 -> 1230 | F9: 8.8 | H9: 到芝加哥后5-7天递送
A10: IND2、IND5、IND9 | B10: 1230 | C10: 1230 | D10: 1230 | F10: 8.8 | H10: 到芝加哥后5-7天递送
A11: SDF8、CMH2、CMH3 | B11: 1230 | C11: 1230 | D11: 1230 | F11: 8.8 | H11: 到芝加哥后5-7天递送
A12: STL4 | B12: 1230 | C12: 1230 | D12: 1230 | F12: 8.8 | H12: 到芝加哥后5-7天递送
A13: DET1/DET2 | B13: 1260 | C13: 1260 | D13: =D8+80 -> 1260 | F13: 9 | H13: 到芝加哥后5-7天递送
A14: BNA2 | B14: 1340 | C14: 1340 | D14: 1340 | F14: 9.5 | H14: 到芝加哥后5-7天递送
A15: SDF其他、LEX1、LEX2 | B15: 1340 | C15: 1340 | D15: 1340 | F15: 9.5 | H15: 到芝加哥后6-10天递送 | J15: 暂停
A16: TUL1、MCI5、MCI7、ORD6 | B16: 1340 | C16: 1340 | D16: 1340 | F16: 9.5 | H16: 到芝加哥后6-10天递送
A17: MSP1、MKE1、MKE5 | B17: 1340 | C17: 1340 | D17: 1340 | F17: 9.5 | H17: 到芝加哥后6-10天递送
A18: MQJ1 | B18: 1420 | C18: 1420 | D18: 1420 | F18: 10 | H18: 到芝加哥后6-10天递送
A19: 船期说明 | B19: 4截1开，航期22天到芝加哥（因美国塞港，最终船期和航期船公司以为准，预计40天+）
A20: 产品说明
A21: 1、单边超120cm的货物需按1.2倍体积计费，超过1.7cm的货物需双板派送，按2倍体积计费
A22: 2、因海关查验，船公司船期/航线变更/延迟到港，不可抗力如罢工、疫情原因导致亚马逊仓库关闭不在此时效范围内
A23: 一、附加费
A24: 1、报关件+350RMB/份单，备案大鹏海关！一达通报关件+500/票！漏报关仅赔偿3倍报关费，不接受可不出！
A25: 2、申报品名超5个以上的部分需加收30元/个
A26: 3、自税渠道：涉FDA、EPA产品+300RMB/品名；商检产品+500/票，移动电源+300/方，纯电池+400/方，需提供MSDS和运输报告
A27: 4、含税渠道：纺织品、木制品、FDA\EPA产品+1；厨房刀具、太阳能产品+2、移动电源、纯电池单询
A28: 5、涉认证产品需提供认证审核，确认OK后方可以出；我司不保证所有认证均可被目的国海关认可，不接受可以不出！
A29: 6、目的港扣货：操作费USD200/票；免柜租7天，超过7天收取USD5/CBM/天，最低收费15USD/天；超过3个月货物自动销毁；
A30: 二、注意事项：
A31: 1、自税渠道不足2CBM按2CBM计费，只保留小数点后1位（进位）
... A48: 3、如派送中收件方或寄件方要求或者错误地址无法投递导致退件,我司只接受货件退回我司美国仓库并免费保存货物7天,超出7天的按人民币5RMB/件/天计费,最低消费10RMB/票;退件过程产生的费用,我司将向发件方收取；如有退回货物要求重发的快件我们将按照12/KG的运费结算并加收50RMB/件操作费。

Sheet 加拿大直航
A1: 深圳市博创兴供应链有限公司
A2: SHENZHEN BOCHANCE SHIPPING INTERNATIONAL SUPPLY CHAIN CO.LTD
A3: 加拿大直航卡派
A4: 仓库代码 | B4: 深圳 | C4: 义乌\宁波 | D4: 参考时效 (开船后第二天起)*天 | E4: 对应区域
A5: 多伦多-FBA仓 仓库代码 | B5: 101KG+ | C5: 101KG+
A6: YYZ3 | B6: 8.6 | C6: 8.6 | D6: 30~35天 | E6: 多伦多-FBA仓仓库代码
A7: YYZ4 | B7: 8.6 | C7: 8.6 | D7: 30~35天 | E7: 多伦多-FBA仓仓库代码
A8: YYZ1 | B8: 8.6 | C8: 8.6 | D8: 30~40天 | E8: 多伦多-FBA仓仓库代码
A9: YYZ2 | B9: 8.6 | C9: 8.6 | D9: 30~40天 | E9: 多伦多-FBA仓仓库代码
A10: YYZ6 | B10: 8.6 | C10: 8.6 | D10: 30~40天 | E10: 多伦多-FBA仓仓库代码
A11: YYZ7 | B11: 8.6 | C11: 8.6 | D11: 30~40天 | E11: 多伦多-FBA仓仓库代码
A12: YYZ9 | B12: 8.6 | C12: 8.6 | D12: 30~40天 | E12: 多伦多-FBA仓仓库代码
A13: YOO1 | B13: 9 | C13: 9 | D13: 30~40天 | E13: 多伦多-FBA仓仓库代码
A14: YHM1 | B14: 9 | C14: 9 | D14: 30~40天 | E14: 多伦多-FBA仓仓库代码
A15: YXU1 | B15: 9 | C15: 9 | D15: 30~40天 | E15: 多伦多-FBA仓仓库代码
A16: XYY1 | B16: 9 | C16: 9 | D16: 30~40天 | E16: 多伦多-FBA仓仓库代码
A17: YOW1 | B17: 9.2 | C17: 9.2 | D17: 30~40天 | E17: 多伦多-FBA仓仓库代码
... A30: YEG2 | B30: 8.4 | C30: 8.4 | D30: 35~45天 | E30: 卡尔加里-FBA仓仓库代码
B31: YGK1最小收货尺寸为:不低于50LBS，尺寸 不小于33*33*59 INCH
A32: 附加费 | B32: 1、含关税和查验费； 2、单票低消21KG，低于100KG的按照21-49KG单价+2RMB*KG 50-99KG单价+1RMB*KG，低消最低1CBM起收，单件最低5KG起，不足5KG按5KG计费，财务默认出账单； 3、计费重：体积重和实重取大者，体积重=长cm*宽cm*高cm*6000； 4、超长*超重附加：120cm＜外箱单边长度≤150cm，包税+RMB1.2*KG,不包税+228*CBM；150cm＜外箱单边长度≤200cm、包税+RMB1.8*KG,不包税+285*CBM；外箱单边长度＞2m单询； 30KG＜单件实重＜70KG，包税+RMB10*件。（适用于商业*私人*亚马逊可接收地址，另亚马逊收货尺寸*重量限制请客户出货前自行确认*咨询我司客服同事）
A33: 拒收产品 | B33: 1、手机、智能手环、假发、汽车诊断仪、望远镜、硒鼓、化妆品（面膜等），3岁以下儿童产品、婴儿玩具、母婴用品，二类医疗产品（牙刷、牙线、冲牙器、吸奶器等）、禁塑令产品（一次性纸杯等）、成人用品； 2、液体、纯电池、食品、粉末、移动电源、电子烟、制毒用品、医疗用品、仿牌商品、化工产品、美国*加拿大反倾销产品等。如发现冲货罚款RMB2000*票。 3、纯太阳能板、筋膜枪等按摩类产品
A34: 备注 | B34: OA为主： 1、含关税和查验费； 2、体积*6000； 3、不分泡，单件最低消费5KG 4、50-99KG +1*KG 5、21-49KG +2*KG 6、不足21KG按21KG计算 单边超120CM以上，单件超50KG以上的货物，请参考《发货必读》 —————————— 1、不含关税、如遇查验费实销； 2、计费重=长cm*宽cm*高cm*1000000，不分泡； 3、单边超120CM以上，请参考《发货必读》 4、如因客户资料\产品问题，需承担因此产生的所有仓租、柜租、罚金、销毁费等，恶意瞒报的还需承担进口商损失费2000美金； 5、表价不含5H,9H退运费,及罚没。

Sheet 沃尔玛专线
A1: 深圳市博创兴供应链有限公司 SHENZHEN BOCHANCE SHIPPING INTERNATIONAL SUPPLY CHAIN CO.LTD
A4: 沃尔玛专线
A5: 仓库代码 | B5: 深圳 | D5: 义乌 | F5: 预计航期*天 | G5: 参考时效 (开船后第二天起)*天 | H5: 目的港 | I5: 对应渠道
B6: 21KG+ | C6: 0.5CBM+ | D6: 21KG+ | E6: 0.5CBM+
A7: WMT-LAX2 | B7: 12.3 | C7: 1990 | D7: 11.8 | E7: 1895 | F7: 11 | G7: 15~20 | H7: LA | I7: 美森正班卡派
A8: WMT-LAX2T | B8: 12.3 | C8: 1990 | D8: 11.8 | E8: 1895 | F8: 11 | G8: 15~20
A9: WMT-LAX2 | B9: 9.6 | C9: 1590 | D9: 9.1 | E9: 1490 | F9: 13 | G9: 17~22 | H9: LA | I9: 以星*合德*带托（统配）卡派
A10: WMT-LAX2T | B10: 9.6 | C10: 1590 | D10: 9.1 | E10: 1490 | F10: 13 | G10: 17~22
A11: WMT-LAX2 | B11: 8.7 | C11: 1440 | D11: 8.9 | E11: 1480 | F11: 14 | G11: 17~22 | H11: LA | I11: EMC快速达卡派
A12: WMT-LAX2T | B12: 8.7 | C12: 1440 | D12: 8.9 | E12: 1480 | F12: 14 | G12: 17~22
A13: WMT-LAX2 | B13: 8 | C13: 1360 | D13: 8 | E13: 1360 | F13: 16 | G13: 22~28 | H13: LA | I13: 美西OA快船专线
A14: WMT-LAX2T | B14: 8 | C14: 1360 | D14: 8 | E14: 1360 | F14: 16 | G14: 22~28
A15: WMT-LAX2 | B15: 7.3 | C15: 1240 | D15: 7.3 | E15: 1280 | F15: 16 | G15: 19~25 | H15: LA | I15: 经济线
A16: WMT-LAX2T | B16: 7.3 | C16: 1240 | D16: 7.3 | E16: 1280 | F16: 16 | G16: 19~25
A17: WMT-DFW5s | B17: 9.2 | C17: 1500 | D17: 9.7 | E17: 1600 | F17: 28~35 | G17: 31~46 | H17: HOU | I17: K13美中专线
A18: WMT-DFW6s | B18: 9.2 | C18: 1500 | D18: 9.7 | E18: 1600 | F18: 28~35 | G18: 31~46
A19: WMT-DFW2n | B19: 9.2 | C19: 1500 | D19: 9.7 | E19: 1600 | F19: 28~35 | G19: 31~46
A20: WMT-IND3 | B20: 9.5 | C20: 1540 | D20: 9.5 | E20: 1540 | F20: 30~38 | G20: 40~48 | H20: CHI | I20: 芝加哥普船卡派
A21: WMT-CVG1n | B21: 10 | C21: 1620 | D21: 10 | E21: 1620 | F21: 30~38 | G21: 40~48
A22: WMT-KS1 | B22: 10.3 | C22: 1680 | D22: 10.3 | E22: 1680 | F22: 30~38 | G22: 40~48
A23: WMT-KY1 | B23: 10.3 | C23: 1680 | D23: 10.3 | E23: 1680 | F23: 30~38 | G23: 40~48
A24: WMT-IND2n | B24: 9.5 | C24: 1540 | D24: 9.5 | E24: 1540 | F24: 30~38 | G24: 40~48
A25: WMT-ORD1s | B25: 9.2 | C25: 1480 | D25: 9.2 | E25: 1480 | F25: 30~38 | G25: 40~48
A26: WMT-MCI1n | B26: 10.3 | C26: 1680 | D26: 10.3 | E26: 1680 | F26: 30~38 | G26: 40~48
A27: WMT-IND1 | B27: 10.7 | C27: 1810 | D27: 10.7 | E27: 1810 | F27: 30~38 | G27: 40~48
A28: WMT-IND2t | B28: 9.5 | C28: 1540 | D28: 9.5 | E28: 1540 | F28: 30~38 | G28: 40~48
A29: WMT-IND2 | B29: 9.5 | C29: 1540 | D29: 9.5 | E29: 1540 | F29: 30~38 | G29: 40~48
A30: WMT-IND3 | B30: 11.1 | C30: 1820 | D30: 11.1 | E30: 1820 | F30: 20 | G30: 37~39 | H30: CHI | I30: 芝加哥快线
A31: WMT-CVG1n | B31: 11.5 | C31: 1880 | D31: 11.5 | E31: 1880 | F31: 20 | G31: 37~39
A32: WMT-KS1 | B32: 11.9 | C32: 1950 | D32: 11.9 | E32: 1950 | F32: 20 | G32: 37~39
A33: WMT-KY1 | B33: 11.9 | C33: 1950 | D33: 11.9 | E33: 1950 | F33: 20 | G33: 37~39
A34: WMT-IND2n | B34: 11.1 | C34: 1820 | D34: 11.1 | E34: 1820 | F34: 20 | G34: 37~39
A35: WMT-ORD1s | B35: 10.8 | C35: 1760 | D35: 10.8 | E35: 1760 | F35: 20 | G35: 37~39
A36: WMT-MCI1n | B36: 11.9 | C36: 1950 | D36: 11.9 | E36: 1950 | F36: 20 | G36: 37~39
A37: WMT-IND1 | B37: 12.3 | C37: 2090 | D37: 12.3 | E37: 2090 | F37: 20 | G37: 37~39
A38: WMT-IND2t | B38: 11.1 | C38: 1820 | D38: 11.1 | E38: 1820 | F38: 20 | G38: 37~39
A39: WMT-IND2 | B39: 11.1 | C39: 1820 | D39: 11.1 | E39: 1820 | F39: 20 | G39: 37~39
A40: WMT-NJ1 | B40: 9.8 | C40: 1640 | D40: 9.8 | E40: 1640 | F40: 32 | G40: 40~47 | H40: NY | I40: 纽约普船
A41: WMT-NJ3 | B41: 10 | C41: 1680 | D41: 10 | E41: 1680 | F41: 32 | G41: 40~47
A42: WMT-NJ3T | B42: 10 | C42: 1680 | D42: 10 | E42: 1680 | F42: 32 | G42: 40~47
...

Sheet 商业地址
A1: 深圳市博创兴供应链有限公司
A2: SHENZHEN BOCHANCE SHIPPING INTERNATIONAL SUPPLY CHAIN CO.LTD
A3: 美森正班卡派 | I3: 以星*合德*带托（统配）卡派 | O3: EMC快速达卡派 | U3: 美西OA快船专线
A4: 仓库代码 | B4: 邮编 | C4: 深圳 | E4: 义乌\宁波 | G4: 参考时效 (开船后第二天起)*天 | H4: 理赔时效(开船后第二天起)*天 | I4: 深圳 | K4: 义乌\宁波 | M4: 参考时效 (开船后第二天起)*天 | N4: 理赔时效(开船后第二天起)*天 | O4: 深圳 | Q4: 义乌\宁波 | S4: 参考时效 (开船后第二天起)*天 | T4: 理赔时效(开船后第二天起)*天 | U4: 仓库代码 | V4: 邮编 | W4: 深圳 | Y4: 义乌\宁波 | AA4: 预计航期*天 | AB4: 参考时效 (开船后第二天起)*天
C5: 334KG+ | D5: 2CBM+ | E5: 334KG+ | F5: 2CBM+ | I5: 334KG+ | J5: 2CBM+ | K5: 334KG+ | L5: 2CBM+ | O5: 334KG+ | P5: 2CBM+ | Q5: 334KG+ | R5: 2CBM+ | W5: 334KG+ | X5: 2CBM+ | Y5: 334KG+ | Z5: 2CBM+
A6: 洛杉矶FBN头程 | B6: / | C6: 12.4 | D6: 2150 | E6: 11.9 | F6: 2060 | G6: 11 | H6: 12~15天 | I6: 9.8 | J6: 1630 | K6: 9.8 | L6: 1630 | M6: 13 | N6: 18~19天 | O6: 9 | P6: 1470 | Q6: 9.5 | R6: 1570 | S6: 14 | T6: 19~20天 | U6: 洛杉矶FBN头程 | V6: / | W6: 8.3 | X6: 1490 | Y6: 8.3 | Z6: 1490 | AA6: 16 | AB6: 21~25天
A7: 云仓-USCA01 | B7: 91761 | C7: 12.4 | D7: 2150 | E7: 11.9 | F7: 2060 | G7: 11 | H7: 15~20天 | I7: 9.8 | J7: 1630 | K7: 9.8 | L7: 1630 | M7: 13 | N7: 18~24天 | O7: 9 | P7: 1470 | Q7: 9.5 | R7: 1570 | S7: 14 | T7: 19~25天 | U7: 云仓-USCA01 | V7: 91761 | W7: 8.3 | X7: 1490 | Y7: 8.3 | Z7: 1490 | AA7: 16 | AB7: 25~32天
A8: YC美西仓 | B8: 91710 | C8: 12.7 | D8: 2280 | E8: 12.2 | F8: 2190 | G8: 11 | H8: 15~20天 | I8: 10.2 | J8: 1980 | K8: 10.2 | L8: 1980 | M8: 13 | N8: 18~24天 | O8: 9.3 | P8: 1800 | Q8: 9.8 | R8: 1900 | S8: 14 | T8: 19~25天 | U8: YC美西仓 | V8: 91710 | W8: 8.8 | X8: 1590 | Y8: 8.8 | Z8: 1590 | AA8: 16 | AB8: 25~32天
A9: 万邑通91789 | B9: 91789 | C9: 13.2 | D9: 2340 | E9: 12.7 | F9: 2250 | G9: 11 | H9: 15~20天 | I9: 10.7 | J9: 2080 | K9: 10.7 | L9: 2080 | M9: 13 | N9: 18~24天 | O9: 9.8 | P9: 1900 | Q9: 10.3 | R9: 2000 | S9: 14 | T9: 19~25天 | U9: 万邑通91789 | V9: 91789 | W9: 9.3 | X9: 1690 | Y9: 9.3 | Z9: 1690 | AA9: 16 | AB9: 25~32天
A10: 万邑通91748 | B10: 91748 | C10: 13.2 | D10: 2340 | E10: 12.7 | F10: 2250 | G10: 11 | H10: 15~20天 | I10: 10.7 | J10: 2080 | K10: 10.7 | L10: 2080 | M10: 13 | N10: 18~24天 | O10: 9.8 | P10: 1900 | Q10: 10.3 | R10: 2000 | S10: 14 | T10: 19~25天 | U10: 万邑通91748 | V10: 91748 | W10: 9.3 | X10: 1690 | Y10: 9.3 | Z10: 1690 | AA10: 16 | AB10: 25~32天
A11: 4PX91730 | B11: 91730 | C11: 12.9 | D11: 2280 | E11: 12.4 | F11: 2190 | G11: 11 | H11: 15~20天 | I11: 10.4 | J11: 2020 | K11: 10.4 | L11: 2020 | M11: 13 | N11: 18~24天 | O11: 9.5 | P11: 1840 | Q11: 10 | R11: 1940 | S11: 14 | T11: 19~25天 | U11: 4PX91730 | V11: 91730 | W11: 9 | X11: 1630 | Y11: 9 | Z11: 1630 | AA11: 16 | AB11: 25~32天
A12: 4PX90022 | B12: 90022 | C12: 13.5 | D12: 2360 | E12: 13 | F12: 2270 | G12: 11 | H12: 15~20天 | I12: 11 | J12: 2140 | K12: 11 | L12: 2140 | M12: 13 | N12: 18~24天 | O12: 10.1 | P12: 1960 | Q12: 10.6 | R12: 2060 | S12: 14 | T12: 19~25天 | U12: 4PX90022 | V12: 90022 | W12: 9.6 | X12: 1750 | Y12: 9.6 | Z12: 1750 | AA12: 16 | AB12: 25~32天
A13: 风雷仓91789 | B13: 91789 | C13: 13.2 | D13: 2340 | E13: 12.7 | F13: 2250 | G13: 11 | H13: 15~20天 | I13: 10.7 | J13: 2080 | K13: 10.7 | L13: 2080 | M13: 13 | N13: 18~24天 | O13: 9.8 | P13: 1900 | Q13: 10.3 | R13: 2000 | S13: 14 | T13: 19~25天 | U13: 风雷仓91789 | V13: 91789 | W13: 9.3 | X13: 1690 | Y13: 9.3 | Z13: 1690 | AA13: 16 | AB13: 25~32天
A14: 橙联仓91730 | B14: 91730 | C14: 12.9 | D14: 2280 | E14: 12.4 | F14: 2190 | G14: 11 | H14: 15~20天 | I14: 10.4 | J14: 2020 | K14: 10.4 | L14: 2020 | M14: 13 | N14: 18~24天 | O14: 9.5 | P14: 1840 | Q14: 10 | R14: 1940 | S14: 14 | T14: 19~25天 | U14: 橙联仓91730 | V14: 91730 | W14: 9 | X14: 1630 | Y14: 9 | Z14: 1630 | AA14: 16 | AB14: 25~32天
A15: 橙联仓91731 | B15: 91731 | C15: 13.4 | D15: 2330 | E15: 12.9 | F15: 2240 | G15: 11 | H15: 15~20天 | I15: 10.9 | J15: 2110 | K15: 10.9 | L15: 2110 | M15: 13 | N15: 18~24天 | O15: 10 | P15: 1930 | Q15: 10.5 | R15: 2030 | S15: 14 | T15: 19~25天 | U15: 橙联仓91731 | V15: 91731 | W15: 9.5 | X15: 1720 | Y15: 9.5 | Z15: 1720 | AA15: 16 | AB15: 25~32天
A16: 西邮仓 91730 | B16: 91730 | C16: 12.9 | D16: 2280 | E16: 12.4 | F16: 2190 | G16: 11 | H16: 15~20天 | I16: 10.4 | J16: 2020 | K16: 10.4 | L16: 2020 | M16: 13 | N16: 18~24天 | O16: 9.5 | P16: 1840 | Q16: 10 | R16: 1940 | S16: 14 | T16: 19~25天 | U16: 西邮仓 91730 | V16: 91730 | W16: 9 | X16: 1630 | Y16: 9 | Z16: 1630 | AA16: 16 | AB16: 25~32天
A17: 美西3号谷仓 | B17: 91761 | C17: 12.9 | D17: 2280 | E17: 12.4 | F17: 2190 | G17: 11 | H17: 15~20天 | I17: 10.4 | J17: 2020 | K17: 10.4 | L17: 2020 | M17: 13 | N17: 18~24天 | O17: 9.5 | P17: 1840 | Q17: 10 | R17: 1940 | S17: 14 | T17: 19~25天 | U17: 美西3号谷仓 | V17: 91761 | W17: 9 | X17: 1630 | Y17: 9 | Z17: 1630 | AA17: 16 | AB17: 25~32天
A18: 美西5号谷仓 | B18: 91710 | C18: 13.1 | D18: 2310 | E18: 12.6 | F18: 2220 | G18: 11 | H18: 15~20天 | I18: 10.6 | J18: 2050 | K18: 10.6 | L18: 2050 | M18: 13 | N18: 18~24天 | O18: 9.7 | P18: 1870 | Q18: 10.2 | R18: 1970 | S18: 14 | T18: 19~25天 | U18: 美西5号谷仓 | V18: 91710 | W18: 9.2 | X18: 1660 | Y18: 9.2 | Z18: 1660 | AA18: 16 | AB18: 25~32天
... A21: 美西10号谷仓 | B21: 92336 | C21: 13.1 | D21: 2310 | E21: 12.6 | F21: 2220 | G21: 11 | H21: 15~20天 | I21: 10.6 | J21: 2050 | K21: 10.6 | L21: 2050 | M21: 13 | N21: 18~24天 | O21: 9.7 | P21: 1870 | Q21: 10.2 | R21: 1970 | S21: 14 | T21: 19~25天 | U21: 美西10号谷仓 | V21: 92336 | W21: 9.2 | X21: 1660 | Y21: 9.2 | Z21: 1660 | AA21: 16 | AB21: 25~32天
A22: ALHAMNRA | B22: 9180X | C22: 13.4 | D22: 2330 | E22: 12.9 | F22: 2240 | G22: 11 | H22: 15~20天 | I22: 10.9 | J22: 2110 | K22: 10.9 | L22: 2110 | M22: 13 | N22: 18~24天 | O22: 10 | P22: 1930 | Q22: 10.5 | R22: 2030 | S22: 14 | T22: 19~25天 | U22: ALHAMNRA | V22: 9180X | W22: 9.5 | X22: 1720 | Y22: 9.5 | Z22: 1720 | AA22: 16 | AB22: 25~32天
A23: ANAHEIM | B23: 9280X | C23: 13.4 | D23: 2330 | E23: 12.9 | F23: 2240 | G23: 11 | H23: 15~20天 | I23: 10.9 | J23: 2110 | K23: 10.9 | L23: 2110 | M23: 13 | N23: 18~24天 | O23: 10 | P23: 1930 | Q23: 10.5 | R23: 2030 | S23: 14 | T23: 19~25天 | U23: ANAHEIM | V23: 9280X | W23: 9.5 | X23: 1720 | Y23: 9.5 | Z23: 1720 | AA23: 16 | AB23: 25~32天
A24: ARCADIA | B24: 9100X | C24: 13.4 | D24: 2330 | E24: 12.9 | F24: 2240 | G24: 11 | H24: 15~20天 | I24: 10.9 | J24: 2110 | K24: 10.9 | L24: 2110 | M24: 13 | N24: 18~24天 | O24: 10 | P24: 1930 | Q24: 10.5 | R24: 2030 | S24: 14 | T24: 19~25天 | U24: ARCADIA | V24: 9100X | W24: 9.5 | X24: 1720 | Y24: 9.5 | Z24: 1720 | AA24: 16 | AB24: 25~32天
A25: AZUSA | B25: 9170X | C25: 13.2 | D25: 2340 | E25: 12.7 | F25: 2250 | G25: 11 | H25: 15~20天 | I25: 10.7 | J25: 2080 | K25: 10.7 | L25: 2080 | M25: 13 | N25: 18~24天 | O25: 9.8 | P25: 1900 | Q25: 10.3 | R25: 2000 | S25: 14 | T25: 19~25天 | U25: AZUSA | V25: 9170X | W25: 9.3 | X25: 1690 | Y25: 9.3 | Z25: 1690 | AA25: 16 | AB25: 25~32天
A26: BREA | B26: 9282X | C26: 13.2 | D26: 2340 | E26: 12.7 | F26: 2250 | G26: 11 | H26: 15~20天 | I26: 10.7 | J26: 2080 | K26: 10.7 | L26: 2080 | M26: 13 | N26: 18~24天 | O26: 9.8 | P26: 1900 | Q26: 10.3 | R26: 2000 | S26: 14 | T26: 19~25天 | U26: BREA | V26: 9282X | W26: 9.3 | X26: 1690 | Y26: 9.3 | Z26: 1690 | AA26: 16 | AB26: 25~32天
A27: CERRITOS | B27: 9070X | C27: 13.5 | D27: 2360 | E27: 13 | F27: 2270 | G27: 11 | H27: 15~20天 | I27: 11 | J27: 2140 | K27: 11 | L27: 2140 | M27: 13 | N27: 18~24天 | O27: 10.1 | P27: 1960 | Q27: 10.6 | R27: 2060 | S27: 14 | T27: 19~25天 | U27: CERRITOS | V27: 9070X | W27: 9.6 | X27: 1750 | Y27: 9.6 | Z27: 1750 | AA27: 16 | AB27: 25~32天
A28: CHINO | B28: 9171X | C28: 13.2 | D28: 2280 | E28: 12.7 | F28: 2190 | G28: 11 | H28: 15~20天 | I28: 10.7 | J28: 2080 | K28: 10.7 | L28: 2080 | M28: 13 | N28: 18~24天 | O28: 9.8 | P28: 1900 | Q28: 10.3 | R28: 2000 | S28: 14 | T28: 19~25天 | U28: CHINO | V28: 9171X | W28: 9.3 | X28: 1690 | Y28: 9.3 | Z28: 1690 | AA28: 16 | AB28: 25~32天
A29: CITY OF INDUSTRY | B29: 9174X | C29: 13.2 | D29: 2340 | E29: 12.7 | F29: 2250 | G29: 11 | H29: 15~20天 | I29: 10.7 | J29: 2080 | K29: 10.7 | L29: 2080 | M29: 13 | N29: 18~24天 | O29: 9.8 | P29: 1900 | Q29: 10.3 | R29: 2000 | S29: 14 | T29: 19~25天 | U29: CITY OF INDUSTRY | V29: 9174X | W29: 9.3 | X29: 1690 | Y29: 9.3 | Z29: 1690 | AA29: 16 | AB29: 25~32天
A30: COLTON | B30: 9232X | C30: 13.1 | D30: 2310 | E30: 12.6 | F30: 2220 | G30: 11 | H30: 15~20天 | I30: 10.6 | J30: 2050 | K30: 10.6 | L30: 2050 | M30: 13 | N30: 18~24天 | O30: 9.7 | P30: 1870 | Q30: 10.2 | R30: 1970 | S30: 14 | T30: 19~25天 | U30: COLTON | V30: 9232X | W30: 9.2 | X30: 1660 | Y30: 9.2 | Z30: 1660 | AA30: 16 | AB30: 25~32天
