Workbook

Sheet 目录
E2: 广东皓辉国际物流有限公司 | H2: 好时效 选皓辉
E3: Guangdong Haohui International Logistics Co., Ltd.
F4: 皓行无疆 辉承品质
B5: 美国自营卡车行，自营海外仓，国内自主装柜，渠道全程自主把控 | H5: 生效日期：2026-06-29
D6: 渠道 | F6: 主打优势 | G6: 时效 | H6: 最新动态
B7: 美国海运 | C7: 洛杉矶拆柜 | D7: FBA海卡服务 | E7: 推荐渠道 皓快达-性价比之王 | F7: OA快船COSCO/OOCL一手船东合约+自营海外仓+自营卡车行 | G7: 17-21个自然日 | H7: 价格更新
E8: 皓速达-带托架 | F8: 以星ZIM-ZEX带车架服务，更快的提柜速度与派送时效 | G8: 14-17个自然日 | H8: 价格更新
E9: 王牌渠道 皓速达-高时效之王 | F9: 以星/合德电商快船+自营海外仓+自营卡车行，做到最快当天到港 当天提、拆、派，最快当天POD回传！ | G9: 14-17个自然日 | H9: 价格更新
E10: 皓森达-美森正班 | F10: 美森正班+自营海外仓+自营卡车送仓，上架快，送仓当天POD回传！ | G10: 12-15个自然日 | H10: 价格更新
D11: 海派服务 | E11: 皓快达-海派 | F11: 覆盖更多地址，尾程快递派送！ | G11: 20-25个自然日 | H11: 价格更新
E12: 皓速达-海派 | G12: 14-17个自然日 | H12: 价格更新
E13: 皓森达-海派 | G13: 12-15个自然日 | H13: 价格更新
D14: LDP商业海卡 | E14: 皓森达-LDP海卡 | F14: 覆盖全美48州、私人地址、商业地址！ 波多黎各、夏威夷、阿拉斯加等岛屿可达 | G14: 12-15个自然日 | H14: 价格更新
E15: 皓速达-LDP海卡 | G15: 14-17个自然日 | H15: 价格更新
E16: 皓快达-LDP海卡 | G16: 17-21个自然日 | H16: 价格更新
C17: 纽约拆柜 | D17: 美东快线 | E17: 纽约皓速达-FBA海卡 | F17: EXX快船，海运+铁路联运至纽约，海铁联运，让美东不再遥远 | G17: 18-26个自然日 | H17: 价格更新
E18: 纽约皓速达-LDP海卡 | F18: EXX快船，海运+铁路联运至纽约，联运创效能，美线新速度 | G18: 18-26个自然日 | H18: 价格更新
D19: 美东直航 | E19: 皓东达-FBA海卡 | F19: OA/以星直航纽约拆柜，就近派送FBA | G19: 40-48个自然日 | H19: 价格更新
E20: 皓东达-LDP海卡 | F20: 直航纽约拆柜，减少中转环节，更实惠 | G20: 40-48个自然日 | H20: 价格更新
C21: 港到港 | D21: 传统拼箱LCL | E21: 传统贸易货 | F21: 美国多个城市直达服务 | G21: 12-40天 | H21: 单询
B22: 空运 | C22: 空派 | D22: 空运服务 | E22: 直飞航班 | F22: 时效稳定 | G22: 5-10个自然日 | H22: 独立价格表
B23: 本土化服务 | C23: 北美本土 | D23: 进口回程物流 | E23: 定制化物流 | F23: 美国退运、本土全境出口，报关拖车订舱一条龙服务 | G23: 视需求而定 | H23: 单询
D24: 整柜直送 | E24: 美国全境 | F24: 传统贸易直送、FBA&沃尔玛 | G24: 可提1-3天送达 | H24: 单询
B25: 交货流程：确认交货-送货到仓/货拉拉（随货清单）→群上通知收货→提醒核对数据(出货后不接受异议）→账单结算-跟进签收【及时付款，否则影响货物转运】
B26: 仓库地址： 广州市白云区大源街道上南路 25 号中科智慧园8 栋整层 皓辉国际物流：联系人：郭良：17702006178 收货时间：周一至周三11点-21点， 周四至周六11点-23点 深圳仓：深圳宝安区白石夏社区永平二路5-6号，联系人：郭良：17817888141 收货时间：周一至周五10点-18点， 周六10点-15点

Sheet 注意事项
C1: 广东皓辉国际物流有限公司
C2: Guangdong Haohui International Logistics Co., Ltd.
C3: 皓行无疆 辉承品质
C4: 如客户一旦交付货物并接受我司服务，我司默认客户已详细阅读过发货须知内容，已同意并接受相关条款的约束！
C5: 发货前须知
C6: 1、 包装及贴标要求 ①硬朗纸箱.每件外箱必须贴有2个以上FBA标签（条形码字体清晰，防潮湿耐磨） ②外箱和产品贴有“MADE IN CHINA”标签，如因包装及标签问题导致亚马逊仓库拒收或清关出现问题，所有责任及费用由发货人承担。（软包装如产品破损，或丢失不予理赔） ③如FBA卡派，送仓前保持Reference ID有效，如因送仓前PO失效导致卡派失败，产生二次派送费用由发货人承担 ④发货前尽量配合贴好入仓标签/FBA标签/SKU标签等，因未贴标签或未及时告知导致仓库未能及时入库延误船期的我司概不负责！（如需我司国内安排贴标，1RMB/张）
C7: 2、有带电、带磁，违禁品，敏感品，未向我司申报/瞒报/少报，此行为视为冲货，由此导致整批货物延误产生额外费用由客户承担，并且我司将追究其责任，并罚款5000RMB以上。
C8: 3、出货后若有拦截件情况，免仓期7天，超免仓期后未操作需要预收一个月仓储费，若超一个月继续存仓则需要继续再预收下一个月仓储费，以此类推。 海外仓货物仓储费阶梯计费：1-7天免费，8-30天/CBM：1.5USD/天/CBM，31-90天：3USD/天/CBM，91天以上：5USD/天/CBM， 按CBM计费（不足1CBM按1CBM计费）；
C9: 索赔须知
C10: 一、索赔标准
C11: 1，海运渠道（海派/FBA海卡）&空派 ①末端快递派送（UPS/DHL/FEDEX等）以官网递送为凭证； 未提取上网，必须在快递交货后1个月内提出申请调查逾期不予受理。经核实丢件，货物提取前丢件海运渠道按RMB20/KG赔偿+不退运费，空运渠道按照按照最高不超RMB40/KG+退运费赔偿。同一票货部份提取,剩下部份超过30个工作日未提取可直接申请赔偿.如遇自然灾害以及不可抗因素，我司将不做任何赔偿！ 提取后丢失或派送异常等问题，我司将协助跟服务商申请调查或者申请索赔（按申报价值赔偿(最高不超（100USD/票)，不承诺索赔成功且不退运费。索赔受理期限为自入库起 30 个自然日内，逾期不予受理。 PS：最高赔偿USD100/票+不退运费具体说明，例如单票10件，UPS提取8件，我司视为UPS丢失2件，将按照UPS标准赔偿USD20）UPS已取件扫描，无签收结果，经证实丢件，最多一票赔100美金，如一票10件丢件一件，赔100美金*1/10=10美金）非亚马逊FBA地址件，同批次订单只要有1件显示正常签收，我司默认同批订单全部正常递送，不再受理任何理赔； ②末端卡车派送以ISA电子版POD为递送凭证 我司卡派渠道上架（整箱未上架的），按照申报价值包赔偿，最高不超100usd/箱（UPS/联邦派送除外，UPS/联邦按照官网标准赔付）。索赔条件：在货件关闭或者取消后2个月内向我司提出索赔，超期拒绝受理；索赔文件：完整亚马逊后台开查记录。免责条款：贵司亚马逊后台选错小包裹；PO或者FBA货件失效、错误等原因造成上架不齐或者如我司能提供到POD,ISA,PRO文件，不做上架赔付。 2，申请开查或者索赔资料：亚马逊货件需提供亚马逊后台接收货物的完整截图（含电脑截取时间）、索赔调查表、产品链接、采购价值等信息；非亚马逊货件需提供调查表、产品链接、采购价值等信息。以上资料提供完整后，我司将在一个月内给予处理结果；所有索赔必须于交货日期起三十天内以书面形式向甲方提出，否则我司将不负任何法律责任。所有索赔限于每件货物只可提出索赔一次，有关索赔处理应为该索赔之全部及作为与所有有关损失或损坏的最终索赔处理。亚马逊件需提供后台接收货物的完整截图（含电脑时间截图）；非亚马逊件需提供产品链接.采购价值等信息。资料不齐全无法开查或者受理赔付。 3，同一票货部份提取,其他子单未更新的都属于UPS/FEDEX更新取件问题，不计入提取延误赔偿。 4，高货值客户可自行购买保保险或委托我司购买保险（保费=货值*3‰-保签收保货值）；赔付金额以保险公司索赔下来为准 5，购买保险默认按照保险理赔；未购买保险按照我司赔付标准理赔（不存在叠加赔付的情况） 2，海运渠道（LDP商业海卡） 如果货物派送时候发现货物破损，签收单上数据与实际派送不符合，包装形态异常，包括但不限于托盘货物被拆散派送。请建议收件人在签收时认真检查货物，确认无误方可签字。如果发现货物有问题请建议收件人拒绝签名或者在POD上做好相关备注并拍照。一旦完成签收动作后，将无法向卡车LTL提交索赔要求。如签收单备注少件或者破损的，需客户提供齐全资料，我司将协助跟服务商申请索赔，最终以LTL赔偿结果为准不承诺索赔成功且不退运费。（按申报价值赔偿(最高不超（100USD/票) 客户可自行购买保保险或委托我司购买保险（保费=货值*3‰-保签收保货值）；赔付金额以保险公司索赔下来为准。 购买保险默认按照保险理赔；未购买保险按照LTL赔付标准理赔 3，传统拼箱LCL 客户可自行购买保保险或委托我司购买保险（保费=货值*3‰-保签收保货值）；赔付金额以保险公司索赔下来为准 请发货前仔细阅读,否则视为同意此规定！
C12: 二、特别申明以下情况不受理赔偿：
... C29: 1、P.O.BOX,阿拉斯加,夏威夷,波多黎各,关岛,军方地址不收。 如果地址错误产生UPS改地址和扣件费用，将按每件120RMB收取；如收件方在UPS远程服务范围，将被加收偏远费用，标准为+4RMB/KG、最低消费200RMB/票，欲知您所发货物目的地是否属偏远地区请上UPS网查询,我司出货时不另行通知（我司提供查询结果仅供参考，以UPS帐单产生为准,6个月补收有效！暂扣件及改派地址业务，我司不承诺百分百成功，如有此问题我司不承担任何赔偿。 2、涉及到FDA&DOT等认证产品，请单独确认！ 3、如派送中收件方或寄件方要求或者错误地址无法投递导致退件,我司只接受货件退回我司美国仓库并免费保存货物7天,超出7天的按人民币5RMB/件/天计费,最低消10RMB/票;退件过程产生的费用,我司将向发件方收取；如有退回货物要求重发的快件我们将按照12RMB/KG的运费结算并加收50RMB/件操作费。 4、如亚马逊仓库因包装问题或其他问题产生拒收等原因，我司不承担任何责任，我司不再对包装做任何审核。 5、不接仿牌,反倾销,冒牌,侵权,纯电池,危险品,液体,和木箱/铁箱等包装难以打开检查的货物,不收不规则货物，非纸箱货物。如发现冲货没收货物且通知相关执法部门并处罚金1000RMB/票； UPS偏远地区查询链接： https://www.ups.com/cn/zh/shipping/zones-and-rates/area-surcharge.page

Sheet 船期表
A1: 德合-【第49周】海运安排计划表
A2: 海运船期表
A3: 渠道 | B3: 船司 | C3: 航线 | D3: 船名航次 | E3: 出发港 | F3: 目的港 | G3: 截单时间 | H3: 预计开船时间 | I3: 预计到港时间 | J3: 航程 （自然日） | K3: 开船后预计派送时效
G4: 广州/深圳仓
A5: 美森-快提 | B5: 美森 | C5: CLX | D5: MAUNAWILI 258E | E5: 上海 | F5: 长滩 | G5: 45626 | H5: 45630 | I5: 45641 | J5: =I5-H5 -> 11 | K5: 12-15个自然日
A6: 以星-快提 | B6: 以星-快提 | C6: ZIM | D6: ZIM Seagull 3E | E6: 盐田 | F6: 洛杉矶 | G6: 45626 | H6: 45630 | I6: 45643 | J6: =I6-H6 -> 13 | K6: 22-30个自然日
A7: 普船 | B7: 中远 | C7: SEA | D7: COSCO SHIPPING ANDES 040E | E7: 盐田 | F7: 长滩 | G7: 11月30日下午6点 | H7: 45631 | I7: 45649 | J7: =I7-H7 -> 18 | K7: 20-25个自然日
B8: 中远 | C8: SEA3 | D8: XIN FEI ZHOU 099E | E8: 盐田 | F8: 长滩 | G8: 11月30日下午6点 | H8: 45635 | I8: 45649 | J8: =I8-H8 -> 14 | K8: 20-25个自然日
B9: 中远 | C9: CEN | D9: COSCO AFRICA 090E | E9: 上海 | F9: 洛杉矶 | G9: 11月30日下午6点 | H9: 45630 | I9: 45644 | J9: =I9-H9 -> 14 | K9: 20-25个自然日
B10: 中远 | C10: AAC2 | D10: EVER LASTING 1146E | E10: 上海 | F10: 洛杉矶 | G10: 11月30日下午6点 | H10: 45634 | I10: 45650 | J10: =I10-H10 -> 16 | K10: 20-25个自然日
A11: 船期来自船司官网，船司可能会有调整。包括但不限于出现延期或者空班等情况，最终时效以实际开船时间为准！ 传统渠道船期请单独咨询我我司客服人员

Sheet 海运船期表
C1: 广东皓辉国际物流有限公司
C2: Guangdong Haohui International Logistics Co., Ltd.
A3: 渠道 | B3: 船司 | C3: 出发港 | D3: 目的港 | E3: 截单时间 | G3: 预计 开船时间 ETD | H3: 预计 到港时间 ETA | I3: 航程 (自然日）
E4: 广州仓 | F4: 深圳仓
A5: 皓森达 | B5: MATSON | C5: 上海港 | D5: 长滩港 | E5: 每周六晚上 11 点 | F5: 每周六下午15 点 | G5: 46211 | H5: 46222 | I5: =H5-G5 -> 11
A6: 皓速达-带托架 | B6: ZIM-ZEX带车架 | C6: 盐田港 | D6: 洛杉矶港 | E6: 每周六晚上 11 点 | F6: 每周六下午15 点 | G6: 46211 | H6: 46224 | I6: =H6-G6 -> 13
A7: 皓速达 | B7: ZIM-ZEX | C7: 盐田港 | D7: 洛杉矶港 | E7: 每周六晚上 11 点 | F7: 每周六下午15 点 | G7: 46211 | H7: 46224 | I7: =H7-G7 -> 13
A8: 皓快达 | B8: COSCO/OOCL | C8: 盐田港 | D8: 长滩港 | E8: 每周六晚上 11 点 | F8: 每周六下午15 点 | G8: 46212 | H8: 46226 | I8: =H8-G8 -> 14
A9: 纽约皓速达 （美东快线） | B9: IPI海铁联运 EXX快船/ZEX带车架 （混配） | C9: 上海港 盐田港 | D9: 纽约火车站 | E9: 每周日晚上 11 点 | F9: 每周日下午15 点 | G9: 46212 | H9: 46232 | I9: =H9-G9 -> 20
A10: 皓东达 纽约直航 | B10: COSCO/OOCL/ZIM | C10: 盐田港 | D10: 纽约港 | E10: 每周二 晚上20点 | F10: 每周二 下午18点 | G10: 46209 | H10: 46238 | I10: =H10-G10 -> 29

Sheet 快速查询价格表
B1: 广东皓辉国际物流有限公司
B2: 皓行无疆,辉承品质；好时效·选皓辉!
B3: FBA渠道请输入仓库代码 | E3: ONT8
B4: 下单渠道 | C4: 12KG+ | D4: 51KG+ | E4: 签收时效 （开船第二天算起） | F4: {赔}理赔时效
B5: {=_xlfn._xlws.FILTER(FBA渠道汇总!C:C,FBA渠道汇总!B:B=E3)} -> 皓快达-FBA海卡 | C5: =IFERROR(VLOOKUP($E$3&B5,FBA渠道汇总!A:G,4,FALSE),"*") -> 6.9 | D5: =IFERROR(VLOOKUP($E$3&B5,FBA渠道汇总!A:G,5,FALSE),"*") -> 6.9 | E5: =IFERROR(VLOOKUP($E$3&B5,FBA渠道汇总!A:G,6,FALSE),"-") -> 17-21个自然日 | F5: =IFERROR(VLOOKUP($E$3&B5,FBA渠道汇总!A:G,7,FALSE),"-") -> *
B6: 皓速达-FBA海卡 | C6: =IFERROR(VLOOKUP($E$3&B6,FBA渠道汇总!A:G,4,FALSE),"*") -> 7.3 | D6: =IFERROR(VLOOKUP($E$3&B6,FBA渠道汇总!A:G,5,FALSE),"*") -> 7.3 | E6: =IFERROR(VLOOKUP($E$3&B6,FBA渠道汇总!A:G,6,FALSE),"-") -> 16-19个自然日 | F6: =IFERROR(VLOOKUP($E$3&B6,FBA渠道汇总!A:G,7,FALSE),"-") -> 25个自然日
B7: 皓速达带托-FBA海卡 | C7: =IFERROR(VLOOKUP($E$3&B7,FBA渠道汇总!A:G,4,FALSE),"*") -> 7.9 | D7: =IFERROR(VLOOKUP($E$3&B7,FBA渠道汇总!A:G,5,FALSE),"*") -> 7.9 | E7: =IFERROR(VLOOKUP($E$3&B7,FBA渠道汇总!A:G,6,FALSE),"-") -> 14-17个自然日 | F7: =IFERROR(VLOOKUP($E$3&B7,FBA渠道汇总!A:G,7,FALSE),"-") -> 23个自然日
B8: 皓森达-FBA海卡 | C8: =IFERROR(VLOOKUP($E$3&B8,FBA渠道汇总!A:G,4,FALSE),"*") -> 10.5 | D8: =IFERROR(VLOOKUP($E$3&B8,FBA渠道汇总!A:G,5,FALSE),"*") -> 10.5 | E8: =IFERROR(VLOOKUP($E$3&B8,FBA渠道汇总!A:G,6,FALSE),"-") -> 12-15个自然日 | F8: =IFERROR(VLOOKUP($E$3&B8,FBA渠道汇总!A:G,7,FALSE),"-") -> 20个自然日
C9: =IFERROR(VLOOKUP($E$3&B9,FBA渠道汇总!A:G,4,FALSE),"*") -> * | D9: =IFERROR(VLOOKUP($E$3&B9,FBA渠道汇总!A:G,5,FALSE),"*") -> * | E9: =IFERROR(VLOOKUP($E$3&B9,FBA渠道汇总!A:G,6,FALSE),"-") -> - | F9: =IFERROR(VLOOKUP($E$3&B9,FBA渠道汇总!A:G,7,FALSE),"-") -> -
C10: =IFERROR(VLOOKUP($E$3&B10,FBA渠道汇总!A:G,4,FALSE),"*") -> * | D10: =IFERROR(VLOOKUP($E$3&B10,FBA渠道汇总!A:G,5,FALSE),"*") -> * | E10: =IFERROR(VLOOKUP($E$3&B10,FBA渠道汇总!A:G,6,FALSE),"-") -> - | F10: =IFERROR(VLOOKUP($E$3&B10,FBA渠道汇总!A:G,7,FALSE),"-") -> -
B11: *请注意：我司不接收任何违禁品，仿牌，纯粉末液体，易燃易爆，国家管制物品，稀有金属木材制品等货物。请勿恶意冲货，一经发现报警处理并保留追究法律责任！

Sheet FBA海卡服务美东（纽约拆柜）
C2: 广东皓辉国际物流有限公司 | I2: 好时效 选皓辉
C3: Guangdong Haohui International Logistics Co., Ltd.
B4: 皓行无疆 辉承品质 | I4: 返回首页
C5: 美东快线采用EXX快船IPI在洛杉矶上火车直达纽约拆柜，美东直航请往下拉价格表； 含税渠道，自营卡车，极速送仓，入仓当天回传POD | I5: 生效日期：2026-06-29
B7: 分区 | C7: FBA仓库代码 | D7: 渠道名称: 纽约皓速达-FBA海卡 (EXX快船） 单位:人民币
D8: 广州仓/深圳仓 | H8: 参考时效 | I8: 备注
D9: 12KG+ | E9: 51KG+ | F9: 101KG+ | G9: 301KG+ | H9: (开船后第二天算起）
C10: TikTok 邮编08846 | D10: ** | E10: ** | F10: ** | G10: 11.9 | H10: 18-22个自然日 | I10: 美东IPI 海铁联运 洛杉矶上火车直达纽约 纽约仓拆柜 EXX/ZIM带车架 混配 周六截单，周日装柜
C11: TikTok 邮编17241 | D11: ** | E11: ** | F11: ** | G11: 12.6 | H11: 18-22个自然日
C12: 希音 邮编08010 | D12: ** | E12: ** | F12: ** | G12: 12.4 | H12: 18-22个自然日
C13: 希音 邮编19030 | D13: ** | E13: ** | F13: ** | G13: 13.1 | H13: 18-22个自然日
C14: 4PX/橙联 邮编08861 | D14: ** | E14: ** | F14: ** | G14: 11.9 | H14: 18-22个自然日
C15: TEMU 邮编08861/07036/08022 | D15: ** | E15: ** | F15: ** | G15: 11.9 | H15: 18-22个自然日
B16: 一区 | C16: ABE8,ACY2,TEB6,TEB9,TTN2 | D16: 12 | E16: 11 | F16: 11 | G16: 11 | H16: 18-22个自然日
B17: 二区 | C17: AVP1,TEB4,TEB3,ABE3,ABE4,XEW5 | D17: 12.2 | E17: 11.2 | F17: 11.2 | G17: 11.2 | H17: 20-24个自然日
B18: 三区 | C18: MDT1,MDT4,PHL6,WBW2,SWF1,SWF2, ILG1,PHL4,IUSL | D18: 12.5 | E18: 11.5 | F18: 11.5 | G18: 11.5 | H18: 22-26个自然日
B19: 四区 | C19: RIC1,XRI3,ORF2,RMN3,IUST,HGR2,HGR6, ALB1,DCA6,XLX1,CHO1，HIA1 | D19: 12.9 | E19: 11.9 | F19: 11.9 | G19: 11.9 | H19: 22-26个自然日
B20: 五区 | C20: CLT2,CLT3,GSO1,GSP1,CMH2,CMH3,PIT2,LBE1, AKR1,RDU2,RDU4,XLX6,DET1,DET2，TPA3，LAN2 | D20: 13.3 | E20: 12.3 | F20: 12.3 | G20: 12.3 | H20: 22-26个自然日
B21: 分区 | C21: FBA仓库代码 | D21: 渠道名称: 皓东达-FBA海卡 单位:人民币
D22: 广州仓/深圳仓 | H22: 参考时效 | I22: 备注
D23: 12KG+ | E23: 51KG+ | F23: 101KG+ | G23: 301KG+ | H23: (开船后第二天算起）
C24: TikTok 邮编08846 | D24: ** | E24: ** | F24: ** | G24: 7.9 | H24: 40-43个自然日 | I24: 纽约拆柜 美东直航
C25: TikTok 邮编17241 | D25: ** | E25: ** | F25: ** | G25: 8.3 | H25: 40-43个自然日
C26: 希音 邮编19030/08010 | D26: ** | E26: ** | F26: ** | G26: 8.4 | H26: 40-43个自然日
C27: 4PX/橙联 邮编08861 | D27: ** | E27: ** | F27: ** | G27: 8.1 | H27: 40-43个自然日
C28: TEMU 邮编08861/07036/08022 | D28: ** | E28: ** | F28: ** | G28: 8.1 | H28: 40-43个自然日
B29: 一区 | C29: ABE8,ACY2,TEB6,TEB9,TTN2 | D29: 7.7 | E29: 7.7 | F29: 7.7 | G29: 7.7 | H29: 40-45个自然日
B30: 二区 | C30: AVP1,TEB4,TEB3,ABE3,ABE4,XEW5 | D30: 7.8 | E30: 7.8 | F30: 7.8 | G30: 7.8 | H30: 40-45个自然日
B31: 三区 | C31: MDT1,HIA1,MDT4,PHL6,WBW2,SWF1,SWF2, ILG1,PHL4,IUSL | D31: 8.2 | E31: 8.2 | F31: 8.2 | G31: 8.2 | H31: 40-45个自然日
B32: 四区 | C32: RIC1,XRI3,ORF2,RMN3,IUST,HGR2,HGR6, ALB1,DCA6,XLX1,CHO1 | D32: 8.6 | E32: 8.6 | F32: 8.6 | G32: 8.6 | H32: 40-45个自然日
B33: 五区 | C33: CLT2,CLT3,GSO1,GSP1,CMH2,CMH3,PIT2,LBE1, AKR1,RDU2,RDU4,XLX6,DET1,DET2，TPA3 | D33: 8.9 | E33: 8.9 | F33: 8.9 | G33: 8.9 | H33: 43-48个自然日
B34: 出货前需提供按我司格式的装箱单发票；每箱货物需贴两个以上的FBA标签
B35: 重货优惠（单票计费重101KG 以上）：货型1：250 优惠0.3元/KG,1:350 优惠0.5元/KG,1:500以上优惠1元/KG
B36: 非热门仓卡派海外仓可能需要5-10天时间集货预约/非大热仓库，不在价格表呈现的仓库代码，价格单询
B37: 其他附加费
B38: 熏蒸费 | D38: 800元/票 | F38: 商检费 | G38: 产品出口如需商检，需工厂自备商检；
B39: 国内单证报关费 | D39: 250元/票，单证退税 | E39: 续页费收 | F39: 续页费收 | G39: 80元/页（产生才收取，不产生不收取）
B40: 国内贴标费（未贴我司入仓单） | D40: 0.5元/箱 | E40: 查验费 | F40: 查验费 | G40: 正报报关的其他费用：如遇查验，查验费800元/票；如查验产生海关罚款，以海关账单为准；以上因正报单证查验产生的费用由发货人承担；
B41: 木制品,电动产品+0/KG，钢铁铝制品+0/KG,玩具/真皮/幼婴/车灯：单询； | D41: 单询 | E41: 钢铁铝制品 | F41: 钢铁铝制品 | G41: *
B42: 报价备注 | C42: 按公斤含税：体积重KG=长cm*宽cm*高cm/6000；
...

Sheet LDP商业海卡服务美东（纽约拆柜）
B2: 广东皓辉国际物流有限公司 | Q2: 好时效 选皓辉
E3: Guangdong Haohui International Logistics Co., Ltd.
F5: 皓行无疆 辉承品质 | Q5: 返回首页
B7: LDP全渠道: 服装+附加费0.5元/Kg | P7: 生效日期：2026-06-29
B8: 渠道名称：皓东达-LDP海卡 （美东直航-纽约拆柜） 单位:人民币RMB
B9: 需要额外加收过桥费地区：长岛、曼哈顿、皇后区、布鲁克林等纽约市区需要加收50USD/票的过桥费
B10: 目的港 | C10: 渠道代码 | D10: 分区（邮编） | E10: 101KG+ (最低消费101KG） | H10: 301KG+ | J10: 1001KG+ | M10: 3001KG+ | N10: 参考时效 （开船次日算起） | P10: 备注
B11: 纽约 拆柜 | C11: 皓东达- LDP海卡 （纽约直航） 美东直航船 | D11: 纽约自提（07036） | E11: 10.8 | H11: 8 | J11: 7.7 | M11: 7.7 | N11: 40-43个自然日 | P11: 海运双清含税到门 单票超30CBM需分票下单 重要事项说明： 1.按KG计费，1CBM=167KG，体积重除6000，实重与体积重那个大取那个计费； 2.国际海运保丢不保损，货值高产品请务必购买保险，易碎物品请自行做好包装； 3.货物的宽度与高度超2.2m货物需单询（需能装得进柜子）； 4.发货前请务必正确填写收货地址和联系人方式正确，如因联系不上收货人而产生的滞留费，由发货人承担，我司有权反弹账单至发货人处，有效期一年； 5.涉及到以下地址会产生额外派送费用，实报实销：建筑和公用事业场所，政府场所、机场、矿山、天然气、油田 ，码头、码头和集装箱货运站等，参展货物，私人物品,学校地址，实验室地址，大使馆等地址； 6.此价格表不适用于展会物流/展会现场；
D12: 邮编开头：07，08， 10，11 | E12: 13.8 | H12: 9.2 | J12: 8.6 | M12: 8.3
D13: 邮编开头：0-1 | E13: 14.8 | H13: 9.8 | J13: 9.3 | M13: 9 | N13: 40-45个自然日
D14: 邮编开头：2 | E14: 16 | H14: 13.2 | J14: 11.7 | M14: 11.3 | N14: 40-45个自然日
D15: 邮编开头：3 | E15: 17 | H15: 14.2 | J15: 12.7 | L15: 3.2 | M15: 12.3 | N15: 43-48个自然日
D16: 如需从纽约派送至以上价格表上未呈现的地区，需单询
B17: 美东快线 渠道名称：纽约皓速达-LDP海卡 （快船从洛杉矶上火车直达纽约拆柜） 单位:人民币RMB
B18: 需要额外加收过桥费地区：长岛、曼哈顿、皇后区、布鲁克林等纽约市区需要加收50USD/票的过桥费
B19: 目的港 | C19: 渠道代码 | D19: 分区（邮编） | E19: 101KG+ (最低消费101KG） | H19: 301KG+ | J19: 1001KG+ | M19: 3001KG+ | N19: 参考时效 （开船次日算起） | P19: 备注
B20: 纽约 拆柜 | C20: 纽约皓速达- LDP海卡 （海铁联运） 美东快线 EXX/ZEX带车架混配 | D20: 纽约自提（07036） | E20: 15.3 | H20: 12.8 | J20: 11.5 | M20: 11.5 | N20: 21-24个自然日 | P20: 海运双清含税到门 单票超30CBM需分票下单 重要事项说明： 1.按KG计费，1CBM=167KG，体积重除6000，实重与体积重那个大取那个计费； 2.国际海运保丢不保损，货值高产品请务必购买保险，易碎物品请自行做好包装； 3.货物的宽度与高度超2.2m货物需单询（需能装得进柜子）； 4.发货前请务必正确填写收货地址和联系人方式正确，如因联系不上收货人而产生的滞留费，由发货人承担，我司有权反弹账单至发货人处，有效期一年； 5.涉及到以下地址会产生额外派送费用，实报实销：建筑和公用事业场所，政府场所、机场、矿山、天然气、油田 ，码头、码头和集装箱货运站等，参展货物，私人物品,学校地址，实验室地址，大使馆等地址； 6.此价格表不适用于展会物流/展会现场；
D21: 邮编开头：07，08， 10，11 | E21: 18.3 | H21: 14 | J21: 12.4 | M21: 12.1
D22: 邮编开头：0-1 | E22: 19.3 | H22: 14.6 | J22: 13.1 | M22: 12.8 | N22: 21-25个自然日
D23: 邮编开头：2 | E23: 21.3 | H23: 18.8 | J23: 16.3 | M23: 15.9 | N23: 23-27个自然日
D24: 邮编开头：3 | E24: 22.3 | H24: 19.8 | J24: 17.3 | L24: 7.8 | M24: 16.9 | N24: 24-28个自然日
D25: 如需从纽约派送至以上价格表上未呈现的地区，需单询
B26: *请注意：我司不接收任何违禁品，仿牌，纯粉末液体，易燃易爆，国家管制物品，稀有金属木材制品等货物。请勿恶意冲货，一经发现报警处理并保留追究法律责任！
B27: 单件货物重量只限在1000KG以内的货物，单件超过1000KG的货物需要单询； 单件超48KG必须打托盘；单票货物超过30CBM需要分票下单；此渠道不接FBA货物；
B28: 岛屿地址价格需单询：邮编：966-969夏威夷、关岛，995-999阿拉斯加，006-009波多黎各、维京岛； 不收PO.X地址，不收军方地址；
B29: 航空箱包装货物价格单询；可接纸箱、木架、木箱包装，纸箱包装需要使用硬朗纸箱，自行做好包装，以免派送途中货物掉落，只保整件到达，不保内质内数；
B30: 此渠道为头程海运+尾程卡车派送（自营车队+商业卡车组合派送），自营海外仓拆柜+自营清关行+自营派送车队，全程一手海卡大庄；
B31: 自提需收取出库费：150元/托盘（2.4米以内），超过2.4米以上货物与木箱木架货需视具体尺寸收取出库费、国内贴标费（未贴我司入仓单）：0.5元/箱
B32: 单证报关货收费 | D32: 国内单证报关费 | E32: 250元/票 | H32: 单证续页费 | J32: 80元/页（产生才收取） | N32: 商检费 | P32: 产品出口如需商检，需工厂自备商检；
B33: 自备单证报关 ：正报报关的其他费用：如遇查验，查验费800元/票；如查验产生海关罚款，以海关账单为准；以上因正报单证查验产生的费用由发货人承担；
B34: 超长货物 附加费 | C34: 任意一边超≥2.35米，加2元/kg，最低收费1000元/票 | H34: 单件超过1.5吨的货物请单询确认装卸货的条件才能交货，特别是目的港收货人是否具备卸货能力，以免产生额外费用；
C35: 任意一边超≥3米，加3元/kg,最低收费2000元/票 | H35: 任意一边超≥4米，加3元/kg,最低收费4000元/票 | N35: 任意一边超≥5米，加3元/kg,最低收费9600元/票
C36: 任意一边超≥6-6.99米，加5元/kg,最低收费15000元/票 | H36: 任意一边超≥7米以上单询，需视具体派送地址而定； | N36: 90-928邮编按计费重收取超长费，无最低消费，其他有最低消费
B37: 商业地址 | C37: 免收 | D37: 私人住宅 | E37: 500元/票 | H37: 薰蒸费 | J37: 5CBM以内800元，最低消费800元；5.01CBM-15CBM之间1200元；15cbm以上1800元；
B38: TikTok仓库价格看FBA渠道价格表 | H38: 品名费 | J38: 免收，请如实申报，玩具/真皮/幼婴/车灯单询 | N38: 国内退仓费 | P38: 10元/CBM，最低消费50元
B39: 国内仓储费：从入仓日起算免仓7天，第8-30天收取2元/CBM/天，第31-60天收取3元/CBM/天，不足1CBM按照1CBM算，超过60天未支付仓储费的按照弃货处理。
B40: 改单费 | C40: 装柜后~到港前：改单费300元/票；到港后~入海外仓前：改单费500元/票；入海外仓后~出仓派送前：改单费800元/票；出仓派送后需要改单改派的，将根据具体情况另议收费。所有到港后改地址的订单，不保证改派成功。由于客户原因需要更改派送地址的，高价区域改低价区域的不退差价，低价区域改高价区域的，必须补齐我司差价。
B41: 海外 费用 | C41: 贴换标费 | D41: 1USD/张 | H41: 指定时间送达 | J41: 单询（客户指定时间点送达） | N41: 特殊预约费 | P41: 350元/票
C42: 海外仓拍照费 | D42: 3USD/张 | H42: 销毁费 | J42: 3USD/KG | N42: 二次派送费 | P42: 视具体情况与距离单询
C43: 海外仓仓储费 | D43: 仓储费阶梯计费：1-7天免费，8-30天/CBM：1.5USD/天/CBM，31-90天：3USD/天/CBM， 91天以上：5USD/天/CBM，按CBM计费（不足1CBM按1CBM计费）； | N43: 卸货等待费 | P43: 85USD/小时，免30分钟卸货时间
...

Sheet LDP商业海卡服务全美（洛杉矶拆柜）
B2: 广东皓辉国际物流有限公司 | Q2: 好时效 选皓辉
E3: Guangdong Haohui International Logistics Co., Ltd.
F5: 皓行无疆 辉承品质 | Q5: 返回首页
B7: 此渠道专注商业地址及私人地址等美国全境48州可达，洛杉矶—卡车全境派送； 提供分批入仓，海外仓集货一起派送或者分批派送等定制化模式； | P7: 生效日期：2026-06-29
B8: LDP全渠道: 服装+附加费0.5元/Kg
B9: 美国商业件LDP海卡 （洛杉矶拆柜 ） 单位:人民币RMB
B10: 目的港 | C10: 渠道代码 | D10: 分区（邮编） | E10: 101KG+ (最低消费101KG） | H10: 301KG+ | J10: 1001KG+ | M10: 3001KG+ | N10: 参考时效 （开船次日算起） | P10: 备注
C11: 皓快达-LDP 性价比之王 （OA船：COSCO/OOCL/EMC） | D11: 自提（91748） | E11: 12.7 | H11: 8 | J11: 7.6 | M11: 7.6 | N11: 17-20个自然日 本地派送只需要1-2天 | P11: 海运双清含税到门 单票超30CBM需分票下单 重要事项说明： 1.按KG计费，1CBM=167KG，体积重除6000，实重与体积重那个大取那个计费； 2.国际海运保丢不保损，货值高产品请务必购买保险，易碎物品请自行做好包装； 3.货物的宽度与高度超2.2m货物需单询（需能装得进柜子）； 4.发货前请务必正确填写收货地址和联系人方式正确，如因联系不上收货人而产生的滞留费，由发货人承担，我司有权反弹账单至发货人处，有效期一年； 5.涉及到以下地址会产生额外派送费用，实报实销：建筑和公用事业场所，政府场所、机场、矿山、天然气、油田 ，码头、码头和集装箱货运站等，参展货物，私人物品,学校地址，实验室地址，大使馆等地址； 6.此价格表不适用于展会物流/展会现场；
D12: 邮编900-928 | E12: 15.7 | H12: 8.5 | J12: 8 | M12: 7.6
D13: 邮编930-937 | E13: 17.7 | H13: 12.1 | J13: 10.1 | M13: 9.9 | N13: 19-24个自然日
D14: 邮编938-954， 956-959，961 | E14: 18.5 | H14: 12.9 | J14: 10.9 | M14: 10.7
D15: 邮编955， 960， 850，890 | E15: 19 | H15: 13.4 | J15: 11.4 | M15: 11.2 | N15: 19-25个自然日
B16: 洛杉矶 | D16: 邮编8-9 （不含上面已列出） | E16: 21.9 | H16: 14.5 | J16: 12 | M16: 11.8 | N16: 19-25个自然日
D17: 邮编7 | E17: 23.6 | H17: 17.2 | J17: 15.2 | M17: 15 | N17: 22-26个自然日
D18: 邮编4-6 | E18: 24.6 | H18: 18.2 | J18: 16.2 | M18: 16 | N18: 22-26个自然日
D19: 邮编0-3 | E19: 25.6 | H19: 19.2 | J19: 17.2 | M19: 17 | N19: 24-30个自然日
B21: 洛杉矶 | C21: 皓速达-LDP (以星/合德快提） 高时效之王 | D21: 自提（91748） | E21: 13.1 | H21: 9 | J21: 8.5 | M21: 8 | N21: 13-16个自然日
D22: 邮编900-928 | E22: 16.1 | H22: 9 | J22: 8.5 | M22: 8
D23: 邮编930-937 | E23: 18.1 | H23: 12.5 | J23: 10.5 | M23: 10.3 | N23: 16-21个自然日
D24: 邮编938-954， 956-959，961 | E24: 18.9 | H24: 13.3 | J24: 11.3 | M24: 11.1
D25: 邮编955， 960， 850，890 | E25: 19.4 | H25: 13.8 | J25: 11.8 | M25: 11.6 | N25: 16-22个自然日
D26: 邮编8-9 （不含上面已列出） | E26: 22.6 | H26: 15.5 | J26: 13 | M26: 12.8 | N26: 16-22个自然日
D27: 邮编7 | E27: 24.3 | H27: 18.2 | J27: 16.2 | M27: 16 | N27: 19-23个自然日
D28: 邮编4-6 | E28: 25.3 | H28: 19.2 | J28: 17.2 | M28: 17 | N28: 19-23个自然日
D29: 邮编0-3 | E29: 26.3 | H29: 20.2 | J29: 18.2 | M29: 18 | N29: 21-27个自然日
B31: 洛杉矶 | C31: 皓森达-LDP 美森正班 | D31: 自提（91748） | E31: 16.6 | H31: 11.4 | J31: 11.2 | M31: 11.2 | N31: 12-14个自然日
D32: 邮编900-928 | E32: 19.3 | H32: 12.1 | J32: 11.6 | M32: 11.4
D33: 邮编930-937 | E33: 21.3 | H33: 14.1 | J33: 13.1 | M33: 12.9 | N33: 15-20个自然日
D34: 邮编938-954， 956-959，961 | E34: 22.1 | H34: 14.9 | J34: 13.9 | M34: 13.7
D35: 邮编955， 960， 850，890 | E35: 22.6 | H35: 15.4 | J35: 14.4 | M35: 14.2 | N35: 15-20个自然日
D36: 邮编8-9 （不含上面已列出） | E36: 25.8 | H36: 16.6 | J36: 15.1 | M36: 14.9 | N36: 16-22个自然日
D37: 邮编7 | E37: 27.5 | H37: 19.3 | J37: 18.3 | M37: 18.1 | N37: 19-23个自然日
D38: 邮编4-6 | E38: 28.5 | H38: 20.3 | J38: 19.3 | M38: 19.1 | N38: 19-23个自然日
D39: 邮编0-3 | E39: 29.5 | H39: 21.3 | J39: 20.3 | M39: 20.1 | N39: 21-27个自然日
B40: *请注意：我司不接收任何违禁品，仿牌，纯粉末液体，易燃易爆，国家管制物品，稀有金属木材制品等货物。请勿恶意冲货，一经发现报警处理并保留追究法律责任！
B41: 单件货物重量只限在1000KG以内的货物，单件超过1000KG的货物需要单询； 单件超48KG必须打托盘；单票货物超过30CBM需要分票下单；此渠道不接FBA货物；
B42: 岛屿地址价格需单询：邮编：966-969夏威夷、关岛，995-999阿拉斯加，006-009波多黎各、维京岛； 不收PO.X地址，不收军方地址；
B43: 航空箱包装货物价格单询；可接纸箱、木架、木箱包装，纸箱包装需要使用硬朗纸箱，自行做好包装，以免派送途中货物掉落，只保整件到达，不保内质内数；
B44: 此渠道为头程海运+尾程卡车派送（自营车队+商业卡车组合派送），自营海外仓拆柜+自营清关行+自营派送车队，全程一手海卡大庄；
B45: 自提需收取出库费：150元/托盘（2.4米以内），超过2.4米以上货物与木箱木架货需视具体尺寸收取出库费、国内贴标费（未贴我司入仓单）：0.5元/箱
...

Sheet FBA海卡服务美西
D2: 广东皓辉国际物流有限公司 | S2: 好时效 选皓辉
D3: Guangdong Haohui International Logistics Co., Ltd.
B4: 皓行无疆 辉承品质 | S4: 返回首页
D5: 该渠道含税，自营卡车与海外仓以最快当天到港当天提柜当天拆柜做到极速送仓，入仓当天回传POD；（受卡车涨价影响，美东的建议走美东快线或者美东直航） | S5: 生效日期：2026-06-29
B6: 分区 | C6: FBA仓库代码 | D6: 皓快达 COSCO/OOCL | G6: 皓速达-带托架 | K6: 皓速达（ZEX不带托架) | O6: 皓森达(美森正班CLX） | S6: 单位:人民币
D7: 广州仓/深圳仓 | F7: 参考时效 (开船后第二天算起） | G7: 广州仓/深圳仓 | I7: 参考时效 | J7: 理赔时效 | K7: 广州仓/深圳仓 | M7: 参考时效 | N7: 理赔时效 | O7: 广州仓/深圳仓 | Q7: 参考时效 | R7: 理赔时效 | S7: 备注
D8: 12KG+ | E8: 51KG+ | G8: 12KG+ | H8: 51KG+ | I8: 开船后 | J8: （开船后第二天算起） | K8: 12KG+ | L8: 51KG+ | M8: 开船后 | N8: （开船后第二天算起） | O8: 12KG+ | P8: 51KG+ | Q8: 开船后 | R8: （开船后第二天算起）
B9: 一区 | C9: ONT8 | D9: 6.9 | E9: 6.9 | F9: 17-21个自然日 | G9: 7.9 | H9: 7.9 | I9: 14-17个自然日 | J9: 23个自然日 | K9: 7.3 | L9: 7.3 | M9: 16-19个自然日 | N9: 25个自然日 | O9: 10.5 | P9: 10.5 | Q9: 12-15个自然日 | R9: 20个自然日 | S9: 我司优势： 目的港自营海外仓、 自营卡车派送， 多年经验的运营团队； 与船司直接签约， 舱位保障性更强， 自有合约， 旺季更强的保柜能力； 挑选船司服务里 最快最优质航线； 含税报价 皓快达渠道- 用的是OA快船里的COSCO的SEA航线与OOCL的PVCS航线为主 皓速达-带托架渠道: 用的是以星ZIM-ZEX航线带托架服务，目的港提柜快一步； 皓速达渠道： 用的是以星ZIM-ZEX不带车架服务，稳定的提柜效率，更短的航程时间； 皓森达渠道: 用的是美森正班CLX航线，上海开船，11天航程，将货物以更快的速度送达的首选渠道，比空运更有优势的价格，美西快至12天签收；
B10: 一区 | C10: LGB8 | D10: 6.9 | E10: 6.9 | F10: 17-21个自然日 | G10: 7.9 | H10: 7.9 | I10: 14-17个自然日 | J10: 23个自然日 | K10: 7.3 | L10: 7.3 | M10: 16-19个自然日 | N10: 25个自然日 | O10: 10.5 | P10: 10.5 | Q10: 12-15个自然日 | R10: 20个自然日
B11: 一区 | C11: SBD1 | D11: 6.9 | E11: 6.9 | F11: 17-21个自然日 | G11: 7.9 | H11: 7.9 | I11: 14-17个自然日 | J11: 23个自然日 | K11: 7.3 | L11: 7.3 | M11: 16-19个自然日 | N11: 25个自然日 | O11: 10.5 | P11: 10.5 | Q11: 12-15个自然日 | R11: 20个自然日
B12: 一区 | C12: LAX9 | D12: 6.9 | E12: 6.9 | F12: 17-21个自然日 | G12: 7.9 | H12: 7.9 | I12: 14-17个自然日 | J12: 23个自然日 | K12: 7.3 | L12: 7.3 | M12: 16-19个自然日 | N12: 25个自然日 | O12: 10.5 | P12: 10.5 | Q12: 12-15个自然日 | R12: 20个自然日
B13: 一区 | C13: POC1 | D13: 7 | E13: 7 | F13: 17-21个自然日 | G13: 8 | H13: 8 | I13: 14-17个自然日 | J13: 23个自然日 | K13: 7.4 | L13: 7.4 | M13: 16-19个自然日 | N13: 25个自然日 | O13: 10.6 | P13: 10.6 | Q13: 12-15个自然日 | R13: 20个自然日
B14: 一区 | C14: POC2 | D14: 7 | E14: 7 | F14: 17-21个自然日 | G14: 8 | H14: 8 | I14: 14-17个自然日 | J14: 23个自然日 | K14: 7.4 | L14: 7.4 | M14: 16-19个自然日 | N14: 25个自然日 | O14: 10.6 | P14: 10.6 | Q14: 12-15个自然日 | R14: 20个自然日
B15: 一区 | C15: POC3 | D15: 7 | E15: 7 | F15: 17-21个自然日 | G15: 8 | H15: 8 | I15: 14-17个自然日 | J15: 23个自然日 | K15: 7.4 | L15: 7.4 | M15: 16-19个自然日 | N15: 25个自然日 | O15: 10.6 | P15: 10.6 | Q15: 12-15个自然日 | R15: 20个自然日
B16: 二区 | C16: PSP3 | D16: 7.7 | E16: 7.7 | F16: 18-22个自然日 | G16: 8.7 | H16: 8.7 | I16: 15-19个自然日 | J16: 23个自然日 | K16: 8.1 | L16: 8.1 | M16: 17-21个自然日 | N16: 27个自然日 | O16: 11.3 | P16: 11.3 | Q16: 13-17个自然日 | R16: 22个自然日
B17: 二区 | C17: SMF3 | D17: 7.7 | E17: 7.7 | F17: 18-22个自然日 | G17: 8.7 | H17: 8.7 | I17: 15-19个自然日 | J17: 23个自然日 | K17: 8.2 | L17: 8.2 | M17: 17-21个自然日 | N17: 27个自然日 | O17: 11.4 | P17: 11.4 | Q17: 13-17个自然日 | R17: 22个自然日
B18: 二区 | C18: SCK4 | D18: 7.7 | E18: 7.7 | F18: 18-22个自然日 | G18: 8.7 | H18: 8.7 | I18: 15-19个自然日 | J18: 23个自然日 | K18: 8.2 | L18: 8.2 | M18: 17-21个自然日 | N18: 27个自然日 | O18: 11.4 | P18: 11.4 | Q18: 13-17个自然日 | R18: 22个自然日
B19: 二区 | C19: GYR2 | D19: 7.7 | E19: 7.7 | F19: 18-22个自然日 | G19: 8.7 | H19: 8.7 | I19: 15-19个自然日 | J19: 23个自然日 | K19: 8.1 | L19: 8.1 | M19: 17-21个自然日 | N19: 27个自然日 | O19: 11.3 | P19: 11.3 | Q19: 13-17个自然日 | R19: 22个自然日
B20: 二区 | C20: GYR3 | D20: 7.7 | E20: 7.7 | F20: 18-22个自然日 | G20: 8.7 | H20: 8.7 | I20: 15-19个自然日 | J20: 23个自然日 | K20: 8.1 | L20: 8.1 | M20: 17-21个自然日 | N20: 27个自然日 | O20: 11.3 | P20: 11.3 | Q20: 13-17个自然日 | R20: 22个自然日
B21: 二区 | C21: LAS1 | D21: 7.7 | E21: 7.7 | F21: 18-22个自然日 | G21: 8.7 | H21: 8.7 | I21: 15-19个自然日 | J21: 23个自然日 | K21: 8.1 | L21: 8.1 | M21: 17-21个自然日 | N21: 27个自然日 | O21: 11.3 | P21: 11.3 | Q21: 13-17个自然日 | R21: 22个自然日
... B68: 其他区 | C68: GEG2 | D68: 14.5 | E68: 14 | F68: 28-34个自然日 | G68: 15.5 | H68: 15 | I68: 23-30个自然日 | J68: 不参与时效赔付 | K68: 14.5 | L68: 14 | M68: 25-32个自然日 | N68: 不参与时效赔付 | O68: 18.1 | P68: 17.6 | Q68: 20-28个自然日 | R68: 不参与时效赔付
B69: 其他区 | C69: MDW6 | D69: 14 | E69: 13.5 | F69: 28-34个自然日 | G69: 15 | H69: 14.5 | I69: 23-30个自然日 | J69: 不参与时效赔付 | K69: 14.1 | L69: 13.6 | M69: 25-32个自然日 | N69: 不参与时效赔付 | O69: ** | P69: ** | Q69: ** | R69: **
B70: 其他区 | C70: BAN2 | D70: 14.5 | E70: 14 | F70: 28-34个自然日 | G70: 15.5 | H70: 15 | I70: 23-30个自然日 | J70: 不参与时效赔付 | K70: 14.1 | L70: 13.6 | M70: 25-32个自然日 | N70: 不参与时效赔付 | O70: ** | P70: ** | Q70: ** | R70: **
B71: 其他区 | C71: TMB8 | D71: 15.1 | E71: 14.6 | F71: 28-34个自然日 | G71: 16 | H71: 15.5 | I71: 23-30个自然日 | J71: 不参与时效赔付 | K71: 15.1 | L71: 14.6 | M71: 25-32个自然日 | N71: 不参与时效赔付 | O71: ** | P71: ** | Q71: ** | R71: **
B72: 其他区 | C72: IUSP | D72: ** | E72: ** | F72: 28-34个自然日 | G72: ** | H72: ** | I72: 23-30个自然日 | J72: 不参与时效赔付 | K72: ** | L72: ** | M72: 25-32个自然日 | N72: 不参与时效赔付 | O72: ** | P72: ** | Q72: ** | R72: **
B73: 其他区 | C73: IUSQ | D73: ** | E73: ** | F73: 22-28个自然日 | G73: ** | H73: ** | I73: 23-30个自然日 | J73: 不参与时效赔付 | K73: ** | L73: ** | M73: 25-32个自然日 | N73: 不参与时效赔付 | O73: ** | P73: ** | Q73: ** | R73: **
B74: 其他区 | C74: FAT2 | D74: 10.3 | E74: 9.8 | F74: 22-28个自然日 | G74: 11.3 | H74: 10.8 | I74: 23-30个自然日 | J74: 不参与时效赔付 | K74: 10.7 | L74: 10.2 | M74: 25-32个自然日 | N74: 不参与时效赔付 | O74: ** | P74: ** | Q74: ** | R74: **
B75: 其他区 | C75: IUSF | D75: ** | E75: ** | F75: 28-34个自然日 | G75: ** | H75: ** | I75: 23-30个自然日 | J75: 不参与时效赔付 | K75: ** | L75: ** | M75: 25-32个自然日 | N75: 不参与时效赔付 | O75: ** | P75: ** | Q75: ** | R75: **
B76: 其他区 | C76: OKC2 | D76: 13.5 | E76: 13 | F76: 28-34个自然日 | G76: 14.5 | H76: 14 | I76: 23-30个自然日 | J76: 不参与时效赔付 | K76: 13.6 | L76: 13.1 | M76: 25-32个自然日 | N76: 不参与时效赔付 | O76: ** | P76: ** | Q76: ** | R76: **
B77: 其他区 | C77: HOU8 | D77: 13.5 | E77: 13 | F77: 28-34个自然日 | G77: 14.4 | H77: 13.9 | I77: 23-30个自然日 | J77: 不参与时效赔付 | K77: 13.9 | L77: 13.4 | M77: 25-32个自然日 | N77: 不参与时效赔付 | O77: ** | P77: ** | Q77: ** | R77: **
B78: 其他区 | C78: STL3 | D78: 13.9 | E78: 13.4 | F78: 28-34个自然日 | G78: 14.9 | H78: 14.4 | I78: 23-30个自然日 | J78: 不参与时效赔付 | K78: 13.9 | L78: 13.4 | M78: 25-32个自然日 | N78: 不参与时效赔付 | O78: ** | P78: ** | Q78: ** | R78: **
B79: 其他区 | C79: STL4 | D79: 13.9 | E79: 13.4 | F79: 28-34个自然日 | G79: 14.9 | H79: 14.4 | I79: 23-30个自然日 | J79: 不参与时效赔付 | K79: 13.9 | L79: 13.4 | M79: 25-32个自然日 | N79: 不参与时效赔付 | O79: ** | P79: ** | Q79: ** | R79: **
B80: 其他区 | C80: FOE1 | D80: 13.9 | E80: 13.4 | F80: 28-34个自然日 | G80: 14.9 | H80: 14.4 | I80: 23-30个自然日 | J80: 不参与时效赔付 | K80: 13.9 | L80: 13.4 | M80: 25-32个自然日 | N80: 不参与时效赔付 | O80: ** | P80: ** | Q80: ** | R80: **
B81: 其他区 | C81: ICT2 | D81: 13.9 | E81: 13.4 | F81: 28-34个自然日 | G81: 14.9 | H81: 14.4 | I81: 23-30个自然日 | J81: 不参与时效赔付 | K81: 13.9 | L81: 13.4 | M81: 25-32个自然日 | N81: 不参与时效赔付 | O81: ** | P81: ** | Q81: ** | R81: **
B82: 其他区 | C82: DEN8 | D82: 13.1 | E82: 12.6 | F82: 28-34个自然日 | G82: 14.1 | H82: 13.6 | I82: 23-30个自然日 | J82: 不参与时效赔付 | K82: 13.6 | L82: 13.1 | M82: 25-32个自然日 | N82: 不参与时效赔付 | O82: ** | P82: ** | Q82: ** | R82: **
B83: 其他区 | C83: ORD2 | D83: 13.9 | E83: 13.4 | F83: 28-34个自然日 | G83: 14.9 | H83: 14.4 | I83: 23-30个自然日 | J83: 不参与时效赔付 | K83: 13.9 | L83: 13.4 | M83: 25-32个自然日 | N83: 不参与时效赔付 | O83: ** | P83: ** | Q83: ** | R83: **
B84: 其他区 | C84: MKC4 | D84: 13.5 | E84: 13 | F84: 28-34个自然日 | G84: 14.5 | H84: 14 | I84: 23-30个自然日 | J84: 不参与时效赔付 | K84: 13.5 | L84: 13 | M84: 25-32个自然日 | N84: 不参与时效赔付 | O84: ** | P84: ** | Q84: ** | R84: **
B85: 其他区 | C85: CHA2 | D85: 14.8 | E85: 14.3 | F85: 28-34个自然日 | G85: 15.8 | H85: 15.3 | I85: 23-30个自然日 | J85: 不参与时效赔付 | K85: 14.5 | L85: 14 | M85: 25-32个自然日 | N85: 不参与时效赔付 | O85: ** | P85: ** | Q85: ** | R85: **
B86: 其他区 | C86: LBE1 | D86: 15.1 | E86: 14.6 | F86: 28-34个自然日 | G86: 16.1 | H86: 15.6 | I86: 23-30个自然日 | J86: 不参与时效赔付 | K86: 15.2 | L86: 14.7 | M86: 25-32个自然日 | N86: 不参与时效赔付 | O86: ** | P86: ** | Q86: ** | R86: **
D87: OA快船：COSCO/OOCL | G87: ZEX带车架 | K87: ZEX不带车架/合德快提混配 | O87: 美森正班CLX，上海港口开船，11天航程
...

Sheet 海派服务
D2: 广东皓辉国际物流有限公司 | K2: 好时效 选皓辉
D3: Guangdong Haohui International Logistics Co., Ltd. | G3: Guangdong Haohui International Logistics Co., Ltd.
D4: 皓行无疆 辉承品质
B5: 渠道名称 | C5: 邮编开头 | D5: 海派渠道（头程海运+尾程快递派送） | J5: 生效日期：2026-06-29 | L5: 邮编 | M5: 是否偏远
D6: 广州仓 | G6: 深圳仓 | J6: 单位:人民币 | L6: 48126 | M6: =_xlfn.IFNA(VLOOKUP(L6,'偏远超偏远超级偏远邮编库 '!C:D,2,0),"普通") -> 普通
D7: 12KG+ | E7: 51KG+ | F7: 101KG+ | G7: 12KG+ | H7: 51KG+ | I7: 101KG+ | J7: 参考时效 | K7: 渠道说明 | L7: 上述查询结果仅做参考，具体以账单下来为准！
B8: 皓快达-海派 OA快船海派 COSCO/OOCL | C8: 美国西部 （邮编8-96开头） | D8: 15.1 | E8: 13.1 | F8: 11.1 | G8: 15.1 | H8: 13.1 | I8: 11.1 | J8: 开船后20-25个 自然日提取 | K8: 1、OA快船 2、本渠道双清含税到门 3、材积比6000 4、UPS/FEDEX派送
C9: 美国西部 （邮编97-99开头） | D9: 15.6 | E9: 13.6 | F9: 11.6 | G9: 15.6 | H9: 13.6 | I9: 11.6
C10: 美国中部 （邮编5、6、7开头） | D10: 16.1 | E10: 14.1 | F10: 12.1 | G10: 16.1 | H10: 14.1 | I10: 12.1
C11: 美国东部 （邮编0、1、2、3、4开头） | D11: 17.1 | E11: 15.1 | F11: 13.1 | G11: 17.1 | H11: 15.1 | I11: 13.1
B13: 皓速达-海派 电商快线海派 以星ZEX/合德 | C13: 美国西部 （邮编8-96开头） | D13: 16 | E13: 14 | F13: 12 | G13: 16 | H13: 14 | I13: 12 | J13: 开船后14-17个 自然日提取 | K13: 1、以星ZEX/合德快船 2、本渠道双清含税到门 3、材积比6000 4、UPS/FEDEX派送
C14: 美国西部 （邮编97-99开头） | D14: 16.5 | E14: 14.5 | F14: 12.5 | G14: 16.5 | H14: 14.5 | I14: 12.5
C15: 美国中部 （邮编5、6、7开头） | D15: 17 | E15: 15 | F15: 13 | G15: 17 | H15: 15 | I15: 13
C16: 美国东部 （邮编0、1、2、3、4开头） | D16: 18 | E16: 16 | F16: 14 | G16: 18 | H16: 16 | I16: 14
B18: 皓森达-海派 美森限时达 海派 | C18: 美国西部 （邮编8-96开头） | D18: 19.3 | E18: 17.3 | F18: 15.3 | G18: 19.3 | H18: 17.3 | I18: 15.3 | J18: 开船后12-15个 自然日 | K18: 1、美森正班CLX 2、本渠道双清含税到门 3、材积比6000 4、UPS/FEDEX派送
C19: 美国西部 （邮编97-99开头） | D19: 19.8 | E19: 17.8 | F19: 15.8 | G19: 19.8 | H19: 17.8 | I19: 15.8
C20: 美国中部 （邮编5、6、7开头） | D20: 20.3 | E20: 18.3 | F20: 16.3 | G20: 20.3 | H20: 18.3 | I20: 16.3
C21: 美国东部 （邮编0、1、2、3、4开头） | D21: 21.3 | E21: 19.3 | F21: 17.3 | G21: 21.3 | H21: 19.3 | I21: 17.3
B23: 非FBA地址+1/KG，住宅地址+2元/KG【低消为100/票】，尾程UPS/Fedex快递派送。体积/6000
B24: 产品附加费 | C24: 1、【免加收】普货（除高价值，高关税产品）/纺织品一律免加收；【拒接】纯电/动植物/反倾销/管制刀具/粉末/侵权等产品拒接；
C25: 2、化妆品等FDA类产品单询
C26: 3、电动产品+1/KG，木制品、钢铁铝制品+0/KG,玩具/幼婴/车灯：单询；国内贴标费（未贴我司入仓单）：0.5元/箱
C27: 4、熏蒸费：800元/票；商检费：产品出口如需商检，需工厂自备商检；
B29: 其他杂费 | C29: 1、单证货物，单证报关250元/票，续页费：RMB80/页
C30: 2、单票品名不能超过5个，超出按加50元/个。
C31: 3、单件不足12KG ，按12KG 计费；单箱实重超22KG-38KG，加收240元/箱,超40KG拒收。
C32: 4、以下情况加180元/件，满足多条件叠加收：①包裹最长的一边超过110cm；②第二长的边超过70cm；③围长（长+2*（宽+高）超266cm【超过320cm拒接】【单边超过120cm拒收】
C33: 5、如收件方在UPS远程服务范围，将被加收偏远或者超极偏远地区费用，标准为+4RMB/KG【低消为200/票】；超极偏远地址拒收。
C34: 6、自备单证报关 ：正报报关的其他费用：如遇查验，查验费800元/票；如查验产生海关罚款，以海关账单为准；以上因正报单证查验产生的费用由发货人承担；
B36: 报价备注 | C36: 1、P.O.BOX,阿拉斯加(AK),夏威夷(HI),波多黎各(PR),关岛,军方地址与967**，968**和995**，999**邮编不接。
C37: 2、快递派产品必须是纸箱货物，外箱包装不能缠膜、带护角、扎带，蛇皮袋、麻袋，带颜色胶纸等均不可使用。纸箱必须为长方体或正方体硬朗，并不能全缠胶纸，否则可能会被认定为异性包装。 若箱子包装未达到快递公司标准包装要求，由此产生的相关费用，我们将根据快递公司实际账单进行实报实销。
C38: 3、不接易燃易爆易腐产品。
C39: 4、不接敏感货：仿牌，古董，液体，食品，膏状，蓄电池,粉末，弹药，化工用品，移动电源，药品，未经授权光碟，枪支等国家禁止运输货物。
C40: 5、蓝牙产品带有字样需要提供授权书。
C41: 6、不接反倾销产品：太阳能板，床垫、蜡纸，铝合金，轮胎，复合实木地板，五金钉，卧室家具等，不接。
C42: 7、特殊地址货物需要额外收费：参展货物，私人物品,学校地址，实验室地址，大使馆等地址，需额外加收2元/KG。
C43: 8.1 客户委托我司购买货物保险： 1.1 保险收费：收取投保金额的 3‰（千分之三），最低收费：RMB30/票； 1.2 投保金额：按照单票货物的实际采购价值乘以1.1来投保；如有不足额投保，最高赔偿不超过投保金额， 1.3 赔偿标准：按照实际货损的采购价值作为赔偿,。另外，保险公司有权对采购货值重新核价，最终以保险公司核价为准； 1.4 赔偿主体：客户提供符合保险理赔的所有证明文件，由我司代为向保险公司申请索赔，待我司收到保险公司赔付金额后再交付给客户。 1.5 其它未列明的保险相关细则以保险公司的官方条款为准； 1.6 购买保险默认按照保险理赔；未购买保险按照我司赔付标准理赔
C44: 2. 客户未委托我司购买运输保险，表示默认我司的赔偿标准，具体赔偿标准如下： 2.1 UPS提取前：货物丢失，我司按照采购货值赔偿（最高不超过RMB 20/KG)，不退运费，赔偿时请提供采购发票、购买证明等资料，提供齐全后，我司安排赔付； 2.2 UPS提取后：货物丢失的赔偿标准为每票货物最高赔偿不超过100USD并不退运费，建议客户高价值货物购买运输保险；如遇战争、自然灾害等不可抗力因素导致，我司不承担赔偿责任；在运输过程中如遇到船期延误/海关查验延误等引起的总体时效延误，本司不承担赔偿责任。 2.3 如是因为客户瞒报、品名申报不符、仿牌侵权、或者产品本身质量问题以及涉及到产品相关认证不合格或者无法提供所需证明文件导致，我司不承担任何责任和赔偿并且保留追究发件人因此对我司造成的损失； 2.4 如遇战争、自然灾害等不可抗力因素导致，我司不承担赔偿责任； 2.5 若亚马逊仓库因包装问题.标签问题产生拒收等原因，不受理赔偿； 2.6 碎品不接受任何损坏赔偿。 2.7 如因发件方或收件方要求，或地址错误、收件方原因、UPS官网显示地址错误等无法投递导致退件的，产生退件费用由发件方承担。
B45: 温馨提示：请按我司提供的样板提供电子版发票和装箱单，如因发票申报不符造成的无法清关，我司概不负责！ （清关延误不算在正常派送日内）

Sheet 整柜直送
C2: 广东皓辉国际物流有限公司 | H2: 皓行无疆 辉承品质
C3: Guangdong Haohui International Logistics Co., Ltd.
D4: 美国全境清关&港口/火车站-整柜派送，传统贸易柜派送价格单询 | H4: 返回首页
B5: DDP报价模式，就近港口整柜提送 | H5: 生效日期： 2025-03-03
B6: 仓库类型 | D6: 仓库代码 | E6: 价格 | G6: 备注
B7: 传统贸易整柜直送 | D7: 具体地址 | E7: 单询 | G7: 询价请提供下面具体信息： ● 服务方式 (港到港/门到门/港到门/门到港) ● 起运港-目的港 ● 柜型柜量 ● 品名、货重 ● 货好时间 ● 是否需要代拖车 ● 是否需要代报关（单证/买单） ● 派送地址（drop/live） ●申报货值、货物图片（如需清关服务）
B8: FBA整柜直送 | D8: ONT8,LGB8,LAX9,SBD1,LAS1,VGT2,GYR3,GYR2,SCK4,SMF3,FAT2,MIT2,GEU3,GEU5,ABQ2 | E8: 单询
B9: 沃尔玛整柜直送 | D9: LAX1,LAX2,LAX2T,SMF1n,NJ3,PHL2,MEM1S,KS1,MCI1,IND1,IND2,ATL2,ATL3，MCO1 | E9: 单询
B10: ①常见港口：洛杉矶/长滩，奥克兰，西雅图，纽约/纽瓦克，萨瓦纳，查尔斯顿，威尔明顿，诺福克，巴尔的摩，威尔明顿，费城，波士顿，奥兰多，坦帕，迈阿密， 杰克逊维 尔，休斯顿，新奥尔良，莫比尔 ②常见火车站：盐湖城，丹佛，沃斯堡，达拉斯，芝加哥，底特律，明尼阿波利斯，堪萨斯城，圣路易斯，辛辛那提，克利夫兰，纳什维尔，孟菲斯，印第安纳波利斯， 哥伦布，夏洛特，亚特兰大 ③其他：波多黎各（圣胡安），夏威夷（希洛，火奴鲁鲁），加拿大（多伦多；温哥华） 包括但不仅限上述港口，具体请咨询我司业务或者客服人员！
B11: 报价备注 | C11: 美国尾程派送规则 ①还空柜规则：通知空柜后三个工作日内安排还空.(码头不收空柜或者码头无还空柜预约除外） ②在运输过程中因车架和柜子所产生的任何额外费用由客户承担.例如集装箱损坏、爆胎、灯光问题、车架故障等. ③默认做现场卸货，如需drop off单询；默认COC柜，如SOC柜需提前告知并单询SOC柜还柜费 ④内陆点务必在柜子到站前一天提供PU#，未及时提供PU#导致我司无法及时安排提柜的，产生柜租客人自行承担（如我司订舱忽略）
C14: 请确保货物的合法合规与进口商的安全使用，如货物在美国清关过程中，被海关或者其他官方政府部门查验，查验结果违规并且影响到进口商的继续使用，我司将向客户收取4000美金/提单的罚款，如造成我司损失，客户需要按照合同条款赔偿我司！
C16: 本报价表结算方式为 头程费用（拖车+海运费）：收到账单 Part A后，7个自然日内付款到账； 尾程费用（清关+派送）：清关结束出预收账单-Part B，需在两个工作日内核对并安排支付。派送结束后提供POD并在5个工作日内出最终账单核算多退少补。 请及时支付费用，如逾期，我司将有权对货物的留置权且因此产生码头堆存等额外杂费由客户自行承担。
C19: 1. 客户委托我司购买货物保险： 1.1 保险收费：收取投保金额的 3‰（千分之三），最低收费：RMB30/票； 1.2 投保金额：按照单票货物的实际采购价值乘以1.1来投保；如有不足额投保，最高赔偿不超过投保金额， 1.3 赔偿标准：按照实际货损的采购价值作为赔偿,。另外，保险公司有权对采购货值重新核价，最终以保险公司核价为准； 1.4 赔偿主体：客户提供符合保险理赔的所有证明文件，由我司代为向保险公司申请索赔，待我司收到保险公司赔付金额后再交付给客户。 1.5 其它未列明的保险相关细则以保险公司的官方条款为准；

Sheet 进口回程物流
C2: 广东皓辉国际物流有限公司 | H2: 皓行无疆 辉承品质
C3: Guangdong Haohui International Logistics Co., Ltd.
B4: 美国本土全境出口，报关拖车订舱一条龙服务 | H4: 返回首页
B5: 美国、加拿大本土出口--------中国、其他国家：到港、双清到门 | H5: 生效日期： 2025-11-17
B6: 渠道类型 | D6: 起运港/起飞机场 | E6: 目的港/落地机场 | F6: 价格 | G6: 备注
B7: 空运 | D7: 洛杉矶 纽约 芝加哥 | E7: 中国大部分机场皆可 | F7: 单询 | G7: 询价请提供下面具体信息： ● 服务方式 (港到港/门到门/港到门/门到港) ● 起运港-目的港 ● 柜型柜量 ● 品名、货重 ● 货好时间 ● 是否需要代拖车 ● 是否需要代报关（单证/买单） ● 派送地址（drop/live） ●申报货值、货物图片（如需清关服务）
B8: 海运 | D8: 洛杉矶 纽约 芝加哥 | E8: 中国大部分港口 香港 其他国家港口 | F8: 单询
B9: 空运：散货、整板订舱（主营南航） 海运：拼箱、整柜订舱（DG柜，冷冻柜、退运货）、美国当地提货报关出口一条龙

Sheet 海外仓服务
A2: 广东皓辉国际物流有限公司 | H2: 皓行无疆 辉承品质
A3: Guangdong Haohui International Logistics Co., Ltd.
H5: 有效至 2025-01-25
A6: 海外仓增值服务
A7: 拆柜地点 | B7: 项目 | C7: 适用港口 | D7: LONG BEACH | E7: 价格（USD） | F7: 备注
A8: 洛杉矶 | B8: 增值服务 | C8: 分拣费 | D8: 每箱 | E8: 1.2 | F8: 海外仓理货操作分拣费用，例：一票货100件，分批出/要求对应着标签覆盖与粘贴，就会产生分拣费用。
C9: 贴标费 | D9: 每张标签 | E9: 0.6 | F9: 换UPS标签与FBA外箱标签，如需换SKU标签单询
C10: 再次托盘费 | D10: 重新打托盘与缠膜 | E10: 15 | F10: 贴标后重新打板会产生此费用，换板的人工材料费。
C11: 海外仓 仓储费 | D11: 每CBM/每天 | E11: 阶梯计费 | F11: 海外仓货物仓储费阶梯计费：1-7天免费，8-30天/CBM：1.5USD/天/CBM，31-90天：3USD/天/CBM，91天以上：5USD/天/CBM， 按CBM计费（不足1CBM按1CBM计费）；
D12: 超规格货板（Over size） | E12: 视情况而定
C13: 分货费 | D13: 每种方式/$50 | E13: 50 | F13: 一个柜子里有UPS/FEDEX/卡派，每一种派送方式为一种。
C14: 出库操作费 | D14: 自提/非亚马逊地址卡车 | E14: 15 | F14: 交快递（UPS/FEDEX）或者亚马逊/自提与非亚马逊地址的会产生此费用，
D15: 亚马逊卡派 | E15: 0 | F15: 亚马逊卡派不产生出库费
C16: 工时费 | D16: 工时费/小时 | E16: 50 | F16: 如需特殊处理时会产生人工工时费,如要求开箱清点，校对库存等。正常理货操作无此费用。
C17: 单箱超重费 | D17: 每箱 | E17: 4 | F17: 入库仓储的货物如每箱大于50磅不超过40箱,每箱将会多收$4,如多于40箱,整柜将多收$160
C18: 超量费 | D18: 超过后每100CTNS | E18: 50 | F18: 单柜超过1000CTNS之后，每超100CTNS加收$50/100箱
B19: 注意事项
B20: 2.本报价表结算方式为预付或者现结，请及时支付费用，如逾期，我司将有权对货物的留置权。

Sheet 入库单
A1: 收货入库单
A2: 广东皓辉国际物流有限公司 Guangdong Haohui International Logistics Co., Ltd.
A3: 订单号:
A4: 客户/ID: | G4: 送货日期: | I4: 年 | K4: 月 | M4: 日
A6: 渠道类型: | B6: □海派服务 | C6: □FBA海卡服务 | D6: □空运服务 | E6: □传统LCL | F6: □LDP商业海卡
A7: 委托我司报关: | B7: □买单 | C7: □单证
A8: 订单信息
A9: 订单品名 | D9: 订单件数 | F9: 实际入库件数 | H9: 体积
A10: 备注：
A11: 收货入库(签字确认)： | E11: 送货人（签字确认）：
A12: FBA号&PO号-件数：（请具体列明）
A13: 送货须知

Sheet 亚马逊仓地址
A1: 首页 | B1: 亚马逊/沃尔玛仓库地址 如遇与亚马逊后台或客户提供地址不一致，请联系相关人员确认/修改
B2: 序号 | C2: 仓库代码 | D2: 国家 | E2: 州 | F2: 城市 | G2: 地址 | H2: 邮编
B3: 1 | C3: PSC2 | D3: 美国 | E3: WA | F3: Pasco | G3: 1351 S Rd 40 E | H3: 99301
B4: 2 | C4: GEG1 | D4: 美国 | E4: WA | F4: SPOKANE | G4: 10010 West Geiger Boulevard | H4: 99224
B5: 3 | C5: GEG2 | D5: 美国 | E5: WA | F5: SPOKANE | G5: 18007 E Garland Ave | H5: 99216
B6: 4 | C6: OLM1 | D6: 美国 | E6: WA | F6: Lacey | G6: 3300 Hogum Bay Rd NE | H6: 98516
B7: 5 | C7: BFI1 | D7: 美国 | E7: WA | F7: Sumner | G7: 1800 140th Avenue E | H7: 98390
B8: 6 | C8: BFI7 | D8: 美国 | E8: WA | F8: Sumner | G8: 1901 140th Ave E | H8: 98390
B9: 7 | C9: BF13 | D9: 美国 | E9: WA | F9: DuPont | G9: 2700 Center Drive | H9: 98327
B10: 8 | C10: BFI3 | D10: 美国 | E10: WA | F10: DuPont | G10: 2700 Center Dr | H10: 98327
B11: 9 | C11: BFL3 | D11: 美国 | E11: WA | F11: DuPont | G11: 2700 Center Drive | H11: 98327
B12: 10 | C12: BFI9 | D12: 美国 | E12: WA | F12: DuPont | G12: 3230 International Pl | H12: 98327
B13: 11 | C13: UWA2 | D13: 美国 | E13: WA | F13: North Seattle | G13: 13537 Aurora Ave. N. | H13: 98133
B14: 12 | C14: UWA3 | D14: 美国 | E14: WA | F14: Seattle | G14: 2121 8th Ave. | H14: 98121
... B52: 50 | C52: FAT1 | D52: 美国 | E52: CA | F52: Fresno | G52: 3575 S. Orange Ave. | H52: 93725
B53: 489 | C53: QXY8 | D53: 美国 | E53: CA | F53: Fresno | G53: 3611 S Northpointe Dr | H53: 93725
B54: 51 | C54: BLF1 | D54: 美国 | E54: CA | F54: Bakersfield | G54: 1601 Petrol Rd | H54: 93308
B55: 52 | C55: BFL1 | D55: 美国 | E55: CA | F55: BAKERSFIELD | G55: 1601 PETROL RD | H55: 93308
B56: 53 | C56: MIT2-ups | D56: 美国 | E56: CA | F56: Visalia | G56: 3256 N Plaza Dr | H56: 93291
B57: 54 | C57: FAT2 | D57: 美国 | E57: CA | F57: VISALIA | G57: 3315 N KELSEY ST | H57: 93291
B58: 55 | C58: MIT2 | D58: 美国 | E58: CA | F58: Shafter | G58: 5408 Express Ave | H58: 93263
B59: 56 | C59: BFL2 | D59: 美国 | E59: CA | F59: Shafte | G59: 4500 Express Ave | H59: 93263
B60: 57 | C60: UCA4 | D60: 美国 | E60: CA | F60: Irvine | G60: 2006 McGaw Ave | H60: 92614
B61: 58 | C61: LGB9 | D61: 美国 | E61: CA | F61: Perris | G61: 4375 N Perris Blvd | H61: 92571
B62: 59 | C62: KRB4 | D62: 美国 | E62: CA | F62: Perris | G62: 4501 Patterson Ave | H62: 92571
B63: 60 | C63: XLX2 | D63: 美国 | E63: CA | F63: PERRIS | G63: 657 W NANCE ST | H63: 92571
B64: 61 | C64: ONT6 | D64: 美国 | E64: CA | F64: Moreno Valley | G64: 24208 San Michele Rd | H64: 92551
B65: 62 | C65: ONT8 | D65: 美国 | E65: CA | F65: Moreno Valley | G65: 24300 Nandina Ave | H65: 92551
... B154: 165 | C154: DEN5 | D154: 美国 | E154: CO | F154: Aurora | G154: 22205 E 19th Ave | H154: 80011
B155: 166 | C155: AMA1 | D155: 美国 | E155: TX | F155: AMARILLO | G155: 8590 NE 24th Ave | H155: 79108
B156: 167 | C156: SAT2 | D156: 美国 | E156: TX | F156: San Marcos | G156: 1401 E McCarty Lane | H156: 78666
B157: 168 | C157: SAT6 | D157: 美国 | E157: TX | F157: San Marcos | G157: 1346 Fortuna Rd | H157: 78666
B158: 169 | C158: SAT4 | D158: 美国 | E158: TX | F158: SAN ANTONIO | G158: 10384 W US HIGHWAY 90 | H158: 78245
B159: 170 | C159: SAT5 | D159: 美国 | E159: TX | F159: San Antonio | G159: 1410 S. Callaghan Road | H159: 78227
B160: 171 | C160: SAT1 | D160: 美国 | E160: TX | F160: Schertz | G160: 6000 Enterprise Avenue | H160: 78154
B161: 172 | C161: HOU8 | D161: 美国 | E161: TX | F161: Fresno | G161: 2303 Hurricane Ln | H161: 77545
B162: 173 | C162: HOU5 | D162: 美国 | E162: TX | F162: Katy | G162: 22525 Clay Rd | H162: 77449
B163: 174 | C163: HOU9 | D163: 美国 | E163: TX | F163: Katy | G163: 22525 Clay Rd | H163: 77449
B164: 175 | C164: HOU3 | D164: 美国 | E164: TX | F164: Brookshire | G164: 31555 Highway 90 E | H164: 77423
B165: 176 | C165: HOU1 | D165: 美国 | E165: TX | F165: Humble | G165: 8120 Humble Westfield Rd | H165: 77338
...

Sheet FBA渠道汇总
A1: 匹配码 | B1: 仓库代码 | C1: 渠道名称 | D1: 12KG+ | E1: 51KG+ | F1: 签收/提取时效（开船后第二天算起） | G1: {赔}理赔时效
A2: =B2&C2 -> IUSP皓森达-FBA海卡 | B2: IUSP | C2: 皓森达-FBA海卡 | D2: =FBA海卡服务美西!O2365 -> 0 | E2: =FBA海卡服务美西!P2365 -> 0 | F2: =FBA海卡服务美西!Q2365 -> 0 | G2: =FBA海卡服务美西!R2365 -> 0
A3: =B3&C3 -> IUSQ皓森达-FBA海卡 | B3: IUSQ | C3: 皓森达-FBA海卡 | D3: =FBA海卡服务美西!O2366 -> 0 | E3: =FBA海卡服务美西!P2366 -> 0 | F3: =FBA海卡服务美西!Q2366 -> 0 | G3: =FBA海卡服务美西!R2366 -> 0
A4: =B4&C4 -> FAT2皓森达-FBA海卡 | B4: FAT2 | C4: 皓森达-FBA海卡 | D4: =FBA海卡服务美西!O2367 -> 0 | E4: =FBA海卡服务美西!P2367 -> 0 | F4: =FBA海卡服务美西!Q2367 -> 0 | G4: =FBA海卡服务美西!R2367 -> 0
A5: =B5&C5 -> IUSF皓森达-FBA海卡 | B5: IUSF | C5: 皓森达-FBA海卡 | D5: =FBA海卡服务美西!O2368 -> 0 | E5: =FBA海卡服务美西!P2368 -> 0 | F5: =FBA海卡服务美西!Q2368 -> 0 | G5: =FBA海卡服务美西!R2368 -> 0
A6: =B6&C6 -> OKC2皓森达-FBA海卡 | B6: OKC2 | C6: 皓森达-FBA海卡 | D6: =FBA海卡服务美西!O2369 -> 0 | E6: =FBA海卡服务美西!P2369 -> 0 | F6: =FBA海卡服务美西!Q2369 -> 0 | G6: =FBA海卡服务美西!R2369 -> 0
A7: =B7&C7 -> HOU8皓森达-FBA海卡 | B7: HOU8 | C7: 皓森达-FBA海卡 | D7: =FBA海卡服务美西!O2370 -> 0 | E7: =FBA海卡服务美西!P2370 -> 0 | F7: =FBA海卡服务美西!Q2370 -> 0 | G7: =FBA海卡服务美西!R2370 -> 0
A8: =B8&C8 -> STL3皓森达-FBA海卡 | B8: STL3 | C8: 皓森达-FBA海卡 | D8: =FBA海卡服务美西!O2371 -> 0 | E8: =FBA海卡服务美西!P2371 -> 0 | F8: =FBA海卡服务美西!Q2371 -> 0 | G8: =FBA海卡服务美西!R2371 -> 0
A9: =B9&C9 -> STL4皓森达-FBA海卡 | B9: STL4 | C9: 皓森达-FBA海卡 | D9: =FBA海卡服务美西!O2372 -> 0 | E9: =FBA海卡服务美西!P2372 -> 0 | F9: =FBA海卡服务美西!Q2372 -> 0 | G9: =FBA海卡服务美西!R2372 -> 0
A10: =B10&C10 -> FOE1皓森达-FBA海卡 | B10: FOE1 | C10: 皓森达-FBA海卡 | D10: =FBA海卡服务美西!O2373 -> 0 | E10: =FBA海卡服务美西!P2373 -> 0 | F10: =FBA海卡服务美西!Q2373 -> 0 | G10: =FBA海卡服务美西!R2373 -> 0
A11: =B11&C11 -> ICT2皓森达-FBA海卡 | B11: ICT2 | C11: 皓森达-FBA海卡 | D11: =FBA海卡服务美西!O2374 -> 0 | E11: =FBA海卡服务美西!P2374 -> 0 | F11: =FBA海卡服务美西!Q2374 -> 0 | G11: =FBA海卡服务美西!R2374 -> 0
A12: =B12&C12 -> DEN8皓森达-FBA海卡 | B12: DEN8 | C12: 皓森达-FBA海卡 | D12: =FBA海卡服务美西!O2375 -> 0 | E12: =FBA海卡服务美西!P2375 -> 0 | F12: =FBA海卡服务美西!Q2375 -> 0 | G12: =FBA海卡服务美西!R2375 -> 0
A13: =B13&C13 -> ORD2皓森达-FBA海卡 | B13: ORD2 | C13: 皓森达-FBA海卡 | D13: =FBA海卡服务美西!O2376 -> 0 | E13: =FBA海卡服务美西!P2376 -> 0 | F13: =FBA海卡服务美西!Q2376 -> 0 | G13: =FBA海卡服务美西!R2376 -> 0
... A16: =B16&C16 -> LBE1皓森达-FBA海卡 | B16: LBE1 | C16: 皓森达-FBA海卡 | D16: =FBA海卡服务美西!O2379 -> 0 | E16: =FBA海卡服务美西!P2379 -> 0 | F16: =FBA海卡服务美西!Q2379 -> 0 | G16: =FBA海卡服务美西!R2379 -> 0
A17: =B17&C17 -> ONT8皓快达-FBA海卡 | B17: ONT8 | C17: 皓快达-FBA海卡 | D17: =FBA海卡服务美西!D9 -> 6.9 | E17: =FBA海卡服务美西!E9 -> 6.9 | F17: =FBA海卡服务美西!F9 -> 17-21个自然日 | G17: *
A18: =B18&C18 -> LGB8皓快达-FBA海卡 | B18: LGB8 | C18: 皓快达-FBA海卡 | D18: =FBA海卡服务美西!D10 -> 6.9 | E18: =FBA海卡服务美西!E10 -> 6.9 | F18: =FBA海卡服务美西!F10 -> 17-21个自然日 | G18: *
A19: =B19&C19 -> SBD1皓快达-FBA海卡 | B19: SBD1 | C19: 皓快达-FBA海卡 | D19: =FBA海卡服务美西!D11 -> 6.9 | E19: =FBA海卡服务美西!E11 -> 6.9 | F19: =FBA海卡服务美西!F11 -> 17-21个自然日 | G19: *
A20: =B20&C20 -> LAX9皓快达-FBA海卡 | B20: LAX9 | C20: 皓快达-FBA海卡 | D20: =FBA海卡服务美西!D12 -> 6.9 | E20: =FBA海卡服务美西!E12 -> 6.9 | F20: =FBA海卡服务美西!F12 -> 17-21个自然日 | G20: *
A21: =B21&C21 -> POC1皓快达-FBA海卡 | B21: POC1 | C21: 皓快达-FBA海卡 | D21: =FBA海卡服务美西!D13 -> 7 | E21: =FBA海卡服务美西!E13 -> 7 | F21: =FBA海卡服务美西!F13 -> 17-21个自然日 | G21: *
A22: =B22&C22 -> POC2皓快达-FBA海卡 | B22: POC2 | C22: 皓快达-FBA海卡 | D22: =FBA海卡服务美西!D14 -> 7 | E22: =FBA海卡服务美西!E14 -> 7 | F22: =FBA海卡服务美西!F14 -> 17-21个自然日 | G22: *
A23: =B23&C23 -> POC3皓快达-FBA海卡 | B23: POC3 | C23: 皓快达-FBA海卡 | D23: =FBA海卡服务美西!D15 -> 7 | E23: =FBA海卡服务美西!E15 -> 7 | F23: =FBA海卡服务美西!F15 -> 17-21个自然日 | G23: *
A24: =B24&C24 -> PSP3皓快达-FBA海卡 | B24: PSP3 | C24: 皓快达-FBA海卡 | D24: =FBA海卡服务美西!D16 -> 7.7 | E24: =FBA海卡服务美西!E16 -> 7.7 | F24: =FBA海卡服务美西!F16 -> 18-22个自然日 | G24: *
A25: =B25&C25 -> SMF3皓快达-FBA海卡 | B25: SMF3 | C25: 皓快达-FBA海卡 | D25: =FBA海卡服务美西!D17 -> 7.7 | E25: =FBA海卡服务美西!E17 -> 7.7 | F25: =FBA海卡服务美西!F17 -> 18-22个自然日 | G25: *
A26: =B26&C26 -> SCK4皓快达-FBA海卡 | B26: SCK4 | C26: 皓快达-FBA海卡 | D26: =FBA海卡服务美西!D18 -> 7.7 | E26: =FBA海卡服务美西!E18 -> 7.7 | F26: =FBA海卡服务美西!F18 -> 18-22个自然日 | G26: *
A27: =B27&C27 -> GYR2皓快达-FBA海卡 | B27: GYR2 | C27: 皓快达-FBA海卡 | D27: =FBA海卡服务美西!D19 -> 7.7 | E27: =FBA海卡服务美西!E19 -> 7.7 | F27: =FBA海卡服务美西!F19 -> 18-22个自然日 | G27: *
A28: =B28&C28 -> GYR3皓快达-FBA海卡 | B28: GYR3 | C28: 皓快达-FBA海卡 | D28: =FBA海卡服务美西!D20 -> 7.7 | E28: =FBA海卡服务美西!E20 -> 7.7 | F28: =FBA海卡服务美西!F20 -> 18-22个自然日 | G28: *
... A37: =B37&C37 -> TCY1皓快达-FBA海卡 | B37: TCY1 | C37: 皓快达-FBA海卡 | D37: =FBA海卡服务美西!D29 -> 7.8 | E37: =FBA海卡服务美西!E29 -> 7.8 | F37: =FBA海卡服务美西!F29 -> 18-22个自然日 | G37: *
A38: =B38&C38 -> ONT8皓速达-FBA海卡 | B38: ONT8 | C38: 皓速达-FBA海卡 | D38: =FBA海卡服务美西!K9 -> 7.3 | E38: =FBA海卡服务美西!L9 -> 7.3 | F38: =FBA海卡服务美西!M9 -> 16-19个自然日 | G38: =FBA海卡服务美西!N9 -> 25个自然日
A39: =B39&C39 -> LGB8皓速达-FBA海卡 | B39: LGB8 | C39: 皓速达-FBA海卡 | D39: =FBA海卡服务美西!K10 -> 7.3 | E39: =FBA海卡服务美西!L10 -> 7.3 | F39: =FBA海卡服务美西!M10 -> 16-19个自然日 | G39: =FBA海卡服务美西!N10 -> 25个自然日
A40: =B40&C40 -> SBD1皓速达-FBA海卡 | B40: SBD1 | C40: 皓速达-FBA海卡 | D40: =FBA海卡服务美西!K11 -> 7.3 | E40: =FBA海卡服务美西!L11 -> 7.3 | F40: =FBA海卡服务美西!M11 -> 16-19个自然日 | G40: =FBA海卡服务美西!N11 -> 25个自然日
A41: =B41&C41 -> LAX9皓速达-FBA海卡 | B41: LAX9 | C41: 皓速达-FBA海卡 | D41: =FBA海卡服务美西!K12 -> 7.3 | E41: =FBA海卡服务美西!L12 -> 7.3 | F41: =FBA海卡服务美西!M12 -> 16-19个自然日 | G41: =FBA海卡服务美西!N12 -> 25个自然日
A42: =B42&C42 -> POC1皓速达-FBA海卡 | B42: POC1 | C42: 皓速达-FBA海卡 | D42: =FBA海卡服务美西!K13 -> 7.4 | E42: =FBA海卡服务美西!L13 -> 7.4 | F42: =FBA海卡服务美西!M13 -> 16-19个自然日 | G42: =FBA海卡服务美西!N13 -> 25个自然日
A43: =B43&C43 -> POC2皓速达-FBA海卡 | B43: POC2 | C43: 皓速达-FBA海卡 | D43: =FBA海卡服务美西!K14 -> 7.4 | E43: =FBA海卡服务美西!L14 -> 7.4 | F43: =FBA海卡服务美西!M14 -> 16-19个自然日 | G43: =FBA海卡服务美西!N14 -> 25个自然日
A44: =B44&C44 -> POC3皓速达-FBA海卡 | B44: POC3 | C44: 皓速达-FBA海卡 | D44: =FBA海卡服务美西!K15 -> 7.4 | E44: =FBA海卡服务美西!L15 -> 7.4 | F44: =FBA海卡服务美西!M15 -> 16-19个自然日 | G44: =FBA海卡服务美西!N15 -> 25个自然日
A45: =B45&C45 -> MCE1皓快达-FBA海卡 | B45: MCE1 | C45: 皓快达-FBA海卡 | D45: =FBA海卡服务美西!D30 -> 7.9 | E45: =FBA海卡服务美西!E30 -> 7.9 | F45: =FBA海卡服务美西!F30 -> 18-22个自然日 | G45: *
A46: =B46&C46 -> MCC1皓快达-FBA海卡 | B46: MCC1 | C46: 皓快达-FBA海卡 | D46: =FBA海卡服务美西!D31 -> 7.9 | E46: =FBA海卡服务美西!E31 -> 7.9 | F46: =FBA海卡服务美西!F31 -> 18-22个自然日 | G46: *
A47: =B47&C47 -> QXY8皓快达-FBA海卡 | B47: QXY8 | C47: 皓快达-FBA海卡 | D47: =FBA海卡服务美西!D32 -> 7.9 | E47: =FBA海卡服务美西!E32 -> 7.9 | F47: =FBA海卡服务美西!F32 -> 18-22个自然日 | G47: *
A48: =B48&C48 -> ABE8皓东达-FBA海卡 | B48: ABE8 | C48: 皓东达-FBA海卡 | D48: ='FBA海卡服务美东（纽约拆柜）'!D$29 -> 7.7 | E48: ='FBA海卡服务美东（纽约拆柜）'!E$29 -> 7.7 | F48: ='FBA海卡服务美东（纽约拆柜）'!H$29 -> 40-45个自然日 | G48: *
A49: =B49&C49 -> ACY2皓东达-FBA海卡 | B49: ACY2 | C49: 皓东达-FBA海卡 | D49: ='FBA海卡服务美东（纽约拆柜）'!D$29 -> 7.7 | E49: ='FBA海卡服务美东（纽约拆柜）'!E$29 -> 7.7 | F49: ='FBA海卡服务美东（纽约拆柜）'!H$29 -> 40-45个自然日 | G49: *
A50: =B50&C50 -> TEB6皓东达-FBA海卡 | B50: TEB6 | C50: 皓东达-FBA海卡 | D50: ='FBA海卡服务美东（纽约拆柜）'!D$29 -> 7.7 | E50: ='FBA海卡服务美东（纽约拆柜）'!E$29 -> 7.7 | F50: ='FBA海卡服务美东（纽约拆柜）'!H$29 -> 40-45个自然日 | G50: *
...

Sheet 偏远超偏远超级偏远邮编库 
A1: 代码 | B1: 邮编 | C1: 邮编 | D1: 地址类型1 | E1: 地址类型2 | F1: 仓库在不停新增，请以仓库对应的邮编搜索为准，此表仅为偏远超偏远超级偏远邮编库，不是代表除此以外都能承接 | Q1: 邮编
A2: US | B2: 01002 | C2: 1002 | D2: 偏远 | E2: US 48 Zip | F2: 不承接：P.O.BOX,阿拉斯加(AK),夏威夷(HI),波多黎各(PR),关岛,海岛，军方地址与967**,968**,995**,999**邮编 | Q2: 1002 | R2: 偏远
A3: US | B3: 01380 | C3: 1380 | D3: 偏远 | E3: US 48 Zip | Q3: 1007 | R3: 偏远
A4: US | B4: 01741 | C4: 1741 | D4: 偏远 | E4: US 48 Zip | Q4: 1010 | R4: 偏远
A5: US | B5: 02114 | C5: 2114 | D5: 偏远 | E5: US 48 Zip | Q5: 1029 | R5: 偏远
A6: US | B6: 02662 | C6: 2662 | D6: 偏远 | E6: US 48 Zip | Q6: 1032 | R6: 偏远
A7: US | B7: 01007 | C7: 1007 | D7: 偏远 | E7: US 48 Zip | Q7: 1033 | R7: 偏远
A8: US | B8: 01420 | C8: 1420 | D8: 偏远 | E8: US 48 Zip | Q8: 1036 | R8: 偏远
A9: US | B9: 01754 | C9: 1754 | D9: 偏远 | E9: US 48 Zip | Q9: 1038 | R9: 偏远
A10: US | B10: 02116 | C10: 2116 | D10: 偏远 | E10: US 48 Zip | Q10: 1039 | R10: 偏远
A11: US | B11: 02668 | C11: 2668 | D11: 偏远 | E11: US 48 Zip | Q11: 1056 | R11: 偏远
A12: US | B12: 01010 | C12: 1010 | D12: 偏远 | E12: US 48 Zip | Q12: 1057 | R12: 偏远
A13: US | B13: 01430 | C13: 1430 | D13: 偏远 | E13: US 48 Zip | Q13: 1069 | R13: 偏远
A14: US | B14: 01770 | C14: 1770 | D14: 偏远 | E14: US 48 Zip | Q14: 1073 | R14: 偏远
... A245: US | B245: 08533 | C245: 8533 | D245: 偏远 | E245: US 48 Zip | Q245: 3461 | R245: 偏远
A246: US | B246: 10001 | C246: 10001 | D246: 偏远 | E246: US 48 Zip | Q246: 3466 | R246: 偏远
A247: US | B247: 07717 | C247: 7717 | D247: 偏远 | E247: US 48 Zip | Q247: 3467 | R247: 偏远
A248: US | B248: 08014 | C248: 8014 | D248: 偏远 | E248: US 48 Zip | Q248: 3469 | R248: 偏远
A249: US | B249: 08241 | C249: 8241 | D249: 偏远 | E249: US 48 Zip | Q249: 3470 | R249: 偏远
A250: US | B250: 08535 | C250: 8535 | D250: 偏远 | E250: US 48 Zip | Q250: 3570 | R250: 偏远
A251: US | B251: 10002 | C251: 10002 | D251: 偏远 | E251: US 48 Zip | Q251: 3575 | R251: 偏远
A252: US | B252: 07719 | C252: 7719 | D252: 偏远 | E252: US 48 Zip | Q252: 3581 | R252: 偏远
A253: US | B253: 08015 | C253: 8015 | D253: 偏远 | E253: US 48 Zip | Q253: 3584 | R253: 偏远
A254: US | B254: 08242 | C254: 8242 | D254: 偏远 | E254: US 48 Zip | Q254: 3585 | R254: 偏远
A255: US | B255: 08551 | C255: 8551 | D255: 偏远 | E255: US 48 Zip | Q255: 3589 | R255: 偏远
A256: US | B256: 10003 | C256: 10003 | D256: 偏远 | E256: US 48 Zip | Q256: 3598 | R256: 偏远
A257: US | B257: 07720 | C257: 7720 | D257: 偏远 | E257: US 48 Zip | Q257: 3604 | R257: 偏远
A258: US | B258: 08022 | C258: 8022 | D258: 偏远 | E258: US 48 Zip | Q258: 3608 | R258: 偏远
A259: US | B259: 08243 | C259: 8243 | D259: 偏远 | E259: US 48 Zip | Q259: 3741 | R259: 偏远
A260: US | B260: 08553 | C260: 8553 | D260: 偏远 | E260: US 48 Zip | Q260: 3743 | R260: 偏远
A261: US | B261: 10004 | C261: 10004 | D261: 偏远 | E261: US 48 Zip | Q261: 3748 | R261: 偏远
A262: US | B262: 07722 | C262: 7722 | D262: 偏远 | E262: US 48 Zip | Q262: 3753 | R262: 偏远
A263: US | B263: 08025 | C263: 8025 | D263: 偏远 | E263: US 48 Zip | Q263: 3754 | R263: 偏远
A264: US | B264: 08245 | C264: 8245 | D264: 偏远 | E264: US 48 Zip | Q264: 3769 | R264: 偏远
A265: US | B265: 08554 | C265: 8554 | D265: 偏远 | E265: US 48 Zip | Q265: 3770 | R265: 偏远
A266: US | B266: 10005 | C266: 10005 | D266: 偏远 | E266: US 48 Zip | Q266: 3771 | R266: 偏远
A267: US | B267: 07727 | C267: 7727 | D267: 偏远 | E267: US 48 Zip | Q267: 3773 | R267: 偏远
A268: US | B268: 08037 | C268: 8037 | D268: 偏远 | E268: US 48 Zip | Q268: 3774 | R268: 偏远
A269: US | B269: 08247 | C269: 8247 | D269: 偏远 | E269: US 48 Zip | Q269: 3785 | R269: 偏远
A270: US | B270: 08555 | C270: 8555 | D270: 偏远 | E270: US 48 Zip | Q270: 3811 | R270: 偏远
...

Sheet UPS偏远表
A1: 代码 | B1: 邮编 | C1: 邮编 | D1: 地址类型 | F1: 1、此表仅做参考，具体以账单下来为准
A2: US | B2: 1002 | C2: 1002 | D2: 偏远 | F2: 2、P.O.BOX地址，阿拉斯加(AK)，夏威夷(HI)，波多黎各(PR)，关岛，海岛，军方地址与967**，968**，995**，999**邮编 不接！
A3: US | B3: 1007 | C3: 1007 | D3: 偏远
A4: US | B4: 1010 | C4: 1010 | D4: 偏远
A5: US | B5: 1029 | C5: 1029 | D5: 偏远
A6: US | B6: 1032 | C6: 1032 | D6: 偏远
A7: US | B7: 1033 | C7: 1033 | D7: 偏远
A8: US | B8: 1036 | C8: 1036 | D8: 偏远
A9: US | B9: 1038 | C9: 1038 | D9: 偏远
A10: US | B10: 1039 | C10: 1039 | D10: 偏远
A11: US | B11: 1056 | C11: 1056 | D11: 偏远
A12: US | B12: 1057 | C12: 1057 | D12: 偏远
A13: US | B13: 1069 | C13: 1069 | D13: 偏远
A14: US | B14: 1073 | C14: 1073 | D14: 偏远
... A7544: US | B7544: 70774 | C7544: 70774 | D7544: 偏远
B7545: 78653 | C7545: 78653 | D7545: 偏远
A7546: US | B7546: 78654 | C7546: 78654 | D7546: 偏远
A7547: US | B7547: 78669 | C7547: 78669 | D7547: 偏远
A7548: US | B7548: 78673 | C7548: 78673 | D7548: 偏远
A7549: US | B7549: 78674 | C7549: 78674 | D7549: 偏远
A7550: US | B7550: 78676 | C7550: 78676 | D7550: 偏远
A7551: US | B7551: 78737 | C7551: 78737 | D7551: 偏远
A7552: US | B7552: 78766 | C7552: 78766 | D7552: 偏远
A7553: US | B7553: 78801 | C7553: 78801 | D7553: 偏远
A7554: US | B7554: 78802 | C7554: 78802 | D7554: 偏远
A7555: US | B7555: 78834 | C7555: 78834 | D7555: 偏远
A7556: US | B7556: 78840 | C7556: 78840 | D7556: 偏远
A7557: US | B7557: 78853 | C7557: 78853 | D7557: 偏远
... A21940: US | B21940: 98619 | C21940: 98619 | D21940: 超偏远
B21941: 98851 | C21941: 98851 | D21941: 超偏远
A21942: US | B21942: 99107 | C21942: 99107 | D21942: 超偏远
A21943: US | B21943: 99330 | C21943: 99330 | D21943: 超偏远
A21944: US | B21944: 98295 | C21944: 98295 | D21944: 超偏远
A21945: US | B21945: 98554 | C21945: 98554 | D21945: 超偏远
A21946: US | B21946: 98620 | C21946: 98620 | D21946: 超偏远
A21947: US | B21947: 98852 | C21947: 98852 | D21947: 超偏远
A21948: US | B21948: 99109 | C21948: 99109 | D21948: 超偏远
A21949: US | B21949: 99332 | C21949: 99332 | D21949: 超偏远
A21950: US | B21950: 98304 | C21950: 98304 | D21950: 超偏远
A21951: US | B21951: 98555 | C21951: 98555 | D21951: 超偏远
...
