Workbook

Sheet 目录
B2: 美 琦 国 际 货 运 代 理（深圳）有 限 公 司 地址：深圳市龙岗区坂田街道坂雪岗大道4088号奥博中心6楼A609-611
B4: 目的地 | C4: 目的港 | D4: 类型 | E4: 渠道名称 | F4: 渠道价格 | G4: 渠道特点分析 | H4: 优势目标区域 | I4: 渠道变动（2026/06/30生效）
D5: 货真价实 Match系列 | E5: Match12-卡派（CLX、MAX-GES服务) | F5: 查看报价 | G5: CLX、MAX-GES服务，时效达标率99%，12天提柜，超15自然日即赔 | H5: 4-9邮编 | I5: 上调0.1/KG或15/CBM
E6: Match15(ZIM带车架、EXX统配） | F6: 查看报价 | G6: EXX+ZIM带车架统配，平均15天签收 | H6: 4-9邮编 | I6: 上调0.5/KG或75/CBM
E7: Match20(长荣定提、合德快提统配） | F7: 查看报价 | G7: 精选快船中的王牌 平均20天签收 | H7: 4-9邮编 | I7: 上调0.8/KG或120/CBM
D8: OA系列 | E8: OA-直送专线（纯正OA） | F8: 查看报价 | G8: 优选COSCO OOCL EMC 最佳船期，永不截单 | H8: 4-9邮编 | I8: 上调0.8/KG或120/CBM
E9: OA-拆送专线（纯正OA） | F9: 查看报价 | G9: 盐田最快的船期，时效王者，稳定时效 | H9: 4-9邮编 | I9: 上调0.8/KG或120/CBM
E10: OA-奥克兰（纯正OA） | F10: 查看报价 | G10: 奥克兰最稳定的海外仓服务 94 95邮编海外仓王牌 | H10: 93-95邮编 | I10: 上调0.8/KG或120/CBM
D11: 海派专线 | E11: 海派渠道 | F11: 查看报价 | G11: 汇总各渠道海派价格 | H11: 0-9邮编 | I11: 对应渠道调整
D12: 海外仓暂存 | E12: 暂存渠道 | F12: 查看报价 | G12: 美西海外仓中转特价 | H12: 0-9邮编 | I12: 上调0.8/KG或120/CBM
C13: 洛杉矶 | D13: 专线渠道 | E13: MT-专线-美西 | F13: 查看报价 | G13: 超实惠，稳定时效 | H13: 9邮编 | I13: 上调0.8/KG或120/CBM
C14: 纽约 | D14: 专线渠道 | E14: MT-专线-纽约 | F14: 查看报价 | G14: 超实惠，稳定时效 | H14: 0-1邮编 | I14: 上调0.8/KG或120/CBM
C15: 萨凡纳 | D15: 专线渠道 | E15: MT-专线-萨凡纳 | F15: 查看报价 | G15: 超实惠，稳定时效 | H15: 3邮编 | I15: 上调0.8/KG或120/CBM
C16: 洛杉矶 | D16: 美东秒送 | E16: 美森美东秒送 | F16: 查看报价 | G16: 美森GES服务，17天到港，21天签收 | H16: 0-3邮编 | I16: 上调0.1/KG或15/CBM
C17: 纽约 | D17: 美东直航 | E17: 美东普快专线 | F17: 查看报价 | G17: 普船到纽约 经济保证 普船价格 | H17: 0-4邮编 | I17: 上调0.8/KG或120/CBM
D18: 美东极速 | E18: 美东极速快车 | F18: 查看报价 | G18: ZIM带车架海铁联运+末端高级卡车 美东26天 | H18: 0-4邮编 | I18: 上调2.3/KG或345/CBM
C19: 芝加哥 | D19: 芝加哥快线 | E19: 芝加哥海铁快车 | F19: 查看报价 | G19: COSCO稳速达，海铁快运到芝加哥 海铁快车 性价比高 时效赔付 | H19: 4-6邮编 | I19: 上调0.6/KG或90/CBM
D20: 芝加哥海铁专线 | E20: 芝加哥海铁联运 | F20: 查看报价 | G20: 芝加哥海铁联运 | H20: 4-6邮编 | I20: 上调0.8/KG或120/CBM
C21: 休斯敦 | D21: 休斯敦专线 | E21: 休斯敦专线 | F21: 查看报价 | G21: 休斯敦直航 质价比高 | H21: 7邮编 | I21: 上调0.8/KG或120/CBM
C22: 萨瓦纳 | D22: 美东南直航 | E22: 萨瓦纳专线 | F22: 查看报价 | G22: 美东南18仓普船价格性价比高 | H22: 28-3邮编 | I22: 上调0.8/KG或120/CBM
B23: 加拿大 | C23: 洛杉矶 | D23: 美转加 | E23: 美转加 | F23: 查看报价 | G23: 北美自由贸易区 时效稳定 急货首选 恢复时效赔付 | H23: 多伦多 卡尔加里 | I23: 不变
C24: 加拿大 | D24: 加拿大直航 | E24: 加拿大直航 | F24: 查看报价 | G24: 加拿大特惠 市场最低价 | H24: 多伦多 卡尔加里 | I24: 上调0.8/KG或120/CBM
B25: 墨西哥 | C25: 洛杉矶 | D25: 美转墨 | E25: 美 墨 快 线 | F25: 查看报价 | G25: 到仓时效稳定 备货有保证 30天左右稳定到仓时间(开船后） | H25: 墨西哥城 | I25: 不变
C26: 墨西哥城 | D26: 墨西哥直航 | E26: 墨西哥直航 | F26: 查看报价 | G26: 清关稳定 查验率不足1.5% | H26: 墨西哥城 | I26: /
B27: 美 琦 国 际 -- 北 美 第 一 站！
B28: 每周船期表 | E28: 美国发货须知 | G28: 合作流程 | I28: 亚马逊仓库地址
B29: 业务联系方式：易强 18320819718 微信同号
B30: 客服联系方式：黄彩琼 18025857142 微信同号
B31: 财务联系方式：汤红旗 13670010730
B32: 东莞1号仓库地址：广东省东莞市东莞市清溪镇银湖工业区科技路70号，导航：科技路70号美琦国际 联系人 陈希平 180 0288 5680
B33: 东莞2号仓库地址：广东省东莞市清溪镇九乡村大为路1号 联系人 邱先生 18318726670
B34: 中山仓库地址：广东省中山市大涌镇青岗村涌横路 35号一楼 电话：杨18928119960
B35: 义乌仓库地址：浙江省金华市金东区菜鸟网络浙江金义2-1期园区地面停车场 13栋1号2号3号4号货台收货 郑先生：195 3765 8019（周一至周日10：00-22:00）
B36: 广州仓库地址：广东省广州市白云区人和镇黄榜岭西二路46号2号仓(收货时间上午10:00-晚上10：00) 联系人：聂显俊13265457191 14737372131
B37: 汕头中转点：澄海区秀水路厂房第一层誉航达仓库 联系人：王：13414061251 胡：13923475593
B38: 厦门仓库地址：厦门市同安区集祥路66-4（2号仓西边） 美琦国际 18179585143 聂 （周一至周日10：00-22:00）
B39: 青岛仓库地址:青岛市城阳区天河路88号普洛斯空港东物流园B3库南区4-5号门 邱先生151 8054 3540
B40: 苏州仓地址：江苏省苏州市姑苏区金筑街588号，传化公路港，金义康物流（8:00-10:30）。叶经理，18862342877

Sheet 快捷查价
B2: 美 琦 国 际 货 运 代 理（深圳）有 限 公 司 地址：深圳市龙岗区坂田街道坂雪岗大道4088号奥博中心6楼A609-611
G4: 快捷查价
G5: 国内站点 | H5: 目的仓 | I5: 清关方式
G6: 深圳/中山/广州/汕头/厦门 | H6: SCK8 | I6: 含税
B7: 区域 | C7: 目的港 | D7: 线路类型 | E7: 渠道名称 | F7: 预配船司 | G7: 单价（KG/CBM） | H7: 截收货时间 | I7: ETD | J7: ETA | K7: 航期 | L7: 提柜时效 | M7: 备注
E8: Match12-卡派（CLX、MAX-GES服务) | F8: MATSON | G8: =IFERROR(_xlfn.IFS(AND(G6="深圳/中山/广州/汕头/厦门",I6="含税"),VLOOKUP("*"&TRIM(SUBSTITUTE(H6,",","|"))&"*",'Match系列 '!C7:I24,2,0),AND(G6="深圳/中山/广州/汕头/厦门",I6="不含税"),VLOOKUP("*"&TRIM(SUBSTITUTE(H6,",","|"))&"*",'Match系列 '!C7:I24,3,0),AND(G6="义乌/苏州",I6="含税"),VLOOKUP("*"&TRIM(SUBSTITUTE(H6,",","|"))&"*",'Match系列 '!C7:I24,4,0),AND(G6="义乌/苏州",I6="不含税"),VLOOKUP("*"&TRIM(SUBSTITUTE(H6,",","|"))&"*",'Match系列 '!C7:I24,5,0),AND(G6="汕头/厦门",I6="含税"),VLOOKUP("*"&TRIM(SUBSTITUTE(H6,",","|"))&"*",'Match系列 '!C7:I24,2,0),AND(G6="汕头/厦门",I6="不含税"),VLOOKUP("*"&TRIM(SUBSTITUTE(H6,",","|"))&"*",'Match系列 '!C7:I24,3,0),AND(G6="青岛",I6="含税"),VLOOKUP("*"&TRIM(SUBSTITUTE(H6,",","|"))&"*",'Match系列 '!C7:I24,6,0),AND(G6="青岛",I6="不含税"),VLOOKUP("*"&TRIM(SUBSTITUTE(H6,",","|"))&"*",'Match系列 '!C7:I24,7,0)),"-") -> 11.8 | H8: =VLOOKUP(E8,[1]Sheet1!$A:$I,4,0) -> 7月2日 22:00 | I8: =VLOOKUP(E8,[1]Sheet1!$A:$I,5,0) -> 46209 | J8: =VLOOKUP(E8,[1]Sheet1!$A:$I,6,0) -> 46222 | K8: =VLOOKUP(E8,[1]Sheet1!$A:$J,7,0) -> 13 | L8: =VLOOKUP(E8,[1]Sheet1!$A:$J,8,0) -> 46223 | M8: =IFERROR(_xlfn.IFS(AND(G6="深圳/中山/广州/汕头/厦门",I6="含税"),VLOOKUP("*"&TRIM(SUBSTITUTE(H6,",","|"))&"*",'[2]Match系列 '!C7:R27,8,0),AND(G6="深圳/中山/广州/汕头/厦门",I6="不含税"),VLOOKUP("*"&TRIM(SUBSTITUTE(H6,",","|"))&"*",'[2]Match系列 '!C7:R27,8,0),AND(G6="义乌/苏州",I6="含税"),VLOOKUP("*"&TRIM(SUBSTITUTE(H6,",","|"))&"*",'[2]Match系列 '!C7:R27,8,0),AND(G6="义乌/苏州",I6="不含税"),VLOOKUP("*"&TRIM(SUBSTITUTE(H6,",","|"))&"*",'[2]Match系列 '!C7:R27,8,0),AND(G6="青岛",I6="含税"),VLOOKUP("*"&TRIM(SUBSTITUTE(H6,",","|"))&"*",'[2]Match系列 '!C7:R27,8,0),AND(G6="青岛",I6="不含税"),VLOOKUP("*"&TRIM(SUBSTITUTE(H6,",","|"))&"*",'[2]Match系列 '!C7:R27,8,0)),"-") -> 15-17
E9: Match15(ZIM带车架、EXX统配） | F9: 以星 EXX | G9: =IFERROR(_xlfn.IFS(AND(G6="深圳/中山/广州/汕头/厦门",I6="含税"),VLOOKUP("*"&TRIM(SUBSTITUTE(H6,",","|"))&"*",'Match系列 '!C7:Z24,10,0),AND(G6="深圳/中山/广州/汕头/厦门",I6="不含税"),VLOOKUP("*"&TRIM(SUBSTITUTE(H6,",","|"))&"*",'Match系列 '!C7:Z24,11,0),AND(G6="义乌/苏州",I6="含税"),VLOOKUP("*"&TRIM(SUBSTITUTE(H6,",","|"))&"*",'Match系列 '!C7:Z24,12,0),AND(G6="义乌/苏州",I6="不含税"),VLOOKUP("*"&TRIM(SUBSTITUTE(H6,",","|"))&"*",'Match系列 '!C7:Z24,13,0),AND(G6="汕头/厦门",I6="含税"),VLOOKUP("*"&TRIM(SUBSTITUTE(H6,",","|"))&"*",'Match系列 '!C31:Q53,2,0),AND(G6="汕头/厦门",I6="不含税"),VLOOKUP("*"&TRIM(SUBSTITUTE(H6,",","|"))&"*",'Match系列 '!C31:Q53,3,0),AND(G6="青岛",I6="含税"),VLOOKUP("*"&TRIM(SUBSTITUTE(H6,",","|"))&"*",'Match系列 '!C7:Z24,14,0),AND(G6="青岛",I6="不含税"),VLOOKUP("*"&TRIM(SUBSTITUTE(H6,",","|"))&"*",'Match系列 '!C7:Z24,15,0)),"-") -> 9.7 | H9: =VLOOKUP(E9,[1]Sheet1!$A:$I,4,0) -> 7月4日 18:00 | I9: =VLOOKUP(E9,[1]Sheet1!$A:$I,5,0) -> 46212 | J9: =VLOOKUP(E9,[1]Sheet1!$A:$I,6,0) -> 46223 | K9: =VLOOKUP(E9,[1]Sheet1!$A:$J,7,0) -> 11 | L9: =VLOOKUP(E9,[1]Sheet1!$A:$J,8,0) -> 46224 | M9: =IFERROR(_xlfn.IFS(AND(G6="深圳/中山/广州/汕头/厦门",I6="含税"),VLOOKUP("*"&TRIM(SUBSTITUTE(H6,",","|"))&"*",'[2]Match系列 '!C7:R27,16,0),AND(G6="深圳/中山/广州/汕头/厦门",I6="不含税"),VLOOKUP("*"&TRIM(SUBSTITUTE(H6,",","|"))&"*",'[2]Match系列 '!C7:R27,16,0),AND(G6="义乌/苏州",I6="含税"),VLOOKUP("*"&TRIM(SUBSTITUTE(H6,",","|"))&"*",'[2]Match系列 '!C7:R27,16,0),AND(G6="义乌/苏州",I6="不含税"),VLOOKUP("*"&TRIM(SUBSTITUTE(H6,",","|"))&"*",'[2]Match系列 '!C7:R27,16,0),AND(G6="青岛",I6="含税"),VLOOKUP("*"&TRIM(SUBSTITUTE(H6,",","|"))&"*",'[2]Match系列 '!C7:R27,16,0),AND(G6="青岛",I6="不含税"),VLOOKUP("*"&TRIM(SUBSTITUTE(H6,",","|"))&"*",'[2]Match系列 '!C7:R27,16,0)),"-") -> 17-19
E10: Match20(长荣定提、合德快提统配） | F10: EMC 合德 | G10: =IFERROR(_xlfn.IFS(AND(G6="深圳/中山/广州/汕头/厦门",I6="含税"),VLOOKUP("*"&TRIM(SUBSTITUTE(H6,",","|"))&"*",'Match系列 '!C7:Z24,18,0),AND(G6="深圳/中山/广州/汕头/厦门",I6="不含税"),VLOOKUP("*"&TRIM(SUBSTITUTE(H6,",","|"))&"*",'Match系列 '!C7:Z24,19,0),AND(G6="义乌/苏州",I6="含税"),VLOOKUP("*"&TRIM(SUBSTITUTE(H6,",","|"))&"*",'Match系列 '!C7:Z24,20,0),AND(G6="义乌/苏州",I6="不含税"),VLOOKUP("*"&TRIM(SUBSTITUTE(H6,",","|"))&"*",'Match系列 '!C7:Z24,21,0),AND(G6="汕头/厦门",I6="含税"),VLOOKUP("*"&TRIM(SUBSTITUTE(H6,",","|"))&"*",'Match系列 '!C31:Q53,10,0),AND(G6="汕头/厦门",I6="不含税"),VLOOKUP("*"&TRIM(SUBSTITUTE(H6,",","|"))&"*",'Match系列 '!C31:Q53,11,0),AND(G6="青岛",I6="含税"),VLOOKUP("*"&TRIM(SUBSTITUTE(H6,",","|"))&"*",'Match系列 '!C7:Z24,22,0),AND(G6="青岛",I6="不含税"),VLOOKUP("*"&TRIM(SUBSTITUTE(H6,",","|"))&"*",'Match系列 '!C7:Z24,23,0)),"-") -> 8.4 | H10: =VLOOKUP(E10,[1]Sheet1!$A:$I,4,0) -> 7月4日 18:00 | I10: =VLOOKUP(E10,[1]Sheet1!$A:$I,5,0) -> 46209 | J10: =VLOOKUP(E10,[1]Sheet1!$A:$I,6,0) -> 46224 | K10: =VLOOKUP(E10,[1]Sheet1!$A:$J,7,0) -> 15 | L10: =VLOOKUP(E10,[1]Sheet1!$A:$J,8,0) -> 46226 | M10: =IFERROR(_xlfn.IFS(AND(G6="深圳/中山/广州/汕头/厦门",I6="含税"),VLOOKUP("*"&TRIM(SUBSTITUTE(H6,",","|"))&"*",'[2]Match系列 '!C7:AA27,24,0),AND(G6="深圳/中山/广州/汕头/厦门",#REF!="不含税"),VLOOKUP("*"&TRIM(SUBSTITUTE(H6,",","|"))&"*",'[2]Match系列 '!C7:AA27,24,0),AND(G6="义乌/苏州",I6="含税"),VLOOKUP("*"&TRIM(SUBSTITUTE(H6,",","|"))&"*",'[2]Match系列 '!C7:AA27,24,0),AND(G6="义乌/苏州",#REF!="不含税"),VLOOKUP("*"&TRIM(SUBSTITUTE(H6,",","|"))&"*",'[2]Match系列 '!C7:AA27,24,0),AND(G6="青岛",I6="含税"),VLOOKUP("*"&TRIM(SUBSTITUTE(H6,",","|"))&"*",'[2]Match系列 '!C7:AA27,24,0),AND(G6="青岛",I6="不含税"),VLOOKUP("*"&TRIM(SUBSTITUTE(H6,",","|"))&"*",'[2]Match系列 '!C7:AA27,24,0)),"-") -> 20-22
D11: 美东秒送 | E11: 美森美东秒送 | F11: MATSON | G11: =IFERROR(_xlfn.IFS(AND(G6="深圳/中山/广州/汕头/厦门",I6="含税"),VLOOKUP("*"&TRIM(SUBSTITUTE(H6,",","|"))&"*",美森美东秒送!C:G,2,0),AND(G6="深圳/中山/广州/汕头/厦门",I6="不含税"),VLOOKUP("*"&TRIM(SUBSTITUTE(H6,",","|"))&"*",美森美东秒送!C:G,3,0),AND(G6="青岛",I6="含税"),VLOOKUP("*"&TRIM(SUBSTITUTE(H6,",","|"))&"*",美森美东秒送!C:G,4,0),AND(G6="青岛",I6="不含税"),VLOOKUP("*"&TRIM(SUBSTITUTE(H6,",","|"))&"*",美森美东秒送!C:G,5,0)),"-") -> - | H11: =VLOOKUP(E11,[1]Sheet1!$A:$I,4,0) -> 7月3日 22:00 | I11: =VLOOKUP(E11,[1]Sheet1!$A:$I,5,0) -> 46212 | J11: =VLOOKUP(E11,[1]Sheet1!$A:$I,6,0) -> 46237 | K11: =VLOOKUP(E11,[1]Sheet1!$A:$J,7,0) -> 25 | L11: =VLOOKUP(E11,[1]Sheet1!$A:$J,8,0) -> 46239 | M11: =IFERROR(_xlfn.IFS(AND(G6="深圳/中山/广州/汕头/厦门",I6="含税"),VLOOKUP("*"&TRIM(SUBSTITUTE(H6,",","|"))&"*",[2]美森美东秒送!C:I,7,0),AND(G6="深圳/中山/广州/汕头/厦门",I6="不含税"),VLOOKUP("*"&TRIM(SUBSTITUTE(H6,",","|"))&"*",[2]美森美东秒送!C:I,7,0),AND(G6="义乌/苏州",I6="含税"),VLOOKUP("*"&TRIM(SUBSTITUTE(H6,",","|"))&"*",[2]美森美东秒送!C:I,7,0),AND(G6="义乌/苏州",I6="不含税"),VLOOKUP("*"&TRIM(SUBSTITUTE(H6,",","|"))&"*",[2]美森美东秒送!C:I,7,0),AND(G6="青岛",I6="含税"),VLOOKUP("*"&TRIM(SUBSTITUTE(H6,",","|"))&"*",[2]美森美东秒送!C:I,7,0),AND(G6="青岛",I6="不含税"),VLOOKUP("*"&TRIM(SUBSTITUTE(H6,",","|"))&"*",[2]美森美东秒送!C:I,7,0)),"-") -> -
D12: OA系列 | E12: OA-拆送专线 | F12: OA | G12: =IFERROR(_xlfn.IFS(AND(G6="深圳/中山/广州/汕头/厦门",I6="含税"),VLOOKUP("*"&TRIM(SUBSTITUTE(H6,",","|"))&"*",'OA-拆送 '!C7:G29,2,0),AND(G6="深圳/中山/广州/汕头/厦门",I6="不含税"),VLOOKUP("*"&TRIM(SUBSTITUTE(H6,",","|"))&"*",'OA-拆送 '!C7:G29,3,0),AND(G6="义乌/苏州",I6="含税"),VLOOKUP("*"&TRIM(SUBSTITUTE(H6,",","|"))&"*",'OA-拆送 '!C7:G29,2,0),AND(G6="义乌/苏州",I6="不含税"),VLOOKUP("*"&TRIM(SUBSTITUTE(H6,",","|"))&"*",'OA-拆送 '!C7:G29,3,0),AND(G6="汕头/厦门",I6="含税"),VLOOKUP("*"&TRIM(SUBSTITUTE(H6,",","|"))&"*",'OA-拆送 '!C7:G29,2,0),AND(G6="汕头/厦门",I6="不含税"),VLOOKUP("*"&TRIM(SUBSTITUTE(H6,",","|"))&"*",'OA-拆送 '!C7:G29,3,0),AND(G6="青岛",I6="含税"),VLOOKUP("*"&TRIM(SUBSTITUTE(H6,",","|"))&"*",'OA-拆送 '!C7:G29,4,0),AND(G6="青岛",I6="不含税"),VLOOKUP("*"&TRIM(SUBSTITUTE(H6,",","|"))&"*",'OA-拆送 '!C7:G29,5,0)),"-") -> 8.1 | H12: =VLOOKUP(E12,[1]Sheet1!$A:$I,4,0) -> 7月4日 18:00 | I12: =VLOOKUP(E12,[1]Sheet1!$A:$I,5,0) -> 46212 | J12: =VLOOKUP(E12,[1]Sheet1!$A:$I,6,0) -> 46228 | K12: =VLOOKUP(E12,[1]Sheet1!$A:$J,7,0) -> 16 | L12: =VLOOKUP(E12,[1]Sheet1!$A:$J,8,0) -> 46232 | M12: =IFERROR(_xlfn.IFS(AND(G6="深圳/中山/广州/汕头/厦门",I6="含税"),VLOOKUP("*"&TRIM(SUBSTITUTE(H6,",","|"))&"*",'[2]OA-拆送 '!C7:I26,7,0),AND(G6="深圳/中山/广州/汕头/厦门",I6="不含税"),VLOOKUP("*"&TRIM(SUBSTITUTE(H6,",","|"))&"*",'[2]OA-拆送 '!C7:I26,7,0),AND(G6="义乌/苏州",I6="含税"),VLOOKUP("*"&TRIM(SUBSTITUTE(H6,",","|"))&"*",'[2]OA-拆送 '!C7:I26,7,0),AND(G6="义乌/苏州",I6="不含税"),VLOOKUP("*"&TRIM(SUBSTITUTE(H6,",","|"))&"*",'[2]OA-拆送 '!C7:I26,7,0),AND(G6="青岛",I6="含税"),VLOOKUP("*"&TRIM(SUBSTITUTE(H6,",","|"))&"*",'[2]OA-拆送 '!C7:I26,7,0),AND(G6="青岛",I6="不含税"),VLOOKUP("*"&TRIM(SUBSTITUTE(H6,",","|"))&"*",'[2]OA-拆送 '!C7:I26,7,0)),"-") -> 26-32
E13: OA-直送专线 | F13: OA | G13: =IFERROR(_xlfn.IFS(AND(G6="深圳/中山/广州/汕头/厦门",I6="含税"),VLOOKUP("*"&TRIM(SUBSTITUTE(H6,",","|"))&"*",'OA-直送'!C7:G16,2,0),AND(G6="深圳/中山/广州/汕头/厦门",I6="不含税"),VLOOKUP("*"&TRIM(SUBSTITUTE(H6,",","|"))&"*",'OA-直送'!C7:G16,3,0),AND(G6="义乌/苏州",I6="含税"),VLOOKUP("*"&TRIM(SUBSTITUTE(H6,",","|"))&"*",'OA-直送'!C7:G16,2,0),AND(G6="义乌/苏州",I6="不含税"),VLOOKUP("*"&TRIM(SUBSTITUTE(H6,",","|"))&"*",'OA-直送'!C7:G16,3,0),AND(G6="汕头/厦门",I6="含税"),VLOOKUP("*"&TRIM(SUBSTITUTE(H6,",","|"))&"*",'OA-直送'!C7:G16,2,0),AND(G6="汕头/厦门",I6="不含税"),VLOOKUP("*"&TRIM(SUBSTITUTE(H6,",","|"))&"*",'OA-直送'!C7:G16,3,0),AND(G6="青岛",I6="含税"),VLOOKUP("*"&TRIM(SUBSTITUTE(H6,",","|"))&"*",'OA-直送'!C7:G16,4,0),AND(G6="青岛",I6="不含税"),VLOOKUP("*"&TRIM(SUBSTITUTE(H6,",","|"))&"*",'OA-直送'!C7:G16,5,0)),"-") -> 7.6 | H13: =VLOOKUP(E13,[1]Sheet1!$A:$I,4,0) -> 7月4日 18:00 | I13: =VLOOKUP(E13,[1]Sheet1!$A:$I,5,0) -> 46209 | J13: =VLOOKUP(E13,[1]Sheet1!$A:$I,6,0) -> 46224 | K13: =VLOOKUP(E13,[1]Sheet1!$A:$J,7,0) -> 15 | L13: =VLOOKUP(E13,[1]Sheet1!$A:$J,8,0) -> 46228 | M13: =IFERROR(_xlfn.IFS(AND(G6="深圳/中山/广州/汕头/厦门",I6="含税"),VLOOKUP("*"&TRIM(SUBSTITUTE(H6,",","|"))&"*",'[2]OA-直送'!C7:I16,7,0),AND(G6="深圳/中山/广州/汕头/厦门",I6="不含税"),VLOOKUP("*"&TRIM(SUBSTITUTE(H6,",","|"))&"*",'[2]OA-直送'!C7:I16,7,0),AND(G6="义乌/苏州",I6="含税"),VLOOKUP("*"&TRIM(SUBSTITUTE(H6,",","|"))&"*",'[2]OA-直送'!C7:I16,7,0),AND(G6="义乌/苏州",I6="不含税"),VLOOKUP("*"&TRIM(SUBSTITUTE(H6,",","|"))&"*",'[2]OA-直送'!C7:I16,7,0),AND(G6="青岛",I6="含税"),VLOOKUP("*"&TRIM(SUBSTITUTE(H6,",","|"))&"*",'[2]OA-直送'!C7:I16,7,0),AND(G6="青岛",I6="不含税"),VLOOKUP("*"&TRIM(SUBSTITUTE(H6,",","|"))&"*",'[2]OA-直送'!C7:I16,7,0)),"-") -> 28-30
E14: OA-美东直送 | F14: OA | G14: =IFERROR(_xlfn.IFS(AND(G6="深圳/中山/广州/汕头/厦门",I6="含税"),VLOOKUP("*"&TRIM(SUBSTITUTE(H6,",","|"))&"*",'OA-直送'!C19:G20,2,0),AND(G6="深圳/中山/广州/汕头/厦门",I6="不含税"),VLOOKUP("*"&TRIM(SUBSTITUTE(H6,",","|"))&"*",'OA-直送'!C19:G20,3,0),AND(G6="义乌/苏州",I6="含税"),VLOOKUP("*"&TRIM(SUBSTITUTE(H6,",","|"))&"*",'OA-直送'!C19:G20,2,0),AND(G6="义乌/苏州",I6="不含税"),VLOOKUP("*"&TRIM(SUBSTITUTE(H6,",","|"))&"*",'OA-直送'!C19:G20,3,0),AND(G6="汕头/厦门",I6="含税"),VLOOKUP("*"&TRIM(SUBSTITUTE(H6,",","|"))&"*",'OA-直送'!C19:G20,2,0),AND(G6="汕头/厦门",I6="不含税"),VLOOKUP("*"&TRIM(SUBSTITUTE(H6,",","|"))&"*",'OA-直送'!C19:G20,3,0),AND(G6="青岛",I6="含税"),VLOOKUP("*"&TRIM(SUBSTITUTE(H6,",","|"))&"*",'OA-直送'!C19:G20,4,0),AND(G6="青岛",I6="不含税"),VLOOKUP("*"&TRIM(SUBSTITUTE(H6,",","|"))&"*",'OA-直送'!C19:G20,5,0)),"-") -> - | H14: =VLOOKUP(E14,[1]Sheet1!$A:$I,4,0) -> 7月4日 18:00 | I14: =VLOOKUP(E14,[1]Sheet1!$A:$I,5,0) -> 46213 | J14: =VLOOKUP(E14,[1]Sheet1!$A:$I,6,0) -> 46250 | K14: =VLOOKUP(E14,[1]Sheet1!$A:$J,7,0) -> 37 | L14: =VLOOKUP(E14,[1]Sheet1!$A:$J,8,0) -> 46254 | M14: =IFERROR(_xlfn.IFS(AND(G6="深圳/中山/广州/汕头/厦门",I6="含税"),VLOOKUP("*"&TRIM(SUBSTITUTE(H6,",","|"))&"*",'[2]OA-直送'!C19:I20,7,0),AND(G6="深圳/中山/广州/汕头/厦门",I6="不含税"),VLOOKUP("*"&TRIM(SUBSTITUTE(H6,",","|"))&"*",'[2]OA-直送'!C19:I20,7,0),AND(G6="义乌/苏州",I6="含税"),VLOOKUP("*"&TRIM(SUBSTITUTE(H6,",","|"))&"*",'[2]OA-直送'!C19:I20,7,0),AND(G6="义乌/苏州",I6="不含税"),VLOOKUP("*"&TRIM(SUBSTITUTE(H6,",","|"))&"*",'[2]OA-直送'!C19:I20,7,0),AND(G6="青岛",I6="含税"),VLOOKUP("*"&TRIM(SUBSTITUTE(H6,",","|"))&"*",'[2]OA-直送'!C19:I20,7,0),AND(G6="青岛",I6="不含税"),VLOOKUP("*"&TRIM(SUBSTITUTE(H6,",","|"))&"*",'[2]OA-直送'!C19:I20,7,0)),"-") -> -
C15: 洛杉矶 | D15: 专线渠道 | E15: MT-专线-美西 | F15: 2M、THE | G15: =IFERROR(_xlfn.IFS(AND(G6="深圳/中山/广州/汕头/厦门",I6="含税"),VLOOKUP("*"&TRIM(SUBSTITUTE(H6,",","|"))&"*",'MT-专线'!C7:G10,2,0),AND(G6="深圳/中山/广州/汕头/厦门",I6="不含税"),VLOOKUP("*"&TRIM(SUBSTITUTE(H6,",","|"))&"*",'MT-专线'!C7:G10,3,0),AND(G6="义乌/苏州",I6="含税"),VLOOKUP("*"&TRIM(SUBSTITUTE(H6,",","|"))&"*",'MT-专线'!C7:G10,2,0),AND(G6="义乌/苏州",I6="不含税"),VLOOKUP("*"&TRIM(SUBSTITUTE(H6,",","|"))&"*",'MT-专线'!C7:G10,3,0),AND(G6="汕头/厦门",I6="含税"),VLOOKUP("*"&TRIM(SUBSTITUTE(H6,",","|"))&"*",'MT-专线'!C7:G10,2,0),AND(G6="汕头/厦门",I6="不含税"),VLOOKUP("*"&TRIM(SUBSTITUTE(H6,",","|"))&"*",'MT-专线'!C7:G10,3,0),AND(G6="青岛",I6="含税"),VLOOKUP("*"&TRIM(SUBSTITUTE(H6,",","|"))&"*",'MT-专线'!C7:G10,4,0),AND(G6="青岛",I6="不含税"),VLOOKUP("*"&TRIM(SUBSTITUTE(H6,",","|"))&"*",'MT-专线'!C7:G10,5,0)),"-") -> 7.4 | H15: =VLOOKUP(E15,[1]Sheet1!$A:$I,4,0) -> 7月4日 18:00 | I15: =VLOOKUP(E15,[1]Sheet1!$A:$I,5,0) -> 46222 | J15: =VLOOKUP(E15,[1]Sheet1!$A:$I,6,0) -> 46237 | K15: =VLOOKUP(E15,[1]Sheet1!$A:$J,7,0) -> 15 | L15: =VLOOKUP(E15,[1]Sheet1!$A:$J,8,0) -> 46241 | M15: =IFERROR(_xlfn.IFS(AND(G6="深圳/中山/广州/汕头/厦门",I6="含税"),VLOOKUP("*"&TRIM(SUBSTITUTE(H6,",","|"))&"*",'MT-专线'!C7:K10,7,0),AND(G6="深圳/中山/广州/汕头/厦门",I6="不含税"),VLOOKUP("*"&TRIM(SUBSTITUTE(H6,",","|"))&"*",'MT-专线'!C7:K10,7,0),AND(G6="义乌/苏州",I6="含税"),VLOOKUP("*"&TRIM(SUBSTITUTE(H6,",","|"))&"*",'MT-专线'!C7:K10,7,0),AND(G6="义乌/苏州",I6="不含税"),VLOOKUP("*"&TRIM(SUBSTITUTE(H6,",","|"))&"*",'MT-专线'!C7:K10,7,0),AND(G6="青岛",I6="含税"),VLOOKUP("*"&TRIM(SUBSTITUTE(H6,",","|"))&"*",'MT-专线'!C7:K10,7,0),AND(G6="青岛",I6="不含税"),VLOOKUP("*"&TRIM(SUBSTITUTE(H6,",","|"))&"*",'MT-专线'!C7:K10,7,0)),"-") -> 32-37
C16: 纽约 | D16: 专线渠道 | E16: MT-专线-纽约 | F16: 2M、THE | G16: =IFERROR(_xlfn.IFS(AND(G6="深圳/中山/广州/汕头/厦门",I6="含税"),VLOOKUP("*"&TRIM(SUBSTITUTE(H6,",","|"))&"*",'MT-专线'!C11:K15,2,0),AND(G6="深圳/中山/广州/汕头/厦门",I6="不含税"),VLOOKUP("*"&TRIM(SUBSTITUTE(H6,",","|"))&"*",'MT-专线'!C11:K15,3,0),AND(G6="义乌/苏州",I6="含税"),VLOOKUP("*"&TRIM(SUBSTITUTE(H6,",","|"))&"*",'MT-专线'!C11:K15,2,0),AND(G6="义乌/苏州",I6="不含税"),VLOOKUP("*"&TRIM(SUBSTITUTE(H6,",","|"))&"*",'MT-专线'!C11:K15,3,0),AND(G6="汕头/厦门",I6="含税"),VLOOKUP("*"&TRIM(SUBSTITUTE(H6,",","|"))&"*",'MT-专线'!C11:K15,2,0),AND(G6="汕头/厦门",I6="不含税"),VLOOKUP("*"&TRIM(SUBSTITUTE(H6,",","|"))&"*",'MT-专线'!C11:K15,3,0),AND(G6="青岛",I6="含税"),VLOOKUP("*"&TRIM(SUBSTITUTE(H6,",","|"))&"*",'MT-专线'!C11:K15,4,0),AND(G6="青岛",I6="不含税"),VLOOKUP("*"&TRIM(SUBSTITUTE(H6,",","|"))&"*",'MT-专线'!C11:K15,5,0)),"-") -> - | H16: =VLOOKUP(E16,[1]Sheet1!$A:$I,4,0) -> 7月4日 18:00 | I16: =VLOOKUP(E16,[1]Sheet1!$A:$I,5,0) -> 46219 | J16: =VLOOKUP(E16,[1]Sheet1!$A:$I,6,0) -> 46258 | K16: =VLOOKUP(E16,[1]Sheet1!$A:$J,7,0) -> 39 | L16: =VLOOKUP(E16,[1]Sheet1!$A:$J,8,0) -> 46262 | M16: =IFERROR(_xlfn.IFS(AND(G6="深圳/中山/广州/汕头/厦门",I6="含税"),VLOOKUP("*"&TRIM(SUBSTITUTE(H6,",","|"))&"*",'MT-专线'!C11:K15,7,0),AND(G6="深圳/中山/广州/汕头/厦门",I6="不含税"),VLOOKUP("*"&TRIM(SUBSTITUTE(H6,",","|"))&"*",'MT-专线'!C11:K15,7,0),AND(G6="义乌/苏州",I6="含税"),VLOOKUP("*"&TRIM(SUBSTITUTE(H6,",","|"))&"*",'MT-专线'!C11:K15,7,0),AND(G6="义乌/苏州",I6="不含税"),VLOOKUP("*"&TRIM(SUBSTITUTE(H6,",","|"))&"*",'MT-专线'!C11:K15,7,0),AND(G6="青岛",I6="含税"),VLOOKUP("*"&TRIM(SUBSTITUTE(H6,",","|"))&"*",'MT-专线'!C11:K15,7,0),AND(G6="青岛",I6="不含税"),VLOOKUP("*"&TRIM(SUBSTITUTE(H6,",","|"))&"*",'MT-专线'!C11:K15,7,0)),"-") -> -
C17: 萨凡纳 | D17: 专线渠道 | E17: MT-专线-萨凡纳 | F17: 2M、THE | G17: =IFERROR(_xlfn.IFS(AND(G6="深圳/中山/广州/汕头/厦门",I6="含税"),VLOOKUP("*"&TRIM(SUBSTITUTE(H6,",","|"))&"*",'MT-专线'!C16:K18,2,0),AND(G6="深圳/中山/广州/汕头/厦门",I6="不含税"),VLOOKUP("*"&TRIM(SUBSTITUTE(H6,",","|"))&"*",'MT-专线'!C16:K18,3,0),AND(G6="义乌/苏州",I6="含税"),VLOOKUP("*"&TRIM(SUBSTITUTE(H6,",","|"))&"*",'MT-专线'!C16:K18,2,0),AND(G6="义乌/苏州",I6="不含税"),VLOOKUP("*"&TRIM(SUBSTITUTE(H6,",","|"))&"*",'MT-专线'!C16:K18,3,0),AND(G6="汕头/厦门",I6="含税"),VLOOKUP("*"&TRIM(SUBSTITUTE(H6,",","|"))&"*",'MT-专线'!C16:K18,2,0),AND(G6="汕头/厦门",I6="不含税"),VLOOKUP("*"&TRIM(SUBSTITUTE(H6,",","|"))&"*",'MT-专线'!C16:K18,3,0),AND(G6="青岛",I6="含税"),VLOOKUP("*"&TRIM(SUBSTITUTE(H6,",","|"))&"*",'MT-专线'!C16:K18,4,0),AND(G6="青岛",I6="不含税"),VLOOKUP("*"&TRIM(SUBSTITUTE(H6,",","|"))&"*",'MT-专线'!C16:K18,5,0)),"-") -> - | H17: =VLOOKUP(E17,[1]Sheet1!$A:$I,4,0) -> 7月4日 18:00 | I17: =VLOOKUP(E17,[1]Sheet1!$A:$I,5,0) -> 46220 | J17: =VLOOKUP(E17,[1]Sheet1!$A:$I,6,0) -> 46251 | K17: =VLOOKUP(E17,[1]Sheet1!$A:$J,7,0) -> 31 | L17: =VLOOKUP(E17,[1]Sheet1!$A:$J,8,0) -> 46255 | M17: =IFERROR(_xlfn.IFS(AND(G6="深圳/中山/广州/汕头/厦门",I6="含税"),VLOOKUP("*"&TRIM(SUBSTITUTE(H6,",","|"))&"*",'MT-专线'!C16:K18,7,0),AND(G6="深圳/中山/广州/汕头/厦门",I6="不含税"),VLOOKUP("*"&TRIM(SUBSTITUTE(H6,",","|"))&"*",'MT-专线'!C16:K18,7,0),AND(G6="义乌/苏州",I6="含税"),VLOOKUP("*"&TRIM(SUBSTITUTE(H6,",","|"))&"*",'MT-专线'!C16:K18,7,0),AND(G6="义乌/苏州",I6="不含税"),VLOOKUP("*"&TRIM(SUBSTITUTE(H6,",","|"))&"*",'MT-专线'!C16:K18,7,0),AND(G6="青岛",I6="含税"),VLOOKUP("*"&TRIM(SUBSTITUTE(H6,",","|"))&"*",'MT-专线'!C16:K18,7,0),AND(G6="青岛",I6="不含税"),VLOOKUP("*"&TRIM(SUBSTITUTE(H6,",","|"))&"*",'MT-专线'!C16:K18,7,0)),"-") -> -
C18: 纽约 | D18: 美东极速 | E18: 美东极速快车 | F18: ZIM带车架 | G18: =IFERROR(_xlfn.IFS(AND(G6="深圳/中山/广州/汕头/厦门",I6="含税"),VLOOKUP("*"&TRIM(SUBSTITUTE(H6,",","|"))&"*",纽约!C:N,2,0),AND(G6="深圳/中山/广州/汕头/厦门",I6="不含税"),VLOOKUP("*"&TRIM(SUBSTITUTE(H6,",","|"))&"*",纽约!C:N,3,0),AND(G6="义乌/苏州",I6="含税"),VLOOKUP("*"&TRIM(SUBSTITUTE(H6,",","|"))&"*",纽约!C:N,2,0),AND(G6="义乌/苏州",I6="不含税"),VLOOKUP("*"&TRIM(SUBSTITUTE(H6,",","|"))&"*",纽约!C:N,3,0),AND(G6="青岛",I6="含税"),VLOOKUP("*"&TRIM(SUBSTITUTE(H6,",","|"))&"*",纽约!C:N,4,0),AND(G6="青岛",I6="不含税"),VLOOKUP("*"&TRIM(SUBSTITUTE(H6,",","|"))&"*",纽约!C:N,5,0)),"-") -> - | H18: =VLOOKUP(E18,[1]Sheet1!$A:$I,4,0) -> 7月4日 22:00 | I18: =VLOOKUP(E18,[1]Sheet1!$A:$I,5,0) -> 46211 | J18: =VLOOKUP(E18,[1]Sheet1!$A:$I,6,0) -> 46228 | K18: =VLOOKUP(E18,[1]Sheet1!$A:$J,7,0) -> 17 | L18: =VLOOKUP(E18,[1]Sheet1!$A:$J,8,0) -> 46229 | M18: =IFERROR(_xlfn.IFS(AND(G6="深圳/中山/广州/汕头/厦门",I6="含税"),VLOOKUP("*"&TRIM(SUBSTITUTE(H6,",","|"))&"*",[2]纽约!C:I,7,0),AND(G6="深圳/中山/广州/汕头/厦门",I6="不含税"),VLOOKUP("*"&TRIM(SUBSTITUTE(H6,",","|"))&"*",[2]纽约!C:I,7,0),AND(G6="义乌/苏州",I6="含税"),VLOOKUP("*"&TRIM(SUBSTITUTE(H6,",","|"))&"*",[2]纽约!C:I,7,0),AND(G6="义乌/苏州",I6="不含税"),VLOOKUP("*"&TRIM(SUBSTITUTE(H6,",","|"))&"*",[2]纽约!C:I,7,0),AND(G6="青岛",I6="含税"),VLOOKUP("*"&TRIM(SUBSTITUTE(H6,",","|"))&"*",[2]纽约!C:I,7,0),AND(G6="青岛",I6="不含税"),VLOOKUP("*"&TRIM(SUBSTITUTE(H6,",","|"))&"*",[2]纽约!C:I,7,0)),"-") -> -
D19: 美东普快 | E19: 美东普快专线 | F19: COSCO | G19: =IFERROR(_xlfn.IFS(AND(G6="深圳/中山/广州/汕头/厦门",I6="含税"),VLOOKUP("*"&TRIM(SUBSTITUTE(H6,",","|"))&"*",纽约!C:N,9,0),AND(G6="深圳/中山/广州/汕头/厦门",I6="不含税"),VLOOKUP("*"&TRIM(SUBSTITUTE(H6,",","|"))&"*",纽约!C:N,10,0),AND(G6="义乌/苏州",I6="含税"),VLOOKUP("*"&TRIM(SUBSTITUTE(H6,",","|"))&"*",纽约!C:N,9,0),AND(G6="义乌/苏州",I6="不含税"),VLOOKUP("*"&TRIM(SUBSTITUTE(H6,",","|"))&"*",纽约!C:N,10,0),AND(G6="青岛",I6="含税"),VLOOKUP("*"&TRIM(SUBSTITUTE(H6,",","|"))&"*",纽约!C:N,11,0),AND(G6="青岛",I6="不含税"),VLOOKUP("*"&TRIM(SUBSTITUTE(H6,",","|"))&"*",纽约!C:N,12,0)),"-") -> - | H19: =VLOOKUP(E19,[1]Sheet1!$A:$I,4,0) -> 7月4日 18:00 | I19: =VLOOKUP(E19,[1]Sheet1!$A:$I,5,0) -> 46215 | J19: =VLOOKUP(E19,[1]Sheet1!$A:$I,6,0) -> 46245 | K19: =VLOOKUP(E19,[1]Sheet1!$A:$J,7,0) -> 30 | L19: =VLOOKUP(E19,[1]Sheet1!$A:$J,8,0) -> 46249 | M19: =IFERROR(_xlfn.IFS(AND(G6="深圳/中山/广州/汕头/厦门",I6="含税"),VLOOKUP("*"&TRIM(SUBSTITUTE(H6,",","|"))&"*",[2]纽约!C:P,14,0),AND(G6="深圳/中山/广州/汕头/厦门",I6="不含税"),VLOOKUP("*"&TRIM(SUBSTITUTE(H6,",","|"))&"*",[2]纽约!C:P,14,0),AND(G6="义乌/苏州",I6="含税"),VLOOKUP("*"&TRIM(SUBSTITUTE(H6,",","|"))&"*",[2]纽约!C:P,14,0),AND(G6="义乌/苏州",I6="不含税"),VLOOKUP("*"&TRIM(SUBSTITUTE(H6,",","|"))&"*",[2]纽约!C:P,14,0),AND(G6="青岛",I6="含税"),VLOOKUP("*"&TRIM(SUBSTITUTE(H6,",","|"))&"*",[2]纽约!C:P,14,0),AND(G6="青岛",I6="不含税"),VLOOKUP("*"&TRIM(SUBSTITUTE(H6,",","|"))&"*",[2]纽约!C:P,14,0)),"-") -> -
C20: 芝加哥 | D20: 芝加哥快线 | E20: 芝加哥海铁快车 | F20: COSCO稳速达 | G20: =IFERROR(_xlfn.IFS(AND(G6="深圳/中山/广州/汕头/厦门",I6="含税"),VLOOKUP("*"&TRIM(SUBSTITUTE(H6,",","|"))&"*",芝加哥!B:M,2,0),AND(G6="深圳/中山/广州/汕头/厦门",I6="不含税"),VLOOKUP("*"&TRIM(SUBSTITUTE(H6,",","|"))&"*",芝加哥!B:M,3,0),AND(G6="义乌/苏州",I6="含税"),VLOOKUP("*"&TRIM(SUBSTITUTE(H6,",","|"))&"*",芝加哥!B:M,2,0),AND(G6="义乌/苏州",I6="不含税"),VLOOKUP("*"&TRIM(SUBSTITUTE(H6,",","|"))&"*",芝加哥!B:M,3,0),AND(G6="青岛",I6="含税"),VLOOKUP("*"&TRIM(SUBSTITUTE(H6,",","|"))&"*",芝加哥!B:M,4,0),AND(G6="青岛",I6="不含税"),VLOOKUP("*"&TRIM(SUBSTITUTE(H6,",","|"))&"*",芝加哥!B:M,5,0)),"-") -> - | H20: =VLOOKUP(E20,[1]Sheet1!$A:$I,4,0) -> 7月4日 18:00 | I20: =VLOOKUP(E20,[1]Sheet1!$A:$I,5,0) -> 46212 | J20: =VLOOKUP(E20,[1]Sheet1!$A:$I,6,0) -> 46236 | K20: =VLOOKUP(E20,[1]Sheet1!$A:$J,7,0) -> 24 | L20: =VLOOKUP(E20,[1]Sheet1!$A:$J,8,0) -> 46238 | M20: =IFERROR(_xlfn.IFS(AND(G6="深圳/中山/广州/汕头/厦门",I6="含税"),VLOOKUP("*"&TRIM(SUBSTITUTE(H6,",","|"))&"*",[2]芝加哥!B:H,7,0),AND(G6="深圳/中山/广州/汕头/厦门",I6="不含税"),VLOOKUP("*"&TRIM(SUBSTITUTE(H6,",","|"))&"*",[2]芝加哥!B:H,7,0),AND(G6="义乌/苏州",I6="含税"),VLOOKUP("*"&TRIM(SUBSTITUTE(H6,",","|"))&"*",[2]芝加哥!B:H,7,0),AND(G6="义乌/苏州",I6="不含税"),VLOOKUP("*"&TRIM(SUBSTITUTE(H6,",","|"))&"*",[2]芝加哥!B:H,7,0),AND(G6="青岛",I6="含税"),VLOOKUP("*"&TRIM(SUBSTITUTE(H6,",","|"))&"*",[2]芝加哥!B:H,7,0),AND(G6="青岛",I6="不含税"),VLOOKUP("*"&TRIM(SUBSTITUTE(H6,",","|"))&"*",[2]芝加哥!B:H,7,0)),"-") -> -
C21: 芝加哥 | D21: 芝加哥海普船 | E21: 芝加哥海铁联运 | F21: COSCO | G21: =IFERROR(_xlfn.IFS(AND(G6="深圳/中山/广州/汕头/厦门",I6="含税"),VLOOKUP("*"&TRIM(SUBSTITUTE(H6,",","|"))&"*",芝加哥!B:M,9,0),AND(G6="深圳/中山/广州/汕头/厦门",I6="不含税"),VLOOKUP("*"&TRIM(SUBSTITUTE(H6,",","|"))&"*",芝加哥!B:M,10,0),AND(G6="义乌/苏州",I6="含税"),VLOOKUP("*"&TRIM(SUBSTITUTE(H6,",","|"))&"*",芝加哥!B:M,9,0),AND(G6="义乌/苏州",I6="不含税"),VLOOKUP("*"&TRIM(SUBSTITUTE(H6,",","|"))&"*",芝加哥!B:M,10,0),AND(G6="青岛",I6="含税"),VLOOKUP("*"&TRIM(SUBSTITUTE(H6,",","|"))&"*",芝加哥!B:M,11,0),AND(G6="青岛",I6="不含税"),VLOOKUP("*"&TRIM(SUBSTITUTE(H6,",","|"))&"*",芝加哥!B:M,12,0)),"-") -> - | H21: =VLOOKUP(E21,[1]Sheet1!$A:$I,4,0) -> 7月4日 18:00 | I21: =VLOOKUP(E21,[1]Sheet1!$A:$I,5,0) -> 46212 | J21: =VLOOKUP(E21,[1]Sheet1!$A:$I,6,0) -> 46243 | K21: =VLOOKUP(E21,[1]Sheet1!$A:$J,7,0) -> 31 | L21: =VLOOKUP(E21,[1]Sheet1!$A:$J,8,0) -> 46245 | M21: =IFERROR(_xlfn.IFS(AND(G6="深圳/中山/广州/汕头/厦门",I6="含税"),VLOOKUP("*"&TRIM(SUBSTITUTE(H6,",","|"))&"*",[2]芝加哥!B:O,14,0),AND(G6="深圳/中山/广州/汕头/厦门",I6="不含税"),VLOOKUP("*"&TRIM(SUBSTITUTE(H6,",","|"))&"*",[2]芝加哥!B:O,14,0),AND(G6="义乌/苏州",I6="含税"),VLOOKUP("*"&TRIM(SUBSTITUTE(H6,",","|"))&"*",[2]芝加哥!B:O,14,0),AND(G6="义乌/苏州",I6="不含税"),VLOOKUP("*"&TRIM(SUBSTITUTE(H6,",","|"))&"*",[2]芝加哥!B:O,14,0),AND(G6="青岛",I6="含税"),VLOOKUP("*"&TRIM(SUBSTITUTE(H6,",","|"))&"*",[2]芝加哥!B:O,14,0),AND(G6="青岛",I6="不含税"),VLOOKUP("*"&TRIM(SUBSTITUTE(H6,",","|"))&"*",[2]芝加哥!B:O,14,0)),"-") -> -
C22: 休斯敦 | D22: 休斯顿专线 | E22: 休斯顿专线 | F22: COSCO/EMC/OOCL | G22: =IFERROR(_xlfn.IFS(AND(G6="深圳/中山/广州/汕头/厦门",I6="含税"),VLOOKUP("*"&TRIM(SUBSTITUTE(H6,",","|"))&"*",休斯敦!B:F,2,0),AND(G6="深圳/中山/广州/汕头/厦门",I6="不含税"),VLOOKUP("*"&TRIM(SUBSTITUTE(H6,",","|"))&"*",休斯敦!B:F,3,0),AND(G6="义乌/苏州",I6="含税"),VLOOKUP("*"&TRIM(SUBSTITUTE(H6,",","|"))&"*",休斯敦!B:F,2,0),AND(G6="义乌/苏州",I6="不含税"),VLOOKUP("*"&TRIM(SUBSTITUTE(H6,",","|"))&"*",休斯敦!B:F,3,0),AND(G6="青岛",I6="含税"),VLOOKUP("*"&TRIM(SUBSTITUTE(H6,",","|"))&"*",休斯敦!B:F,4,0),AND(G6="青岛",I6="不含税"),VLOOKUP("*"&TRIM(SUBSTITUTE(H6,",","|"))&"*",休斯敦!B:F,5,0)),"-") -> - | H22: =VLOOKUP(E22,[1]Sheet1!$A:$I,4,0) -> 7月4日 18:00 | I22: =VLOOKUP(E22,[1]Sheet1!$A:$I,5,0) -> 46215 | J22: =VLOOKUP(E22,[1]Sheet1!$A:$I,6,0) -> 46241 | K22: =VLOOKUP(E22,[1]Sheet1!$A:$J,7,0) -> 26 | L22: =VLOOKUP(E22,[1]Sheet1!$A:$J,8,0) -> 46245 | M22: =IFERROR(_xlfn.IFS(AND(G6="深圳/中山/广州/汕头/厦门",I6="含税"),VLOOKUP("*"&TRIM(SUBSTITUTE(H6,",","|"))&"*",[2]休斯敦!B7:H18,7,0),AND(G6="深圳/中山/广州/汕头/厦门",I6="不含税"),VLOOKUP("*"&TRIM(SUBSTITUTE(H6,",","|"))&"*",[2]休斯敦!B7:H18,7,0),AND(G6="义乌/苏州",I6="含税"),VLOOKUP("*"&TRIM(SUBSTITUTE(H6,",","|"))&"*",[2]休斯敦!B7:H18,7,0),AND(G6="义乌/苏州",I6="不含税"),VLOOKUP("*"&TRIM(SUBSTITUTE(H6,",","|"))&"*",[2]休斯敦!B7:H18,7,0),AND(G7="青岛",I6="含税"),VLOOKUP("*"&TRIM(SUBSTITUTE(H6,",","|"))&"*",[2]休斯敦!B7:H18,7,0),AND(G6="青岛",I6="不含税"),VLOOKUP("*"&TRIM(SUBSTITUTE(H6,",","|"))&"*",[2]休斯敦!B7:H18,7,0)),"-") -> -
C23: 萨瓦纳 | D23: 美东南普船 | E23: 萨瓦纳专线 | F23: EMC | G23: =IFERROR(_xlfn.IFS(AND(G6="深圳/中山/广州/汕头/厦门",I6="含税"),VLOOKUP("*"&TRIM(SUBSTITUTE(H6,",","|"))&"*",萨瓦纳!B:F,2,0),AND(G6="深圳/中山/广州/汕头/厦门",I6="不含税"),VLOOKUP("*"&TRIM(SUBSTITUTE(H6,",","|"))&"*",萨瓦纳!B:F,3,0),AND(G6="义乌/苏州",I6="含税"),VLOOKUP("*"&TRIM(SUBSTITUTE(H6,",","|"))&"*",萨瓦纳!B:F,2,0),AND(G6="义乌/苏州",I6="不含税"),VLOOKUP("*"&TRIM(SUBSTITUTE(H6,",","|"))&"*",萨瓦纳!B:F,3,0),AND(G6="青岛",I6="含税"),VLOOKUP("*"&TRIM(SUBSTITUTE(H6,",","|"))&"*",萨瓦纳!B:F,4,0),AND(G6="青岛",I6="不含税"),VLOOKUP("*"&TRIM(SUBSTITUTE(H6,",","|"))&"*",萨瓦纳!B:F,5,0)),"-") -> - | H23: =VLOOKUP(E23,[1]Sheet1!$A:$I,4,0) -> 7月4日 18:00 | I23: =VLOOKUP(E23,[1]Sheet1!$A:$I,5,0) -> 46213 | J23: =VLOOKUP(E23,[1]Sheet1!$A:$I,6,0) -> 46245 | K23: =VLOOKUP(E23,[1]Sheet1!$A:$J,7,0) -> 32 | L23: =VLOOKUP(E23,[1]Sheet1!$A:$J,8,0) -> 46249 | M23: =IFERROR(_xlfn.IFS(AND(G6="深圳/中山/广州/汕头/厦门",I6="含税"),VLOOKUP("*"&TRIM(SUBSTITUTE(H6,",","|"))&"*",[2]萨瓦纳!B7:H20,7,0),AND(G6="深圳/中山/广州/汕头/厦门",I6="不含税"),VLOOKUP("*"&TRIM(SUBSTITUTE(H6,",","|"))&"*",[2]萨瓦纳!B7:H20,7,0),AND(G6="义乌/苏州",I6="含税"),VLOOKUP("*"&TRIM(SUBSTITUTE(H6,",","|"))&"*",[2]萨瓦纳!B7:H20,7,0),AND(G6="义乌/苏州",I6="不含税"),VLOOKUP("*"&TRIM(SUBSTITUTE(H6,",","|"))&"*",[2]萨瓦纳!B7:H20,7,0),AND(G6="青岛",I6="含税"),VLOOKUP("*"&TRIM(SUBSTITUTE(H6,",","|"))&"*",[2]萨瓦纳!B7:H20,7,0),AND(G6="青岛",I6="不含税"),VLOOKUP("*"&TRIM(SUBSTITUTE(H6,",","|"))&"*",[2]萨瓦纳!B7:H20,7,0)),"-") -> -
C24: 加拿大 | D24: 加拿大直航 | E24: 加拿大直航 | F24: COSCO | G24: =IFERROR(_xlfn.IFS(AND(G6="深圳/中山/广州",I6="含税"),VLOOKUP("*"&TRIM(SUBSTITUTE(H6,",","|"))&"*",加拿大!C:K,2,0),AND(G6="深圳/中山/广州",I6="不含税"),VLOOKUP("*"&TRIM(SUBSTITUTE(H6,",","|"))&"*",加拿大!C:K,3,0),AND(G6="义乌/苏州",I6="含税"),VLOOKUP("*"&TRIM(SUBSTITUTE(H6,",","|"))&"*",加拿大!C:K,4,0),AND(G6="义乌/苏州",I6="不含税"),VLOOKUP("*"&TRIM(SUBSTITUTE(H6,",","|"))&"*",加拿大!C:K,5,0),AND(G6="汕头/厦门",I6="含税"),VLOOKUP("*"&TRIM(SUBSTITUTE(H6,",","|"))&"*",加拿大!C:K,6,0),AND(G6="汕头/厦门",I6="不含税"),VLOOKUP("*"&TRIM(SUBSTITUTE(H6,",","|"))&"*",加拿大!C:K,7,0),AND(G6="青岛",I6="含税"),VLOOKUP("*"&TRIM(SUBSTITUTE(H6,",","|"))&"*",加拿大!C:K,8,0),AND(G6="青岛",I6="不含税"),VLOOKUP("*"&TRIM(SUBSTITUTE(H6,",","|"))&"*",加拿大!C:K,9,0)),"-") -> - | H24: =VLOOKUP(E24,[1]Sheet1!$A:$I,4,0) -> 7月4日 18:00 | I24: =VLOOKUP(E24,[1]Sheet1!$A:$I,5,0) -> 46214 | J24: =VLOOKUP(E24,[1]Sheet1!$A:$I,6,0) -> 46233 | K24: =VLOOKUP(E24,[1]Sheet1!$A:$J,7,0) -> 19 | L24: =VLOOKUP(E24,[1]Sheet1!$A:$J,8,0) -> 46237 | M24: =IFERROR(_xlfn.IFS(AND(G3="深圳/中山/广州/汕头/厦门",I3="含税"),VLOOKUP("*"&TRIM(SUBSTITUTE(H3,",","|"))&"*",[2]加拿大!C4:L9,10,0),AND(G3="深圳/中山/广州/汕头/厦门",I3="不含税"),VLOOKUP("*"&TRIM(SUBSTITUTE(H3,",","|"))&"*",[2]加拿大!C4:L9,10,0),AND(G3="义乌/苏州",I3="含税"),VLOOKUP("*"&TRIM(SUBSTITUTE(H3,",","|"))&"*",[2]加拿大!C4:L9,10,0),AND(G3="义乌/苏州",I3="不含税"),VLOOKUP("*"&TRIM(SUBSTITUTE(H3,",","|"))&"*",[2]加拿大!C4:L9,10,0),AND(G3="青岛",I3="含税"),VLOOKUP("*"&TRIM(SUBSTITUTE(H3,",","|"))&"*",[2]加拿大!C4:L9,10,0),AND(G3="青岛",I3="不含税"),VLOOKUP("*"&TRIM(SUBSTITUTE(H3,",","|"))&"*",[2]加拿大!C4:L9,10,0)),"-") -> -
B25: 墨西哥 | C25: 洛杉矶 | D25: 美转墨 | E25: 美 墨 快 线 | F25: / | G25: / | H25: / | I25: / | J25: / | K25: / | L25: /
C26: 墨西哥城 | D26: 墨西哥直航 | E26: 墨西哥直航 | F26: / | G26: / | H26: / | I26: / | J26: / | K26: / | L26: /
M27: =IFERROR(_xlfn.IFS(AND(G6="深圳/中山/广州/汕头/厦门",I6="含税"),VLOOKUP("*"&TRIM(SUBSTITUTE(H6,",","|"))&"*",[2]加拿大!C7:L12,10,0),AND(G6="深圳/中山/广州/汕头/厦门",I6="不含税"),VLOOKUP("*"&TRIM(SUBSTITUTE(H6,",","|"))&"*",[2]加拿大!C7:L12,10,0),AND(G6="义乌/苏州",I6="含税"),VLOOKUP("*"&TRIM(SUBSTITUTE(H6,",","|"))&"*",[2]加拿大!C7:L12,10,0),AND(G6="义乌/苏州",I6="不含税"),VLOOKUP("*"&TRIM(SUBSTITUTE(H6,",","|"))&"*",[2]加拿大!C7:L12,10,0),AND(G6="青岛",I6="含税"),VLOOKUP("*"&TRIM(SUBSTITUTE(H6,",","|"))&"*",[2]加拿大!C7:L12,10,0),AND(G6="青岛",I6="不含税"),VLOOKUP("*"&TRIM(SUBSTITUTE(H6,",","|"))&"*",[2]加拿大!C7:L12,10,0)),"-") -> -
G28: 12KG+（包税） | H28: 100KG+（包税） | I28: 分区 | J28: 邮编 | M28: 参考提取时效（开船后）
D29: 海派专线 | E29: Match12-海派 | F29: MATSON | G29: =IFERROR(_xlfn.IFS(AND(G6="深圳/中山/广州/汕头/厦门",I6="含税"),VLOOKUP("*"&TRIM(SUBSTITUTE(I29,",","|"))&"*",海派渠道!B5:I10,3,0),AND(G6="义乌/苏州",I6="含税"),VLOOKUP("*"&TRIM(SUBSTITUTE(I29,",","|"))&"*",海派渠道!B5:I10,5,0),AND(G6="青岛",I6="含税"),VLOOKUP("*"&TRIM(SUBSTITUTE(I29,",","|"))&"*",海派渠道!B5:I10,7,0)),"-") -> 16.2 | H29: =IFERROR(_xlfn.IFS(AND(G6="深圳/中山/广州/汕头/厦门",I6="含税"),VLOOKUP("*"&TRIM(SUBSTITUTE(I29,",","|"))&"*",海派渠道!B5:I10,4,0),AND(G6="义乌/苏州",I6="含税"),VLOOKUP("*"&TRIM(SUBSTITUTE(I29,",","|"))&"*",海派渠道!B5:I10,6,0),AND(G6="青岛",I6="含税"),VLOOKUP("*"&TRIM(SUBSTITUTE(I29,",","|"))&"*",海派渠道!B5:I10,8,0)),"-") -> 13.2 | I29: =VLOOKUP(H6,分区!A:D,4,0) -> 美西 | J29: =VLOOKUP(H6,分区!A:E,2,0) -> 94561-2677 | K29: 11 | L29: 查看报价 | M29: 14-15天
E30: Match15-海派 | F30: 以星 EXX | G30: =IFERROR(_xlfn.IFS(AND(G6="深圳/中山/广州/汕头/厦门",I6="含税"),VLOOKUP("*"&TRIM(SUBSTITUTE(I29,",","|"))&"*",海派渠道!B6:R11,12,0),AND(G6="义乌/苏州",I6="含税"),VLOOKUP("*"&TRIM(SUBSTITUTE(I29,",","|"))&"*",海派渠道!B6:R11,14,0),AND(G6="青岛",I6="含税"),VLOOKUP("*"&TRIM(SUBSTITUTE(I29,",","|"))&"*",海派渠道!B6:R11,16,0)),"-") -> 14.6 | H30: =IFERROR(_xlfn.IFS(AND(G6="深圳/中山/广州/汕头/厦门",I6="含税"),VLOOKUP("*"&TRIM(SUBSTITUTE(I29,",","|"))&"*",海派渠道!B6:T11,13,0),AND(G6="义乌/苏州",I6="含税"),VLOOKUP("*"&TRIM(SUBSTITUTE(I29,",","|"))&"*",海派渠道!B6:T11,15,0),AND(G6="青岛",I6="含税"),VLOOKUP("*"&TRIM(SUBSTITUTE(I29,",","|"))&"*",海派渠道!B6:T11,17,0)),"-") -> 11.6 | K30: 11 | L30: 查看报价 | M30: 16-17天
E31: Match20-海派 | F31: EMC 合德 | G31: =IFERROR(_xlfn.IFS(AND(G6="深圳/中山/广州/汕头/厦门",I6="含税"),VLOOKUP("*"&TRIM(SUBSTITUTE(I29,",","|"))&"*",海派渠道!B16:I20,3,0),AND(G6="义乌/苏州",I6="含税"),VLOOKUP("*"&TRIM(SUBSTITUTE(I29,",","|"))&"*",海派渠道!B16:I20,5,0),AND(G6="青岛",I6="含税"),VLOOKUP("*"&TRIM(SUBSTITUTE(I29,",","|"))&"*",海派渠道!B16:I20,7,0)),"-") -> 12.7 | H31: =IFERROR(_xlfn.IFS(AND(G6="深圳/中山/广州/汕头/厦门",I6="含税"),VLOOKUP("*"&TRIM(SUBSTITUTE(I29,",","|"))&"*",海派渠道!B16:I20,4,0),AND(G6="义乌/苏州",I6="含税"),VLOOKUP("*"&TRIM(SUBSTITUTE(I29,",","|"))&"*",海派渠道!B16:I20,6,0),AND(G6="青岛",I6="含税"),VLOOKUP("*"&TRIM(SUBSTITUTE(I29,",","|"))&"*",海派渠道!B16:I20,8,0)),"-") -> 9.7 | K31: 14 | L31: 查看报价 | M31: 21-22天
E32: OA-拆送海派 | F32: OA | G32: =IFERROR(_xlfn.IFS(AND(G6="深圳/中山/广州/汕头/厦门",I6="含税"),VLOOKUP("*"&TRIM(SUBSTITUTE(I29,",","|"))&"*",海派渠道!B16:R21,12,0),AND(G6="义乌/苏州",I6="含税"),VLOOKUP("*"&TRIM(SUBSTITUTE(I29,",","|"))&"*",海派渠道!B16:R21,14,0),AND(G6="青岛",I6="含税"),VLOOKUP("*"&TRIM(SUBSTITUTE(I29,",","|"))&"*",海派渠道!B16:R21,16,0)),"-") -> 12.5 | H32: =IFERROR(_xlfn.IFS(AND(G6="深圳/中山/广州/汕头/厦门",I6="含税"),VLOOKUP("*"&TRIM(SUBSTITUTE(I29,",","|"))&"*",海派渠道!B16:R21,13,0),AND(G6="义乌/苏州",I6="含税"),VLOOKUP("*"&TRIM(SUBSTITUTE(I29,",","|"))&"*",海派渠道!B16:R21,15,0),AND(G6="青岛",I6="含税"),VLOOKUP("*"&TRIM(SUBSTITUTE(I29,",","|"))&"*",海派渠道!B16:R21,17,0)),"-") -> 9.5 | K32: 14 | L32: 查看报价 | M32: 26-28天

Sheet 发货须知
B2: 美 琦 国 际 货 运 代 理（深圳）有 限 公 司 地址：深圳市龙岗区坂田街道坂雪岗大道4088号奥博中心6楼A609-611
B4: 附加费 | C4: 渠道 | D4: 海卡包税 | E4: 海卡不包税 | F4: 海派渠道 | G4: 直通车（包税） | H4: 直通车（不包税）
C5: 末端派送类型 | D5: 卡派 | E5: 卡派 | F5: UPS | G5: 卡派 | H5: 卡派不包税
B6: 报关费 | C6: 买单报关 | D6: 0 | E6: 0 | F6: 0 | G6: 0 | H6: 0
C7: 一般贸易报关费 | D7: 350 | E7: 350 | F7: 350 | G7: 350 | H7: 350 | J7: 国内仓库费用 | K7: 收费项目 | L7: 单价/RMB | M7: 单位 | N7: 备注 | O7: 备注
C8: 手册报关/其他报关（9710/9810，一达通报关） | D8: 350 | E8: 350 | F8: 350 | G8: 350 | H8: 350 | K8: 更改包装费 | L8: 10 | M8: 箱 | N8: 不含纸箱费用
B9: 产品附加费 | C9: 服装类（穿戴类纺织品） | D9: 0.5/KG | E9: 0 | F9: 0.5/KG | G9: 0.5/KG | H9: 0 | K9: 产品贴标签 | L9: 1 | M9: 个标签 | N9: 含标签纸
C10: 木制品（报关件单询） | D10: 0.5/KG | E10: 500 | F10: 0.5/KG | G10: 0.5/KG | H10: 500 | K10: 换外箱标签 | L10: 1 | M10: 个标签 | N10: 含标签纸
C11: 包包 | D11: 0.5/KG | E11: 500 | F11: 0.5/KG | G11: 0.5/KG | H11: 500
C12: FDA\EPA\DOT认证产品 | D12: 单询 | E12: 单询 | F12: 单询 | G12: 单询 | H12: 单询 | K12: 割包装袋/带 | L12: 1 | M12: 箱
C13: 涉FDA产品 | D13: 单询 | E13: 单询 | F13: 单询 | G13: 单询 | H13: 单询 | K13: 开木箱查货 | L13: 30 | M13: 箱 | N13: 含封箱
C14: 厨房刀具 | D14: 单询 | E14: 单询 | F14: 单询 | G14: 单询 | H14: 单询 | K14: 仓租 | L14: 3.5/天 | M14: CBM | N14: 自入仓日起免租期7天，最久存仓1个月 | O14: 免仓期7天
C15: 涉太阳能产品 | D15: 单询 | E15: 单询 | F15: 单询 | G15: 单询 | H15: 单询
C16: 移动电源\纯电池\暖手宝 | D16: 单询 | E16: 单询 | F16: 单询 | G16: 单询 | H16: 单询
C17: 单件计费重低消 | D17: 5KG/件 | E17: 5KG/件 | F17: 12KG/件 | G17: 5KG/件 | H17: 5KG/件
B18: 特殊地址附加费 | C18: 商业地址 | D18: 0 | E18: 0 | F18: 0 | G18: 0 | H18: 0
C19: 私人地址 | D19: 0 | E19: 0 | F19: 25/件 | G19: 0 | H19: 0
C20: 偏远附加费 | D20: 0 | E20: 0 | F20: 40/件 | G20: 0 | H20: 0
B21: 超重超尺寸附加费 | C21: 140cm≤最长边＜169cm | D21: 1/KG | E21: 200/CBM | F21: 无服务 | G21: 无服务 | H21: 无服务
C22: 120cm≤最长边＜140cm | D22: 0 | E22: 0 | F22: 160/件 | G22: 无服务 | H22: 无服务
C23: 第二边长≥76cm | D23: 0 | E23: 0 | F23: 120/件 | G23: 无服务 | H23: 无服务
C24: 三边相乘体积>0.17立方米 | D24: 0 | E24: 0 | F24: 160/件 | G24: 无服务 | H24: 无服务
C25: 22.5KG≤实重≤40KG | D25: 0 | E25: 0 | F25: 160/件 | G25: 无服务 | H25: 无服务
C26: 实重＞40KG | D26: 单询 | E26: 单询 | F26: 500/件 | G26: 单询 | H26: 单询
C27: 266cm≤长+2x(宽+高)≤330cm | D27: 单询 | E27: 单询 | F27: 160/件 | G27: 单询 | H27: 单询
C28: 330cm≤长+2x(宽+高)≤419cm | D28: 单询 | E28: 单询 | F28: 900/件 | G28: 单询 | H28: 单询
C29: 三边相乘体积>0.28立方米 | D29: 单询 | E29: 单询 | F29: 600/件 | G29: 单询 | H29: 单询
C30: 单件重量超过49.8KG | D30: 单询 | E30: 单询 | F30: 600/件 | G30: 单询 | H30: 单询
C31: 长+2x(宽+高)＞419cm | D31: 单询 | E31: 单询 | F31: 无服务 | G31: 单询 | H31: 单询
B32: 其他附加费 | C32: 关税和查验费 | D32: 0 | E32: 实报实销 | F32: 0 | G32: 0 | H32: 实报实销
C33: 清关超品名费 | D33: 30/品名 | E33: 30/品名 | F33: 30/品名 | G33: 30/品名 | H33: 30/品名
C34: 退件费（打单后） | D34: 0 | E34: 0 | F34: 100/票 | G34: 0 | H34: 0
C35: 目的港扣货 | D35: USD200/票 | E35: USD200/票 | F35: USD200/票 | G35: USD1200/票 | H35: USD1200/票
C36: 申请POD | D36: 免费 | E36: 免费 | F36: 35/主单号 | G36: 免费 | H36: 免费
B37: 拒收产品 | C37: 1、带有以下标识：LASER，ACT等授权认证的产品（无论是否有认证）
C38: 2、手机、笔记本电脑等高货值产品、婴儿用品（包括衣服），激光产品，蝴蝶刀、液体、粉末、U盘、光驱、内存条、家具、指尖陀螺、电弧打火机，带压缩机产品，活性植物，太阳眼镜、化妆品等
C39: 3、仿牌产品，液体、粉末、食品、药品、易燃易爆、古董、货币等国家禁止出口产品，如发现罚款2000/票，情节严重上报公安局处理
C40: 4、反倾销产品（点我看清单）
B41: 海外仓仓租 | C41: 提柜起免租7天，第8-60天收取USD2/CBM/天,第61天起收取USD3/CBM/天，（每票最低消费收费5USD/天） 超过3个月未出货物默认销毁，已产生的仓租正常收取
B42: 开 查 | C42: 货物派送后，请客户在签收后7-10个工作日内查询FBA后台是否上架，如递送后15个工作日内提供货物未上架，请提供后台截图至我司客服。
...

Sheet MATCH闪送
A1: 美 琦 国 际 货 运 代 理（深圳）有 限 公 司 地址：深圳市龙岗区坂田街道坂雪岗大道4088号奥博中心6楼A609-611
A3: MATCH 闪送系列
A4: 目的港 | B4: Match美西闪送-海派 | K4: 返回目录
A5: 洛杉矶 | B5: 邮编 | C5: 12KG+(海派包税） | D5: 50KG+(海派包税） | E5: 100KG+(海派包税） | F5: 参考时效（开船后） | G5: 理赔时效（开船后提取） | H5: 备注
B6: 邮编 8 9 | C6: - | D6: - | E6: - | F6: 13Day | G6: 13Day | H6: 重货优惠 1 :200 =-0.3/KG 1:240= -0.6/KG 1:280= -0.9/KG 1:320 =-1.2/KG 1:360= -1.5/KG 1:420 = -1.8/KG 1:480=- 2.1/KG 1:500=-2.5/KG （封顶）
B7: 邮编（97 98 99） | C7: - | D7: - | E7: - | F7: 13Day | G7: 13Day
B8: 邮编 5 6 7 | C8: - | D8: - | E8: - | F8: 13Day | G8: 13Day
B9: 邮编 0 1 2 3 4 | C9: - | D9: - | E9: - | F9: 13Day | G9: 13Day
B10: 下单渠道 | C10: Match美西闪送海派包税 | D10: Y-Match美西闪送海派包税 | E10: Match美西闪送海派包税 | F10: 美西闪送-海派（汕头/厦门中转仓到货的按深圳价格+0.3，青岛仓价格按义乌报价+0.5）
A11: Match美西闪送
A12: 目的港 | C12: 深圳/中山/广州/义乌 | D12: 汕头/厦门 | E12: 青岛
A13: 洛杉矶 | B13: 亚马逊仓库地址 | C13: 21KG+（卡派包税） | D13: 21KG+（卡派包税） | E13: 21KG+（卡派包税） | F13: 参考时效（开船后） | G13: 理赔时效（开船后）
B14: ONT8，LGB8，SBD1，LAX9 | C14: - | D14: - | E14: - | F14: 13Day | G14: 14Day
B15: POC1，POC3 | C15: - | D15: - | E15: - | F15: 13Day | G15: 15Day
B16: 下单渠道 | C16: Match美西闪送卡派包税 | D16: Match美西闪送卡派包税 | E16: Match美西闪送卡派包税
A17: 时效赔付说明 | C17: 理赔时效计算标准：实际开船日期第二天算起 时效赔偿：RMB1.5/KG/自然日（含税），最高赔偿4.5KG 海派第13天未提取开始理赔，无论国内外任何查验 都计入理赔时效 闪送闪赔 赔偿方案7工作日内到位
A20: 上架延误险 | C20: 上架延误险：+0.1RMB/KG，如签收后72小时无上架信息（check in ）,每工作日赔偿0.1/KG，最多赔偿0.5RMB/KG！
C22: Match美东闪送
C23: 深圳/中山/广州/义乌/汕头/厦门 | E23: 青岛 | G23: 时效
A24: 亚马逊仓库地址（低于50KG 需+2/KG） | C24: 包税50KG+ | D24: 不包税1CBM+ | E24: 包税50KG+ | F24: 不包税1CBM+ | G24: 航程 (开船后) | H24: 参考时效(开船后) | I24: 参考时效(开船后) | J24: 备注
A25: 正常派送区 | B25: TEB6、TEB9、EWR5、EWR4、EWR6、EWR7、EWR9 | C25: - | D25: - | E25: - | F25: - | G25: 19-21 | H25: 25-27 | I25: 28天 | J25: 【含税】渠道： 1、含关税和查验费； 2、体积/6000，不分泡 3、单件最低消费5KG，美东极速快车渠道单票低消21KG,21-49KG单价+2/KG： 【不含税】渠道： 1、不含关税，查验费和查验产生的其他费用； 2、体积/1000000，不分泡，单件最低消费5KG，单票低消1CBM 3.重货按每363KG=1CBM (产品附加费/特殊附加费等详见发货必读) 重货优惠： 包税渠道重货优惠 重货优惠 1 :200 =-0.3/KG 1:240= -0.6/KG 1:280= -0.9/KG 1:320 =-1.2/KG 1:360= -1.5/KG 1:420 = -1.8/KG 1:480=- 2.1/KG 1:500=-2.5/KG （封顶）
B26: ABE8、ACY2、TTN2、LGA9、ACY1、JFK8、JFK2 | C26: - | D26: - | E26: - | F26: - | G26: 19-21 | H26: 25-27 | I26: 28天
B27: TEB3、TEB4、ABE4、ABE3、ABE5、ABE2 | C27: - | D27: - | E27: - | F27: - | G27: 19-21 | H27: 25-27 | I27: 28天
B28: AVP1、AVP9、WBW2、AVP3 | C28: - | D28: - | E28: - | F28: - | G28: 19-21 | H28: 25-27 | I28: 28天
B29: PHL4、PHL5、PHL6、MDT1、RDG1、MDT2 | C29: - | D29: - | E29: - | F29: - | G29: 19-21 | H29: 25-27 | I29: 28天
B30: HIA1、DCA6、DCA1 | C30: - | D30: - | E30: - | F30: - | G30: 19-21 | H30: 27-29 | I30: 30天
B31: SWF2、SWF1、ILG1、PHL3、PHL7、PHL1 | C31: - | D31: - | E31: - | F31: - | G31: 19-21 | H31: 27-29 | I31: 30天
B32: MDT4、ALB1、XLX1、HGR6、HGR2 | C32: - | D32: - | E32: - | F32: - | G32: 19-21 | H32: 28-30 | I32: 31天
B33: IUST、IUSL | C33: - | D33: - | E33: - | F33: - | G33: 19-21 | H33: 27-29 | I33: 30天
B34: BWI2、BDL6、BDL3、BDL2、BWI1、BWI4 | C34: - | D34: - | E34: - | F34: - | G34: 19-21 | H34: 27-29 | I34: 30天
B35: AKR1、CMH6、CMH2、CMH7、RMN3 | C35: - | D35: - | E35: - | F35: - | G35: 19-21 | H35: 28-30 | I35: -
B36: PIT2、LBE1、RIC1、RIC3、XRI3、CHO1、RIC2 | C36: - | D36: - | E36: - | F36: - | G36: 19-21 | H36: 28-30 | I36: -
B37: CMH3、XPH1、ORF2、GSO1 | C37: - | D37: - | E37: - | F37: - | G37: 19-21 | H37: 28-30 | I37: -
... B53: TPA1、TPA2、MCO2、TPA3、TPA6、MCO1 | C53: - | D53: - | E53: - | F53: - | G53: 无 | H53: 无 | I53: 无
A54: 纽约自提 | C54: - | D54: - | E54: - | F54: - | G54: 19-21 | H54: 25-27 | I54: 无
A55: 08邮编海外仓（单票低消500KG或3个方） | C55: - | D55: - | E55: - | F55: - | G55: 19-21 | H55: 25-27 | I55: 无
A56: 08邮编海外仓（1500KG+或6个方+） | C56: - | D56: - | E56: - | F56: - | G56: 19-21 | H56: 25-27 | I56: 无
A57: 沃尔玛仓库 | B57: 沃尔玛 低消费300KG 2CBM+ | C57: 300KG+ | D57: 2CBM+ (不包税) | E57: 300KG+ | F57: 2CBM+ (不包税)
B58: WMT-NJ3 | C58: - | D58: - | G58: - | I58: -
B59: WNT-IND2，WNT-IND1，WNT-BNA1s | C59: - | D59: - | G59: - | I59: -
...

Sheet Match系列 
B2: 美 琦 国 际 货 运 代 理（深圳）有 限 公 司 地址：深圳市龙岗区坂田街道坂雪岗大道4088号奥博中心6楼A609-611
B3: M A T C H 系 列 王 牌 产 品
D4: Match12-卡派（CLX+MAX-GES服务) | L4: Match15-卡派（ZIM带车架、EXX统配） | T4: Match20-卡派（长荣定提 、合德快提统配）
D5: 深圳/中山/广州/汕头/厦门 | F5: 义乌/苏州 | H5: 青岛 | J5: 时效 | L5: 深圳/中山/广州/汕头/厦门 | N5: 义乌/苏州 | P5: 青岛 | R5: 时效 | T5: 深圳/中山/广州/汕头/厦门 | V5: 义乌/苏州 | X5: 青岛 | Z5: 时效
B6: 亚马逊仓库地址 | D6: 21KG+ （包税） | E6: 1CBM+（不包税） | F6: 21KG+ （包税） | G6: 1CBM+（不包税） | H6: 21KG+ （包税） | I6: 1CBM+（不包税） | J6: 参考时效（开船后） | K6: 理赔时效（开船后） | L6: 21KG+ （包税） | M6: 1CBM+（不包税） | N6: 21KG+ （包税） | O6: 1CBM+（不包税） | P6: 21KG+ （包税） | Q6: 1CBM+（不包税） | R6: 参考时效（开船后） | S6: 理赔时效（开船后） | T6: 21KG+ （包税） | U6: 1CBM+（不包税） | V6: 21KG+ （包税） | W6: 1CBM+（不包税） | X6: 21KG+ （包税） | Y6: 1CBM+（不包税） | Z6: 参考时效（开船后） | AA6: 理赔时效（开船后） | AB6: 返回目录 | AC6: 涨价幅度
B7: 热门仓 | C7: ONT8、LGB8、SBD1、LAX9 | D7: 11.2 | E7: 1580 | F7: 10.7 | G7: 1505 | H7: 11.2 | I7: 1580 | J7: 13-15 | K7: 15天 | L7: 8.8 | M7: 1210 | N7: 8.8 | O7: 1210 | P7: 9.3 | Q7: 1285 | R7: 15-17 | S7: 19天 | T7: 7.5 | U7: 1060 | V7: 7.5 | W7: 1060 | X7: 8 | Y7: 1135 | Z7: 19-21 | AA7: 23天 | AB7: 重货优惠 1 :200 =-0.3/KG 1:240= -0.6/KG 1:280= -0.9/KG 1:320 =-1.2/KG 1:360= -1.5/KG 1:420 = -1.8/KG 1:480=- 2.1/KG 1:500=-2.5/KG （封顶） 1、包税渠道含关税和查验费； 2、体积/6000； 3、不分泡 4、不包税渠道不含关税和查验费；如查验按照68CBM分摊查验费 8、体积/6000； 6、不分泡，最低消费1个方 ，不足1个方按照1个方算 10、1CBM=363KG (产品附加费/特殊附加费等详见发货必读) | AC7: Match12 | AD7: 0.1 | AE7: 15
C8: POC1、POC2、POC3 | D8: 11.2 | E8: 1580 | F8: 10.7 | G8: 1505 | H8: 11.2 | I8: 1580 | J8: 13-15 | K8: 15天 | L8: 8.8 | M8: 1210 | N8: 8.8 | O8: 1210 | P8: 9.3 | Q8: 1285 | R8: 15-17 | S8: 19天 | T8: 7.5 | U8: 1060 | V8: 7.5 | W8: 1060 | X8: 8 | Y8: 1135 | Z8: 19-21 | AA8: 24天 | AC8: Match15 | AD8: 0.5 | AE8: 75
C9: SMF3、SCK4、SCK4、SCK8、HLI2、TCY1、TCY2、PSP3 | D9: 11.8 | E9: 1670 | F9: 11.3 | G9: 1595 | H9: 11.8 | I9: 1670 | J9: 15-17 | K9: 无 | L9: 9.7 | M9: 1345 | N9: 9.7 | O9: 1345 | P9: 10.2 | Q9: 1420 | R9: 17-19 | S9: 无 | T9: 8.4 | U9: 1195 | V9: 8.4 | W9: 1195 | X9: 8.9 | Y9: 1270 | Z9: 20-22 | AA9: 无 | AC9: Match20 | AD9: 0.8 | AE9: 120
C10: LAS1、VGT2、GYR2、GYR3、LAS6、IUTE | D10: 11.8 | E10: 1670 | F10: 11.3 | G10: 1595 | H10: 11.8 | I10: 1670 | J10: 15-17 | K10: 无 | L10: 9.7 | M10: 1345 | N10: 9.7 | O10: 1345 | P10: 10.2 | Q10: 1420 | R10: 17-19 | S10: 无 | T10: 8.4 | U10: 1195 | V10: 8.4 | W10: 1195 | X10: 8.9 | Y10: 1270 | Z10: 20-22 | AA10: 无
C11: GEU2、GEU3、MIT2 | D11: 11.8 | E11: 1670 | F11: 11.3 | G11: 1595 | H11: 11.8 | I11: 1670 | J11: 15-17 | K11: 无 | L11: 9.7 | M11: 1345 | N11: 9.7 | O11: 1345 | P11: 10.2 | Q11: 1420 | R11: 17-19 | S11: 无 | T11: 8.4 | U11: 1195 | V11: 8.4 | W11: 1195 | X11: 8.9 | Y11: 1270 | Z11: 20-22 | AA11: 无
C12: ABQ2 | D12: 12.8 | E12: 1820 | F12: 12.3 | G12: 1745 | H12: 12.8 | I12: 1820 | J12: 15-19 | K12: 无 | L12: 10.9 | M12: 1525 | N12: 10.9 | O12: 1525 | P12: 11.4 | Q12: 1600 | R12: 19-21 | S12: 无 | T12: 9.6 | U12: 1375 | V12: 9.6 | W12: 1375 | X12: 10.1 | Y12: 1450 | Z12: 22-24 | AA12: 无
C13: PSC2 | D13: 13.2 | E13: 1880 | F13: 12.7 | G13: 1805 | H13: 13.2 | I13: 1880 | J13: 15-19 | K13: 无 | L13: 11.3 | M13: 1585 | N13: 11.3 | O13: 1585 | P13: 11.8 | Q13: 1660 | R13: 19-21 | S13: 无 | T13: 10 | U13: 1435 | V13: 10 | W13: 1435 | X13: 10.5 | Y13: 1510 | Z13: 22-24 | AC13: 0.4 | AD13: 60
C14: FTW1、MDW2、IND9、MEM1 | D14: 14 | E14: 2000 | F14: 13.5 | G14: 1925 | H14: 14 | I14: 2000 | J14: 16-20 | K14: 无 | L14: 11.6 | M14: 1630 | N14: 11.6 | O14: 1630 | P14: 12.1 | Q14: 1705 | R14: 20-22 | S14: 无 | T14: 10.3 | U14: 1480 | V14: 10.3 | W14: 1480 | X14: 10.8 | Y14: 1555 | Z14: 22-24 | AA14: 无
C15: IAH3 | D15: 14.1 | E15: 2015 | F15: 13.6 | G15: 2030 | H15: 14.1 | I15: 2015 | J15: 16-20 | K15: 无 | L15: 11.7 | M15: 1645 | N15: 11.7 | O15: 1645 | P15: 12.2 | Q15: 1720 | R15: 20-22 | S15: 无 | T15: 10.4 | U15: 1495 | V15: 10.4 | W15: 1495 | X15: 10.9 | Y15: 1570 | Z15: 22-24 | AA15: 无
C16: LGB4、LGB9、LGB9、ONT6、ONT9、XLX7、LGB6、 SBD2、IUS1、IUSW、IUT1 | D16: 11.5 | E16: 1625 | F16: 11 | G16: 1550 | H16: 11.5 | I16: 1625 | J16: 15-17 | K16: 无 | L16: 8.9 | M16: 1225 | N16: 8.9 | O16: 1225 | P16: 9.4 | Q16: 1300 | R16: 18-20 | S16: 无 | T16: 7.6 | U16: 1075 | V16: 7.6 | W16: 1075 | X16: 8.1 | Y16: 1150 | Z16: 22-24 | AA16: 无
B17: 加州其他仓库 | C17: SCK1、SCK3、OAK3、SJC7、SMF6、QXY5、QZZ7 | D17: 12 | E17: 1700 | F17: 11.5 | G17: 1625 | H17: 12 | I17: 1700 | J17: 15-18 | K17: 无 | L17: 9.7 | M17: 1345 | N17: 9.7 | O17: 1345 | P17: 10.2 | Q17: 1420 | R17: 18-20 | S17: 无 | T17: 8.4 | U17: 1195 | V17: 8.4 | W17: 1195 | X17: 8.9 | Y17: 1270 | Z17: 24-26 | AA17: 无
B18: 海外仓 | C18: 仓库自提（出仓费15USD/板） | D18: 11 | E18: 1550 | F18: 10.5 | G18: 1475 | H18: 11.1 | I18: 1565 | J18: 13-15 | K18: 无 | L18: 8.6 | M18: 1180 | N18: 8.6 | O18: 1180 | P18: 9.1 | Q18: 1255 | R18: 15-17 | S18: 无 | T18: 7.3 | U18: 1030 | V18: 7.3 | W18: 1030 | X18: 7.8 | Y18: 1105 | Z18: 19-21 | AA18: 无
C19: 亚马逊仓库地址（以下地址 不足50KG 需+2） | D19: 50KG+（包税） | E19: 1CBM+（不包税） | F19: 50KG+（包税） | G19: 1CBM+（不包税） | H19: 50KG+（包税） | I19: 1CBM+（不包税） | J19: 参考时效（开船后） | K19: 理赔时效（开船后） | L19: 50KG+（包税） | M19: 1CBM+（不包税） | N19: 50KG+（包税） | O19: 1CBM+（不包税） | P19: 50KG+（包税） | Q19: 1CBM+（不包税） | R19: 参考时效（开船后） | S19: 理赔时效（开船后） | T19: 50KG+（包税） | U19: 1CBM+（不包税） | V19: 50KG+（包税） | W19: 1CBM+（不包税） | X19: 50KG+（包税） | Y19: 1CBM+（不包税） | Z19: 参考时效（开船后） | AA19: 理赔时效（开船后）
B20: 外州 | C20: PHX5、PHX7、RNO4 | D20: 12.1 | E20: 1715 | F20: 11.6 | G20: 1640 | H20: 12.1 | I20: 1715 | J20: 20-22 | K20: 无 | L20: 10 | M20: 1390 | N20: 10 | O20: 1390 | P20: 10.5 | Q20: 1465 | R20: 20-22 | S20: 无 | T20: 8.7 | U20: 1240 | V20: 8.7 | W20: 1240 | X20: 9.2 | Y20: 1315 | Z20: 21-23 | AA20: 无
C21: DEN2、DEN8、SLC2 | D21: 13.6 | E21: 1940 | F21: 13.1 | G21: 1865 | H21: 13.6 | I21: 1940 | J21: 20-23 | K21: 无 | L21: 10.7 | M21: 1495 | N21: 10.7 | O21: 1495 | P21: 11.2 | Q21: 1570 | R21: 21-23 | S21: 无 | T21: 9.4 | U21: 1345 | V21: 9.4 | W21: 1345 | X21: 9.9 | Y21: 1420 | Z21: 22-24 | AA21: 无
C22: GEG2、PDX7 | D22: 13.9 | E22: 1985 | F22: 13.4 | G22: 1910 | H22: 13.9 | I22: 1985 | J22: 20-23 | K22: 无 | L22: 11.5 | M22: 1615 | N22: 11.5 | O22: 1615 | P22: 12 | Q22: 1690 | R22: 21-23 | S22: 无 | T22: 10.2 | U22: 1465 | V22: 10.2 | W22: 1465 | X22: 10.7 | Y22: 1540 | Z22: 22-24 | AA22: 无
C23: CLT2、PBI3 | D23: 15 | E23: 2150 | F23: 14.5 | G23: 2075 | H23: 15 | I23: 2150 | J23: 25-28 | K23: 无 | L23: 11.9 | M23: 1675 | N23: 11.9 | O23: 1675 | P23: 12.4 | Q23: 1750 | R23: 27-29 | S23: 无 | T23: 10.6 | U23: 1525 | V23: 10.6 | W23: 1525 | X23: 11.1 | Y23: 1600 | Z23: 28-30 | AA23: 无
C24: ABE8、AVP1、RMN3、TEB9 | D24: 15.7 | E24: 2255 | F24: 15.2 | G24: 2180 | H24: 15.7 | I24: 2255 | J24: 25-28 | K24: 无 | L24: 13.2 | M24: 1870 | N24: 13.2 | O24: 1870 | P24: 13.7 | Q24: 1955 | R24: 27-29 | S24: 无 | T24: 11.8 | U24: 1660 | V24: 11.8 | W24: 1660 | X24: 12.3 | Y24: 1735 | Z24: 28-30 | AA24: 无 | AC24: 0.9 | AD24: 135
B25: 下单渠道 | D25: Match12-卡派 | E25: Match12-卡派-BB | F25: Match12-卡派 | G25: Match12-卡派-BB | H25: Match12-卡派 | I25: Match12-卡派-BB | L25: Match15-卡派 | M25: Match15-卡派-BB | N25: Match15-卡派 | O25: Match15-卡派-BB | P25: Match15-卡派 | Q25: Match15-卡派-BB | T25: Match20-卡派 | U25: Match20-卡派-BB | V25: Match20-卡派 | W25: Match20-卡派-BB | X25: Match20-卡派 | Y25: Match20-卡派-BB
B26: 时效赔付说明（实际开船日期第二天算起） | D26: RMB 0.5/KG/工作日，最高赔偿1.5RMB/KG，不包税渠道RMB 75/CBM/工作日，最高赔偿150RMB/CBM，无论进出口查验赔偿统一最高赔偿统一最高1/KG | L26: RMB 0.5/KG/工作日，最高赔偿1.5RMB/KG，不包税渠道RMB 75/CBM/工作日，最高赔偿150RMB/CBM进出口查验、船期延误 亚马逊删约改约、拒收不赔 | T26: RMB 0.5/KG/工作日，最高赔偿1RMB/KG，不包税渠道RMB 75/CBM/工作日，最高赔偿75RMB/CBM进出口查验、船期延误 亚马逊删约改约、拒收不赔
B27: 上架延误险 | D27: 上架延误险：+0.1RMB/KG，如签收后72小时无上架信息（check in ）,每工作日赔偿0.1/KG，最多赔偿0.5RMB/KG！ | L27: 上架延误险：+0.1RMB/KG，如签收后72小时无上架信息（check in ）,每工作日赔偿0.1/KG，最多赔偿0.5RMB/KG！ | T27: 上架延误险：+0.1RMB/KG，如签收后72小时无上架信息（check in ）,每工作日赔偿0.1/KG，最多赔偿0.5RMB/KG！

Sheet 美森美东秒送
B2: 美 琦 国 际 货 运 代 理（深圳）有 限 公 司 地址：深圳市龙岗区坂田街道坂雪岗大道4088号奥博中心6楼A609-611
B4: 美森美东秒送 | L4: 返回目录
D5: 深圳/中山/广州/义乌/苏州/汕头/厦门 | F5: 青岛 | H5: 产品说明
B6: 亚马逊仓库地址（低于50KG 需+2/KG） | D6: 包税 50KG+ | E6: 不包税 1CBM+ | F6: 包税 50KG+ | G6: 不包税 1CBM+ | H6: 航程 (开船后) | I6: 参考时效 (开船后) | J6: 时效赔付 | K6: 备注 | L6: 涨价幅度
B7: 正常派送区 | C7: TEB4、TEB3、TEB6、TEB9、XEW5、ABE8、ABE4 | D7: 15 | E7: 2345 | F7: 15.2 | G7: 2375 | H7: 17-18 | I7: 21-22 | J7: 23天 | K7: 【含税】渠道： 1、含关税和查验费； 2、体积/6000，不分泡 3、单件最低消费5KG，渠道单票低消21KG,21-49KG单价+2/KG： 【不含税】渠道： 1、不含关税，查验费和查验产生的其他费用； 2、体积/1000000，不分泡，单件最低消费5KG，单票低消1CBM 3.重货按每363KG=1CBM (产品附加费/特殊附加费等详见发货必读) 包税渠道重货优惠 1:200= -0.3/KG 1:240= -0.6/KG 1:280= -0.9/KG 1:320= -1.2/KG 1:360= -1.5/KG 1:420= -1.8/KG 1:480= -2.1/KG 1:500= -2.5/KG（封顶） | L7: 0.1 | M7: 15
C8: SWF2、AVP1、ILG1、MDT1 | D8: 15.2 | E8: 2375 | F8: 15.4 | G8: 2405 | H8: 17-18 | I8: 21-22 | J8: 23天
C9: ALB1、XLX1、MDT4 | D9: 16.2 | E9: 2575 | F9: 16.4 | G9: 2605 | H9: 17-18 | I9: 23-24 | J9: 25天
C10: RMN3 | D10: 16.8 | E10: 2665 | F10: 17 | G10: 2695 | H10: 17-18 | I10: 23-24 | J10: 25天
C11: ORF2、XLX6 | D11: 16.9 | E11: 2680 | F11: 17.1 | G11: 2710 | H11: 17-18 | I11: 23-24 | J11: 25天
C12: EWR5、EWR4、EWR6、EWR7、EWR9 | D12: 15 | E12: 2345 | F12: 15.2 | G12: 2375 | H12: 17-18 | I12: 21-22 | J12: /
C13: ACY2、TTN2、LGA9、ACY1、JFK8、JFK2 | D13: 15 | E13: 2345 | F13: 15.2 | G13: 2375 | H13: 17-18 | I13: 21-22 | J13: /
C14: ABE3、ABE5、ABE2 | D14: 15.1 | E14: 2360 | F14: 15.3 | G14: 2390 | H14: 17-18 | I14: 21-22 | J14: /
C15: AVP9、AVP3 | D15: 15.2 | E15: 2375 | F15: 15.4 | G15: 2405 | H15: 17-18 | I15: 21-22 | J15: /
C16: PHL4、PHL5、PHL6、RDG1、MDT2 | D16: 15.2 | E16: 2375 | F16: 15.4 | G16: 2405 | H16: 17-18 | I16: 23-24 | J16: /
C17: HIA1、DCA6、DCA1 | D17: 16 | E17: 2545 | F17: 16.2 | G17: 2575 | H17: 17-18 | I17: 23-24 | J17: /
C18: PHL3、PHL7、PHL1、SWF1 | D18: 15.2 | E18: 2375 | F18: 15.4 | G18: 2405 | H18: 17-18 | I18: 23-24 | J18: /
C19: HGR6、HGR2 | D19: 16.2 | E19: 2575 | F19: 16.4 | G19: 2605 | H19: 17-18 | I19: 23-24 | J19: /
... C25: CLT3、CLT4、CLT2、CLT6、DET1、DET2、TOL3 | D25: 16.9 | E25: 2680 | F25: 17.1 | G25: 2710 | H25: 17-18 | I25: 23-24 | J25: /
B26: 其他 | C26: 纽约自提（出仓费15USD/板） | D26: 14.8 | E26: 2315 | F26: 15 | G26: 2345 | H26: 17-18 | I26: 21-22 | J26: /
B27: 下单渠道 | D27: 美森美东秒送 | E27: 美森美东秒送-BB | F27: 美森美东秒送 | G27: 美森美东秒送-BB
D28: CLX-GEX服务
B29: 赔付说明 | D29: 1.5RMB/KG起赔，+0.5RMB/KG递增，赔付上限3.5RMB/KG

Sheet OA-拆送 
B2: 美 琦 国 际 货 运 代 理（深圳）有 限 公 司 地址：深圳市龙岗区坂田街道坂雪岗大道4088号奥博中心6楼A609-611
B4: OA-拆送（OA联盟）
D5: 深圳/中山/广州/义乌/苏州/汕头/厦门 | F5: 青岛 | L5: 返回目录
B6: 亚马逊仓库地址 | D6: 21KG+ （包税） | E6: 1CBM+ （不包税） | F6: 21KG+ （包税） | G6: 1CBM+ （不包税） | H6: 航程 | I6: 派送时效 | J6: 报关条件 | K6: 包税渠道重货优惠 1 :200 =-0.3/KG 1:240= -0.6/KG 1:280= -0.9/KG 1:320 =-1.2/KG 1:360= -1.5/KG 1:420 = -1.8/KG 1:480=- 2.1/KG 1:500=-2.5/KG (封顶) 1、包税渠道含关税和查验费； 2、体积/6000； 3、不分泡 4、不包税渠道不含关税和查验费；如查验按照68CBM分摊查验费 8、体积/6000； 6、不分泡，最低消费1个方 ，不足1个方按照1个方算 10、1CBM=363KG (产品附加费/特殊附加费等详见发货必读) | L6: 涨价幅度
B7: 热门仓 | C7: ONT8、LGB8、SBD1、LAX9 | D7: 6.8 | E7: 980 | F7: 7 | G7: 1010 | H7: 14-16 | I7: 24-26 | J7: 该区域内可合并报关 | L7: 0.8 | M7: 120
C8: POC1、POC2、POC3 | D8: 6.8 | E8: 980 | F8: 7 | G8: 1010 | H8: 14-16 | I8: 24-26
C9: IUSJ、IUSP、IUSQ | D9: 7.4 | E9: 1070 | F9: 7.6 | G9: 1100 | H9: 14-16 | I9: 24-28
C10: SBD2、SNA4、LGB6、LGB9、LGB4、XLX7、IUSI、IUSW、IUTI | D10: 7.4 | E10: 1070 | F10: 7.6 | G10: 1100 | H10: 14-16 | I10: 24-28
C11: LAS1、VGT2、GYR2、GYR3、LAS6、IUTE | D11: 7.5 | E11: 1085 | F11: 7.7 | G11: 1115 | H11: 14-16 | I11: 24-28
C12: SMF3、SCK4、HLI2、PSP3 | D12: 7.9 | E12: 1130 | F12: =D12+0.2 -> 8.1 | G12: =E12+30 -> 1160 | H12: 14-16 | I12: 24-26
C13: GEU2、GEU3、MIT2、TCY1、TCY2 | D13: 7.9 | E13: 1130 | F13: =D13+0.2 -> 8.1 | G13: =E13+30 -> 1160 | H13: 14-16 | I13: 24-28
C14: SCK1、SCK3、SCK8、OAK3、SJC7、SMF6、QZZ7 | D14: 8.1 | E14: 1160 | F14: =D14+0.2 -> 8.3 | G14: =E14+30 -> 1190 | H14: 14-16 | I14: 26-32
C15: FAT2、QXY8、MCC1、MCE1 | D15: 8.1 | E15: 1160 | F15: =D15+0.2 -> 8.3 | G15: =E15+30 -> 1190 | H15: 14-16 | I15: 26-32
C16: ABQ2 | D16: 8.8 | E16: 1280 | F16: =D16+0.2 -> 9 | G16: =E16+30 -> 1310 | H16: 14-16 | I16: 26-32
C17: PSC2 | D17: 9.2 | E17: 1340 | F17: 9.4 | G17: 1370 | H17: 14-16 | I17: 26-32 | L17: 0.4 | M17: 60
C18: MDW2、IND9、MQJ1、MEM1、FWA4 | D18: 9.9 | E18: 1445 | F18: 10.1 | G18: 1475 | H18: 14-16 | I18: 26-32 | J18: 该区域内可合并报关
C19: PBI3、BNA6 | D19: 10.4 | E19: 1520 | F19: 10.6 | G19: 1550 | H19: 14-16 | I19: 26-32
B20: 海外仓 | C20: 仓库自提（出仓费15USD/板） | D20: 6.6 | E20: 950 | F20: 6.8 | G20: 980 | H20: 14-16 | I20: 24-26
C21: 亚马逊仓库地址（以下地址 不足50KG 需+2） | D21: 50KG+ （包税） | E21: 1CBM+ （不包税） | F21: 50KG+ （包税） | G21: 1CBM+ （不包税） | H21: 航程 | I21: 派送时效
B22: 外州 | C22: PHX5、PHX6、PHX7、AZA4、RNO4 | D22: 8.5 | E22: 1235 | F22: 8.7 | G22: 1265 | H22: 14-16 | I22: 26-30 | J22: 该区域内可合并报关
C23: BFI3、PDX7、GEG2 | D23: 10.1 | E23: 1475 | F23: 10.3 | G23: 1505 | H23: 14-16 | I23: 27-33
C24: SLC2、DEN2、DEN8 | D24: 10.1 | E24: 1475 | F24: 10.3 | G24: 1505 | H24: 14-16 | I24: 27-33
C25: HOU8、SAT1、SAT4、OKC2、FTW1、IAH3 | D25: 10.2 | E25: 1490 | F25: 10.4 | G25: 1520 | H25: 14-16 | I25: 27-33
C26: 万邑通（USKY3、USKY5、USTX） | D26: 10.2 | E26: 1490 | F26: 10.4 | G26: 1520 | H26: 14-16 | I26: 27-33
C27: CLT2、CLT3 、RDU2、MGE3、GSO1、JAX3、CHA1、CHA2、TOL3 | D27: 11 | E27: 1610 | F27: =D27+0.2 -> 11.2 | G27: =E27+30 -> 1640 | H27: 14-16 | I27: 30-36 | J27: 该区域内可合并报关 | L27: 新增仓点
C28: ABE8、 ABE4、TEB6、TEB9、TEB4、AVP1、SWF2、PHL4 | D28: 11.1 | E28: 1625 | F28: =D28+0.2 -> 11.3 | G28: =E28+30 -> 1655 | H28: 14-16 | I28: 33-39 | L28: 新增仓点
B29: 沃尔玛 | C29: WM-LAX1、WM-LAX2、WM-LAX2N | D29: 8.1 | E29: 1175 | F29: 8.3 | G29: 1205 | H29: 14-16 | I29: 26-30
B30: 下单渠道 | D30: OA-拆送 | E30: OA-拆送-BB | F30: OA-拆送 | G30: OA-拆送-BB
B31: 预配船公司 | D31: OA联盟
B32: 注意事项 | D32: 可接受单件超22.5KG 单边超63CM 货件。 扣货费200USD/票。 （注：PSC2，BFI3,PDX7,GEG2目的港-西雅图）

Sheet OA-直送
B2: 美 琦 国 际 货 运 代 理（深圳）有 限 公 司 地址：深圳市龙岗区坂田街道坂雪岗大道4088号奥博中心6楼A609-611
B4: OA-直送包税（OA联盟）
D5: 深圳/中山/广州/义乌/苏州/汕头/厦门 | F5: 青岛 | N5: 返回目录
B6: 亚马逊仓库地址 | D6: 21KG+（包税） | E6: 1CBM+（不包税） | F6: 21KG+（包税） | G6: 1CBM+（不包税） | H6: 航程 | I6: 整体时效 | J6: 目的港口 | K6: 备注 | L6: 涨价幅度
C7: ONT8，LGB8，SBD1，LAX9 | D7: 6.6 | E7: 935 | F7: 6.8 | G7: 965 | H7: 14-16 | I7: 24-26 | J7: LA | K7: 包税渠道重货优惠 1 :200 =-0.3/KG 1:240= -0.6/KG 1:280= -0.9/KG 1:320 =-1.2/KG 1:360= -1.5/KG 1:420 = -1.8/KG 1:480=- 2.1/KG 1:500=-2.5/KG （封顶） 1、包税渠道含关税和查验费； 2、体积/6000； 3、不分泡 4、不包税渠道不含关税和查验费；如查验按照68CBM分摊查验费 8、体积/6000； 6、不分泡，最低消费1个方 ，不足1个方按照1个方算 10、1CBM=363KG (产品附加费/特殊附加费等详见发货必读) | L7: 0.8 | M7: 120
C8: POC1，POC2，POC3 | D8: 6.6 | E8: 935 | F8: 6.8 | G8: 965 | H8: 14-16 | I8: 24-26
C9: SMF3、SCK4 | D9: 7.5 | E9: 1070 | F9: 7.7 | G9: 1100 | H9: 16-19 | I9: 28-30
C10: SCK8，TCY1，TCY2 | D10: 7.6 | E10: 1085 | F10: 7.8 | G10: 1115 | H10: 14-16 | I10: 28-30
C11: PSP3 | D11: 7.3 | E11: 1040 | F11: 7.5 | G11: 1070 | H11: 16-19 | I11: 28-30
C12: MIT2 | D12: 7.3 | E12: 1040 | F12: 7.5 | G12: 1070 | H12: 14-16 | I12: 24-26
C13: LAS1,VGT2,GYR2,GYR3 | D13: 7.3 | E13: 1040 | F13: 7.5 | G13: 1070 | H13: 14-16 | I13: 24-26
C14: GEU3 ，GEU2 | D14: 7.3 | E14: 1040 | F14: 7.5 | G14: 1070 | H14: 14-16 | I14: 24-26
C15: ABQ2 | D15: 8.7 | E15: 1250 | F15: =D15+0.2 -> 8.9 | G15: =E15+30 -> 1280 | H15: 14-16 | I15: 28-32
C16: PSC2 | D16: 9.1 | E16: 1310 | F16: =D16+0.2 -> 9.3 | G16: =E16+30 -> 1340 | H16: 14-16 | I16: 28-32 | L16: 0.4 | M16: 60
C17: 下单渠道 | D17: OA-直送 | E17: OA-直送-BB | F17: OA-直送 | G17: OA-直送-BB
B18: 美东直送
C19: ABE8,TEB9 | D19: 7.5 | E19: 1070 | F19: 7.7 | G19: 1100 | H19: 28-35 | I19: 35-45 | J19: 美东
C20: AVP1 | D20: 7.6 | E20: 1085 | F20: 7.8 | G20: 1115 | H20: 28-35 | I20: 35-45
C21: 下单渠道 | D21: OA-美东直送 | E21: OA-美东直送-BB | F21: OA-美东直送 | G21: OA-美东直送-BB
B22: 预配船公司 | D22: OA联盟
B23: 注意事项 | D23: 不接受单件超22.5/KG 最长边超80CM货件 扣货费1200USD/票 请谨慎扣货

Sheet 商业|私人地址
A2: 美 琦 国 际 货 运 代 理（深圳）有 限 公 司 地址：深圳市龙岗区坂田街道坂雪岗大道4088号奥博中心6楼A609-611
B4: 深圳/中山/广州/汕头/厦门 | J4: 义乌/苏州 | P4: 青岛 | W4: 备注
A5: 美西 （90、91、92邮编） | B5: 渠道 | D5: 300KG+ （包税） | E5: 1.5CBM+ （不包税） | F5: 500KG+ （包税） | G5: 2CBM+ （不包税） | H5: 1500KG+ （包税） | I5: 6CBM+ （不包税） | J5: 300KG+ （包税） | K5: 1.5CBM+ （不包税） | L5: 500KG+ （包税） | M5: 2CBM+ （不包税） | N5: 1500KG+ （包税） | O5: 6CBM+ （不包税） | P5: 300KG+ （包税） | Q5: 1.5CBM+ （不包税） | R5: 500KG+ （包税） | S5: 2CBM+ （不包税） | T5: 1500KG+ （包税） | U5: 6CBM+ （不包税） | V5: 参考时效 （开船后） | W5: 重货优惠 1 :200 =-0.3/KG 1:240= -0.6/KG 1:280= -0.9/KG 1:320 =-1.2/KG 1:360= -1.5/KG 1:420 = -1.8/KG 1:480=- 2.1/KG 1:500=-2.5/KG （封顶） 1、包税渠道含关税和查验费； 2、体积/6000； 3、不分泡 4、不包税渠道不含关税和查验费；如查验按照68CBM分摊查验费 5、体积/6000； 6、不分泡，最低消费1个方 ，不足1个方按照1个方算 7、1CBM=363KG (产品附加费/特殊附加费等详见发货必读) | X5: 涨价幅度
B6: Match12 （500KG起） | D6: / | E6: / | F6: 11.5 | G6: 1625 | H6: 11.2 | I6: 1580 | J6: / | K6: / | L6: 11 | M6: 1550 | N6: 10.7 | O6: 1505 | P6: / | Q6: / | R6: 11.7 | S6: 1655 | T6: 11.4 | U6: 1610 | V6: 13-15 | X6: 0.1 | Y6: 15
B7: Match15 （500KG起） | D7: / | E7: / | F7: 9.1 | G7: 1255 | H7: 8.7 | I7: 1195 | J7: / | K7: / | L7: 9.1 | M7: 1255 | N7: 8.7 | O7: 1195 | P7: / | Q7: / | R7: 9.3 | S7: 1285 | T7: 8.9 | U7: 1225 | V7: 15-17 | X7: 0.5 | Y7: 75
B8: Match20 （500KG起） | D8: / | E8: / | F8: 8 | G8: 1160 | H8: 7.8 | I8: 1130 | J8: 8.5 | K8: 1235 | L8: 8 | M8: 1160 | N8: 7.8 | O8: 1130 | P8: 8.7 | Q8: 1265 | R8: 8.2 | S8: 1190 | T8: 8 | U8: 1160 | V8: 19-21 | X8: 0.8 | Y8: 120
B9: OA-拆送 （300KG起） | D9: 7.8 | E9: 1130 | F9: 7.3 | G9: 1055 | H9: 7.1 | I9: 1025 | J9: 7.8 | K9: 1130 | L9: 7.3 | M9: 1055 | N9: 7.1 | O9: 1025 | P9: 8 | Q9: 1160 | R9: 7.5 | S9: 1085 | T9: 7.3 | U9: 1055 | V9: 24-26 | X9: 0.8 | Y9: 120
A11: 美东 （07、08邮编） | B11: 美东普快专线 07邮编（500KG起） | D11: / | E11: / | F11: 9.5 | G11: 1380 | H11: 9.1 | I11: 1320 | J11: / | K11: / | L11: 9.5 | M11: 1380 | N11: 9.1 | O11: 1320 | P11: / | Q11: / | R11: 9.7 | S11: 1410 | T11: 9.3 | U11: 1350 | V11: 40-45 | X11: 0.8 | Y11: 120
B12: 美东普快专线 08邮编（500KG起） | D12: / | E12: / | F12: 8.5 | G12: 1230 | H12: 8.1 | I12: 1170 | J12: / | K12: / | L12: 8.5 | M12: 1230 | N12: 8.1 | O12: 1170 | P12: / | Q12: / | R12: 8.7 | S12: 1260 | T12: 8.3 | U12: 1200 | V12: 40-45 | X12: 0.8 | Y12: 120
B13: 美东极速快车 07邮编（500KG起） | D13: / | E13: / | F13: 15.4 | G13: 1755 | H13: 15 | I13: 1695 | J13: / | K13: / | L13: 15.4 | M13: 1755 | N13: 15 | O13: 1695 | P13: / | Q13: / | R13: 15.6 | S13: 1785 | T13: 15.2 | U13: 1725 | V13: 30-32 | X13: 2.3 | Y13: 345
B14: 美东极速快车 08邮编（500KG起） | D14: / | E14: / | F14: 14.4 | G14: 1605 | H14: 14 | I14: 1545 | J14: / | K14: / | L14: 14.4 | M14: 1605 | N14: 14 | O14: 1545 | P14: / | Q14: / | R14: 14.6 | S14: 1635 | T14: 14.2 | U14: 1575 | V14: 30-32 | X14: 2.3 | Y14: 345
B15: 美森美东秒送 07邮编（500KG起） | D15: / | E15: / | F15: 17.7 | G15: 2800 | H15: 17.3 | I15: 2740 | J15: / | K15: / | L15: 17.2 | M15: 2725 | N15: 16.8 | O15: 2665 | P15: / | Q15: / | R15: 17.9 | S15: 2830 | T15: 17.5 | U15: 2770 | V15: 21-22 | X15: 0.1 | Y15: 15
B16: 美森美东秒送 08邮编（500KG起） | D16: / | E16: / | F16: 16.7 | G16: 2650 | H16: 16.3 | I16: 2540 | J16: / | K16: / | L16: 16.2 | M16: 2575 | N16: 15.8 | O16: 2465 | P16: / | Q16: / | R16: 16.9 | S16: 2680 | T16: 16.5 | U16: 2570 | V16: 21-22 | X16: 0.1 | Y16: 15
A18: 芝加哥 （60邮编） | B18: 芝加哥海铁快车 （500KG起） | D18: / | E18: / | F18: 10.6 | G18: 1535 | H18: 10.2 | I18: 1475 | J18: / | K18: / | L18: 10.6 | M18: 1535 | N18: 10.2 | O18: 1475 | P18: / | Q18: / | R18: 10.8 | S18: 1565 | T18: 10.4 | U18: 1505 | V18: 38-45 | X18: 0.6 | Y18: 90
B19: 芝加哥海铁联运 （500KG起） | D19: / | E19: / | F19: 9.4 | G19: 1355 | H19: 9 | I19: 1295 | J19: / | K19: / | L19: 9.4 | M19: 1355 | N19: 9 | O19: 1295 | P19: / | Q19: / | R19: 9.6 | S19: 1385 | T19: 9.2 | U19: 1325 | V19: 38-45 | X19: 0.8 | Y19: 120
D20: 备注 | E20: ----------------------不满低消，按照低消金额计算！-----------------------
